Workbook

Sheet EYLÜL 2025 (2)
B1: EYLÜL | Q1: 45705
A2: S.NO | B2: STOK ADI | F2: DEVİR MİK | H2: BİRİM | I2: GİRİŞ | J2: 45905 | K2: 45912 | L2: 45919 | M2: 45926 | N2: 45930 | O2: KALAN | P2: MİNİMUN | Q2: MAKSİMUN
A3: 1 | B3: AMORTİSÖR 80 LİK KROM | F3: 690 | H3: Adet | I3: 1000 | J3: 240 | K3: 0 | L3: 170 | M3: 140 | N3: 670 | O3: =+F3+I3-J3-K3-L3-M3-N3 -> 470 | P3: 500 | Q3: 3000
A4: 2 | B4: AMORTİSÖR 3 KLAS 100 LÜK KROM | F4: 1700 | H4: Adet | I4: 0 | J4: 140 | K4: 440 | L4: 180 | M4: 40 | N4: 0 | O4: =+F4+I4-J4-K4-L4-M4-N4 -> 900 | P4: 500 | Q4: 3000
A5: 3 | B5: ZZ.AMORTİSÖR 80 LİK 3 KLASS | F5: 0 | H5: Adet | I5: 0 | J5: 0 | K5: 0 | L5: 0 | M5: 0 | N5: 0 | O5: =+F5+I5-J5-K5-L5-M5-N5 -> 0 | P5: 500 | Q5: 3000
A6: 4 | B6: 260 LIK AMORTİSÖR | F6: 286 | H6: Adet | I6: 0 | J6: 6 | K6: 15 | L6: 5 | M6: 0 | N6: 0 | O6: =+F6+I6-J6-K6-L6-M6-N6 -> 260 | P6: 50 | Q6: 200
A7: 5 | B7: AMORTİSÖR 120 LİK 3 CLASS | F7: 320 | H7: Adet | I7: 500 | J7: 0 | K7: 0 | L7: 0 | M7: 100 | N7: 160 | O7: =+F7+I7-J7-K7-L7-M7-N7 -> 560 | P7: 500 | Q7: 3000
A8: 6 | B8: KONUM KORUYUCU D 26 KISA | F8: 340 | H8: Adet | I8: 1000 | J8: 320 | K8: 0 | L8: 0 | M8: 0 | N8: 0 | O8: =+F8+I8-J8-K8-L8-M8-N8 -> 1020 | P8: 200 | Q8: 1000
A9: 7 | B9: 100 LÜK KROM AMORTİSÖR 4 CLASS | F9: 800 | H9: Adet | I9: 0 | J9: 0 | K9: 0 | L9: 0 | M9: 0 | N9: 0 | O9: =+F9+I9-J9-K9-L9-M9-N9 -> 800 | P9: 300 | Q9: 3000
A10: 8 | B10: 100 LÜK AMORTİSÖR 3 CLASS | F10: 15 | H10: Adet | I10: 1000 | J10: 0 | K10: 0 | L10: 0 | M10: 0 | N10: 140 | O10: =+F10+I10-J10-K10-L10-M10-N10 -> 875 | P10: 1000 | Q10: 5000
A11: 9 | B11: AMORTİSÖRÜ 200 LÜK SİYAH | F11: 72 | H11: Adet | I11: 500 | J11: 0 | K11: 0 | L11: 0 | M11: 0 | N11: 0 | O11: =+F11+I11-J11-K11-L11-M11-N11 -> 572 | P11: 200 | Q11: 2000 | R11: *
A12: 10 | B12: AMORTİSÖR 60 LIK 3 CLASS | F12: 2109 | H12: Adet | I12: 0 | J12: 0 | K12: 0 | L12: 0 | M12: 0 | N12: 0 | O12: =+F12+I12-J12-K12-L12-M12-N12 -> 2109 | P12: 200 | Q12: 1000
A13: 11 | B13: 140 LIK AMORTİSÖR 3 KLASS | F13: 230 | H13: Adet | I13: 359 | J13: 150 | K13: 0 | L13: 75 | M13: 0 | N13: 0 | O13: =+F13+I13-J13-K13-L13-M13-N13 -> 364 | P13: 100 | Q13: 500
A14: 12 | F14: 0 | I14: 0 | J14: 0 | K14: 0 | L14: 0 | M14: 0 | N14: 0 | O14: =+F14+I14-J14-K14-L14-M14-N14 -> 0 | P14: 0 | Q14: 0
A15: 13 | F15: 0 | I15: 0 | J15: 0 | K15: 0 | L15: 0 | M15: 0 | N15: 0 | O15: =+F15+I15-J15-K15-L15-M15-N15 -> 0 | P15: 0 | Q15: 0

Sheet 1 HAFTA
I2: 1 | J2: 2 | K2: 3 | L2: 4 | M2: 5
A3: STOK ADI | E3: MİKTAR | G3: BİRİM | H3: GİRİŞ | I3: 44803 | J3: 44804 | K3: 44805 | L3: 44806 | N3: KALAN
A4: ZZ.AMORTİSÖR 100 LÜK | E4: 674 | G4: Adet | H4: 0 | I4: 64 | J4: 28 | K4: 40 | L4: 20 | M4: 0 | N4: =+E4+H4-I4-J4-K4-L4-M4 -> 522
A5: ZZ.AMORTİSÖR 120 LÜK | E5: 2821 | G5: Adet | I5: 55 | N5: =+E5+H5-I5-J5-K5-L5-M5 -> 2766
A6: ZZ.AMORTİSÖR 80 LİK | E6: 4165 | G6: Adet | N6: =+E6+H6-I6-J6-K6-L6-M6 -> 4165
A7: ZZ.AMORTİSÖR 140 LIK | E7: 94 | G7: Adet | I7: 35 | N7: =+E7+H7-I7-J7-K7-L7-M7 -> 59
A8: AMORTİSÖR 120 LİK CROM 3 CLASS | E8: 20 | G8: Adet | N8: =+E8+H8-I8-J8-K8-L8-M8 -> 20
A9: KONUM KORUYUCU D 26 KISA | E9: 300 | G9: Adet | K9: 20 | N9: =+E9+H9-I9-J9-K9-L9-M9 -> 280
A10: 100 LÜK KROM AMORTİSÖR 4 CLASS | E10: 1020 | G10: Adet | N10: =+E10+H10-I10-J10-K10-L10-M10 -> 1020
A11: 100 LÜK KROM AMORTİSÖR 3 CLASS | E11: 371 | G11: Adet | N11: =+E11+H11-I11-J11-K11-L11-M11 -> 371
A12: AMORTİSÖR 100 LÜK 3 CLASS | E12: 576 | G12: Adet | N12: =+E12+H12-I12-J12-K12-L12-M12 -> 576
A13: AMORTİSÖRÜ 200 LÜK | E13: 39 | G13: Adet | I13: 2 | N13: =+E13+H13-I13-J13-K13-L13-M13 -> 37
A14: AMORTİSÖR 120 LİK CROM 4 CLASS | E14: 50 | G14: Adet | N14: =+E14+H14-I14-J14-K14-L14-M14 -> 50
A15: AMORTİSÖR 140 LIK CROM | E15: 80 | G15: Adet | N15: =+E15+H15-I15-J15-K15-L15-M15 -> 80
N16: =+E16+H16-I16-J16-K16-L16-M16 -> 0

Sheet eylül 4 HAFTA
A2: STOK ADI | E2: DEVİR MİK | G2: BİRİM | H2: GİRİŞ | I2: 44830 | J2: 44831 | K2: 44832 | L2: 44833 | M2: 44834 | N2: KALAN | O2: MİNİMUN | P2: MAKSİ
A3: ZZ.AMORTİSÖR 100 LÜK | E3: 4811 | G3: Adet | H3: 0 | I3: 0 | J3: 20 | K3: 80 | L3: 0 | M3: 0 | N3: =+E3+H3-I3-J3-K3-L3-M3 -> 4711 | O3: 750 | P3: 5000
A4: ZZ.AMORTİSÖR 120 LÜK | E4: 2541 | G4: Adet | H4: 0 | I4: 0 | J4: 0 | K4: 0 | L4: 0 | M4: 0 | N4: =+E4+H4-I4-J4-K4-L4-M4 -> 2541 | O4: 500 | P4: 3000
A5: ZZ.AMORTİSÖR 80 LİK | E5: 4165 | G5: Adet | H5: 0 | I5: 0 | J5: 4 | K5: 0 | L5: 0 | M5: 0 | N5: =+E5+H5-I5-J5-K5-L5-M5 -> 4161 | O5: 300 | P5: 3000
A6: ZZ.AMORTİSÖR 140 LIK | E6: 800 | G6: Adet | H6: 0 | I6: 0 | J6: 0 | K6: 20 | L6: 0 | M6: 0 | N6: =+E6+H6-I6-J6-K6-L6-M6 -> 780 | O6: 200 | P6: 2000
A7: AMORTİSÖR 120 LİK CROM 3 CLASS | E7: 20 | G7: Adet | H7: 0 | I7: 0 | J7: 0 | K7: 0 | L7: 0 | M7: 0 | N7: =+E7+H7-I7-J7-K7-L7-M7 -> 20
A8: KONUM KORUYUCU D 26 KISA | E8: 260 | G8: Adet | H8: 0 | I8: 0 | J8: 0 | K8: 20 | L8: 0 | M8: 0 | N8: =+E8+H8-I8-J8-K8-L8-M8 -> 240
A9: 100 LÜK KROM AMORTİSÖR 4 CLASS | E9: 1020 | G9: Adet | H9: 0 | I9: 0 | J9: 0 | K9: 0 | L9: 0 | M9: 0 | N9: =+E9+H9-I9-J9-K9-L9-M9 -> 1020
A10: 100 LÜK KROM AMORTİSÖR 3 CLASS | E10: 371 | G10: Adet | H10: 0 | I10: 0 | J10: 0 | K10: 0 | L10: 0 | M10: 0 | N10: =+E10+H10-I10-J10-K10-L10-M10 -> 371
A11: AMORTİSÖR 100 LÜK 3 CLASS | E11: 576 | G11: Adet | H11: 0 | I11: 0 | J11: 0 | K11: 0 | L11: 0 | M11: 0 | N11: =+E11+H11-I11-J11-K11-L11-M11 -> 576
A12: AMORTİSÖRÜ 200 LÜK | E12: 150 | G12: Adet | H12: 50 | I12: 0 | J12: 100 | K12: 50 | L12: 0 | M12: 0 | N12: =+E12+H12-I12-J12-K12-L12-M12 -> 50 | O12: 150 | P12: 2000
A13: AMORTİSÖR 120 LİK CROM 4 CLASS | E13: 50 | G13: Adet | H13: 0 | I13: 0 | J13: 0 | K13: 0 | L13: 0 | M13: 0 | N13: =+E13+H13-I13-J13-K13-L13-M13 -> 50
E14: 0 | H14: 0 | I14: 0 | J14: 0 | K14: 0 | L14: 0 | M14: 0 | N14: =+E14+H14-I14-J14-K14-L14-M14 -> 0
H15: 0 | I15: 0 | J15: 0 | K15: 0 | L15: 0 | M15: 0 | N15: =+E15+H15-I15-J15-K15-L15-M15 -> 0
I16: =SUM(I3:I15) -> 0 | J16: =SUM(J3:J15) -> 124 | K16: =SUM(K3:K15) -> 170

Sheet ekim 1 hafta
A2: STOK ADI | E2: DEVİR MİK | G2: BİRİM | H2: GİRİŞ | I2: 44837 | J2: 44838 | K2: 44839 | L2: 44840 | M2: 44841 | N2: KALAN | O2: MİNİMUN | P2: MAKSİ
A3: ZZ.AMORTİSÖR 100 LÜK | E3: 4711 | G3: Adet | H3: 0 | I3: 0 | J3: 20 | K3: 200 | L3: 4 | M3: 20 | N3: =+E3+H3-I3-J3-K3-L3-M3 -> 4467 | O3: 750 | P3: 5000
A4: ZZ.AMORTİSÖR 120 LÜK | E4: 2541 | G4: Adet | H4: 0 | I4: 0 | J4: 0 | K4: 0 | L4: 0 | M4: 0 | N4: =+E4+H4-I4-J4-K4-L4-M4 -> 2541 | O4: 500 | P4: 3000
A5: ZZ.AMORTİSÖR 80 LİK | E5: 4161 | G5: Adet | H5: 0 | I5: 0 | J5: 0 | K5: 0 | L5: 0 | M5: 0 | N5: =+E5+H5-I5-J5-K5-L5-M5 -> 4161 | O5: 300 | P5: 3000
A6: ZZ.AMORTİSÖR 140 LIK | E6: 780 | G6: Adet | H6: 0 | I6: 0 | J6: 0 | K6: 120 | L6: 0 | M6: 220 | N6: =+E6+H6-I6-J6-K6-L6-M6 -> 440 | O6: 200 | P6: 2000
A7: AMORTİSÖR 120 LİK CROM 3 CLASS | E7: 20 | G7: Adet | H7: 0 | I7: 0 | J7: 0 | K7: 0 | L7: 0 | M7: 0 | N7: =+E7+H7-I7-J7-K7-L7-M7 -> 20
A8: KONUM KORUYUCU D 26 KISA | E8: 240 | G8: Adet | H8: 0 | I8: 0 | J8: 0 | K8: 0 | L8: 0 | M8: 0 | N8: =+E8+H8-I8-J8-K8-L8-M8 -> 240
A9: 100 LÜK KROM AMORTİSÖR 4 CLASS | E9: 1020 | G9: Adet | H9: 0 | I9: 0 | J9: 0 | K9: 0 | L9: 0 | M9: 0 | N9: =+E9+H9-I9-J9-K9-L9-M9 -> 1020
A10: 100 LÜK KROM AMORTİSÖR 3 CLASS | E10: 371 | G10: Adet | H10: 0 | I10: 0 | J10: 0 | K10: 0 | L10: 0 | M10: 0 | N10: =+E10+H10-I10-J10-K10-L10-M10 -> 371
A11: AMORTİSÖR 100 LÜK 3 CLASS | E11: 576 | G11: Adet | H11: 0 | I11: 0 | J11: 0 | K11: 0 | L11: 0 | M11: 0 | N11: =+E11+H11-I11-J11-K11-L11-M11 -> 576
A12: AMORTİSÖRÜ 200 LÜK | E12: 50 | G12: Adet | H12: 0 | I12: 0 | J12: 0 | K12: 0 | L12: 0 | M12: 0 | N12: =+E12+H12-I12-J12-K12-L12-M12 -> 50 | O12: 150 | P12: 2000
A13: AMORTİSÖR 120 LİK CROM 4 CLASS | E13: 50 | G13: Adet | H13: 0 | I13: 0 | J13: 0 | K13: 0 | L13: 0 | M13: 0 | N13: =+E13+H13-I13-J13-K13-L13-M13 -> 50
E14: 0 | H14: 0 | I14: 0 | J14: 0 | K14: 0 | L14: 0 | M14: 0 | N14: =+E14+H14-I14-J14-K14-L14-M14 -> 0
H15: 0 | I15: 0 | J15: 0 | K15: 0 | L15: 0 | M15: 0 | N15: =+E15+H15-I15-J15-K15-L15-M15 -> 0
I16: =SUM(I3:I15) -> 0 | J16: =SUM(J3:J15) -> 20 | K16: =SUM(K3:K15) -> 320 | L16: =SUM(L3:L15) -> 4 | M16: =SUM(M3:M15) -> 240

Sheet ekim 2 hafta 
A2: STOK ADI | E2: DEVİR MİK | G2: BİRİM | H2: GİRİŞ | I2: 44844 | J2: 44845 | K2: 44846 | L2: 44847 | M2: 44848 | N2: KALAN | O2: MİNİMUN | P2: MAKSİ
A3: ZZ.AMORTİSÖR 100 LÜK | E3: 4467 | G3: Adet | H3: 0 | I3: 200 | J3: 0 | K3: 0 | L3: 40 | M3: 100 | N3: =+E3+H3-I3-J3-K3-L3-M3 -> 4127 | O3: 750 | P3: 5000
A4: ZZ.AMORTİSÖR 120 LÜK | E4: 2541 | G4: Adet | H4: 0 | I4: 0 | J4: 0 | K4: 0 | L4: 0 | M4: 0 | N4: =+E4+H4-I4-J4-K4-L4-M4 -> 2541 | O4: 500 | P4: 3000
A5: ZZ.AMORTİSÖR 80 LİK | E5: 4161 | G5: Adet | H5: 0 | I5: 0 | J5: 0 | K5: 2 | L5: 0 | M5: 0 | N5: =+E5+H5-I5-J5-K5-L5-M5 -> 4159 | O5: 300 | P5: 3000
A6: ZZ.AMORTİSÖR 140 LIK | E6: 440 | G6: Adet | H6: 0 | I6: 0 | J6: 0 | K6: 0 | L6: 0 | M6: 0 | N6: =+E6+H6-I6-J6-K6-L6-M6 -> 440 | O6: 200 | P6: 2000
A7: AMORTİSÖR 120 LİK CROM 3 CLASS | E7: 20 | G7: Adet | H7: 0 | I7: 0 | J7: 0 | K7: 0 | L7: 0 | M7: 0 | N7: =+E7+H7-I7-J7-K7-L7-M7 -> 20
A8: KONUM KORUYUCU D 26 KISA | E8: 240 | G8: Adet | H8: 0 | I8: 0 | J8: 0 | K8: 20 | L8: 60 | M8: 0 | N8: =+E8+H8-I8-J8-K8-L8-M8 -> 160
A9: 100 LÜK KROM AMORTİSÖR 4 CLASS | E9: 1020 | G9: Adet | H9: 0 | I9: 0 | J9: 0 | K9: 0 | L9: 0 | M9: 0 | N9: =+E9+H9-I9-J9-K9-L9-M9 -> 1020
A10: 100 LÜK KROM AMORTİSÖR 3 CLASS | E10: 371 | G10: Adet | H10: 0 | I10: 0 | J10: 0 | K10: 0 | L10: 0 | M10: 0 | N10: =+E10+H10-I10-J10-K10-L10-M10 -> 371
A11: AMORTİSÖR 100 LÜK 3 CLASS | E11: 576 | G11: Adet | H11: 0 | I11: 0 | J11: 0 | K11: 0 | L11: 0 | M11: 0 | N11: =+E11+H11-I11-J11-K11-L11-M11 -> 576
A12: AMORTİSÖRÜ 200 LÜK | E12: 50 | G12: Adet | H12: 500 | I12: 0 | J12: 0 | K12: 50 | L12: 0 | M12: 0 | N12: =+E12+H12-I12-J12-K12-L12-M12 -> 500 | O12: 150 | P12: 2000
A13: AMORTİSÖR 120 LİK CROM 4 CLASS | E13: 50 | G13: Adet | H13: 0 | I13: 0 | J13: 0 | K13: 0 | L13: 0 | M13: 0 | N13: =+E13+H13-I13-J13-K13-L13-M13 -> 50
E14: 0 | H14: 0 | I14: 0 | J14: 0 | K14: 0 | L14: 0 | M14: 0 | N14: =+E14+H14-I14-J14-K14-L14-M14 -> 0
E15: 0 | H15: 0 | I15: 0 | J15: 0 | K15: 0 | L15: 0 | M15: 0 | N15: =+E15+H15-I15-J15-K15-L15-M15 -> 0
I16: =SUM(I3:I15) -> 200 | J16: =SUM(J3:J15) -> 0 | K16: =SUM(K3:K15) -> 72 | L16: =SUM(L3:L15) -> 100 | M16: =SUM(M3:M15) -> 100

Sheet ekim 3 hafta 
A2: STOK ADI | E2: DEVİR MİK | G2: BİRİM | H2: GİRİŞ | I2: 44851 | J2: 44852 | K2: 44853 | L2: 44854 | M2: 44855 | N2: KALAN | O2: MİNİMUN | P2: MAKSİ | Q2: yıllık tahmini sarf
A3: ZZ.AMORTİSÖR 100 LÜK | E3: ='ekim 2 hafta '!N3 -> 4127 | G3: Adet | H3: 0 | I3: 176 | J3: 120 | K3: 70 | L3: 45 | M3: 1 | N3: =+E3+H3-I3-J3-K3-L3-M3 -> 3715 | O3: 750 | P3: 5000 | Q3: 10000
A4: ZZ.AMORTİSÖR 120 LÜK | E4: ='ekim 2 hafta '!N4 -> 2541 | G4: Adet | H4: 0 | I4: 0 | J4: 0 | K4: 0 | L4: 0 | M4: 0 | N4: =+E4+H4-I4-J4-K4-L4-M4 -> 2541 | O4: 500 | P4: 3000
A5: ZZ.AMORTİSÖR 80 LİK | E5: ='ekim 2 hafta '!N5 -> 4159 | G5: Adet | H5: 0 | I5: 0 | J5: 20 | K5: 0 | L5: 60 | M5: 0 | N5: =+E5+H5-I5-J5-K5-L5-M5 -> 4079 | O5: 300 | P5: 3000
A6: ZZ.AMORTİSÖR 140 LIK | E6: ='ekim 2 hafta '!N6 -> 440 | G6: Adet | H6: 0 | I6: 0 | J6: 80 | K6: 0 | L6: 24 | M6: 0 | N6: =+E6+H6-I6-J6-K6-L6-M6 -> 336 | O6: 200 | P6: 2000
A7: AMORTİSÖR 120 LİK CROM 3 CLASS | E7: ='ekim 2 hafta '!N7 -> 20 | G7: Adet | H7: 0 | I7: 0 | J7: 0 | K7: 0 | L7: 0 | M7: 0 | N7: =+E7+H7-I7-J7-K7-L7-M7 -> 20
A8: KONUM KORUYUCU D 26 KISA | E8: ='ekim 2 hafta '!N8 -> 160 | G8: Adet | H8: 0 | I8: 0 | J8: 0 | K8: 0 | L8: 0 | M8: 0 | N8: =+E8+H8-I8-J8-K8-L8-M8 -> 160
A9: 100 LÜK KROM AMORTİSÖR 4 CLASS | E9: ='ekim 2 hafta '!N9 -> 1020 | G9: Adet | H9: 0 | I9: 0 | J9: 0 | K9: 0 | L9: 0 | M9: 0 | N9: =+E9+H9-I9-J9-K9-L9-M9 -> 1020
A10: 100 LÜK KROM AMORTİSÖR 3 CLASS | E10: ='ekim 2 hafta '!N10 -> 371 | G10: Adet | H10: 0 | I10: 0 | J10: 0 | K10: 0 | L10: 0 | M10: 0 | N10: =+E10+H10-I10-J10-K10-L10-M10 -> 371
A11: AMORTİSÖR 100 LÜK 3 CLASS | E11: ='ekim 2 hafta '!N11 -> 576 | G11: Adet | H11: 0 | I11: 0 | J11: 0 | K11: 0 | L11: 0 | M11: 0 | N11: =+E11+H11-I11-J11-K11-L11-M11 -> 576
A12: AMORTİSÖRÜ 200 LÜK | E12: ='ekim 2 hafta '!N12 -> 500 | G12: Adet | H12: 0 | I12: 0 | J12: 0 | K12: 0 | L12: 200 | M12: 0 | N12: =+E12+H12-I12-J12-K12-L12-M12 -> 300 | O12: 150 | P12: 2000
A13: AMORTİSÖR 120 LİK CROM 4 CLASS | E13: ='ekim 2 hafta '!N13 -> 50 | G13: Adet | H13: 0 | I13: 0 | J13: 0 | K13: 0 | L13: 0 | M13: 0 | N13: =+E13+H13-I13-J13-K13-L13-M13 -> 50
A14: YARASA ŞASE | E14: 35 | G14: Adet | H14: 0 | I14: 0 | J14: 0 | K14: 0 | L14: 20 | M14: 0 | N14: =+E14+H14-I14-J14-K14-L14-M14 -> 15
E15: 0 | H15: 0 | I15: 0 | J15: 0 | K15: 0 | L15: 0 | M15: 0 | N15: =+E15+H15-I15-J15-K15-L15-M15 -> 0
I16: =SUM(I3:I15) -> 176 | J16: =SUM(J3:J15) -> 220 | K16: =SUM(K3:K15) -> 70 | L16: =SUM(L3:L15) -> 349 | M16: =SUM(M3:M15) -> 1

Sheet ekim 4 hafta 
A2: STOK ADI | E2: DEVİR MİK | G2: BİRİM | H2: GİRİŞ | I2: 44858 | J2: 44859 | K2: 44860 | L2: 44861 | M2: 44862 | N2: KALAN | O2: MİNİMUN | P2: MAKSİ
A3: ZZ.AMORTİSÖR 100 LÜK | E3: ='ekim 3 hafta '!N3 -> 3715 | G3: Adet | H3: 0 | I3: 0 | J3: 0 | K3: 0 | L3: 0 | M3: 0 | N3: =+E3+H3-I3-J3-K3-L3-M3 -> 3715 | O3: 750 | P3: 5000
A4: ZZ.AMORTİSÖR 120 LÜK | E4: ='ekim 3 hafta '!N4 -> 2541 | G4: Adet | H4: 0 | I4: 0 | J4: 0 | K4: 0 | L4: 0 | M4: 0 | N4: =+E4+H4-I4-J4-K4-L4-M4 -> 2541 | O4: 500 | P4: 3000
A5: ZZ.AMORTİSÖR 80 LİK | E5: ='ekim 3 hafta '!N5 -> 4079 | G5: Adet | H5: 0 | I5: 0 | J5: 0 | K5: 0 | L5: 0 | M5: 0 | N5: =+E5+H5-I5-J5-K5-L5-M5 -> 4079 | O5: 300 | P5: 3000
A6: ZZ.AMORTİSÖR 140 LIK | E6: ='ekim 3 hafta '!N6 -> 336 | G6: Adet | H6: 0 | I6: 0 | J6: 10 | K6: 0 | L6: 0 | M6: 0 | N6: =+E6+H6-I6-J6-K6-L6-M6 -> 326 | O6: 200 | P6: 2000
A7: AMORTİSÖR 120 LİK CROM 3 CLASS | E7: ='ekim 3 hafta '!N7 -> 20 | G7: Adet | H7: 0 | I7: 0 | J7: 0 | K7: 0 | L7: 0 | M7: 0 | N7: =+E7+H7-I7-J7-K7-L7-M7 -> 20
A8: KONUM KORUYUCU D 26 KISA | E8: ='ekim 3 hafta '!N8 -> 160 | G8: Adet | H8: 0 | I8: 0 | J8: 0 | K8: 0 | L8: 0 | M8: 0 | N8: =+E8+H8-I8-J8-K8-L8-M8 -> 160
A9: 100 LÜK KROM AMORTİSÖR 4 CLASS | E9: ='ekim 3 hafta '!N9 -> 1020 | G9: Adet | H9: 0 | I9: 0 | J9: 0 | K9: 0 | L9: 0 | M9: 0 | N9: =+E9+H9-I9-J9-K9-L9-M9 -> 1020
A10: 100 LÜK KROM AMORTİSÖR 3 CLASS | E10: ='ekim 3 hafta '!N10 -> 371 | G10: Adet | H10: 0 | I10: 0 | J10: 0 | K10: 0 | L10: 0 | M10: 0 | N10: =+E10+H10-I10-J10-K10-L10-M10 -> 371
A11: AMORTİSÖR 100 LÜK 3 CLASS | E11: ='ekim 3 hafta '!N11 -> 576 | G11: Adet | H11: 0 | I11: 0 | J11: 0 | K11: 100 | L11: 0 | M11: 0 | N11: =+E11+H11-I11-J11-K11-L11-M11 -> 476
A12: AMORTİSÖRÜ 200 LÜK | E12: ='ekim 3 hafta '!N12 -> 300 | G12: Adet | H12: 0 | I12: 0 | J12: 200 | K12: 0 | L12: 0 | M12: 0 | N12: =+E12+H12-I12-J12-K12-L12-M12 -> 100 | O12: 150 | P12: 2000
A13: AMORTİSÖR 120 LİK CROM 4 CLASS | E13: ='ekim 3 hafta '!N13 -> 50 | G13: Adet | H13: 0 | I13: 0 | J13: 0 | K13: 0 | L13: 0 | M13: 0 | N13: =+E13+H13-I13-J13-K13-L13-M13 -> 50
A14: YARASA ŞASE | E14: ='ekim 3 hafta '!N14 -> 15 | G14: Adet | H14: 0 | I14: 0 | J14: 0 | K14: 0 | L14: 0 | M14: 0 | N14: =+E14+H14-I14-J14-K14-L14-M14 -> 15
A15: AMORTİSÖR 60 LIK 3 CLASS SİYAH | E15: ='ekim 3 hafta '!N15 -> 0 | G15: Adet | H15: 200 | I15: 0 | J15: 0 | K15: 0 | L15: 0 | M15: 20 | N15: =+E15+H15-I15-J15-K15-L15-M15 -> 180

Sheet KASIM 1 HAFTA
A2: STOK ADI | E2: DEVİR MİK | G2: BİRİM | H2: GİRİŞ | I2: 44865 | J2: 44866 | K2: 44867 | L2: 44868 | M2: 44869 | N2: KALAN | O2: MİNİMUN | P2: MAKSİ
A3: ZZ.AMORTİSÖR 100 LÜK | E3: ='ekim 4 hafta '!N3 -> 3715 | G3: Adet | H3: 0 | I3: 0 | J3: 100 | K3: 0 | L3: 0 | M3: 0 | N3: =+E3+H3-I3-J3-K3-L3-M3 -> 3615 | O3: 750 | P3: 5000
A4: ZZ.AMORTİSÖR 120 LÜK | E4: ='ekim 4 hafta '!N4 -> 2541 | G4: Adet | H4: 0 | I4: 0 | J4: 490 | K4: 0 | L4: 0 | M4: 0 | N4: =+E4+H4-I4-J4-K4-L4-M4 -> 2051 | O4: 500 | P4: 3000
A5: ZZ.AMORTİSÖR 80 LİK | E5: ='ekim 4 hafta '!N5 -> 4079 | G5: Adet | H5: 0 | I5: 0 | J5: 0 | K5: 0 | L5: 0 | M5: 0 | N5: =+E5+H5-I5-J5-K5-L5-M5 -> 4079 | O5: 300 | P5: 3000
A6: ZZ.AMORTİSÖR 140 LIK | E6: ='ekim 4 hafta '!N6 -> 326 | G6: Adet | H6: 0 | I6: 0 | J6: 20 | K6: 0 | L6: 0 | M6: 0 | N6: =+E6+H6-I6-J6-K6-L6-M6 -> 306 | O6: 200 | P6: 2000
A7: AMORTİSÖR 120 LİK CROM 3 CLASS | E7: ='ekim 4 hafta '!N7 -> 20 | G7: Adet | H7: 0 | I7: 0 | J7: 0 | K7: 0 | L7: 0 | M7: 0 | N7: =+E7+H7-I7-J7-K7-L7-M7 -> 20
A8: KONUM KORUYUCU D 26 KISA | E8: ='ekim 4 hafta '!N8 -> 160 | G8: Adet | H8: 0 | I8: 0 | J8: 0 | K8: 0 | L8: 0 | M8: 0 | N8: =+E8+H8-I8-J8-K8-L8-M8 -> 160
A9: 100 LÜK KROM AMORTİSÖR 4 CLASS | E9: ='ekim 4 hafta '!N9 -> 1020 | G9: Adet | H9: 0 | I9: 0 | J9: 0 | K9: 0 | L9: 0 | M9: 0 | N9: =+E9+H9-I9-J9-K9-L9-M9 -> 1020
A10: 100 LÜK KROM AMORTİSÖR 3 CLASS | E10: ='ekim 4 hafta '!N10 -> 371 | G10: Adet | H10: 0 | I10: 0 | J10: 0 | K10: 0 | L10: 0 | M10: 0 | N10: =+E10+H10-I10-J10-K10-L10-M10 -> 371
A11: AMORTİSÖR 100 LÜK 3 CLASS | E11: ='ekim 4 hafta '!N11 -> 476 | G11: Adet | H11: 0 | I11: 0 | J11: 0 | K11: 0 | L11: 0 | M11: 0 | N11: =+E11+H11-I11-J11-K11-L11-M11 -> 476
A12: AMORTİSÖRÜ 200 LÜK | E12: ='ekim 4 hafta '!N12 -> 100 | G12: Adet | H12: 0 | I12: 0 | J12: 5 | K12: 0 | L12: 0 | M12: 0 | N12: =+E12+H12-I12-J12-K12-L12-M12 -> 95 | O12: 150 | P12: 2000
A13: AMORTİSÖR 120 LİK CROM 4 CLASS | E13: ='ekim 4 hafta '!N13 -> 50 | G13: Adet | H13: 0 | I13: 0 | J13: 0 | K13: 0 | L13: 0 | M13: 0 | N13: =+E13+H13-I13-J13-K13-L13-M13 -> 50
A14: YARASA ŞASE | E14: ='ekim 4 hafta '!N14 -> 15 | G14: Adet | H14: 0 | I14: 0 | J14: 0 | K14: 0 | L14: 0 | M14: 0 | N14: =+E14+H14-I14-J14-K14-L14-M14 -> 15
A15: AMORTİSÖR 60 LIK 3 CLASS SİYAH | E15: ='ekim 4 hafta '!N15 -> 180 | G15: Adet | H15: 0 | I15: 0 | J15: 0 | K15: 0 | L15: 0 | M15: 0 | N15: =+E15+H15-I15-J15-K15-L15-M15 -> 180

Sheet KASIM 2 HAFTA 
A2: STOK ADI | E2: DEVİR MİK | G2: BİRİM | H2: GİRİŞ | I2: 44872 | J2: 44873 | K2: 44874 | L2: 44875 | M2: 44876 | N2: KALAN | O2: MİNİMUN | P2: MAKSİMUN
A3: ZZ.AMORTİSÖR 100 LÜK | E3: ='KASIM 1 HAFTA'!N3 -> 3615 | G3: Adet | H3: 0 | I3: 0 | J3: 0 | K3: 10 | L3: 0 | M3: 0 | N3: =+E3+H3-I3-J3-K3-L3-M3 -> 3605 | O3: 1000 | P3: 5000
A4: ZZ.AMORTİSÖR 120 LÜK | E4: ='KASIM 1 HAFTA'!N4 -> 2051 | G4: Adet | H4: 0 | I4: 0 | J4: 0 | K4: 0 | L4: 0 | M4: 0 | N4: =+E4+H4-I4-J4-K4-L4-M4 -> 2051 | O4: 500 | P4: 3000
A5: ZZ.AMORTİSÖR 80 LİK | E5: ='KASIM 1 HAFTA'!N5 -> 4079 | G5: Adet | H5: 0 | I5: 0 | J5: 0 | K5: 0 | L5: 0 | M5: 60 | N5: =+E5+H5-I5-J5-K5-L5-M5 -> 4019 | O5: 300 | P5: 3000
A6: ZZ.AMORTİSÖR 140 LIK | E6: ='KASIM 1 HAFTA'!N6 -> 306 | G6: Adet | H6: 0 | I6: 0 | J6: 0 | K6: 0 | L6: 0 | M6: 0 | N6: =+E6+H6-I6-J6-K6-L6-M6 -> 306 | O6: 200 | P6: 2000
A7: AMORTİSÖR 120 LİK CROM 3 CLASS | E7: ='KASIM 1 HAFTA'!N7 -> 20 | G7: Adet | H7: 0 | I7: 0 | J7: 0 | K7: 0 | L7: 0 | M7: 0 | N7: =+E7+H7-I7-J7-K7-L7-M7 -> 20 | O7: 0 | P7: 0
A8: KONUM KORUYUCU D 26 KISA | E8: ='KASIM 1 HAFTA'!N8 -> 160 | G8: Adet | H8: 0 | I8: 0 | J8: 0 | K8: 0 | L8: 0 | M8: 0 | N8: =+E8+H8-I8-J8-K8-L8-M8 -> 160 | O8: 100 | P8: 500
A9: 100 LÜK KROM AMORTİSÖR 4 CLASS | E9: ='KASIM 1 HAFTA'!N9 -> 1020 | G9: Adet | H9: 0 | I9: 0 | J9: 0 | K9: 0 | L9: 0 | M9: 0 | N9: =+E9+H9-I9-J9-K9-L9-M9 -> 1020 | O9: 0 | P9: 0
A10: 100 LÜK KROM AMORTİSÖR 3 CLASS | E10: ='KASIM 1 HAFTA'!N10 -> 371 | G10: Adet | H10: 0 | I10: 0 | J10: 0 | K10: 0 | L10: 0 | M10: 0 | N10: =+E10+H10-I10-J10-K10-L10-M10 -> 371 | O10: 0 | P10: 0
A11: AMORTİSÖR 100 LÜK 3 CLASS | E11: ='KASIM 1 HAFTA'!N11 -> 476 | G11: Adet | H11: 0 | I11: 0 | J11: 0 | K11: 0 | L11: 0 | M11: 10 | N11: =+E11+H11-I11-J11-K11-L11-M11 -> 466 | O11: 0 | P11: 0
A12: AMORTİSÖRÜ 200 LÜK | E12: 0 | G12: Adet | H12: 250 | I12: 140 | J12: 50 | K12: 0 | L12: 0 | M12: 0 | N12: =+E12+H12-I12-J12-K12-L12-M12 -> 60 | O12: 150 | P12: 2000
A13: AMORTİSÖR 120 LİK CROM 4 CLASS | E13: ='KASIM 1 HAFTA'!N13 -> 50 | G13: Adet | H13: 0 | I13: 0 | J13: 0 | K13: 0 | L13: 0 | M13: 0 | N13: =+E13+H13-I13-J13-K13-L13-M13 -> 50 | O13: 0 | P13: 0
A14: YARASA ŞASE | E14: ='KASIM 1 HAFTA'!N14 -> 15 | G14: Adet | H14: 0 | I14: 0 | J14: 0 | K14: 0 | L14: 0 | M14: 0 | N14: =+E14+H14-I14-J14-K14-L14-M14 -> 15 | O14: 0 | P14: 0
A15: AMORTİSÖR 60 LIK 3 CLASS SİYAH | E15: ='KASIM 1 HAFTA'!N15 -> 180 | G15: Adet | H15: 0 | I15: 0 | J15: 0 | K15: 0 | L15: 0 | M15: 0 | N15: =+E15+H15-I15-J15-K15-L15-M15 -> 180 | O15: 100 | P15: 300
A16: 140 LIK AMORTİSÖR 3 KLASS | H16: 200 | J16: 100 | M16: 100 | N16: =+E16+H16-I16-J16-K16-L16-M16 -> 0 | O16: 0 | P16: 0

Sheet KASIM 3 HAFTA 
B1: AMORTİSÖR
A2: S.NO | B2: STOK ADI | F2: DEVİR MİK | H2: BİRİM | I2: GİRİŞ | J2: 44879 | K2: 44880 | L2: 44881 | M2: 44882 | N2: 44883 | O2: KALAN | P2: MİNİMUN | Q2: MAKSİMUN
A3: 1 | B3: ZZ.AMORTİSÖR 100 LÜK | F3: ='KASIM 2 HAFTA '!N3 -> 3605 | H3: Adet | I3: 0 | J3: 10 | K3: 0 | L3: 0 | M3: 0 | N3: 160 | O3: =+F3+I3-J3-K3-L3-M3-N3 -> 3435 | P3: 1000 | Q3: 5000
A4: 2 | B4: ZZ.AMORTİSÖR 120 LÜK | F4: ='KASIM 2 HAFTA '!N4 -> 2051 | H4: Adet | I4: 0 | J4: 0 | K4: 0 | L4: 3 | M4: 0 | N4: 0 | O4: =+F4+I4-J4-K4-L4-M4-N4 -> 2048 | P4: 500 | Q4: 3000
A5: 3 | B5: ZZ.AMORTİSÖR 80 LİK | F5: ='KASIM 2 HAFTA '!N5 -> 4019 | H5: Adet | I5: 0 | J5: 0 | K5: 0 | L5: 0 | M5: 0 | N5: 0 | O5: =+F5+I5-J5-K5-L5-M5-N5 -> 4019 | P5: 300 | Q5: 3000
A6: 4 | B6: ZZ.AMORTİSÖR 140 LIK | F6: ='KASIM 2 HAFTA '!N6 -> 306 | H6: Adet | I6: 100 | J6: 0 | K6: 0 | L6: 0 | M6: 0 | N6: 0 | O6: =+F6+I6-J6-K6-L6-M6-N6 -> 406 | P6: 200 | Q6: 2000
A7: 5 | B7: AMORTİSÖR 120 LİK CROM 3 CLASS | F7: ='KASIM 2 HAFTA '!N7 -> 20 | H7: Adet | I7: 0 | J7: 0 | K7: 0 | L7: 0 | M7: 0 | N7: 0 | O7: =+F7+I7-J7-K7-L7-M7-N7 -> 20 | P7: 0 | Q7: 0
A8: 6 | B8: KONUM KORUYUCU D 26 KISA | F8: 0 | H8: Adet | I8: 260 | J8: 0 | K8: 0 | L8: 40 | M8: 0 | N8: 0 | O8: =+F8+I8-J8-K8-L8-M8-N8 -> 220 | P8: 100 | Q8: 500
A9: 7 | B9: 100 LÜK KROM AMORTİSÖR 4 CLASS | F9: ='KASIM 2 HAFTA '!N9 -> 1020 | H9: Adet | I9: 0 | J9: 0 | K9: 0 | L9: 0 | M9: 0 | N9: 0 | O9: =+F9+I9-J9-K9-L9-M9-N9 -> 1020 | P9: 0 | Q9: 0
A10: 8 | B10: 100 LÜK KROM AMORTİSÖR 3 CLASS | F10: ='KASIM 2 HAFTA '!N10 -> 371 | H10: Adet | I10: 0 | J10: 0 | K10: 0 | L10: 0 | M10: 0 | N10: 0 | O10: =+F10+I10-J10-K10-L10-M10-N10 -> 371 | P10: 0 | Q10: 0
A11: 9 | B11: AMORTİSÖR 100 LÜK 3 CLASS | F11: ='KASIM 2 HAFTA '!N11 -> 466 | H11: Adet | I11: 0 | J11: 0 | K11: 0 | L11: 0 | M11: 110 | N11: 0 | O11: =+F11+I11-J11-K11-L11-M11-N11 -> 356 | P11: 0 | Q11: 0
A12: 10 | B12: AMORTİSÖRÜ 200 LÜK | F12: ='KASIM 2 HAFTA '!N12 -> 60 | H12: Adet | I12: 0 | J12: 0 | K12: 0 | L12: 0 | M12: 0 | N12: 0 | O12: =+F12+I12-J12-K12-L12-M12-N12 -> 60 | P12: 150 | Q12: 2000
A13: 11 | B13: AMORTİSÖR 120 LİK CROM 4 CLASS | F13: ='KASIM 2 HAFTA '!N13 -> 50 | H13: Adet | I13: 0 | J13: 0 | K13: 0 | L13: 0 | M13: 0 | N13: 0 | O13: =+F13+I13-J13-K13-L13-M13-N13 -> 50 | P13: 0 | Q13: 0
A14: 12 | B14: YARASA ŞASE | F14: ='KASIM 2 HAFTA '!N14 -> 15 | H14: Adet | I14: 0 | J14: 0 | K14: 0 | L14: 0 | M14: 0 | N14: 0 | O14: =+F14+I14-J14-K14-L14-M14-N14 -> 15 | P14: 0 | Q14: 0
A15: 13 | B15: AMORTİSÖR 60 LIK 3 CLASS SİYAH | F15: ='KASIM 2 HAFTA '!N15 -> 180 | H15: Adet | I15: 0 | J15: 0 | K15: 0 | L15: 0 | M15: 0 | N15: 0 | O15: =+F15+I15-J15-K15-L15-M15-N15 -> 180 | P15: 100 | Q15: 300
A16: 14 | B16: 140 LIK AMORTİSÖR 3 KLASS | F16: 0 | H16: Adet | I16: 0 | K16: 0 | N16: 0 | O16: =+F16+I16-J16-K16-L16-M16-N16 -> 0 | P16: 0 | Q16: 0

Sheet KASIM 4 HAFTA 
A2: S.NO | B2: STOK ADI | F2: DEVİR MİK | H2: BİRİM | I2: GİRİŞ | J2: 44886 | K2: 44887 | L2: 44888 | M2: 44889 | N2: 44890 | O2: KALAN | P2: MİNİMUN | Q2: MAKSİMUN
A3: 1 | B3: ZZ.AMORTİSÖR 100 LÜK | F3: ='KASIM 3 HAFTA '!O3 -> 3435 | H3: Adet | I3: 0 | J3: 0 | K3: 0 | L3: 0 | M3: 80 | N3: 0 | O3: =+F3+I3-J3-K3-L3-M3-N3 -> 3355 | P3: 1000 | Q3: 5000
A4: 2 | B4: ZZ.AMORTİSÖR 120 LÜK | F4: ='KASIM 3 HAFTA '!O4 -> 2048 | H4: Adet | I4: 0 | J4: 20 | K4: 0 | L4: 100 | M4: 80 | N4: 7 | O4: =+F4+I4-J4-K4-L4-M4-N4 -> 1841 | P4: 500 | Q4: 3000
A5: 3 | B5: ZZ.AMORTİSÖR 80 LİK | F5: ='KASIM 3 HAFTA '!O5 -> 4019 | H5: Adet | I5: 0 | J5: 20 | K5: 40 | L5: 0 | M5: 0 | N5: 40 | O5: =+F5+I5-J5-K5-L5-M5-N5 -> 3919 | P5: 300 | Q5: 3000
A6: 4 | B6: ZZ.AMORTİSÖR 140 LIK | F6: ='KASIM 3 HAFTA '!O6 -> 406 | H6: Adet | I6: 0 | J6: 24 | K6: 0 | L6: 0 | M6: 0 | N6: 0 | O6: =+F6+I6-J6-K6-L6-M6-N6 -> 382 | P6: 200 | Q6: 2000
A7: 5 | B7: AMORTİSÖR 120 LİK CROM 3 CLASS | F7: ='KASIM 3 HAFTA '!O7 -> 20 | H7: Adet | I7: 0 | J7: 0 | K7: 0 | L7: 0 | M7: 0 | N7: 0 | O7: =+F7+I7-J7-K7-L7-M7-N7 -> 20 | P7: 0 | Q7: 0
A8: 6 | B8: KONUM KORUYUCU D 26 KISA | F8: ='KASIM 3 HAFTA '!O8 -> 220 | H8: Adet | I8: 0 | J8: 20 | K8: 0 | L8: 0 | M8: 0 | N8: 0 | O8: =+F8+I8-J8-K8-L8-M8-N8 -> 200 | P8: 100 | Q8: 500
A9: 7 | B9: 100 LÜK KROM AMORTİSÖR 4 CLASS | F9: ='KASIM 3 HAFTA '!O9 -> 1020 | H9: Adet | I9: 0 | J9: 0 | K9: 0 | L9: 0 | M9: 0 | N9: 0 | O9: =+F9+I9-J9-K9-L9-M9-N9 -> 1020 | P9: 0 | Q9: 0
A10: 8 | B10: 100 LÜK KROM AMORTİSÖR 3 CLASS | F10: 356 | H10: Adet | I10: 0 | J10: 0 | K10: 0 | L10: 60 | M10: 0 | N10: 0 | O10: =+F10+I10-J10-K10-L10-M10-N10 -> 296 | P10: 0 | Q10: 0
A11: 9 | B11: AMORTİSÖRÜ 200 LÜK | F11: ='KASIM 3 HAFTA '!O12 -> 60 | H11: Adet | I11: 0 | J11: 21 | K11: 0 | L11: 0 | M11: 25 | N11: 4 | O11: =+F11+I11-J11-K11-L11-M11-N11 -> 10 | P11: 150 | Q11: 2000
A12: 10 | B12: AMORTİSÖR 120 LİK CROM 4 CLASS | F12: ='KASIM 3 HAFTA '!O13 -> 50 | H12: Adet | I12: 0 | J12: 20 | K12: 0 | L12: 0 | M12: 0 | N12: 0 | O12: =+F12+I12-J12-K12-L12-M12-N12 -> 30 | P12: 0 | Q12: 0
A13: 11 | B13: YARASA ŞASE | F13: ='KASIM 3 HAFTA '!O14 -> 15 | H13: Adet | I13: 0 | J13: 0 | K13: 0 | L13: 0 | M13: 0 | N13: 0 | O13: =+F13+I13-J13-K13-L13-M13-N13 -> 15 | P13: 0 | Q13: 0
A14: 12 | B14: AMORTİSÖR 60 LIK 3 CLASS SİYAH | F14: ='KASIM 3 HAFTA '!O15 -> 180 | H14: Adet | I14: 0 | J14: 0 | K14: 0 | L14: 0 | M14: 0 | N14: 0 | O14: =+F14+I14-J14-K14-L14-M14-N14 -> 180 | P14: 100 | Q14: 300
A15: 13 | B15: 140 LIK AMORTİSÖR 3 KLASS | F15: 0 | H15: Adet | I15: 0 | K15: 0 | L15: 0 | M15: 0 | N15: 0 | O15: =+F15+I15-J15-K15-L15-M15-N15 -> 0 | P15: 0 | Q15: 0

Sheet KASIM 5 HAFTA 
A2: S.NO | B2: STOK ADI | F2: DEVİR MİK | H2: BİRİM | I2: GİRİŞ | J2: 44893 | K2: 44894 | L2: 44895 | M2: 44896 | N2: 44897 | O2: KALAN | P2: MİNİMUN | Q2: MAKSİMUN
A3: 1 | B3: ZZ.AMORTİSÖR 100 LÜK | F3: 3010 | H3: Adet | I3: 0 | J3: 10 | K3: 0 | L3: 100 | M3: 0 | N3: 0 | O3: =+F3+I3-J3-K3-L3-M3-N3 -> 2900 | P3: 1000 | Q3: 5000
A4: 2 | B4: ZZ.AMORTİSÖR 120 LÜK | F4: 1600 | H4: Adet | I4: 0 | J4: 0 | K4: 100 | L4: 0 | M4: 0 | N4: 0 | O4: =+F4+I4-J4-K4-L4-M4-N4 -> 1500 | P4: 500 | Q4: 3000
A5: 3 | B5: ZZ.AMORTİSÖR 80 LİK | F5: 3919 | H5: Adet | I5: 0 | J5: 0 | K5: 20 | L5: 0 | M5: 0 | N5: 80 | O5: =+F5+I5-J5-K5-L5-M5-N5 -> 3819 | P5: 300 | Q5: 3000
A6: 4 | B6: ZZ.AMORTİSÖR 140 LIK | F6: 382 | H6: Adet | I6: 0 | J6: 4 | K6: 0 | L6: 80 | M6: 0 | N6: 0 | O6: =+F6+I6-J6-K6-L6-M6-N6 -> 298 | P6: 200 | Q6: 2000
A7: 5 | B7: AMORTİSÖR 120 LİK CROM 3 CLASS | F7: 0 | H7: Adet | I7: 0 | J7: 0 | K7: 0 | L7: 0 | M7: 0 | N7: 0 | O7: =+F7+I7-J7-K7-L7-M7-N7 -> 0 | P7: 0 | Q7: 0
A8: 6 | B8: KONUM KORUYUCU D 26 KISA | F8: 200 | H8: Adet | I8: 0 | J8: 0 | K8: 0 | L8: 0 | M8: 42 | N8: 20 | O8: =+F8+I8-J8-K8-L8-M8-N8 -> 138 | P8: 100 | Q8: 500
A9: 7 | B9: 100 LÜK KROM AMORTİSÖR 4 CLASS | F9: ='KASIM 3 HAFTA '!O9 -> 1020 | H9: Adet | I9: 0 | J9: 0 | K9: 0 | L9: 0 | M9: 0 | N9: 0 | O9: =+F9+I9-J9-K9-L9-M9-N9 -> 1020 | P9: 0 | Q9: 0
A10: 8 | B10: 100 LÜK KROM AMORTİSÖR 3 CLASS | F10: 296 | H10: Adet | I10: 0 | J10: 0 | K10: 0 | L10: 0 | M10: 111 | N10: 0 | O10: =+F10+I10-J10-K10-L10-M10-N10 -> 185 | P10: 0 | Q10: 0
A11: 9 | B11: AMORTİSÖRÜ 200 LÜK | F11: 10 | H11: Adet | I11: 0 | J11: 0 | K11: 0 | L11: 0 | M11: 0 | N11: 0 | O11: =+F11+I11-J11-K11-L11-M11-N11 -> 10 | P11: 150 | Q11: 2000
A12: 10 | B12: AMORTİSÖR 120 LİK CROM 4 CLASS | F12: 30 | H12: Adet | I12: 0 | J12: 0 | K12: 12 | L12: 0 | M12: 0 | N12: 0 | O12: =+F12+I12-J12-K12-L12-M12-N12 -> 18 | P12: 0 | Q12: 0
A13: 11 | B13: YARASA ŞASE | F13: ='KASIM 3 HAFTA '!O14 -> 15 | H13: Adet | I13: 0 | J13: 0 | K13: 0 | L13: 0 | M13: 0 | N13: 0 | O13: =+F13+I13-J13-K13-L13-M13-N13 -> 15 | P13: 0 | Q13: 0
A14: 12 | B14: AMORTİSÖR 60 LIK 3 CLASS SİYAH | F14: ='KASIM 3 HAFTA '!O15 -> 180 | H14: Adet | I14: 0 | J14: 0 | K14: 0 | L14: 0 | M14: 0 | N14: 0 | O14: =+F14+I14-J14-K14-L14-M14-N14 -> 180 | P14: 100 | Q14: 300
A15: 13 | B15: 140 LIK AMORTİSÖR 3 KLASS | F15: 160 | H15: Adet | I15: 0 | J15: 0 | K15: 0 | L15: 0 | M15: 0 | N15: 0 | O15: =+F15+I15-J15-K15-L15-M15-N15 -> 160 | P15: 0 | Q15: 0

Sheet ARALIK 1 HAFTA 
B1: ARALIK 1 HAFTA
A2: S.NO | B2: STOK ADI | F2: DEVİR MİK | H2: BİRİM | I2: GİRİŞ | J2: 44900 | K2: 44901 | L2: 44902 | M2: 44903 | N2: 44904 | O2: KALAN | P2: MİNİMUN | Q2: MAKSİMUN
A3: 1 | B3: ZZ.AMORTİSÖR 100 LÜK | F3: 2900 | H3: Adet | I3: 0 | J3: 0 | K3: 140 | L3: 0 | M3: 80 | N3: 6 | O3: =+F3+I3-J3-K3-L3-M3-N3 -> 2674 | P3: 1000 | Q3: 5000
A4: 2 | B4: ZZ.AMORTİSÖR 120 LÜK 3K | F4: 1500 | H4: Adet | I4: 0 | J4: 0 | K4: 0 | L4: 0 | M4: 0 | N4: 180 | O4: =+F4+I4-J4-K4-L4-M4-N4 -> 1320 | P4: 500 | Q4: 3000
A5: 3 | B5: ZZ.AMORTİSÖR 80 LİK | F5: 3819 | H5: Adet | I5: 0 | J5: 0 | K5: 0 | L5: 0 | M5: 0 | N5: 0 | O5: =+F5+I5-J5-K5-L5-M5-N5 -> 3819 | P5: 300 | Q5: 3000
A6: 4 | B6: ZZ.AMORTİSÖR 140 LIK | F6: 298 | H6: Adet | I6: 0 | J6: 5 | K6: 0 | L6: 0 | M6: 0 | N6: 0 | O6: =+F6+I6-J6-K6-L6-M6-N6 -> 293 | P6: 200 | Q6: 2000
A7: 5 | B7: AMORTİSÖR 120 LİK CROM 3 CLASS | F7: 0 | H7: Adet | I7: 500 | J7: 0 | K7: 0 | L7: 0 | M7: 115 | N7: 0 | O7: =+F7+I7-J7-K7-L7-M7-N7 -> 385 | P7: 0 | Q7: 0
A8: 6 | B8: KONUM KORUYUCU D 26 KISA | F8: 138 | H8: Adet | I8: 0 | J8: 0 | K8: 0 | L8: 40 | M8: 0 | N8: 20 | O8: =+F8+I8-J8-K8-L8-M8-N8 -> 78 | P8: 100 | Q8: 500
A9: 7 | B9: 100 LÜK KROM AMORTİSÖR 4 CLASS | F9: ='KASIM 3 HAFTA '!O9 -> 1020 | H9: Adet | I9: 2500 | J9: 0 | K9: 0 | L9: 0 | M9: 0 | N9: 0 | O9: =+F9+I9-J9-K9-L9-M9-N9 -> 3520 | P9: 0 | Q9: 0
A10: 8 | B10: 100 LÜK KROM AMORTİSÖR 3 CLASS | F10: 185 | H10: Adet | I10: 500 | J10: 0 | K10: 0 | L10: 0 | M10: 40 | N10: 20 | O10: =+F10+I10-J10-K10-L10-M10-N10 -> 625 | P10: 0 | Q10: 0
A11: 9 | B11: AMORTİSÖRÜ 200 LÜK | F11: 10 | H11: Adet | I11: 0 | J11: 0 | K11: 0 | L11: 0 | M11: 0 | N11: 0 | O11: =+F11+I11-J11-K11-L11-M11-N11 -> 10 | P11: 150 | Q11: 2000
A12: 10 | B12: AMORTİSÖR 120 LİK CROM 4 CLASS | F12: 18 | H12: Adet | I12: 0 | J12: 0 | K12: 0 | L12: 0 | M12: 0 | N12: 0 | O12: =+F12+I12-J12-K12-L12-M12-N12 -> 18 | P12: 0 | Q12: 0
A13: 11 | B13: YARASA ŞASE | F13: ='KASIM 3 HAFTA '!O14 -> 15 | H13: Adet | I13: 0 | J13: 0 | K13: 0 | L13: 0 | M13: 0 | N13: 0 | O13: =+F13+I13-J13-K13-L13-M13-N13 -> 15 | P13: 0 | Q13: 0
A14: 12 | B14: AMORTİSÖR 60 LIK 3 CLASS SİYAH | F14: ='KASIM 3 HAFTA '!O15 -> 180 | H14: Adet | I14: 0 | J14: 0 | K14: 20 | L14: 0 | M14: 0 | N14: 0 | O14: =+F14+I14-J14-K14-L14-M14-N14 -> 160 | P14: 100 | Q14: 300
A15: 13 | B15: 140 LIK AMORTİSÖR 3 KLASS | F15: 160 | H15: Adet | I15: 0 | J15: 0 | K15: 0 | L15: 0 | M15: 0 | N15: 0 | O15: =+F15+I15-J15-K15-L15-M15-N15 -> 160 | P15: 0 | Q15: 0

Sheet ARALIK 2 HAFTA 
B1: ARALIK 2 HAFTA
A2: S.NO | B2: STOK ADI | F2: DEVİR MİK | H2: BİRİM | I2: GİRİŞ | J2: 44907 | K2: 44908 | L2: 44909 | M2: 44910 | N2: 44911 | O2: KALAN | P2: MİNİMUN | Q2: MAKSİMUN
A3: 1 | B3: ZZ.AMORTİSÖR 100 LÜK | F3: 2674 | H3: Adet | I3: 0 | J3: 20 | K3: 0 | L3: 0 | M3: 0 | N3: 0 | O3: =+F3+I3-J3-K3-L3-M3-N3 -> 2654 | P3: 1000 | Q3: 5000
A4: 2 | B4: ZZ.AMORTİSÖR 120 LÜK 3K | F4: 1320 | H4: Adet | I4: 0 | J4: 4 | K4: 0 | L4: 0 | M4: 0 | N4: 0 | O4: =+F4+I4-J4-K4-L4-M4-N4 -> 1316 | P4: 500 | Q4: 3000
A5: 3 | B5: ZZ.AMORTİSÖR 80 LİK | F5: 3819 | H5: Adet | I5: 0 | J5: 0 | K5: 0 | L5: 0 | M5: 0 | N5: 120 | O5: =+F5+I5-J5-K5-L5-M5-N5 -> 3699 | P5: 300 | Q5: 3000
A6: 4 | B6: ZZ.AMORTİSÖR 140 LIK | F6: 293 | H6: Adet | I6: 0 | J6: 0 | K6: 0 | L6: 0 | M6: 0 | N6: 0 | O6: =+F6+I6-J6-K6-L6-M6-N6 -> 293 | P6: 200 | Q6: 2000
A7: 5 | B7: AMORTİSÖR 120 LİK CROM 3 CLASS | F7: 385 | H7: Adet | I7: 0 | J7: 0 | K7: 0 | L7: 0 | M7: 0 | N7: 0 | O7: =+F7+I7-J7-K7-L7-M7-N7 -> 385 | P7: 0 | Q7: 0
A8: 6 | B8: KONUM KORUYUCU D 26 KISA | F8: 160 | H8: Adet | I8: 0 | J8: 0 | K8: 0 | L8: 0 | M8: 40 | N8: 0 | O8: =+F8+I8-J8-K8-L8-M8-N8 -> 120 | P8: 100 | Q8: 500
A9: 7 | B9: 100 LÜK KROM AMORTİSÖR 4 CLASS | F9: 3520 | H9: Adet | I9: 0 | J9: 0 | K9: 0 | L9: 2500 | M9: 0 | N9: 0 | O9: =+F9+I9-J9-K9-L9-M9-N9 -> 1020 | P9: 0 | Q9: 0
A10: 8 | B10: 100 LÜK KROM AMORTİSÖR 3 CLASS | F10: 625 | H10: Adet | I10: 0 | J10: 0 | K10: 0 | L10: 0 | M10: 0 | N10: 0 | O10: =+F10+I10-J10-K10-L10-M10-N10 -> 625 | P10: 0 | Q10: 0
A11: 9 | B11: AMORTİSÖRÜ 200 LÜK | F11: 10 | H11: Adet | I11: 0 | J11: 0 | K11: 0 | L11: 0 | M11: 0 | N11: 0 | O11: =+F11+I11-J11-K11-L11-M11-N11 -> 10 | P11: 150 | Q11: 2000
A12: 10 | B12: AMORTİSÖR 120 LİK CROM 4 CLASS | F12: 18 | H12: Adet | I12: 0 | J12: 0 | K12: 0 | L12: 0 | M12: 0 | N12: 0 | O12: =+F12+I12-J12-K12-L12-M12-N12 -> 18 | P12: 0 | Q12: 0
A13: 11 | B13: YARASA ŞASE | F13: ='KASIM 3 HAFTA '!O14 -> 15 | H13: Adet | I13: 0 | J13: 0 | K13: 0 | L13: 0 | M13: 0 | N13: 0 | O13: =+F13+I13-J13-K13-L13-M13-N13 -> 15 | P13: 0 | Q13: 0
A14: 12 | B14: AMORTİSÖR 60 LIK 3 CLASS SİYAH | F14: 160 | H14: Adet | I14: 0 | J14: 0 | K14: 0 | L14: 60 | M14: 0 | N14: 0 | O14: =+F14+I14-J14-K14-L14-M14-N14 -> 100 | P14: 100 | Q14: 300
A15: 13 | B15: 140 LIK AMORTİSÖR 3 KLASS | F15: 160 | H15: Adet | I15: 0 | J15: 0 | K15: 0 | L15: 0 | M15: 0 | N15: 0 | O15: =+F15+I15-J15-K15-L15-M15-N15 -> 160 | P15: 0 | Q15: 0

Sheet ARALIK 3 HAFTA 
B1: ARALIK 3 HAFTA
A2: S.NO | B2: STOK ADI | F2: DEVİR MİK | H2: BİRİM | I2: GİRİŞ | J2: 44914 | K2: 44915 | L2: 44916 | M2: 44917 | N2: 44918 | O2: KALAN | P2: MİNİMUN | Q2: MAKSİMUN
A3: 1 | B3: ZZ.AMORTİSÖR 100 LÜK | F3: 2654 | H3: Adet | I3: 0 | J3: 160 | K3: 4 | L3: 0 | M3: 20 | N3: 40 | O3: =+F3+I3-J3-K3-L3-M3-N3 -> 2430 | P3: 1000 | Q3: 5000
A4: 2 | B4: ZZ.AMORTİSÖR 120 LÜK 3K | F4: 1316 | H4: Adet | I4: 0 | J4: 160 | K4: 0 | L4: 100 | M4: 0 | N4: 0 | O4: =+F4+I4-J4-K4-L4-M4-N4 -> 1056 | P4: 500 | Q4: 3000
A5: 3 | B5: ZZ.AMORTİSÖR 80 LİK | F5: 3699 | H5: Adet | I5: 0 | J5: 0 | K5: 0 | L5: 0 | M5: 20 | N5: 20 | O5: =+F5+I5-J5-K5-L5-M5-N5 -> 3659 | P5: 300 | Q5: 3000
A6: 4 | B6: ZZ.AMORTİSÖR 140 LIK | F6: 293 | H6: Adet | I6: 0 | J6: 0 | K6: 0 | L6: 0 | M6: 0 | N6: 5 | O6: =+F6+I6-J6-K6-L6-M6-N6 -> 288 | P6: 200 | Q6: 2000
A7: 5 | B7: AMORTİSÖR 120 LİK CROM 3 CLASS | F7: 385 | H7: Adet | I7: 0 | J7: 0 | K7: 0 | L7: 0 | M7: 0 | N7: 0 | O7: =+F7+I7-J7-K7-L7-M7-N7 -> 385 | P7: 0 | Q7: 0
A8: 6 | B8: KONUM KORUYUCU D 26 KISA | F8: 120 | H8: Adet | I8: 0 | J8: 0 | K8: 0 | L8: 0 | M8: 0 | N8: 60 | O8: =+F8+I8-J8-K8-L8-M8-N8 -> 60 | P8: 100 | Q8: 500
A9: 7 | B9: 100 LÜK KROM AMORTİSÖR 4 CLASS | F9: 1020 | H9: Adet | I9: 0 | J9: 0 | K9: 0 | L9: 0 | M9: 0 | N9: 0 | O9: =+F9+I9-J9-K9-L9-M9-N9 -> 1020 | P9: 0 | Q9: 0
A10: 8 | B10: 100 LÜK KROM AMORTİSÖR 3 CLASS | F10: 625 | H10: Adet | I10: 0 | J10: 0 | K10: 0 | L10: 100 | M10: 0 | N10: 0 | O10: =+F10+I10-J10-K10-L10-M10-N10 -> 525 | P10: 0 | Q10: 0
A11: 9 | B11: AMORTİSÖRÜ 200 LÜK | F11: 10 | H11: Adet | I11: 0 | J11: 0 | K11: 0 | L11: 0 | M11: 0 | N11: 0 | O11: =+F11+I11-J11-K11-L11-M11-N11 -> 10 | P11: 150 | Q11: 2000
A12: 10 | B12: AMORTİSÖR 120 LİK CROM 4 CLASS | F12: 18 | H12: Adet | I12: 0 | J12: 0 | K12: 0 | L12: 0 | M12: 0 | N12: 0 | O12: =+F12+I12-J12-K12-L12-M12-N12 -> 18 | P12: 0 | Q12: 0
A13: 11 | B13: YARASA ŞASE | F13: ='KASIM 3 HAFTA '!O14 -> 15 | H13: Adet | I13: 0 | J13: 0 | K13: 0 | L13: 0 | M13: 0 | N13: 0 | O13: =+F13+I13-J13-K13-L13-M13-N13 -> 15 | P13: 0 | Q13: 0
A14: 12 | B14: AMORTİSÖR 60 LIK 3 CLASS SİYAH | F14: 100 | H14: Adet | I14: 0 | J14: 0 | K14: 0 | L14: 0 | M14: 0 | N14: 20 | O14: =+F14+I14-J14-K14-L14-M14-N14 -> 80 | P14: 100 | Q14: 300
A15: 13 | B15: 140 LIK AMORTİSÖR 3 KLASS | F15: 160 | H15: Adet | I15: 0 | J15: 0 | K15: 0 | L15: 0 | M15: 0 | N15: 0 | O15: =+F15+I15-J15-K15-L15-M15-N15 -> 160 | P15: 0 | Q15: 0

Sheet ARALIK 4 HAFTA 
B1: ARALIK 4 HAFTA
A2: S.NO | B2: STOK ADI | F2: DEVİR MİK | H2: BİRİM | I2: GİRİŞ | J2: 44921 | K2: 44922 | L2: 44923 | M2: 44924 | N2: 44925 | O2: KALAN | P2: MİNİMUN | Q2: MAKSİMUN
A3: 1 | B3: ZZ.AMORTİSÖR 100 LÜK | F3: 2430 | H3: Adet | I3: 0 | J3: 40 | K3: 0 | L3: 3 | M3: 0 | N3: 240 | O3: =+F3+I3-J3-K3-L3-M3-N3 -> 2147 | P3: 1000 | Q3: 5000
A4: 2 | B4: ZZ.AMORTİSÖR 120 LÜK 3K | F4: 1056 | H4: Adet | I4: 0 | J4: 0 | K4: 0 | L4: 3 | M4: 0 | N4: 120 | O4: =+F4+I4-J4-K4-L4-M4-N4 -> 933 | P4: 500 | Q4: 3000
A5: 3 | B5: ZZ.AMORTİSÖR 80 LİK | F5: 3659 | H5: Adet | I5: 0 | J5: 0 | K5: 0 | L5: 0 | M5: 0 | N5: 0 | O5: =+F5+I5-J5-K5-L5-M5-N5 -> 3659 | P5: 300 | Q5: 3000
A6: 4 | B6: ZZ.AMORTİSÖR 140 LIK | F6: 288 | H6: Adet | I6: 0 | J6: 0 | K6: 0 | L6: 10 | M6: 0 | N6: 0 | O6: =+F6+I6-J6-K6-L6-M6-N6 -> 278 | P6: 200 | Q6: 2000
A7: 5 | B7: AMORTİSÖR 120 LİK CROM 3 CLASS | F7: 385 | H7: Adet | I7: 0 | J7: 0 | K7: 0 | L7: 0 | M7: 0 | N7: 0 | O7: =+F7+I7-J7-K7-L7-M7-N7 -> 385 | P7: 0 | Q7: 0
A8: 6 | B8: KONUM KORUYUCU D 26 KISA | F8: 60 | H8: Adet | I8: 500 | J8: 0 | K8: 0 | L8: 0 | M8: 0 | N8: 0 | O8: =+F8+I8-J8-K8-L8-M8-N8 -> 560 | P8: 100 | Q8: 500
A9: 7 | B9: 100 LÜK KROM AMORTİSÖR 4 CLASS | F9: 1020 | H9: Adet | I9: 0 | J9: 0 | K9: 0 | L9: 0 | M9: 0 | N9: 100 | O9: =+F9+I9-J9-K9-L9-M9-N9 -> 920 | P9: 0 | Q9: 0
A10: 8 | B10: 100 LÜK KROM AMORTİSÖR 3 CLASS | F10: 525 | H10: Adet | I10: 0 | J10: 0 | K10: 0 | L10: 0 | M10: 0 | N10: 0 | O10: =+F10+I10-J10-K10-L10-M10-N10 -> 525 | P10: 0 | Q10: 0
A11: 9 | B11: AMORTİSÖRÜ 200 LÜK | F11: 10 | H11: Adet | I11: 0 | J11: 0 | K11: 0 | L11: 10 | M11: 0 | N11: 0 | O11: =+F11+I11-J11-K11-L11-M11-N11 -> 0 | P11: 150 | Q11: 2000
A12: 10 | B12: AMORTİSÖR 120 LİK CROM 4 CLASS | F12: 18 | H12: Adet | I12: 0 | J12: 0 | K12: 0 | L12: 0 | M12: 0 | N12: 0 | O12: =+F12+I12-J12-K12-L12-M12-N12 -> 18 | P12: 0 | Q12: 0
A13: 11 | B13: YARASA ŞASE | F13: ='KASIM 3 HAFTA '!O14 -> 15 | H13: Adet | I13: 0 | J13: 0 | K13: 0 | L13: 0 | M13: 0 | N13: 0 | O13: =+F13+I13-J13-K13-L13-M13-N13 -> 15 | P13: 0 | Q13: 0
A14: 12 | B14: AMORTİSÖR 60 LIK 3 CLASS SİYAH | F14: 80 | H14: Adet | I14: 0 | J14: 0 | K14: 0 | L14: 0 | M14: 0 | N14: 0 | O14: =+F14+I14-J14-K14-L14-M14-N14 -> 80 | P14: 100 | Q14: 300
A15: 13 | B15: 140 LIK AMORTİSÖR 3 KLASS | F15: 160 | H15: Adet | I15: 0 | J15: 0 | K15: 0 | L15: 0 | M15: 0 | N15: 0 | O15: =+F15+I15-J15-K15-L15-M15-N15 -> 160 | P15: 0 | Q15: 0

Sheet OCAK 1 HAFTA
B1: OCAK 1 HAFTA
A2: S.NO | B2: STOK ADI | F2: DEVİR MİK | H2: BİRİM | I2: GİRİŞ | J2: 44928 | K2: 44929 | L2: 44930 | M2: 44931 | N2: 44932 | O2: KALAN | P2: MİNİMUN | Q2: MAKSİMUN
A3: 1 | B3: ZZ.AMORTİSÖR 100 LÜK | F3: 2340 | H3: Adet | I3: 0 | J3: 0 | K3: 0 | L3: 0 | M3: 60 | N3: 0 | O3: =+F3+I3-J3-K3-L3-M3-N3 -> 2280 | P3: 1000 | Q3: 5000
A4: 2 | B4: ZZ.AMORTİSÖR 120 LÜK 3K | F4: 280 | H4: Adet | I4: 0 | J4: 0 | K4: 0 | L4: 0 | M4: 0 | N4: 0 | O4: =+F4+I4-J4-K4-L4-M4-N4 -> 280 | P4: 500 | Q4: 3000
A5: 3 | B5: ZZ.AMORTİSÖR 80 LİK | F5: 3600 | H5: Adet | I5: 0 | J5: 0 | K5: 0 | L5: 0 | M5: 0 | N5: 0 | O5: =+F5+I5-J5-K5-L5-M5-N5 -> 3600 | P5: 300 | Q5: 3000
A6: 4 | B6: ZZ.AMORTİSÖR 140 LIK | F6: 260 | H6: Adet | I6: 0 | J6: 20 | K6: 0 | L6: 0 | M6: 0 | N6: 0 | O6: =+F6+I6-J6-K6-L6-M6-N6 -> 240 | P6: 200 | Q6: 2000
A7: 5 | B7: AMORTİSÖR 120 LİK CROM 3 CLASS | F7: 1120 | H7: Adet | I7: 3000 | J7: 0 | K7: 0 | L7: 0 | M7: 0 | N7: 0 | O7: =+F7+I7-J7-K7-L7-M7-N7 -> 4120 | P7: 0 | Q7: 0
A8: 6 | B8: KONUM KORUYUCU D 26 KISA | F8: 500 | H8: Adet | I8: 0 | J8: 0 | K8: 0 | L8: 2 | M8: 100 | N8: 0 | O8: =+F8+I8-J8-K8-L8-M8-N8 -> 398 | P8: 100 | Q8: 500
A9: 7 | B9: 100 LÜK KROM AMORTİSÖR 4 CLASS | F9: 760 | H9: Adet | I9: 0 | J9: 0 | K9: 0 | L9: 0 | M9: 0 | N9: 0 | O9: =+F9+I9-J9-K9-L9-M9-N9 -> 760 | P9: 0 | Q9: 0
A10: 8 | B10: 100 LÜK KROM AMORTİSÖR 3 CLASS | F10: 780 | H10: Adet | I10: 5000 | J10: 0 | K10: 0 | L10: 0 | M10: 0 | N10: 0 | O10: =+F10+I10-J10-K10-L10-M10-N10 -> 5780 | P10: 0 | Q10: 0
A11: 9 | B11: AMORTİSÖRÜ 200 LÜK | F11: 0 | H11: Adet | I11: 1000 | J11: 0 | K11: 0 | L11: 0 | M11: 10 | N11: 10 | O11: =+F11+I11-J11-K11-L11-M11-N11 -> 980 | P11: 150 | Q11: 2000
A12: 10 | B12: AMORTİSÖR 120 LİK CROM 4 CLASS | F12: 0 | H12: Adet | I12: 0 | J12: 0 | K12: 0 | L12: 0 | M12: 0 | N12: 0 | O12: =+F12+I12-J12-K12-L12-M12-N12 -> 0 | P12: 0 | Q12: 0
A13: 11 | B13: YARASA ŞASE | F13: 0 | H13: Adet | I13: 0 | J13: 0 | K13: 0 | L13: 0 | M13: 0 | N13: 0 | O13: =+F13+I13-J13-K13-L13-M13-N13 -> 0 | P13: 0 | Q13: 0
A14: 12 | B14: AMORTİSÖR 60 LIK 3 CLASS SİYAH | F14: 240 | H14: Adet | I14: 1000 | J14: 0 | K14: 0 | L14: 0 | M14: 0 | N14: 0 | O14: =+F14+I14-J14-K14-L14-M14-N14 -> 1240 | P14: 100 | Q14: 300
A15: 13 | B15: 140 LIK AMORTİSÖR 3 KLASS | F15: 160 | H15: Adet | I15: 7 | J15: 0 | K15: 0 | L15: 0 | M15: 0 | N15: 0 | O15: =+F15+I15-J15-K15-L15-M15-N15 -> 167 | P15: 0 | Q15: 0

Sheet OCAK 2 HAFTA 
B1: OCAK 2 HAFTA
A2: S.NO | B2: STOK ADI | F2: DEVİR MİK | H2: BİRİM | I2: GİRİŞ | J2: 44935 | K2: 44936 | L2: 44937 | M2: 44938 | N2: 44939 | O2: KALAN | P2: MİNİMUN | Q2: MAKSİMUN
A3: 1 | B3: ZZ.AMORTİSÖR 100 LÜK | F3: 2280 | H3: Adet | I3: 0 | J3: 0 | K3: 180 | L3: 100 | M3: 0 | N3: 0 | O3: =+F3+I3-J3-K3-L3-M3-N3 -> 2000 | P3: 1000 | Q3: 5000
A4: 2 | B4: ZZ.AMORTİSÖR 120 LÜK 3K | F4: 280 | H4: Adet | I4: 0 | J4: 0 | K4: 0 | L4: 0 | M4: 0 | N4: 0 | O4: =+F4+I4-J4-K4-L4-M4-N4 -> 280 | P4: 500 | Q4: 3000
A5: 3 | B5: ZZ.AMORTİSÖR 80 LİK | F5: 3600 | H5: Adet | I5: 0 | J5: 0 | K5: 0 | L5: 0 | M5: 0 | N5: 40 | O5: =+F5+I5-J5-K5-L5-M5-N5 -> 3560 | P5: 300 | Q5: 3000
A6: 4 | B6: ZZ.AMORTİSÖR 140 LIK | F6: 240 | H6: Adet | I6: 0 | J6: 0 | K6: 0 | L6: 0 | M6: 0 | N6: 0 | O6: =+F6+I6-J6-K6-L6-M6-N6 -> 240 | P6: 200 | Q6: 2000
A7: 5 | B7: AMORTİSÖR 120 LİK CROM 3 CLASS | F7: 4120 | H7: Adet | I7: 0 | J7: 0 | K7: 0 | L7: 0 | M7: 0 | N7: 20 | O7: =+F7+I7-J7-K7-L7-M7-N7 -> 4100 | P7: 0 | Q7: 0
A8: 6 | B8: KONUM KORUYUCU D 26 KISA | F8: 398 | H8: Adet | I8: 0 | J8: 0 | K8: 0 | L8: 0 | M8: 0 | N8: 0 | O8: =+F8+I8-J8-K8-L8-M8-N8 -> 398 | P8: 100 | Q8: 500
A9: 7 | B9: 100 LÜK KROM AMORTİSÖR 4 CLASS | F9: 760 | H9: Adet | I9: 0 | J9: 0 | K9: 0 | L9: 0 | M9: 0 | N9: 0 | O9: =+F9+I9-J9-K9-L9-M9-N9 -> 760 | P9: 0 | Q9: 0
A10: 8 | B10: 100 LÜK KROM AMORTİSÖR 3 CLASS | F10: 5780 | H10: Adet | I10: 0 | J10: 0 | K10: 0 | L10: 0 | M10: 0 | N10: 0 | O10: =+F10+I10-J10-K10-L10-M10-N10 -> 5780 | P10: 0 | Q10: 0
A11: 9 | B11: AMORTİSÖRÜ 200 LÜK | F11: 980 | H11: Adet | I11: 0 | J11: 0 | K11: 15 | L11: 0 | M11: 0 | N11: 10 | O11: =+F11+I11-J11-K11-L11-M11-N11 -> 955 | P11: 150 | Q11: 2000
A12: 10 | B12: AMORTİSÖR 120 LİK CROM 4 CLASS | F12: 0 | H12: Adet | I12: 0 | J12: 0 | K12: 0 | L12: 0 | M12: 0 | N12: 0 | O12: =+F12+I12-J12-K12-L12-M12-N12 -> 0 | P12: 0 | Q12: 0
A13: 11 | B13: YARASA ŞASE | F13: 0 | H13: Adet | I13: 0 | J13: 0 | K13: 0 | L13: 0 | M13: 0 | N13: 0 | O13: =+F13+I13-J13-K13-L13-M13-N13 -> 0 | P13: 0 | Q13: 0
A14: 12 | B14: AMORTİSÖR 60 LIK 3 CLASS SİYAH | F14: 1240 | H14: Adet | I14: 0 | J14: 0 | K14: 0 | L14: 0 | M14: 0 | N14: 20 | O14: =+F14+I14-J14-K14-L14-M14-N14 -> 1220 | P14: 100 | Q14: 300
A15: 13 | B15: 140 LIK AMORTİSÖR 3 KLASS | F15: 0 | H15: Adet | I15: 0 | J15: 0 | K15: 0 | L15: 0 | M15: 0 | N15: 0 | O15: =+F15+I15-J15-K15-L15-M15-N15 -> 0 | P15: 0 | Q15: 0

Sheet OCAK 3 HAFTA 
B1: OCAK 3 HAFTA
A2: S.NO | B2: STOK ADI | F2: DEVİR MİK | H2: BİRİM | I2: GİRİŞ | J2: 44942 | K2: 44943 | L2: 44944 | M2: 44945 | N2: 44946 | O2: KALAN | P2: MİNİMUN | Q2: MAKSİMUN
A3: 1 | B3: ZZ.AMORTİSÖR 100 LÜK | F3: 1720 | H3: Adet | I3: 0 | J3: 0 | K3: 0 | L3: 0 | M3: 100 | N3: 0 | O3: =+F3+I3-J3-K3-L3-M3-N3 -> 1620 | P3: 1000 | Q3: 5000
A4: 2 | B4: ZZ.AMORTİSÖR 120 LÜK | F4: 280 | H4: Adet | I4: 0 | J4: 0 | K4: 0 | L4: 0 | M4: 0 | N4: 0 | O4: =+F4+I4-J4-K4-L4-M4-N4 -> 280 | P4: 500 | Q4: 3000
A5: 3 | B5: ZZ.AMORTİSÖR 80 LİK | F5: 3530 | H5: Adet | I5: 0 | J5: 0 | K5: 0 | L5: 0 | M5: 0 | N5: 0 | O5: =+F5+I5-J5-K5-L5-M5-N5 -> 3530 | P5: 300 | Q5: 3000
A6: 4 | B6: ZZ.AMORTİSÖR 140 LIK | F6: 80 | H6: Adet | I6: 0 | J6: 0 | K6: 0 | L6: 0 | M6: 0 | N6: 0 | O6: =+F6+I6-J6-K6-L6-M6-N6 -> 80 | P6: 200 | Q6: 2000
A7: 5 | B7: AMORTİSÖR 120 LİK CROM 3 CLASS | F7: 4060 | H7: Adet | I7: 0 | J7: 0 | K7: 60 | L7: 0 | M7: 0 | N7: 0 | O7: =+F7+I7-J7-K7-L7-M7-N7 -> 4000 | P7: 0 | Q7: 0
A8: 6 | B8: KONUM KORUYUCU D 26 KISA | F8: 340 | H8: Adet | I8: 0 | J8: 0 | K8: 0 | L8: 0 | M8: 100 | N8: 0 | O8: =+F8+I8-J8-K8-L8-M8-N8 -> 240 | P8: 100 | Q8: 500
A9: 7 | B9: 100 LÜK KROM AMORTİSÖR 4 CLASS | F9: 850 | H9: Adet | I9: 0 | J9: 0 | K9: 0 | L9: 0 | M9: 0 | N9: 0 | O9: =+F9+I9-J9-K9-L9-M9-N9 -> 850 | P9: 0 | Q9: 0
A10: 8 | B10: 100 LÜK KROM AMORTİSÖR 3 CLASS | F10: 5300 | H10: Adet | I10: 0 | J10: 0 | K10: 260 | L10: 0 | M10: 0 | N10: 6 | O10: =+F10+I10-J10-K10-L10-M10-N10 -> 5034 | P10: 0 | Q10: 0
A11: 9 | B11: AMORTİSÖRÜ 200 LÜK | F11: 955 | H11: Adet | I11: 0 | J11: 0 | K11: 1 | L11: 0 | M11: 0 | N11: 1 | O11: =+F11+I11-J11-K11-L11-M11-N11 -> 953 | P11: 150 | Q11: 2000
A12: 10 | B12: AMORTİSÖR 120 LİK CROM 4 CLASS | F12: 0 | H12: Adet | I12: 0 | J12: 0 | K12: 0 | L12: 0 | M12: 0 | N12: 0 | O12: =+F12+I12-J12-K12-L12-M12-N12 -> 0 | P12: 0 | Q12: 0
A13: 11 | B13: YARASA ŞASE | F13: 0 | H13: Adet | I13: 0 | J13: 0 | K13: 0 | L13: 0 | M13: 0 | N13: 0 | O13: =+F13+I13-J13-K13-L13-M13-N13 -> 0 | P13: 0 | Q13: 0
A14: 12 | B14: AMORTİSÖR 60 LIK 3 CLASS SİYAH | F14: 1060 | H14: Adet | I14: 0 | J14: 0 | K14: 0 | L14: 0 | M14: 0 | N14: 0 | O14: =+F14+I14-J14-K14-L14-M14-N14 -> 1060 | P14: 100 | Q14: 300
A15: 13 | B15: 140 LIK AMORTİSÖR 3 KLASS | F15: 1500 | H15: Adet | I15: 0 | J15: 0 | K15: 0 | L15: 500 | M15: 0 | N15: 0 | O15: =+F15+I15-J15-K15-L15-M15-N15 -> 1000 | P15: 0 | Q15: 0

Sheet OCAK 4 HAFTA 
B1: OCAK 4 HAFTA
A2: S.NO | B2: STOK ADI | F2: DEVİR MİK | H2: BİRİM | I2: GİRİŞ | J2: 44949 | K2: 44950 | L2: 44951 | M2: 44952 | N2: 44953 | O2: KALAN | P2: MİNİMUN | Q2: MAKSİMUN
A3: 1 | B3: ZZ.AMORTİSÖR 100 LÜK | F3: 1620 | H3: Adet | I3: 0 | J3: 0 | K3: 0 | L3: 0 | M3: 40 | N3: 40 | O3: =+F3+I3-J3-K3-L3-M3-N3 -> 1540 | P3: 1000 | Q3: 5000
A4: 2 | B4: ZZ.AMORTİSÖR 120 LÜK | F4: 280 | H4: Adet | I4: 0 | J4: 0 | K4: 0 | L4: 0 | M4: 0 | N4: 0 | O4: =+F4+I4-J4-K4-L4-M4-N4 -> 280 | P4: 500 | Q4: 3000
A5: 3 | B5: ZZ.AMORTİSÖR 80 LİK | F5: 3530 | H5: Adet | I5: 0 | J5: 0 | K5: 0 | L5: 0 | M5: 0 | N5: 0 | O5: =+F5+I5-J5-K5-L5-M5-N5 -> 3530 | P5: 300 | Q5: 3000
A6: 4 | B6: ZZ.AMORTİSÖR 140 LIK | F6: 80 | H6: Adet | I6: 0 | J6: 0 | K6: 0 | L6: 0 | M6: 0 | N6: 0 | O6: =+F6+I6-J6-K6-L6-M6-N6 -> 80 | P6: 200 | Q6: 2000
A7: 5 | B7: AMORTİSÖR 120 LİK CROM 3 CLASS | F7: 4000 | H7: Adet | I7: 0 | J7: 0 | K7: 0 | L7: 0 | M7: 0 | N7: 0 | O7: =+F7+I7-J7-K7-L7-M7-N7 -> 4000 | P7: 0 | Q7: 0
A8: 6 | B8: KONUM KORUYUCU D 26 KISA | F8: 240 | H8: Adet | I8: 0 | J8: 0 | K8: 0 | L8: 0 | M8: 0 | N8: 0 | O8: =+F8+I8-J8-K8-L8-M8-N8 -> 240 | P8: 100 | Q8: 500
A9: 7 | B9: 100 LÜK KROM AMORTİSÖR 4 CLASS | F9: 850 | H9: Adet | I9: 0 | J9: 0 | K9: 0 | L9: 0 | M9: 0 | N9: 0 | O9: =+F9+I9-J9-K9-L9-M9-N9 -> 850 | P9: 0 | Q9: 0
A10: 8 | B10: 100 LÜK KROM AMORTİSÖR 3 CLASS | F10: 5034 | H10: Adet | I10: 0 | J10: 0 | K10: 0 | L10: 0 | M10: 0 | N10: 0 | O10: =+F10+I10-J10-K10-L10-M10-N10 -> 5034 | P10: 0 | Q10: 0
A11: 9 | B11: AMORTİSÖRÜ 200 LÜK | F11: 953 | H11: Adet | I11: 0 | J11: 0 | K11: 0 | L11: 10 | M11: 10 | N11: 0 | O11: =+F11+I11-J11-K11-L11-M11-N11 -> 933 | P11: 150 | Q11: 2000
A12: 10 | B12: AMORTİSÖR 120 LİK CROM 4 CLASS | F12: 0 | H12: Adet | I12: 0 | J12: 0 | K12: 0 | L12: 0 | M12: 0 | N12: 0 | O12: =+F12+I12-J12-K12-L12-M12-N12 -> 0 | P12: 0 | Q12: 0
A13: 11 | B13: YARASA ŞASE | F13: 0 | H13: Adet | I13: 0 | J13: 0 | K13: 0 | L13: 0 | M13: 0 | N13: 0 | O13: =+F13+I13-J13-K13-L13-M13-N13 -> 0 | P13: 0 | Q13: 0
A14: 12 | B14: AMORTİSÖR 60 LIK 3 CLASS SİYAH | F14: 1060 | H14: Adet | I14: 0 | J14: 0 | K14: 0 | L14: 0 | M14: 0 | N14: 20 | O14: =+F14+I14-J14-K14-L14-M14-N14 -> 1040 | P14: 100 | Q14: 300
A15: 13 | B15: 140 LIK AMORTİSÖR 3 KLASS | F15: 1000 | H15: Adet | I15: 0 | J15: 0 | K15: 0 | L15: 0 | M15: 0 | N15: 0 | O15: =+F15+I15-J15-K15-L15-M15-N15 -> 1000 | P15: 0 | Q15: 0

Sheet OCAK5-ŞUBAT 1 HAFTA 
B1: OCAK5 -ŞUBAT 1 HAFTA
A2: S.NO | B2: STOK ADI | F2: DEVİR MİK | H2: BİRİM | I2: GİRİŞ | J2: 44956 | K2: 44957 | L2: 44958 | M2: 44959 | N2: 44960 | O2: KALAN | P2: MİNİMUN | Q2: MAKSİMUN
A3: 1 | B3: ZZ.AMORTİSÖR 100 LÜK | F3: 1540 | H3: Adet | I3: 0 | J3: 40 | K3: 40 | L3: 0 | M3: 160 | N3: 240 | O3: =+F3+I3-J3-K3-L3-M3-N3 -> 1060 | P3: 1000 | Q3: 5000
A4: 2 | B4: ZZ.AMORTİSÖR 120 LÜK | F4: 280 | H4: Adet | I4: 0 | J4: 0 | K4: 0 | L4: 0 | M4: 0 | N4: 20 | O4: =+F4+I4-J4-K4-L4-M4-N4 -> 260 | P4: 500 | Q4: 3000
A5: 3 | B5: ZZ.AMORTİSÖR 80 LİK | F5: 3530 | H5: Adet | I5: 0 | J5: 0 | K5: 20 | L5: 0 | M5: 0 | N5: 20 | O5: =+F5+I5-J5-K5-L5-M5-N5 -> 3490 | P5: 300 | Q5: 3000
A6: 4 | B6: ZZ.AMORTİSÖR 140 LIK | F6: 80 | H6: Adet | I6: 0 | J6: 0 | K6: 0 | L6: 0 | M6: 20 | N6: 0 | O6: =+F6+I6-J6-K6-L6-M6-N6 -> 60 | P6: 200 | Q6: 2000
A7: 5 | B7: AMORTİSÖR 120 LİK CROM 3 CLASS | F7: 4000 | H7: Adet | I7: 0 | J7: 0 | K7: 0 | L7: 0 | M7: 0 | N7: 0 | O7: =+F7+I7-J7-K7-L7-M7-N7 -> 4000 | P7: 0 | Q7: 0
A8: 6 | B8: KONUM KORUYUCU D 26 KISA | F8: 240 | H8: Adet | I8: 0 | J8: 0 | K8: 0 | L8: 0 | M8: 0 | N8: 100 | O8: =+F8+I8-J8-K8-L8-M8-N8 -> 140 | P8: 100 | Q8: 500
A9: 7 | B9: 100 LÜK KROM AMORTİSÖR 4 CLASS | F9: 0 | H9: Adet | I9: 2500 | J9: 0 | K9: 0 | L9: 0 | M9: 140 | N9: 120 | O9: =+F9+I9-J9-K9-L9-M9-N9 -> 2240 | P9: 0 | Q9: 0
A10: 8 | B10: 100 LÜK KROM AMORTİSÖR 3 CLASS | F10: 5034 | H10: Adet | I10: 0 | J10: 0 | K10: 0 | L10: 0 | M10: 0 | N10: 0 | O10: =+F10+I10-J10-K10-L10-M10-N10 -> 5034 | P10: 0 | Q10: 0
A11: 9 | B11: AMORTİSÖRÜ 200 LÜK | F11: 933 | H11: Adet | I11: 0 | J11: 10 | K11: 0 | L11: 0 | M11: 0 | N11: 0 | O11: =+F11+I11-J11-K11-L11-M11-N11 -> 923 | P11: 150 | Q11: 2000
A12: 10 | B12: AMORTİSÖR 120 LİK CROM 4 CLASS | F12: 0 | H12: Adet | I12: 0 | J12: 0 | K12: 0 | L12: 0 | M12: 0 | N12: 0 | O12: =+F12+I12-J12-K12-L12-M12-N12 -> 0 | P12: 0 | Q12: 0
A13: 11 | B13: 100 LÜK AQMORT 4 CLS. BEYAZ | F13: 710 | H13: Adet | I13: 0 | J13: 0 | K13: 0 | L13: 0 | M13: 0 | N13: 0 | O13: =+F13+I13-J13-K13-L13-M13-N13 -> 710 | P13: 0 | Q13: 0
A14: 12 | B14: AMORTİSÖR 60 LIK 3 CLASS SİYAH | F14: 1040 | H14: Adet | I14: 0 | J14: 0 | K14: 0 | L14: 0 | M14: 0 | N14: 0 | O14: =+F14+I14-J14-K14-L14-M14-N14 -> 1040 | P14: 100 | Q14: 300
A15: 13 | B15: 140 LIK AMORTİSÖR 3 KLASS | F15: 1000 | H15: Adet | I15: 0 | J15: 0 | K15: 0 | L15: 0 | M15: 0 | N15: 0 | O15: =+F15+I15-J15-K15-L15-M15-N15 -> 1000 | P15: 0 | Q15: 0

Sheet MART 3 HAFTA
B1: MART 3 HAFTA
A2: S.NO | B2: STOK ADI | F2: DEVİR MİK | H2: BİRİM | I2: GİRİŞ | J2: 45005 | K2: 45006 | L2: 45007 | M2: 45072 | N2: 45051 | O2: KALAN | P2: MİNİMUN | Q2: MAKSİMUN
A3: 1 | B3: ZZ.AMORTİSÖR 100 LÜK | F3: 1060 | H3: Adet | I3: 0 | J3: 194 | K3: 10 | L3: 0 | M3: 115 | N3: 16 | O3: =+F3+I3-J3-K3-L3-M3-N3 -> 725 | P3: 1000 | Q3: 5000
A4: 2 | B4: ZZ.AMORTİSÖR 120 LÜK | F4: 260 | H4: Adet | I4: 0 | J4: 0 | K4: 0 | L4: 0 | M4: 0 | N4: 0 | O4: =+F4+I4-J4-K4-L4-M4-N4 -> 260 | P4: 500 | Q4: 3000
A5: 3 | B5: ZZ.AMORTİSÖR 80 LİK | F5: 3490 | H5: Adet | I5: 0 | J5: 0 | K5: 0 | L5: 0 | M5: 80 | N5: 0 | O5: =+F5+I5-J5-K5-L5-M5-N5 -> 3410 | P5: 300 | Q5: 3000
A6: 4 | B6: ZZ.AMORTİSÖR 140 LIK | F6: 60 | H6: Adet | I6: 0 | J6: 0 | K6: 5 | L6: 0 | M6: 0 | N6: 0 | O6: =+F6+I6-J6-K6-L6-M6-N6 -> 55 | P6: 200 | Q6: 2000
A7: 5 | B7: AMORTİSÖR 120 LİK CROM 3 CLASS | F7: 4000 | H7: Adet | I7: 0 | J7: 0 | K7: 0 | L7: 0 | M7: 0 | N7: 0 | O7: =+F7+I7-J7-K7-L7-M7-N7 -> 4000 | P7: 0 | Q7: 0
A8: 6 | B8: KONUM KORUYUCU D 26 KISA | F8: 140 | H8: Adet | I8: 0 | J8: 0 | K8: 40 | L8: 0 | M8: 20 | N8: 0 | O8: =+F8+I8-J8-K8-L8-M8-N8 -> 80 | P8: 100 | Q8: 500
A9: 7 | B9: 100 LÜK KROM AMORTİSÖR 4 CLASS | F9: 2240 | H9: Adet | I9: 0 | J9: 0 | K9: 0 | L9: 0 | M9: 2240 | N9: 0 | O9: =+F9+I9-J9-K9-L9-M9-N9 -> 0 | P9: 0 | Q9: 0
A10: 8 | B10: 100 LÜK KROM AMORTİSÖR 3 CLASS | F10: 5034 | H10: Adet | I10: 0 | J10: 0 | K10: 0 | L10: 0 | M10: 0 | N10: 0 | O10: =+F10+I10-J10-K10-L10-M10-N10 -> 5034 | P10: 0 | Q10: 0
A11: 9 | B11: AMORTİSÖRÜ 200 LÜK | F11: 923 | H11: Adet | I11: 0 | J11: 4 | K11: 0 | L11: 0 | M11: 5 | N11: 300 | O11: =+F11+I11-J11-K11-L11-M11-N11 -> 614 | P11: 150 | Q11: 2000
A12: 10 | B12: AMORTİSÖR 120 LİK CROM 4 CLASS | F12: 0 | H12: Adet | I12: 0 | J12: 0 | K12: 0 | L12: 0 | M12: 0 | N12: 0 | O12: =+F12+I12-J12-K12-L12-M12-N12 -> 0 | P12: 0 | Q12: 0
A13: 11 | B13: YARASA ŞASE | F13: 0 | H13: Adet | I13: 0 | J13: 0 | K13: 0 | L13: 0 | M13: 0 | N13: 0 | O13: =+F13+I13-J13-K13-L13-M13-N13 -> 0 | P13: 0 | Q13: 0
A14: 12 | B14: AMORTİSÖR 60 LIK 3 CLASS SİYAH | F14: 1040 | H14: Adet | I14: 0 | J14: 0 | K14: 0 | L14: 0 | M14: 0 | N14: 0 | O14: =+F14+I14-J14-K14-L14-M14-N14 -> 1040 | P14: 100 | Q14: 300
A15: 13 | B15: 140 LIK AMORTİSÖR 3 KLASS | F15: 1000 | H15: Adet | I15: 0 | J15: 0 | K15: 0 | L15: 0 | M15: 0 | N15: 0 | O15: =+F15+I15-J15-K15-L15-M15-N15 -> 1000 | P15: 0 | Q15: 0

Sheet HAZ.TEM.2023
B1: HAZİRAN HAFTA
A2: S.NO | B2: STOK ADI | F2: DEVİR MİK | H2: BİRİM | I2: GİRİŞ | J2: 45083 | K2: 45096 | L2: 45100 | M2: 45114 | N2: 45122 | O2: KALAN | P2: MİNİMUN | Q2: MAKSİMUN
A3: 1 | B3: ZZ.AMORTİSÖR 100 LÜK | F3: 725 | H3: Adet | I3: 0 | J3: 0 | K3: 20 | L3: 0 | M3: 100 | N3: 0 | O3: =+F3+I3-J3-K3-L3-M3-N3 -> 605 | P3: 1000 | Q3: 5000
A4: 2 | B4: ZZ.AMORTİSÖR 120 LÜK | F4: 260 | H4: Adet | I4: 0 | J4: 0 | K4: 0 | L4: 0 | M4: 100 | N4: 60 | O4: =+F4+I4-J4-K4-L4-M4-N4 -> 100 | P4: 500 | Q4: 3000
A5: 3 | B5: ZZ.AMORTİSÖR 80 LİK | F5: 3410 | H5: Adet | I5: 0 | J5: 0 | K5: 0 | L5: 0 | M5: 60 | N5: 120 | O5: =+F5+I5-J5-K5-L5-M5-N5 -> 3230 | P5: 300 | Q5: 3000
A6: 4 | B6: ZZ.AMORTİSÖR 140 LIK | F6: 55 | H6: Adet | I6: 0 | J6: 0 | K6: 0 | L6: 0 | M6: 0 | N6: 0 | O6: =+F6+I6-J6-K6-L6-M6-N6 -> 55 | P6: 200 | Q6: 2000
A7: 5 | B7: AMORTİSÖR 120 LİK CROM 3 CLASS | F7: 4000 | H7: Adet | I7: 0 | J7: 0 | K7: 10 | L7: 0 | M7: 0 | N7: 60 | O7: =+F7+I7-J7-K7-L7-M7-N7 -> 3930 | P7: 0 | Q7: 0
A8: 6 | B8: KONUM KORUYUCU D 26 KISA | F8: 80 | H8: Adet | I8: 500 | J8: 80 | K8: 0 | L8: 0 | M8: 0 | N8: 0 | O8: =+F8+I8-J8-K8-L8-M8-N8 -> 500 | P8: 100 | Q8: 500
A9: 7 | B9: 100 LÜK KROM AMORTİSÖR 4 CLASS | F9: 0 | H9: Adet | I9: 0 | J9: 0 | K9: 0 | L9: 0 | M9: 0 | N9: 0 | O9: =+F9+I9-J9-K9-L9-M9-N9 -> 0 | P9: 0 | Q9: 0
A10: 8 | B10: 100 LÜK KROM AMORTİSÖR 3 CLASS | F10: 5034 | H10: Adet | I10: 0 | J10: 0 | K10: 0 | L10: 160 | M10: 0 | N10: 300 | O10: =+F10+I10-J10-K10-L10-M10-N10 -> 4574 | P10: 1000 | Q10: 5000
A11: 9 | B11: AMORTİSÖRÜ 200 LÜK | F11: 614 | H11: Adet | I11: 0 | J11: 7 | K11: 0 | L11: 0 | M11: 0 | N11: 4 | O11: =+F11+I11-J11-K11-L11-M11-N11 -> 603 | P11: 150 | Q11: 2000
A12: 10 | B12: AMORTİSÖR 120 LİK CROM 4 CLASS | F12: 0 | H12: Adet | I12: 0 | J12: 0 | K12: 0 | L12: 0 | M12: 0 | N12: 0 | O12: =+F12+I12-J12-K12-L12-M12-N12 -> 0 | P12: 0 | Q12: 0
A13: 11 | B13: YARASA ŞASE | F13: 0 | H13: Adet | I13: 0 | J13: 0 | K13: 0 | L13: 0 | M13: 0 | N13: 0 | O13: =+F13+I13-J13-K13-L13-M13-N13 -> 0 | P13: 0 | Q13: 0
A14: 12 | B14: AMORTİSÖR 60 LIK 3 CLASS SİYAH | F14: 1040 | H14: Adet | I14: 0 | J14: 0 | K14: 0 | L14: 0 | M14: 40 | N14: 60 | O14: =+F14+I14-J14-K14-L14-M14-N14 -> 940 | P14: 100 | Q14: 300
A15: 13 | B15: 140 LIK AMORTİSÖR 3 KLASS | F15: 1000 | H15: Adet | I15: 0 | J15: 0 | K15: 0 | L15: 0 | M15: 0 | N15: 0 | O15: =+F15+I15-J15-K15-L15-M15-N15 -> 1000 | P15: 0 | Q15: 0

Sheet TEMMUZ 2023
B1: TEMMUZ HAFTA
A2: S.NO | B2: STOK ADI | F2: DEVİR MİK | H2: BİRİM | I2: GİRİŞ | J2: 45128 | K2: 45133 | L2: 45133 | M2: 45136 | N2: 45138 | O2: KALAN | P2: MİNİMUN | Q2: MAKSİMUN
A3: 1 | B3: ZZ.AMORTİSÖR 100 LÜK | F3: 605 | H3: Adet | I3: 0 | J3: 0 | K3: 240 | L3: 0 | M3: 0 | N3: 0 | O3: =+F3+I3-J3-K3-L3-M3-N3 -> 365 | P3: 1000 | Q3: 5000
A4: 2 | B4: ZZ.AMORTİSÖR 120 LÜK | F4: 100 | H4: Adet | I4: 0 | J4: 20 | K4: 0 | L4: 0 | M4: 0 | N4: 0 | O4: =+F4+I4-J4-K4-L4-M4-N4 -> 80 | P4: 500 | Q4: 3000
A5: 3 | B5: ZZ.AMORTİSÖR 80 LİK | F5: 3230 | H5: Adet | I5: 0 | J5: 0 | K5: 0 | L5: 0 | M5: 0 | N5: 0 | O5: =+F5+I5-J5-K5-L5-M5-N5 -> 3230 | P5: 300 | Q5: 3000
A6: 4 | B6: ZZ.AMORTİSÖR 140 LIK | F6: 55 | H6: Adet | I6: 0 | J6: 0 | K6: 0 | L6: 0 | M6: 0 | N6: 0 | O6: =+F6+I6-J6-K6-L6-M6-N6 -> 55 | P6: 200 | Q6: 2000
A7: 5 | B7: AMORTİSÖR 120 LİK CROM 3 CLASS | F7: 3930 | H7: Adet | I7: 0 | J7: 0 | K7: 100 | L7: 0 | M7: 0 | N7: 0 | O7: =+F7+I7-J7-K7-L7-M7-N7 -> 3830 | P7: 0 | Q7: 0
A8: 6 | B8: KONUM KORUYUCU D 26 KISA | F8: 500 | H8: Adet | I8: 0 | J8: 0 | K8: 20 | L8: 0 | M8: 0 | N8: 0 | O8: =+F8+I8-J8-K8-L8-M8-N8 -> 480 | P8: 100 | Q8: 500
A9: 7 | B9: 100 LÜK KROM AMORTİSÖR 4 CLASS | F9: 0 | H9: Adet | I9: 0 | J9: 0 | K9: 0 | L9: 0 | M9: 0 | N9: 0 | O9: =+F9+I9-J9-K9-L9-M9-N9 -> 0 | P9: 0 | Q9: 0
A10: 8 | B10: 100 LÜK KROM AMORTİSÖR 3 CLASS | F10: 4574 | H10: Adet | I10: 0 | J10: 0 | K10: 0 | L10: 0 | M10: 0 | N10: 0 | O10: =+F10+I10-J10-K10-L10-M10-N10 -> 4574 | P10: 1000 | Q10: 5000
A11: 9 | B11: AMORTİSÖRÜ 200 LÜK | F11: 603 | H11: Adet | I11: 0 | J11: 14 | K11: 0 | L11: 0 | M11: 0 | N11: 0 | O11: =+F11+I11-J11-K11-L11-M11-N11 -> 589 | P11: 150 | Q11: 2000
A12: 10 | B12: AMORTİSÖR 120 LİK CROM 4 CLASS | F12: 0 | H12: Adet | I12: 0 | J12: 0 | K12: 0 | L12: 0 | M12: 0 | N12: 0 | O12: =+F12+I12-J12-K12-L12-M12-N12 -> 0 | P12: 0 | Q12: 0
A13: 11 | B13: YARASA ŞASE | F13: 0 | H13: Adet | I13: 0 | J13: 0 | K13: 0 | L13: 0 | M13: 0 | N13: 0 | O13: =+F13+I13-J13-K13-L13-M13-N13 -> 0 | P13: 0 | Q13: 0
A14: 12 | B14: AMORTİSÖR 60 LIK 3 CLASS SİYAH | F14: 940 | H14: Adet | I14: 0 | J14: 0 | K14: 0 | L14: 0 | M14: 0 | N14: 0 | O14: =+F14+I14-J14-K14-L14-M14-N14 -> 940 | P14: 100 | Q14: 300
A15: 13 | B15: 140 LIK AMORTİSÖR 3 KLASS | F15: 1000 | H15: Adet | I15: 0 | J15: 0 | K15: 0 | L15: 0 | M15: 0 | N15: 0 | O15: =+F15+I15-J15-K15-L15-M15-N15 -> 1000 | P15: 0 | Q15: 0

Sheet AĞUSTOS 2023 
B1: 45139
A2: S.NO | B2: STOK ADI | F2: DEVİR MİK | H2: BİRİM | I2: GİRİŞ | J2: 45145 | K2: 45152 | L2: 45159 | M2: 45166 | N2: 45169 | O2: KALAN | P2: MİNİMUN | Q2: MAKSİMUN
A3: 1 | B3: ZZ.AMORTİSÖR 100 LÜK | F3: 0 | H3: Adet | I3: 0 | J3: 0 | K3: 0 | L3: 0 | M3: 0 | N3: 0 | O3: =+F3+I3-J3-K3-L3-M3-N3 -> 0 | P3: 1000 | Q3: 5000
A4: 2 | B4: ZZ.AMORTİSÖR 120 LÜK | F4: 0 | H4: Adet | I4: 0 | J4: 0 | K4: 0 | L4: 0 | M4: 0 | N4: 0 | O4: =+F4+I4-J4-K4-L4-M4-N4 -> 0 | P4: 500 | Q4: 3000
A5: 3 | B5: ZZ.AMORTİSÖR 80 LİK | F5: 2765 | H5: Adet | I5: 0 | J5: 0 | K5: 100 | L5: 40 | M5: 0 | N5: 0 | O5: =+F5+I5-J5-K5-L5-M5-N5 -> 2625 | P5: 300 | Q5: 3000
A6: 4 | B6: ZZ.AMORTİSÖR 140 LIK | F6: 0 | H6: Adet | I6: 0 | J6: 0 | K6: 0 | L6: 0 | M6: 0 | N6: 0 | O6: =+F6+I6-J6-K6-L6-M6-N6 -> 0 | P6: 200 | Q6: 2000
A7: 5 | B7: AMORTİSÖR 120 LİK 3 CLASS | F7: 3515 | H7: Adet | I7: 0 | J7: 120 | K7: 21 | L7: 300 | M7: 40 | N7: 0 | O7: =+F7+I7-J7-K7-L7-M7-N7 -> 3034 | P7: 0 | Q7: 0
A8: 6 | B8: KONUM KORUYUCU D 26 KISA | F8: 480 | H8: Adet | I8: 0 | J8: 0 | K8: 40 | L8: 0 | M8: 0 | N8: 20 | O8: =+F8+I8-J8-K8-L8-M8-N8 -> 420 | P8: 100 | Q8: 500
A9: 7 | B9: 100 LÜK KROM AMORTİSÖR 4 CLASS | F9: 1210 | H9: Adet | I9: 0 | J9: 0 | K9: 0 | L9: 0 | M9: 0 | N9: 0 | O9: =+F9+I9-J9-K9-L9-M9-N9 -> 1210 | P9: 0 | Q9: 0
A10: 8 | B10: 100 LÜK AMORTİSÖR 3 CLASS | F10: 4920 | H10: Adet | I10: 0 | J10: 0 | K10: 95 | L10: 580 | M10: 0 | N10: 0 | O10: =+F10+I10-J10-K10-L10-M10-N10 -> 4245 | P10: 1000 | Q10: 5000
A11: 9 | B11: AMORTİSÖRÜ 200 LÜK SİYAH | F11: 358 | H11: Adet | I11: 0 | J11: 0 | K11: 0 | L11: 2 | M11: 0 | N11: 10 | O11: =+F11+I11-J11-K11-L11-M11-N11 -> 346 | P11: 150 | Q11: 2000
A12: 10 | B12: AMORTİSÖR 60 LIK 3 CLASS SİYAH | F12: 740 | H12: Adet | I12: 0 | J12: 0 | K12: 0 | L12: 0 | M12: 0 | N12: 0 | O12: =+F12+I12-J12-K12-L12-M12-N12 -> 740 | P12: 200 | Q12: 0
A13: 11 | B13: 140 LIK AMORTİSÖR 3 KLASS | F13: 1040 | H13: Adet | I13: 0 | J13: 0 | K13: 0 | L13: 20 | M13: 0 | N13: 0 | O13: =+F13+I13-J13-K13-L13-M13-N13 -> 1020 | P13: 500 | Q13: 1000
A14: 12 | B14: AMORTİSÖRÜ 200 LÜK KROM | F14: 125 | H14: Adet | I14: 0 | J14: 0 | K14: 0 | L14: 0 | M14: 0 | N14: 0 | O14: =+F14+I14-J14-K14-L14-M14-N14 -> 125 | P14: 0 | Q14: 0
A15: 13 | F15: 0 | H15: Adet | I15: 0 | J15: 0 | K15: 0 | L15: 0 | M15: 0 | N15: 0 | O15: =+F15+I15-J15-K15-L15-M15-N15 -> 0 | P15: 0 | Q15: 0

Sheet EYLÜL 2023
B1: 45170
