Workbook
Name PENTA: 'AĞUSTOS 2023'!$K$5
Name PENTA: 'AĞUSTOS 2024'!$K$5
Name PENTA: 'AĞUSTOS 2025'!$K$5
Name PENTA: 'ARALIK 1 HAFTA'!$K$5
Name PENTA: 'ARALIK 2 HAFTA '!$K$5
Name PENTA: 'ARALIK 2025'!$K$5
Name PENTA: 'ARALIK 3 HAFTA '!$K$5
Name PENTA: 'ARALIK 4 HAFTA '!$K$5
Name PENTA: ARALIK2023!$K$5
Name PENTA: 'ekim 1 hafta'!$K$5
Name PENTA: 'ekim 2 hafta '!$K$5
Name PENTA: 'EKİM 2023'!$K$5
Name PENTA: 'EKİM 2024'!$K$5
Name PENTA: 'EKİM 2025'!$K$5
Name PENTA: 'ekim 3 hafta'!$K$5
Name PENTA: 'ekim 4 hafta '!$K$5
Name PENTA: 'EYLÜL 2023'!$K$5
Name PENTA: 'EYLÜL 2024'!$K$5
Name PENTA: 'EYLÜL 2025'!$K$5
Name PENTA: 'HAZİRAN 2024'!$K$5
Name PENTA: 'HAZİRAN 2025'!$K$5
Name PENTA: 'HAZ-TEM.2023'!$K$5
Name PENTA: 'KASIM 1 HAFTA'!$K$5
Name PENTA: 'KASIM 2 HAFTA '!$K$5
Name PENTA: 'KASIM 2023'!$K$5
Name PENTA: 'KASIM 2024'!$K$5
Name PENTA: 'KASIM 2025'!$K$5
Name PENTA: 'KASIM 3 HAFTA '!$K$5
Name PENTA: 'KASIM 4 HAFTA '!$K$5
Name PENTA: 'KASIM 5 HAFTA '!$K$5
Name PENTA: 'MART 2024'!$K$5
Name PENTA: 'MART 2025'!$K$5
Name PENTA: 'MART-NİSAN'!$K$5
Name PENTA: 'MAYIS 2024'!$K$5
Name PENTA: 'MAYIS 2025'!$K$5
Name PENTA: 'NİSAN 2024'!$K$5
Name PENTA: 'NİSAN 2025'!$K$5
Name PENTA: 'OCAK 1 HAFTA'!$K$5
Name PENTA: 'OCAK 2 HAFTA '!$K$5
Name PENTA: 'OCAK 2024'!$K$5
Name PENTA: 'OCAK 2025'!$K$5
Name PENTA: 'OCAK 2026'!$K$5
Name PENTA: 'OCAK 3 HAFTA '!$K$5
Name PENTA: 'OCAK 4 HAFTA '!$K$5
Name PENTA: 'OCAK 5..ŞUBAT 1 HAFTA '!$K$5
Name PENTA: 'ŞUBAT 2024'!$K$5
Name PENTA: 'ŞUBAT 2025'!$K$5
Name PENTA: 'ŞUBAT 2026'!$K$5
Name PENTA: 'TEMMUZ 2023'!$K$5
Name PENTA: 'TEMMUZ 2024'!$K$5
Name PENTA: 'TEMMUZ 2025'!$K$5
Name PENTA: 'eylül 4 hafta'!$K$5

Sheet eylül 4 hafta
P1: =+H1+J1-K1-L1-M1-N1-O1 -> 0
O2: 13.09.2022 10:30:27
A3: S.NO | D3: ÜRÜN ADI | H3: ADET | I3: BİRİM | J3: GİRİŞ | K3: 44830 | L3: 44831 | M3: 44832 | N3: 44833 | O3: 44834 | P3: KALAN
A4: 1 | D4: ZZ.KORUMA FİLESİ | H4: 351 | I4: Kg | J4: 0 | K4: 0 | L4: 17 | M4: 0 | N4: 0 | O4: 0 | P4: =+H4+J4-K4-L4-M4-N4-O4 -> 334 | Q4: 17 KĞ
A5: 2 | D5: ZZ.RADO (NİTRO) AYAKLI KOL | H5: 30 | I5: Adet | J5: 0 | K5: 0 | L5: 0 | M5: 0 | N5: 0 | O5: 0 | P5: =+H5+J5-K5-L5-M5-N5-O5 -> 30
A6: 3 | D6: ZZ.ORBİT (BİLGİN) KOL | H6: 40 | I6: Adet | J6: 0 | K6: 0 | L6: 0 | M6: 0 | N6: 0 | O6: 0 | P6: =+H6+J6-K6-L6-M6-N6-O6 -> 40
A7: 4 | D7: ZZ.MAKER YAY KOL | H7: 58 | I7: Adet | J7: 0 | K7: 0 | L7: 0 | M7: 0 | N7: 0 | O7: 0 | P7: =+H7+J7-K7-L7-M7-N7-O7 -> 58
A8: 5 | D8: ZZ.JAZZ T KOL | H8: 280 | I8: Adet | J8: 0 | K8: 8 | L8: 40 | M8: 0 | N8: 0 | O8: 0 | P8: =+H8+J8-K8-L8-M8-N8-O8 -> 232
A9: 6 | D9: ZZ.STELLA ÜÇGEN PLASTİK KROM KOL | H9: 138 | I9: Adet | J9: 0 | K9: 0 | L9: 0 | M9: 0 | N9: 0 | O9: 0 | P9: =+H9+J9-K9-L9-M9-N9-O9 -> 138
A10: 7 | D10: ZZ.PENTA KOL | H10: 2408 | I10: Adet | J10: 0 | K10: 0 | L10: 0 | M10: 0 | N10: 0 | O10: 0 | P10: =+H10+J10-K10-L10-M10-N10-O10 -> 2408
A11: 8 | D11: ZZ.WENGE KOL PLASTİK | H11: 496 | I11: Adet | J11: 0 | K11: 0 | L11: 0 | M11: 0 | N11: 0 | O11: 0 | P11: =+H11+J11-K11-L11-M11-N11-O11 -> 496
A12: 9 | D12: ZZ.PRESTİJ (KİNG EKO PLASTİK ) KOL | H12: 60 | I12: Adet | J12: 0 | K12: 0 | L12: 0 | M12: 0 | N12: 0 | O12: 0 | P12: =+H12+J12-K12-L12-M12-N12-O12 -> 60
A13: 10 | D13: ZZ.WARLOCK (ELEGANCE) KOL | H13: 42 | I13: Adet | J13: 0 | K13: 0 | L13: 0 | M13: 0 | N13: 0 | O13: 0 | P13: =+H13+J13-K13-L13-M13-N13-O13 -> 42
A14: 11 | D14: CYBORG KOL | H14: 24 | I14: Adet | J14: 0 | K14: 0 | L14: 0 | M14: 0 | N14: 0 | O14: 0 | P14: =+H14+J14-K14-L14-M14-N14-O14 -> 24
A15: 12 | D15: ZZ. MARKOL(SAKURE) (AHŞAP AÇIK KOL) | H15: 26 | I15: Adet | J15: 0 | K15: 0 | L15: 0 | M15: 0 | N15: 0 | O15: 0 | P15: =+H15+J15-K15-L15-M15-N15-O15 -> 26
A16: 13 | D16: ZZ.SEAT ALÜMİNYUM KOL | H16: 90 | I16: Adet | J16: 0 | K16: 0 | L16: 0 | M16: 0 | N16: 0 | O16: 0 | P16: =+H16+J16-K16-L16-M16-N16-O16 -> 90
... A53: 50 | D53: ZZ.JAZZ OTURAK DIŞ PLASTİĞİ | H53: 60 | I53: Adet | J53: 0 | K53: 0 | L53: 0 | M53: 0 | N53: 0 | O53: 0 | P53: =+H53+J53-K53-L53-M53-N53-O53 -> 60
A54: 51 | D54: ZZ.YAPIŞTIRICI (UNITEK 63) | H54: 256 | I54: Kg | J54: 0 | K54: 48 | L54: 32 | M54: 17 | N54: 17 | O54: 0 | P54: =+H54+J54-K54-L54-M54-N54-O54 -> 142 | Q54: 16 KĞ
A55: 52 | D55: ZZ.32Q İÇ TAKOZ | H55: 10000 | I55: Adet | J55: 0 | K55: 0 | L55: 0 | M55: 0 | N55: 0 | O55: 0 | P55: =+H55+J55-K55-L55-M55-N55-O55 -> 10000
A56: 53 | D56: ZZ.40x40 İÇ TAKOZ | H56: 2000 | I56: Adet | J56: 0 | K56: 0 | L56: 0 | M56: 0 | N56: 0 | O56: 0 | P56: =+H56+J56-K56-L56-M56-N56-O56 -> 2000
A57: 54 | D57: ZZ.32Q IZGARA TAKOZ | H57: 2800 | I57: Adet | J57: 0 | K57: 0 | L57: 0 | M57: 0 | N57: 0 | O57: 0 | P57: =+H57+J57-K57-L57-M57-N57-O57 -> 2800
A58: 55 | D58: ZZ.20x40 İÇ TAKOZ | H58: 3000 | I58: Adet | J58: 0 | K58: 0 | L58: 0 | M58: 0 | N58: 0 | O58: 0 | P58: =+H58+J58-K58-L58-M58-N58-O58 -> 3000
A59: 56 | D59: ZZ.25Q İÇ TAKOZ | H59: 5000 | I59: Adet | J59: 0 | K59: 0 | L59: 0 | M59: 0 | N59: 0 | O59: 0 | P59: =+H59+J59-K59-L59-M59-N59-O59 -> 5000
A60: 57 | D60: ZZ.25x50 ELİPS İÇ TAKOZ | H60: 3000 | I60: Adet | J60: 0 | K60: 0 | L60: 0 | M60: 0 | N60: 0 | O60: 0 | P60: =+H60+J60-K60-L60-M60-N60-O60 -> 3000
A61: 58 | D61: ZZ.25x25 İÇ TAKOZ | H61: 5000 | I61: Adet | J61: 0 | K61: 0 | L61: 0 | M61: 0 | N61: 0 | O61: 0 | P61: =+H61+J61-K61-L61-M61-N61-O61 -> 5000
A62: 59 | D62: OYUNCU KOLTUĞU MEKANİZMA TKM | H62: 494 | I62: Adet | J62: 0 | K62: 0 | L62: 0 | M62: 0 | N62: 0 | O62: 0 | P62: =+H62+J62-K62-L62-M62-N62-O62 -> 494
A63: 60 | D63: OFİS (DIAMOND) PLSTK AYAK | H63: 100 | I63: Adet | J63: 0 | K63: 0 | L63: 0 | M63: 0 | N63: 0 | O63: 0 | P63: =+H63+J63-K63-L63-M63-N63-O63 -> 100
A64: 61 | D64: ZZ.Plastik L Ayak 180X180 | H64: 297 | I64: Adet | J64: 0 | K64: 0 | L64: 0 | M64: 0 | N64: 0 | O64: 0 | P64: =+H64+J64-K64-L64-M64-N64-O64 -> 297
A65: 62 | D65: ZZ.PLASTİK ÜÇGEN AYAK 10 CM (TIESTO) | H65: 315 | I65: Adet | J65: 0 | K65: 0 | L65: 0 | M65: 0 | N65: 0 | O65: 0 | P65: =+H65+J65-K65-L65-M65-N65-O65 -> 315
A66: 63 | D66: ZZ.STINGER PLASTİK AYAK -5.5 Ebru M8*35 | H66: 350 | I66: Adet | J66: 0 | K66: 0 | L66: 0 | M66: 0 | N66: 0 | O66: 0 | P66: =+H66+J66-K66-L66-M66-N66-O66 -> 350
... A78: 75 | D78: EXPERİ KOL | H78: 2 | I78: Adet | J78: 0 | K78: 0 | L78: 0 | M78: 0 | N78: 0 | O78: 0 | P78: =+H78+J78-K78-L78-M78-N78-O78 -> 2
D79: BONCUK ELYAF | I79: KĞ | J79: 100 | N79: 30 | P79: =+H79+J79-K79-L79-M79-N79-O79 -> 70 | Q79: 10 KĞ
P80: =+H80+J80-K80-L80-M80-N80-O80 -> 0
P81: =+H81+J81-K81-L81-M81-N81-O81 -> 0
P82: =+H82+J82-K82-L82-M82-N82-O82 -> 0
P83: =+H83+J83-K83-L83-M83-N83-O83 -> 0

Sheet ekim 1 hafta
P1: =+H1+J1-K1-L1-M1-N1-O1 -> 0
O2: 44837
A3: S.NO | D3: ÜRÜN ADI | H3: ADET | I3: BİRİM | J3: GİRİŞ | K3: 44837 | L3: 44838 | M3: 44839 | N3: 44840 | O3: 44841 | P3: KALAN
A4: 1 | D4: ZZ.KORUMA FİLESİ | H4: 334 | I4: Kg | J4: 0 | K4: 0 | L4: 17 | M4: 0 | N4: 0 | O4: 0 | P4: =+H4+J4-K4-L4-M4-N4-O4 -> 317 | Q4: 17 KĞ
A5: 2 | D5: ZZ.RADO (NİTRO) AYAKLI KOL | H5: 30 | I5: Adet | J5: 0 | K5: 0 | L5: 0 | M5: 0 | N5: 0 | O5: 0 | P5: =+H5+J5-K5-L5-M5-N5-O5 -> 30
A6: 3 | D6: ZZ.ORBİT (BİLGİN) KOL | H6: 40 | I6: Adet | J6: 0 | K6: 0 | L6: 0 | M6: 0 | N6: 0 | O6: 0 | P6: =+H6+J6-K6-L6-M6-N6-O6 -> 40
A7: 4 | D7: ZZ.MAKER YAY KOL | H7: 58 | I7: Adet | J7: 0 | K7: 0 | L7: 0 | M7: 0 | N7: 0 | O7: 0 | P7: =+H7+J7-K7-L7-M7-N7-O7 -> 58
A8: 5 | D8: ZZ.JAZZ T KOL | H8: 232 | I8: Adet | J8: 0 | K8: 0 | L8: 0 | M8: 0 | N8: 0 | O8: 0 | P8: =+H8+J8-K8-L8-M8-N8-O8 -> 232
A9: 6 | D9: ZZ.STELLA ÜÇGEN PLASTİK KROM KOL | H9: 138 | I9: Adet | J9: 0 | K9: 0 | L9: 0 | M9: 0 | N9: 0 | O9: 138 | P9: =+H9+J9-K9-L9-M9-N9-O9 -> 0
A10: 7 | D10: ZZ.PENTA KOL | H10: 2408 | I10: Adet | J10: 0 | K10: 0 | L10: 40 | M10: 20 | N10: 0 | O10: 0 | P10: =+H10+J10-K10-L10-M10-N10-O10 -> 2348
A11: 8 | D11: ZZ.WENGE KOL PLASTİK | H11: 496 | I11: Adet | J11: 0 | K11: 0 | L11: 0 | M11: 0 | N11: 0 | O11: 0 | P11: =+H11+J11-K11-L11-M11-N11-O11 -> 496
A12: 9 | D12: ZZ.PRESTİJ (KİNG EKO PLASTİK ) KOL | H12: 60 | I12: Adet | J12: 0 | K12: 0 | L12: 0 | M12: 0 | N12: 0 | O12: 0 | P12: =+H12+J12-K12-L12-M12-N12-O12 -> 60
A13: 10 | D13: ZZ.WARLOCK (ELEGANCE) KOL | H13: 42 | I13: Adet | J13: 0 | K13: 0 | L13: 0 | M13: 0 | N13: 0 | O13: 0 | P13: =+H13+J13-K13-L13-M13-N13-O13 -> 42
A14: 11 | D14: CYBORG KOL | H14: 24 | I14: Adet | J14: 0 | K14: 0 | L14: 0 | M14: 0 | N14: 0 | O14: 0 | P14: =+H14+J14-K14-L14-M14-N14-O14 -> 24
A15: 12 | D15: ZZ. MARKOL(SAKURE) (AHŞAP AÇIK KOL) | H15: 26 | I15: Adet | J15: 0 | K15: 0 | L15: 0 | M15: 0 | N15: 0 | O15: 0 | P15: =+H15+J15-K15-L15-M15-N15-O15 -> 26
A16: 13 | D16: ZZ.SEAT ALÜMİNYUM KOL | H16: 90 | I16: Adet | J16: 0 | K16: 0 | L16: 0 | M16: 0 | N16: 0 | O16: 0 | P16: =+H16+J16-K16-L16-M16-N16-O16 -> 90
... A48: 45 | D48: ZZ.BOGA PLASTİK BAŞLIK | H48: 28 | I48: Adet | J48: 0 | K48: 0 | L48: 0 | M48: 16 | N48: 0 | O48: 0 | P48: =+H48+J48-K48-L48-M48-N48-O48 -> 12
A49: 46 | D49: ZZ.60 GR VATKA ELYAF (1 TORBA = 5 KG ) | H49: 310 | I49: Kg | J49: 0 | K49: 0 | L49: 0 | M49: 0 | N49: 0 | O49: 20 | P49: =+H49+J49-K49-L49-M49-N49-O49 -> 290 | Q49: 5 kğ
A50: 47 | D50: ZZ.KROM HONİK AYAK | H50: 209 | I50: Adet | J50: 0 | K50: 0 | L50: 0 | M50: 20 | N50: 0 | O50: 2 | P50: =+H50+J50-K50-L50-M50-N50-O50 -> 187
A51: 48 | D51: ZZ.JAZZ SIRT PLASTİĞİ | H51: 124 | I51: Adet | J51: 0 | K51: 0 | L51: 0 | M51: 0 | N51: 0 | O51: 0 | P51: =+H51+J51-K51-L51-M51-N51-O51 -> 124
A52: 49 | D52: ZZ.JAZZ OTURAK İÇ PLASTİĞİ | H52: 60 | I52: Adet | J52: 0 | K52: 0 | L52: 0 | M52: 0 | N52: 0 | O52: 0 | P52: =+H52+J52-K52-L52-M52-N52-O52 -> 60
A53: 50 | D53: ZZ.JAZZ OTURAK DIŞ PLASTİĞİ | H53: 60 | I53: Adet | J53: 0 | K53: 0 | L53: 0 | M53: 0 | N53: 0 | O53: 0 | P53: =+H53+J53-K53-L53-M53-N53-O53 -> 60
A54: 51 | D54: ZZ.YAPIŞTIRICI (UNITEK 63) | H54: 85 | I54: Kg | J54: 1050 | K54: 34 | L54: 34 | M54: 0 | N54: 32 | O54: 60 | P54: =+H54+J54-K54-L54-M54-N54-O54 -> 975 | Q54: 15 kğ
A55: 52 | D55: ZZ.32Q İÇ TAKOZ | H55: 10000 | I55: Adet | J55: 0 | K55: 0 | L55: 0 | M55: 0 | N55: 0 | O55: 0 | P55: =+H55+J55-K55-L55-M55-N55-O55 -> 10000
A56: 53 | D56: ZZ.40x40 İÇ TAKOZ | H56: 2000 | I56: Adet | J56: 0 | K56: 0 | L56: 0 | M56: 0 | N56: 0 | O56: 0 | P56: =+H56+J56-K56-L56-M56-N56-O56 -> 2000
A57: 54 | D57: ZZ.32Q IZGARA TAKOZ | H57: 2800 | I57: Adet | J57: 0 | K57: 0 | L57: 0 | M57: 0 | N57: 0 | O57: 0 | P57: =+H57+J57-K57-L57-M57-N57-O57 -> 2800
A58: 55 | D58: ZZ.20x40 İÇ TAKOZ | H58: 3000 | I58: Adet | J58: 0 | K58: 0 | L58: 0 | M58: 0 | N58: 0 | O58: 0 | P58: =+H58+J58-K58-L58-M58-N58-O58 -> 3000
A59: 56 | D59: ZZ.25Q İÇ TAKOZ | H59: 5000 | I59: Adet | J59: 0 | K59: 0 | L59: 0 | M59: 0 | N59: 0 | O59: 0 | P59: =+H59+J59-K59-L59-M59-N59-O59 -> 5000
A60: 57 | D60: ZZ.25x50 ELİPS İÇ TAKOZ | H60: 3000 | I60: Adet | J60: 0 | K60: 0 | L60: 0 | M60: 0 | N60: 0 | O60: 0 | P60: =+H60+J60-K60-L60-M60-N60-O60 -> 3000
A61: 58 | D61: ZZ.25x25 İÇ TAKOZ | H61: 5000 | I61: Adet | J61: 0 | K61: 0 | L61: 0 | M61: 0 | N61: 0 | O61: 0 | P61: =+H61+J61-K61-L61-M61-N61-O61 -> 5000
A62: 59 | D62: OYUNCU KOLTUĞU MEKANİZMA TKM | H62: 494 | I62: Adet | J62: 0 | K62: 0 | L62: 0 | M62: 0 | N62: 0 | O62: 0 | P62: =+H62+J62-K62-L62-M62-N62-O62 -> 494
A63: 60 | D63: OFİS (DIAMOND) PLSTK AYAK | H63: 100 | I63: Adet | J63: 0 | K63: 0 | L63: 0 | M63: 0 | N63: 0 | O63: 0 | P63: =+H63+J63-K63-L63-M63-N63-O63 -> 100
A64: 61 | D64: ZZ.Plastik L Ayak 180X180 | H64: 297 | I64: Adet | J64: 0 | K64: 0 | L64: 0 | M64: 0 | N64: 0 | O64: 0 | P64: =+H64+J64-K64-L64-M64-N64-O64 -> 297
A65: 62 | D65: ZZ.PLASTİK ÜÇGEN AYAK 10 CM (TIESTO) | H65: 315 | I65: Adet | J65: 0 | K65: 0 | L65: 0 | M65: 0 | N65: 0 | O65: 0 | P65: =+H65+J65-K65-L65-M65-N65-O65 -> 315
A66: 63 | D66: ZZ.STINGER PLASTİK AYAK -5.5 Ebru M8*35 | H66: 350 | I66: Adet | J66: 0 | K66: 0 | L66: 0 | M66: 0 | N66: 0 | O66: 0 | P66: =+H66+J66-K66-L66-M66-N66-O66 -> 350
... A72: 69 | D72: ZZ.VEGA (FORM) KOL TABLASI | H72: 0 | I72: Adet | J72: 0 | K72: 0 | L72: 0 | M72: 0 | N72: 0 | O72: 0 | P72: =+H72+J72-K72-L72-M72-N72-O72 -> 0
A73: 70 | D73: TELA BEZ 20 GR | H73: 160 | I73: KĞ | J73: 0 | K73: 32 | L73: 0 | M73: 0 | N73: 0 | O73: 0 | P73: =+H73+J73-K73-L73-M73-N73-O73 -> 128 | Q73: 32 kğ
A74: 71 | D74: SİEANNA,KARİNA PLASTİK KOL | H74: 184 | I74: Adet | J74: 0 | K74: 0 | L74: 0 | M74: 0 | N74: 0 | O74: 0 | P74: =+H74+J74-K74-L74-M74-N74-O74 -> 184
A75: 72 | D75: VOX OTURAK,SIRT İÇ DIŞ PLS. | H75: 76 | I75: Adet | J75: 0 | K75: 4 | L75: 0 | M75: 0 | N75: 0 | O75: 0 | P75: =+H75+J75-K75-L75-M75-N75-O75 -> 72
A76: 73 | D76: POLO PLASTİK TAKIMI | H76: 38 | I76: Adet | J76: 0 | K76: 0 | L76: 0 | M76: 0 | N76: 0 | O76: 0 | P76: =+H76+J76-K76-L76-M76-N76-O76 -> 38
...

Sheet ekim 2 hafta 
P1: =+H1+J1-K1-L1-M1-N1-O1 -> 0
O2: 44837
A3: S.NO | D3: ÜRÜN ADI | H3: ADET | I3: BİRİM | J3: GİRİŞ | K3: 44844 | L3: 44845 | M3: 44846 | N3: 44847 | O3: 44848 | P3: KALAN
A4: 1 | D4: ZZ.KORUMA FİLESİ | H4: 317 | I4: Kg | J4: 0 | K4: 34 | L4: 0 | M4: 0 | N4: 17 | O4: 0 | P4: =+H4+J4-K4-L4-M4-N4-O4 -> 266 | Q4: 17 KĞ
A5: 2 | D5: ZZ.RADO (NİTRO) AYAKLI KOL | H5: 30 | I5: Adet | J5: 0 | K5: 0 | L5: 0 | M5: 0 | N5: 0 | O5: 0 | P5: =+H5+J5-K5-L5-M5-N5-O5 -> 30
A6: 3 | D6: ZZ.ORBİT (BİLGİN) KOL | H6: 40 | I6: Adet | J6: 0 | K6: 0 | L6: 0 | M6: 0 | N6: 0 | O6: 0 | P6: =+H6+J6-K6-L6-M6-N6-O6 -> 40
A7: 4 | D7: ZZ.MAKER YAY KOL | H7: 58 | I7: Adet | J7: 0 | K7: 0 | L7: 0 | M7: 0 | N7: 0 | O7: 0 | P7: =+H7+J7-K7-L7-M7-N7-O7 -> 58
A8: 5 | D8: ZZ.JAZZ T KOL | H8: 232 | I8: Adet | J8: 0 | K8: 0 | L8: 0 | M8: 0 | N8: 0 | O8: 0 | P8: =+H8+J8-K8-L8-M8-N8-O8 -> 232
A9: 6 | D9: ZZ.STELLA ÜÇGEN PLASTİK KROM KOL | H9: 0 | I9: Adet | J9: 100 | K9: 0 | L9: 0 | M9: 0 | N9: 40 | O9: 0 | P9: =+H9+J9-K9-L9-M9-N9-O9 -> 60
A10: 7 | D10: ZZ.PENTA KOL (AYARLI KOL) | H10: 2348 | I10: Adet | J10: 0 | K10: 0 | L10: 6 | M10: 2 | N10: 0 | O10: 0 | P10: =+H10+J10-K10-L10-M10-N10-O10 -> 2340
A11: 8 | D11: ZZ.WENGE KOL PLASTİK | H11: 496 | I11: Adet | J11: 0 | K11: 0 | L11: 0 | M11: 0 | N11: 0 | O11: 0 | P11: =+H11+J11-K11-L11-M11-N11-O11 -> 496
A12: 9 | D12: ZZ.PRESTİJ (KİNG EKO PLASTİK ) KOL | H12: 60 | I12: Adet | J12: 0 | K12: 0 | L12: 0 | M12: 0 | N12: 0 | O12: 0 | P12: =+H12+J12-K12-L12-M12-N12-O12 -> 60
A13: 10 | D13: ZZ.WARLOCK (ELEGANCE) KOL | H13: 42 | I13: Adet | J13: 0 | K13: 0 | L13: 0 | M13: 0 | N13: 0 | O13: 0 | P13: =+H13+J13-K13-L13-M13-N13-O13 -> 42
A14: 11 | D14: CYBORG KOL | H14: 24 | I14: Adet | J14: 0 | K14: 0 | L14: 0 | M14: 0 | N14: 0 | O14: 0 | P14: =+H14+J14-K14-L14-M14-N14-O14 -> 24
A15: 12 | D15: ZZ. MARKOL(SAKURE) (AHŞAP AÇIK KOL) | H15: 26 | I15: Adet | J15: 0 | K15: 0 | L15: 0 | M15: 0 | N15: 0 | O15: 0 | P15: =+H15+J15-K15-L15-M15-N15-O15 -> 26
A16: 13 | D16: ZZ.SEAT ALÜMİNYUM KOL | H16: 90 | I16: Adet | J16: 0 | K16: 0 | L16: 0 | M16: 0 | N16: 0 | O16: 0 | P16: =+H16+J16-K16-L16-M16-N16-O16 -> 90
... A53: 50 | D53: ZZ.JAZZ OTURAK DIŞ PLASTİĞİ | H53: 60 | I53: Adet | J53: 0 | K53: 0 | L53: 0 | M53: 0 | N53: 0 | O53: 0 | P53: =+H53+J53-K53-L53-M53-N53-O53 -> 60
A54: 51 | D54: ZZ.YAPIŞTIRICI (UNITEK 63) | H54: 975 | I54: Kg | J54: 150 | K54: 0 | L54: 30 | M54: 45 | N54: 15 | O54: 30 | P54: =+H54+J54-K54-L54-M54-N54-O54 -> 1005 | Q54: 16 KĞ
A55: 52 | D55: ZZ.32Q İÇ TAKOZ | H55: 10000 | I55: Adet | J55: 0 | K55: 0 | L55: 2000 | M55: 0 | N55: 0 | O55: 0 | P55: =+H55+J55-K55-L55-M55-N55-O55 -> 8000
A56: 53 | D56: ZZ.40x40 İÇ TAKOZ | H56: 2000 | I56: Adet | J56: 0 | K56: 0 | L56: 0 | M56: 0 | N56: 0 | O56: 0 | P56: =+H56+J56-K56-L56-M56-N56-O56 -> 2000
A57: 54 | D57: ZZ.32Q IZGARA TAKOZ | H57: 2800 | I57: Adet | J57: 0 | K57: 0 | L57: 0 | M57: 0 | N57: 0 | O57: 0 | P57: =+H57+J57-K57-L57-M57-N57-O57 -> 2800
A58: 55 | D58: ZZ.20x40 İÇ TAKOZ | H58: 3000 | I58: Adet | J58: 0 | K58: 0 | L58: 0 | M58: 0 | N58: 0 | O58: 0 | P58: =+H58+J58-K58-L58-M58-N58-O58 -> 3000
A59: 56 | D59: ZZ.25Q İÇ TAKOZ | H59: 5000 | I59: Adet | J59: 0 | K59: 0 | L59: 0 | M59: 0 | N59: 0 | O59: 0 | P59: =+H59+J59-K59-L59-M59-N59-O59 -> 5000
A60: 57 | D60: ZZ.25x50 ELİPS İÇ TAKOZ | H60: 3000 | I60: Adet | J60: 0 | K60: 0 | L60: 0 | M60: 0 | N60: 0 | O60: 0 | P60: =+H60+J60-K60-L60-M60-N60-O60 -> 3000
A61: 58 | D61: ZZ.25x25 İÇ TAKOZ | H61: 5000 | I61: Adet | J61: 0 | K61: 0 | L61: 0 | M61: 0 | N61: 0 | O61: 0 | P61: =+H61+J61-K61-L61-M61-N61-O61 -> 5000
A62: 59 | D62: OYUNCU KOLTUĞU MEKANİZMA TKM | H62: 494 | I62: Adet | J62: 0 | K62: 0 | L62: 0 | M62: 0 | N62: 0 | O62: 0 | P62: =+H62+J62-K62-L62-M62-N62-O62 -> 494
A63: 60 | D63: OFİS (DIAMOND) PLSTK AYAK | H63: 100 | I63: Adet | J63: 200 | K63: 0 | L63: 10 | M63: 0 | N63: 0 | O63: 6 | P63: =+H63+J63-K63-L63-M63-N63-O63 -> 284
A64: 61 | D64: ZZ.Plastik L Ayak 180X180 | H64: 297 | I64: Adet | J64: 0 | K64: 0 | L64: 0 | M64: 0 | N64: 0 | O64: 0 | P64: =+H64+J64-K64-L64-M64-N64-O64 -> 297
A65: 62 | D65: ZZ.PLASTİK ÜÇGEN AYAK 10 CM (TIESTO) | H65: 315 | I65: Adet | J65: 0 | K65: 0 | L65: 0 | M65: 0 | N65: 0 | O65: 0 | P65: =+H65+J65-K65-L65-M65-N65-O65 -> 315
A66: 63 | D66: ZZ.STINGER PLASTİK AYAK -5.5 Ebru M8*35 | H66: 350 | I66: Adet | J66: 0 | K66: 0 | L66: 0 | M66: 0 | N66: 0 | O66: 0 | P66: =+H66+J66-K66-L66-M66-N66-O66 -> 350
... A72: 69 | D72: ZZ.VEGA (FORM) KOL TABLASI | H72: 0 | I72: Adet | J72: 0 | K72: 0 | L72: 0 | M72: 0 | N72: 0 | O72: 0 | P72: =+H72+J72-K72-L72-M72-N72-O72 -> 0
A73: 70 | D73: TELA BEZ 20 GR | H73: 128 | I73: KĞ | J73: 0 | K73: 0 | L73: 0 | M73: 64 | N73: 0 | O73: 0 | P73: =+H73+J73-K73-L73-M73-N73-O73 -> 64 | Q73: 32 kğ
A74: 71 | D74: SİEANNA,KARİNA PLASTİK KOL | H74: 184 | I74: Adet | J74: 0 | K74: 0 | L74: 30 | M74: 0 | N74: 0 | O74: 0 | P74: =+H74+J74-K74-L74-M74-N74-O74 -> 154
A75: 72 | D75: VOX OTURAK,SIRT İÇ DIŞ PLS. | H75: 72 | I75: Adet | J75: 0 | K75: 0 | L75: 0 | M75: 0 | N75: 0 | O75: 0 | P75: =+H75+J75-K75-L75-M75-N75-O75 -> 72
A76: 73 | D76: POLO PLASTİK TAKIMI | H76: 38 | I76: Adet | J76: 0 | K76: 0 | L76: 0 | M76: 0 | N76: 0 | O76: 0 | P76: =+H76+J76-K76-L76-M76-N76-O76 -> 38
A77: 74 | D77: VEGA FORM ÇAKMA KOL | H77: 50 | I77: Adet | J77: 0 | K77: 0 | L77: 0 | M77: 0 | N77: 0 | O77: 0 | P77: =+H77+J77-K77-L77-M77-N77-O77 -> 50
A78: 75 | D78: EXPERİ KOL | H78: 2 | I78: Adet | J78: 0 | K78: 0 | L78: 2 | M78: 0 | N78: 0 | O78: 0 | P78: =+H78+J78-K78-L78-M78-N78-O78 -> 0
D79: 100*160 balonlu naylon | H79: 75 | I79: kğ | J79: 446 | K79: 0 | L79: 0 | M79: 0 | N79: 0 | O79: 75 | P79: =+H79+J79-K79-L79-M79-N79-O79 -> 446 | Q79: 1 pk.25
H80: 0 | J80: 0 | K80: 0 | L80: 0 | M80: 0 | N80: 0 | O80: 0 | P80: =+H80+J80-K80-L80-M80-N80-O80 -> 0
H81: 0 | J81: 0 | K81: 0 | L81: 0 | M81: 0 | N81: 0 | O81: 0 | P81: =+H81+J81-K81-L81-M81-N81-O81 -> 0
...

Sheet ekim 3 hafta
P1: =+H1+J1-K1-L1-M1-N1-O1 -> 0
O2: 44837
A3: S.NO | D3: ÜRÜN ADI | H3: ADET | I3: BİRİM | J3: GİRİŞ | K3: 44851 | L3: 44852 | M3: 44853 | N3: 44854 | O3: 44855 | P3: KALAN
A4: 1 | D4: ZZ.KORUMA FİLESİ | H4: 266 | I4: Kg | J4: 0 | K4: 0 | L4: 0 | M4: 17 | N4: 0 | O4: 0 | P4: =+H4+J4-K4-L4-M4-N4-O4 -> 249 | Q4: 17 KĞ
A5: 2 | D5: ZZ.RADO (NİTRO) AYAKLI KOL | H5: 30 | I5: Adet | J5: 0 | K5: 0 | L5: 0 | M5: 0 | N5: 0 | O5: 0 | P5: =+H5+J5-K5-L5-M5-N5-O5 -> 30
A6: 3 | D6: ZZ.ORBİT (BİLGİN) KOL | H6: 40 | I6: Adet | J6: 0 | K6: 0 | L6: 0 | M6: 0 | N6: 0 | O6: 0 | P6: =+H6+J6-K6-L6-M6-N6-O6 -> 40
A7: 4 | D7: ZZ.MAKER YAY KOL | H7: 58 | I7: Adet | J7: 0 | K7: 0 | L7: 0 | M7: 0 | N7: 0 | O7: 0 | P7: =+H7+J7-K7-L7-M7-N7-O7 -> 58
A8: 5 | D8: ZZ.JAZZ T KOL | H8: 232 | I8: Adet | J8: 0 | K8: 18 | L8: 0 | M8: 0 | N8: 0 | O8: 0 | P8: =+H8+J8-K8-L8-M8-N8-O8 -> 214
A9: 6 | D9: ZZ.STELLA ÜÇGEN PLASTİK KROM KOL | H9: 60 | I9: Adet | J9: 0 | K9: 0 | L9: 0 | M9: 0 | N9: 0 | O9: 0 | P9: =+H9+J9-K9-L9-M9-N9-O9 -> 60
A10: 7 | D10: ZZ.PENTA KOL | H10: 2340 | I10: Adet | J10: 0 | K10: 86 | L10: 0 | M10: 0 | N10: 0 | O10: 0 | P10: =+H10+J10-K10-L10-M10-N10-O10 -> 2254
A11: 8 | D11: ZZ.WENGE KOL PLASTİK | H11: 496 | I11: Adet | J11: 0 | K11: 0 | L11: 0 | M11: 0 | N11: 0 | O11: 0 | P11: =+H11+J11-K11-L11-M11-N11-O11 -> 496
A12: 9 | D12: ZZ.PRESTİJ (KİNG EKO PLASTİK ) KOL | H12: 60 | I12: Adet | J12: 0 | K12: 0 | L12: 0 | M12: 0 | N12: 0 | O12: 0 | P12: =+H12+J12-K12-L12-M12-N12-O12 -> 60
A13: 10 | D13: ZZ.WARLOCK (ELEGANCE) KOL | H13: 42 | I13: Adet | J13: 0 | K13: 0 | L13: 0 | M13: 0 | N13: 0 | O13: 0 | P13: =+H13+J13-K13-L13-M13-N13-O13 -> 42
A14: 11 | D14: CYBORG KOL | H14: 24 | I14: Adet | J14: 0 | K14: 0 | L14: 0 | M14: 0 | N14: 0 | O14: 0 | P14: =+H14+J14-K14-L14-M14-N14-O14 -> 24
A15: 12 | D15: ZZ. MARKOL(SAKURE) (AHŞAP AÇIK KOL) | H15: 26 | I15: Adet | J15: 0 | K15: 0 | L15: 0 | M15: 0 | N15: 0 | O15: 0 | P15: =+H15+J15-K15-L15-M15-N15-O15 -> 26
A16: 13 | D16: ZZ.SEAT ALÜMİNYUM KOL | H16: 90 | I16: Adet | J16: 0 | K16: 0 | L16: 0 | M16: 0 | N16: 0 | O16: 0 | P16: =+H16+J16-K16-L16-M16-N16-O16 -> 90
... A42: 39 | D42: ZZ.BETTA KOL | H42: 155 | I42: Adet | J42: 0 | K42: 16 | L42: 0 | M42: 0 | N42: 0 | O42: 0 | P42: =+H42+J42-K42-L42-M42-N42-O42 -> 139
A43: 40 | D43: ZZ.BETTA SIRT PLASTİĞİ | H43: 151 | I43: Adet | J43: 0 | K43: 8 | L43: 0 | M43: 0 | N43: 0 | P43: =+H43+J43-K43-L43-M43-N43-O43 -> 143
A44: 41 | D44: ZZ.BETTA FONT DIŞ PLASTİĞİ | H44: 25 | I44: Adet | J44: 10 | K44: 8 | L44: 0 | M44: 0 | N44: 0 | O44: 16 | P44: =+H44+J44-K44-L44-M44-N44-O44 -> 11
A45: 42 | D45: ZZ.BETTA FONT İÇ PLASTİĞİ | H45: 20 | I45: Adet | J45: 60 | K45: 8 | L45: 0 | M45: 0 | N45: 0 | O45: 16 | P45: =+H45+J45-K45-L45-M45-N45-O45 -> 56
A46: 43 | D46: ZZ.BOGA SIRT İÇ - DIŞ PLASTİĞİ BEYAZ | H46: 54 | I46: Adet | J46: 0 | K46: 10 | L46: 0 | M46: 0 | N46: 0 | O46: 0 | P46: =+H46+J46-K46-L46-M46-N46-O46 -> 44
A47: 44 | D47: ZZ.BOGA SIRT İÇ - DIŞ PLASTİĞİ | H47: 42 | I47: Adet | J47: 7 | K47: 10 | L47: 0 | M47: 0 | N47: 0 | O47: 0 | P47: =+H47+J47-K47-L47-M47-N47-O47 -> 39
A48: 45 | D48: ZZ.BOGA PLASTİK BAŞLIK | H48: 11 | I48: Adet | J48: 0 | K48: 10 | L48: 0 | M48: 0 | N48: 0 | O48: 0 | P48: =+H48+J48-K48-L48-M48-N48-O48 -> 1
A49: 46 | D49: ZZ.60 GR VATKA ELYAF (1 TORBA = 5 KG ) | H49: 270 | I49: Kg | J49: 0 | K49: 0 | L49: 0 | M49: 0 | N49: 0 | O49: 0 | P49: =+H49+J49-K49-L49-M49-N49-O49 -> 270
A50: 47 | D50: ZZ.KROM HONİK AYAK | H50: 186 | I50: Adet | J50: 0 | K50: 0 | L50: 3 | M50: 0 | N50: 0 | O50: 0 | P50: =+H50+J50-K50-L50-M50-N50-O50 -> 183
A51: 48 | D51: ZZ.JAZZ SIRT PLASTİĞİ | H51: 124 | I51: Adet | J51: 0 | K51: 5 | L51: 0 | M51: 0 | N51: 0 | O51: 0 | P51: =+H51+J51-K51-L51-M51-N51-O51 -> 119
A52: 49 | D52: ZZ.JAZZ OTURAK İÇ PLASTİĞİ | H52: 60 | I52: Adet | J52: 0 | K52: 5 | L52: 0 | M52: 0 | N52: 0 | O52: 0 | P52: =+H52+J52-K52-L52-M52-N52-O52 -> 55
A53: 50 | D53: ZZ.JAZZ OTURAK DIŞ PLASTİĞİ | H53: 60 | I53: Adet | J53: 0 | K53: 5 | L53: 0 | M53: 0 | N53: 0 | O53: 0 | P53: =+H53+J53-K53-L53-M53-N53-O53 -> 55
A54: 51 | D54: ZZ.YAPIŞTIRICI (UNITEK 63) | H54: 1005 | I54: Kg | J54: 150 | K54: 30 | L54: 15 | M54: 30 | N54: 30 | O54: 45 | P54: =+H54+J54-K54-L54-M54-N54-O54 -> 1005 | Q54: 16 KĞ
A55: 52 | D55: ZZ.32Q İÇ TAKOZ | H55: 8000 | I55: Adet | J55: 0 | K55: 0 | L55: 0 | M55: 0 | N55: 0 | O55: 0 | P55: =+H55+J55-K55-L55-M55-N55-O55 -> 8000
A56: 53 | D56: ZZ.40x40 İÇ TAKOZ | H56: 2000 | I56: Adet | J56: 0 | K56: 0 | L56: 0 | M56: 0 | N56: 0 | O56: 0 | P56: =+H56+J56-K56-L56-M56-N56-O56 -> 2000
A57: 54 | D57: ZZ.32Q IZGARA TAKOZ | H57: 2800 | I57: Adet | J57: 0 | K57: 0 | L57: 0 | M57: 0 | N57: 0 | O57: 0 | P57: =+H57+J57-K57-L57-M57-N57-O57 -> 2800
A58: 55 | D58: ZZ.20x40 İÇ TAKOZ | H58: 3000 | I58: Adet | J58: 0 | K58: 0 | L58: 0 | M58: 0 | N58: 0 | O58: 0 | P58: =+H58+J58-K58-L58-M58-N58-O58 -> 3000
A59: 56 | D59: ZZ.25Q İÇ TAKOZ | H59: 5000 | I59: Adet | J59: 0 | K59: 0 | L59: 0 | M59: 0 | N59: 0 | O59: 0 | P59: =+H59+J59-K59-L59-M59-N59-O59 -> 5000
A60: 57 | D60: ZZ.25x50 ELİPS İÇ TAKOZ | H60: 3000 | I60: Adet | J60: 0 | K60: 0 | L60: 0 | M60: 0 | N60: 0 | O60: 0 | P60: =+H60+J60-K60-L60-M60-N60-O60 -> 3000
A61: 58 | D61: ZZ.25x25 İÇ TAKOZ | H61: 5000 | I61: Adet | J61: 0 | K61: 0 | L61: 0 | M61: 0 | N61: 0 | O61: 0 | P61: =+H61+J61-K61-L61-M61-N61-O61 -> 5000
A62: 59 | D62: OYUNCU KOLTUĞU MEKANİZMA TKM | H62: 494 | I62: Adet | J62: 0 | K62: 0 | L62: 0 | M62: 0 | N62: 0 | O62: 0 | P62: =+H62+J62-K62-L62-M62-N62-O62 -> 494
A63: 60 | D63: OFİS (DIAMOND) PLSTK AYAK | H63: 284 | I63: Adet | J63: 100 | K63: 100 | L63: 0 | M63: 0 | N63: 0 | O63: 0 | P63: =+H63+J63-K63-L63-M63-N63-O63 -> 284
A64: 61 | D64: ZZ.Plastik L Ayak 180X180 | H64: 297 | I64: Adet | J64: 150 | K64: 0 | L64: 0 | M64: 0 | N64: 0 | O64: 0 | P64: =+H64+J64-K64-L64-M64-N64-O64 -> 447
A65: 62 | D65: ZZ.PLASTİK ÜÇGEN AYAK 10 CM (TIESTO) | H65: 315 | I65: Adet | J65: 0 | K65: 0 | L65: 0 | M65: 0 | N65: 0 | O65: 0 | P65: =+H65+J65-K65-L65-M65-N65-O65 -> 315
...

Sheet ekim 4 hafta 
P1: =+H1+J1-K1-L1-M1-N1-O1 -> 0
O2: 44837
A3: S.NO | D3: ÜRÜN ADI | H3: ADET | I3: BİRİM | J3: GİRİŞ | K3: 44858 | L3: 44859 | M3: 44860 | N3: 44861 | O3: 44862 | P3: KALAN
A4: 1 | D4: ZZ.KORUMA FİLESİ | H4: ='ekim 3 hafta'!P4 -> 249 | I4: Kg | J4: 0 | K4: 34 | L4: 0 | M4: 0 | N4: 17 | O4: 0 | P4: =+H4+J4-K4-L4-M4-N4-O4 -> 198 | Q4: 17 KĞ
A5: 2 | D5: ZZ.RADO (NİTRO) AYAKLI KOL | H5: ='ekim 3 hafta'!P5 -> 30 | I5: Adet | J5: 0 | K5: 0 | L5: 0 | M5: 0 | N5: 0 | O5: 0 | P5: =+H5+J5-K5-L5-M5-N5-O5 -> 30
A6: 3 | D6: ZZ.ORBİT (BİLGİN) KOL | H6: ='ekim 3 hafta'!P6 -> 40 | I6: Adet | J6: 0 | K6: 0 | L6: 0 | M6: 0 | N6: 0 | O6: 0 | P6: =+H6+J6-K6-L6-M6-N6-O6 -> 40
A7: 4 | D7: ZZ.MAKER YAY KOL | H7: ='ekim 3 hafta'!P7 -> 58 | I7: Adet | J7: 0 | K7: 0 | L7: 0 | M7: 0 | N7: 0 | O7: 0 | P7: =+H7+J7-K7-L7-M7-N7-O7 -> 58
A8: 5 | D8: ZZ.JAZZ T KOL | H8: ='ekim 3 hafta'!P8 -> 214 | I8: Adet | J8: 0 | K8: 0 | L8: 0 | M8: 0 | N8: 0 | O8: 0 | P8: =+H8+J8-K8-L8-M8-N8-O8 -> 214
A9: 6 | D9: ZZ.STELLA ÜÇGEN PLASTİK KROM KOL | H9: ='ekim 3 hafta'!P9 -> 60 | I9: Adet | J9: 10 | K9: 20 | L9: 0 | M9: 0 | N9: 40 | O9: 0 | P9: =+H9+J9-K9-L9-M9-N9-O9 -> 10
A10: 7 | D10: ZZ.PENTA KOL (ayarlı,onyar başlı) | H10: ='ekim 3 hafta'!P10 -> 2254 | I10: Adet | J10: 0 | K10: 15 | L10: 0 | M10: 32 | N10: 0 | O10: 6 | P10: =+H10+J10-K10-L10-M10-N10-O10 -> 2201
A11: 8 | D11: ZZ.WENGE KOL PLASTİK | H11: ='ekim 3 hafta'!P11 -> 496 | I11: Adet | J11: 0 | K11: 0 | L11: 0 | M11: 0 | N11: 0 | O11: 0 | P11: =+H11+J11-K11-L11-M11-N11-O11 -> 496
A12: 9 | D12: ZZ.PRESTİJ (KİNG EKO PLASTİK ) KOL | H12: ='ekim 3 hafta'!P12 -> 60 | I12: Adet | J12: 0 | K12: 0 | L12: 0 | M12: 0 | N12: 0 | O12: 0 | P12: =+H12+J12-K12-L12-M12-N12-O12 -> 60
A13: 10 | D13: ZZ.WARLOCK (ELEGANCE) KOL | H13: ='ekim 3 hafta'!P13 -> 42 | I13: Adet | J13: 0 | K13: 0 | L13: 0 | M13: 0 | N13: 0 | O13: 0 | P13: =+H13+J13-K13-L13-M13-N13-O13 -> 42
A14: 11 | D14: CYBORG KOL | H14: ='ekim 3 hafta'!P14 -> 24 | I14: Adet | J14: 0 | K14: 10 | L14: 0 | M14: 0 | N14: 0 | O14: 0 | P14: =+H14+J14-K14-L14-M14-N14-O14 -> 14
A15: 12 | D15: ZZ. MARKOL(SAKURE) (AHŞAP AÇIK KOL) | H15: ='ekim 3 hafta'!P15 -> 26 | I15: Adet | J15: 0 | K15: 0 | L15: 0 | M15: 0 | N15: 0 | O15: 0 | P15: =+H15+J15-K15-L15-M15-N15-O15 -> 26
A16: 13 | D16: ZZ.SEAT ALÜMİNYUM KOL | H16: ='ekim 3 hafta'!P16 -> 90 | I16: Adet | J16: 0 | K16: 0 | L16: 0 | M16: 0 | N16: 0 | O16: 0 | P16: =+H16+J16-K16-L16-M16-N16-O16 -> 90
... A53: 50 | D53: ZZ.JAZZ OTURAK DIŞ PLASTİĞİ | H53: ='ekim 3 hafta'!P53 -> 55 | I53: Adet | J53: 0 | K53: 0 | L53: 0 | M53: 0 | N53: 0 | O53: 0 | P53: =+H53+J53-K53-L53-M53-N53-O53 -> 55
A54: 51 | D54: ZZ.YAPIŞTIRICI (UNITEK 63) | H54: ='ekim 3 hafta'!P54 -> 1005 | I54: Kg | J54: 15 | K54: 0 | L54: 45 | M54: 30 | N54: 0 | O54: 15 | P54: =+H54+J54-K54-L54-M54-N54-O54 -> 930 | Q54: 16 KĞ
A55: 52 | D55: ZZ.32Q İÇ TAKOZ | H55: ='ekim 3 hafta'!P55 -> 8000 | I55: Adet | J55: 0 | K55: 0 | L55: 0 | M55: 0 | N55: 0 | O55: 0 | P55: =+H55+J55-K55-L55-M55-N55-O55 -> 8000
A56: 53 | D56: ZZ.40x40 İÇ TAKOZ | H56: ='ekim 3 hafta'!P56 -> 2000 | I56: Adet | J56: 0 | K56: 0 | L56: 0 | M56: 0 | N56: 0 | O56: 0 | P56: =+H56+J56-K56-L56-M56-N56-O56 -> 2000
A57: 54 | D57: ZZ.32Q IZGARA TAKOZ | H57: ='ekim 3 hafta'!P57 -> 2800 | I57: Adet | J57: 0 | K57: 0 | L57: 0 | M57: 0 | N57: 0 | O57: 0 | P57: =+H57+J57-K57-L57-M57-N57-O57 -> 2800
A58: 55 | D58: ZZ.20x40 İÇ TAKOZ | H58: ='ekim 3 hafta'!P58 -> 3000 | I58: Adet | J58: 0 | K58: 0 | L58: 0 | M58: 0 | N58: 0 | O58: 0 | P58: =+H58+J58-K58-L58-M58-N58-O58 -> 3000
A59: 56 | D59: ZZ.25Q İÇ TAKOZ | H59: ='ekim 3 hafta'!P59 -> 5000 | I59: Adet | J59: 0 | K59: 0 | L59: 0 | M59: 0 | N59: 0 | O59: 0 | P59: =+H59+J59-K59-L59-M59-N59-O59 -> 5000
A60: 57 | D60: ZZ.25x50 ELİPS İÇ TAKOZ | H60: ='ekim 3 hafta'!P60 -> 3000 | I60: Adet | J60: 0 | K60: 0 | L60: 0 | M60: 0 | N60: 0 | O60: 0 | P60: =+H60+J60-K60-L60-M60-N60-O60 -> 3000
A61: 58 | D61: ZZ.25x25 İÇ TAKOZ | H61: ='ekim 3 hafta'!P61 -> 5000 | I61: Adet | J61: 0 | K61: 0 | L61: 0 | M61: 0 | N61: 0 | O61: 0 | P61: =+H61+J61-K61-L61-M61-N61-O61 -> 5000
A62: 59 | D62: OYUNCU KOLTUĞU MEKANİZMA TKM | H62: ='ekim 3 hafta'!P62 -> 494 | I62: Adet | J62: 0 | K62: 0 | L62: 0 | M62: 0 | N62: 0 | O62: 0 | P62: =+H62+J62-K62-L62-M62-N62-O62 -> 494
A63: 60 | D63: OFİS (DIAMOND) PLSTK AYAK | H63: ='ekim 3 hafta'!P63 -> 284 | I63: Adet | J63: 0 | K63: 0 | L63: 0 | M63: 0 | N63: 0 | O63: 0 | P63: =+H63+J63-K63-L63-M63-N63-O63 -> 284
A64: 61 | D64: ZZ.Plastik L Ayak 180X180 | H64: ='ekim 3 hafta'!P64 -> 447 | I64: Adet | J64: 0 | K64: 0 | L64: 0 | M64: 0 | N64: 0 | O64: 0 | P64: =+H64+J64-K64-L64-M64-N64-O64 -> 447
A65: 62 | D65: ZZ.PLASTİK ÜÇGEN AYAK 10 CM (TIESTO) | H65: ='ekim 3 hafta'!P65 -> 315 | I65: Adet | J65: 0 | K65: 0 | L65: 0 | M65: 0 | N65: 0 | O65: 0 | P65: =+H65+J65-K65-L65-M65-N65-O65 -> 315
A66: 63 | D66: ZZ.STINGER PLASTİK AYAK -5.5 Ebru M8*35 | H66: ='ekim 3 hafta'!P66 -> 350 | I66: Adet | J66: 0 | K66: 0 | L66: 0 | M66: 0 | N66: 0 | O66: 0 | P66: =+H66+J66-K66-L66-M66-N66-O66 -> 350
... A72: 69 | D72: ZZ.VEGA (FORM) KOL TABLASI | H72: ='ekim 3 hafta'!P72 -> 0 | I72: Adet | J72: 0 | K72: 0 | L72: 0 | M72: 0 | N72: 0 | O72: 0 | P72: =+H72+J72-K72-L72-M72-N72-O72 -> 0
A73: 70 | D73: TELA BEZ 20 GR | H73: ='ekim 3 hafta'!P73 -> 64 | I73: KĞ | J73: 0 | K73: 0 | L73: 0 | M73: 0 | N73: 0 | O73: 0 | P73: =+H73+J73-K73-L73-M73-N73-O73 -> 64 | Q73: 32 kğ
A74: 71 | D74: SİEANNA,KARİNA PLASTİK KOL | H74: ='ekim 3 hafta'!P74 -> 152 | I74: Adet | J74: 0 | K74: 0 | L74: 0 | M74: 0 | N74: 0 | O74: 0 | P74: =+H74+J74-K74-L74-M74-N74-O74 -> 152
A75: 72 | D75: VOX OTURAK,SIRT İÇ DIŞ PLS. | H75: ='ekim 3 hafta'!P75 -> 67 | I75: Adet | J75: 0 | K75: 0 | L75: 0 | M75: 0 | N75: 0 | O75: 0 | P75: =+H75+J75-K75-L75-M75-N75-O75 -> 67
A76: 73 | D76: POLO PLASTİK TAKIMI | H76: ='ekim 3 hafta'!P76 -> 37 | I76: Adet | J76: 0 | K76: 0 | L76: 0 | M76: 0 | N76: 0 | O76: 0 | P76: =+H76+J76-K76-L76-M76-N76-O76 -> 37
A77: 74 | D77: VEGA FORM ÇAKMA KOL | H77: ='ekim 3 hafta'!P77 -> 50 | I77: Adet | J77: 0 | K77: 0 | L77: 0 | M77: 0 | N77: 0 | O77: 0 | P77: =+H77+J77-K77-L77-M77-N77-O77 -> 50
A78: 75 | D78: EXPERİ KOL | H78: ='ekim 3 hafta'!P78 -> 0 | I78: Adet | J78: 0 | K78: 0 | L78: 0 | M78: 0 | N78: 0 | O78: 0 | P78: =+H78+J78-K78-L78-M78-N78-O78 -> 0
D79: 100*160 BALONLU NAYLON | H79: ='ekim 3 hafta'!P79 -> 421 | I79: Adet | J79: 0 | K79: 25 | L79: 0 | M79: 0 | N79: 0 | O79: 0 | P79: =+H79+J79-K79-L79-M79-N79-O79 -> 396
D80: HARMANY S KOL PLSTİK | H80: ='ekim 3 hafta'!P80 -> 40 | I80: Adet | J80: 0 | K80: 0 | L80: 0 | M80: 0 | N80: 0 | O80: 0 | P80: =+H80+J80-K80-L80-M80-N80-O80 -> 40
D81: STREÇ NAYLON | H81: ='ekim 3 hafta'!P81 -> 0 | I81: Adet | J81: 140 | K81: 0 | L81: 0 | M81: 0 | N81: 0 | O81: 0 | P81: =+H81+J81-K81-L81-M81-N81-O81 -> 140
...

Sheet KASIM 1 HAFTA
P1: =+H1+J1-K1-L1-M1-N1-O1 -> 0
O2: 44837
A3: S.NO | D3: ÜRÜN ADI | H3: ADET | I3: BİRİM | J3: GİRİŞ | K3: 44865 | L3: 44866 | M3: 44867 | N3: 44868 | O3: 44869 | P3: KALAN
A4: 1 | D4: ZZ.KORUMA FİLESİ | H4: ='ekim 4 hafta '!P4 -> 198 | I4: Kg | J4: 0 | K4: 0 | L4: 0 | M4: 0 | N4: 0 | O4: 0 | P4: =+H4+J4-K4-L4-M4-N4-O4 -> 198 | Q4: 17 KĞ
A5: 2 | D5: ZZ.RADO (NİTRO) AYAKLI KOL | H5: ='ekim 4 hafta '!P5 -> 30 | I5: Adet | J5: 0 | K5: 0 | L5: 0 | M5: 0 | N5: 0 | O5: 0 | P5: =+H5+J5-K5-L5-M5-N5-O5 -> 30
A6: 3 | D6: ZZ.ORBİT (BİLGİN) KOL | H6: ='ekim 4 hafta '!P6 -> 40 | I6: Adet | J6: 0 | K6: 0 | L6: 0 | M6: 0 | N6: 0 | O6: 0 | P6: =+H6+J6-K6-L6-M6-N6-O6 -> 40
A7: 4 | D7: ZZ.MAKER YAY KOL | H7: ='ekim 4 hafta '!P7 -> 58 | I7: Adet | J7: 0 | K7: 0 | L7: 0 | M7: 0 | N7: 0 | O7: 0 | P7: =+H7+J7-K7-L7-M7-N7-O7 -> 58
A8: 5 | D8: ZZ.JAZZ T KOL | H8: ='ekim 4 hafta '!P8 -> 214 | I8: Adet | J8: 0 | K8: 0 | L8: 0 | M8: 0 | N8: 0 | O8: 0 | P8: =+H8+J8-K8-L8-M8-N8-O8 -> 214
A9: 6 | D9: ZZ.STELLA ÜÇGEN PLASTİK KROM KOL | H9: ='ekim 4 hafta '!P9 -> 10 | I9: Adet | J9: 0 | K9: 0 | L9: 0 | M9: 0 | N9: 0 | O9: 0 | P9: =+H9+J9-K9-L9-M9-N9-O9 -> 10
A10: 7 | D10: ZZ.PENTA KOL (ayarlı,onyar başlı) | H10: ='ekim 4 hafta '!P10 -> 2201 | I10: Adet | J10: 0 | K10: 0 | L10: 50 | M10: 0 | N10: 0 | O10: 0 | P10: =+H10+J10-K10-L10-M10-N10-O10 -> 2151
A11: 8 | D11: ZZ.WENGE KOL PLASTİK | H11: ='ekim 4 hafta '!P11 -> 496 | I11: Adet | J11: 0 | K11: 0 | L11: 0 | M11: 0 | N11: 0 | O11: 0 | P11: =+H11+J11-K11-L11-M11-N11-O11 -> 496
A12: 9 | D12: ZZ.PRESTİJ (KİNG EKO PLASTİK ) KOL | H12: ='ekim 4 hafta '!P12 -> 60 | I12: Adet | J12: 0 | K12: 0 | L12: 0 | M12: 0 | N12: 0 | O12: 0 | P12: =+H12+J12-K12-L12-M12-N12-O12 -> 60
A13: 10 | D13: ZZ.WARLOCK (ELEGANCE) KOL | H13: ='ekim 4 hafta '!P13 -> 42 | I13: Adet | J13: 0 | K13: 0 | L13: 0 | M13: 0 | N13: 0 | O13: 0 | P13: =+H13+J13-K13-L13-M13-N13-O13 -> 42
A14: 11 | D14: CYBORG KOL | H14: ='ekim 4 hafta '!P14 -> 14 | I14: Adet | J14: 0 | K14: 0 | L14: 0 | M14: 0 | N14: 0 | O14: 0 | P14: =+H14+J14-K14-L14-M14-N14-O14 -> 14
A15: 12 | D15: ZZ. MARKOL(SAKURE) (AHŞAP AÇIK KOL) | H15: ='ekim 4 hafta '!P15 -> 26 | I15: Adet | J15: 0 | K15: 0 | L15: 0 | M15: 0 | N15: 0 | O15: 0 | P15: =+H15+J15-K15-L15-M15-N15-O15 -> 26
A16: 13 | D16: ZZ.SEAT ALÜMİNYUM KOL | H16: ='ekim 4 hafta '!P16 -> 90 | I16: Adet | J16: 0 | K16: 0 | L16: 0 | M16: 0 | N16: 0 | O16: 0 | P16: =+H16+J16-K16-L16-M16-N16-O16 -> 90
... A53: 50 | D53: ZZ.JAZZ OTURAK DIŞ PLASTİĞİ | H53: ='ekim 4 hafta '!P53 -> 55 | I53: Adet | J53: 0 | K53: 0 | L53: 6 | M53: 0 | N53: 0 | O53: 0 | P53: =+H53+J53-K53-L53-M53-N53-O53 -> 49
A54: 51 | D54: ZZ.YAPIŞTIRICI (UNITEK 63) | H54: ='ekim 4 hafta '!P54 -> 930 | I54: Kg | J54: 0 | K54: 0 | L54: 115 | M54: 0 | N54: 30 | O54: 15 | P54: =+H54+J54-K54-L54-M54-N54-O54 -> 770 | Q54: 16 KĞ
A55: 52 | D55: ZZ.32Q İÇ TAKOZ | H55: ='ekim 4 hafta '!P55 -> 8000 | I55: Adet | J55: 0 | K55: 0 | L55: 0 | M55: 0 | N55: 0 | O55: 0 | P55: =+H55+J55-K55-L55-M55-N55-O55 -> 8000
A56: 53 | D56: ZZ.40x40 İÇ TAKOZ | H56: ='ekim 4 hafta '!P56 -> 2000 | I56: Adet | J56: 0 | K56: 0 | L56: 0 | M56: 0 | N56: 0 | O56: 0 | P56: =+H56+J56-K56-L56-M56-N56-O56 -> 2000
A57: 54 | D57: ZZ.32Q IZGARA TAKOZ | H57: ='ekim 4 hafta '!P57 -> 2800 | I57: Adet | J57: 0 | K57: 0 | L57: 0 | M57: 0 | N57: 0 | O57: 0 | P57: =+H57+J57-K57-L57-M57-N57-O57 -> 2800
A58: 55 | D58: ZZ.20x40 İÇ TAKOZ | H58: ='ekim 4 hafta '!P58 -> 3000 | I58: Adet | J58: 0 | K58: 0 | L58: 0 | M58: 0 | N58: 0 | O58: 0 | P58: =+H58+J58-K58-L58-M58-N58-O58 -> 3000
A59: 56 | D59: ZZ.25Q İÇ TAKOZ | H59: ='ekim 4 hafta '!P59 -> 5000 | I59: Adet | J59: 0 | K59: 0 | L59: 0 | M59: 0 | N59: 0 | O59: 0 | P59: =+H59+J59-K59-L59-M59-N59-O59 -> 5000
A60: 57 | D60: ZZ.25x50 ELİPS İÇ TAKOZ | H60: ='ekim 4 hafta '!P60 -> 3000 | I60: Adet | J60: 0 | K60: 0 | L60: 0 | M60: 0 | N60: 0 | O60: 0 | P60: =+H60+J60-K60-L60-M60-N60-O60 -> 3000
A61: 58 | D61: ZZ.25x25 İÇ TAKOZ | H61: ='ekim 4 hafta '!P61 -> 5000 | I61: Adet | J61: 0 | K61: 0 | L61: 0 | M61: 0 | N61: 0 | O61: 0 | P61: =+H61+J61-K61-L61-M61-N61-O61 -> 5000
A62: 59 | D62: OYUNCU KOLTUĞU MEKANİZMA TKM | H62: ='ekim 4 hafta '!P62 -> 494 | I62: Adet | J62: 0 | K62: 0 | L62: 0 | M62: 0 | N62: 0 | O62: 0 | P62: =+H62+J62-K62-L62-M62-N62-O62 -> 494
A63: 60 | D63: OFİS (DIAMOND) PLSTK AYAK | H63: ='ekim 4 hafta '!P63 -> 284 | I63: Adet | J63: 600 | K63: 0 | L63: 0 | M63: 0 | N63: 100 | O63: 100 | P63: =+H63+J63-K63-L63-M63-N63-O63 -> 684
A64: 61 | D64: ZZ.Plastik L Ayak 180X180 | H64: ='ekim 4 hafta '!P64 -> 447 | I64: Adet | J64: 0 | K64: 0 | L64: 0 | M64: 0 | N64: 0 | O64: 0 | P64: =+H64+J64-K64-L64-M64-N64-O64 -> 447
A65: 62 | D65: ZZ.PLASTİK ÜÇGEN AYAK 10 CM (TIESTO) | H65: ='ekim 4 hafta '!P65 -> 315 | I65: Adet | J65: 0 | K65: 0 | L65: 0 | M65: 0 | N65: 0 | O65: 0 | P65: =+H65+J65-K65-L65-M65-N65-O65 -> 315
A66: 63 | D66: ZZ.STINGER PLASTİK AYAK -5.5 Ebru M8*35 | H66: ='ekim 4 hafta '!P66 -> 350 | I66: Adet | J66: 0 | K66: 0 | L66: 0 | M66: 0 | N66: 0 | O66: 0 | P66: =+H66+J66-K66-L66-M66-N66-O66 -> 350
... A72: 69 | D72: ZZ.VEGA (FORM) KOL TABLASI | H72: ='ekim 4 hafta '!P72 -> 0 | I72: Adet | J72: 0 | K72: 0 | L72: 0 | M72: 0 | N72: 0 | O72: 0 | P72: =+H72+J72-K72-L72-M72-N72-O72 -> 0
A73: 70 | D73: TELA BEZ 20 GR | H73: ='ekim 4 hafta '!P73 -> 64 | I73: KĞ | J73: 0 | K73: 32 | L73: 0 | M73: 0 | N73: 0 | O73: 0 | P73: =+H73+J73-K73-L73-M73-N73-O73 -> 32 | Q73: 32 kğ
A74: 71 | D74: SİEANNA,KARİNA PLASTİK KOL | H74: ='ekim 4 hafta '!P74 -> 152 | I74: Adet | J74: 0 | K74: 0 | L74: 0 | M74: 0 | N74: 0 | O74: 0 | P74: =+H74+J74-K74-L74-M74-N74-O74 -> 152
A75: 72 | D75: VOX OTURAK,SIRT İÇ DIŞ PLS. | H75: ='ekim 4 hafta '!P75 -> 67 | I75: Adet | J75: 0 | K75: 0 | L75: 35 | M75: 0 | N75: 0 | O75: 0 | P75: =+H75+J75-K75-L75-M75-N75-O75 -> 32
A76: 73 | D76: POLO PLASTİK TAKIMI | H76: ='ekim 4 hafta '!P76 -> 37 | I76: Adet | J76: 0 | K76: 0 | L76: 0 | M76: 0 | N76: 0 | O76: 0 | P76: =+H76+J76-K76-L76-M76-N76-O76 -> 37
A77: 74 | D77: VEGA FORM ÇAKMA KOL | H77: ='ekim 4 hafta '!P77 -> 50 | I77: Adet | J77: 0 | K77: 0 | L77: 0 | M77: 0 | N77: 0 | O77: 0 | P77: =+H77+J77-K77-L77-M77-N77-O77 -> 50
A78: 75 | D78: EXPERİ KOL | H78: ='ekim 4 hafta '!P78 -> 0 | I78: Adet | J78: 0 | K78: 0 | L78: 0 | M78: 0 | N78: 0 | O78: 0 | P78: =+H78+J78-K78-L78-M78-N78-O78 -> 0
A79: 76 | D79: 100*160 BALONLU NAYLON | H79: ='ekim 4 hafta '!P79 -> 396 | I79: KĞ | J79: 0 | K79: 0 | L79: 100 | M79: 0 | N79: 0 | O79: 0 | P79: =+H79+J79-K79-L79-M79-N79-O79 -> 296
A80: 77 | D80: HARMANY S KOL PLSTİK | H80: ='ekim 4 hafta '!P80 -> 40 | I80: Adet | J80: 0 | K80: 0 | L80: 0 | M80: 0 | N80: 0 | O80: 0 | P80: =+H80+J80-K80-L80-M80-N80-O80 -> 40
A81: 78 | D81: STREÇ NAYLON | H81: 130 | I81: Adet | J81: 0 | K81: 16 | L81: 0 | M81: 0 | N81: 0 | O81: 0 | P81: =+H81+J81-K81-L81-M81-N81-O81 -> 114
...

Sheet KASIM 2 HAFTA 
P1: =+H1+J1-K1-L1-M1-N1-O1 -> 0
O2: 44837
A3: S.NO | D3: ÜRÜN ADI | H3: ADET | I3: BİRİM | J3: GİRİŞ | K3: 44872 | L3: 44873 | M3: 44874 | N3: 44875 | O3: 44876 | P3: KALAN | R3: MİNİMUN | S3: MAKSİMUN
A4: 1 | D4: ZZ.KORUMA FİLESİ 17KĞ | H4: ='KASIM 1 HAFTA'!P4 -> 198 | I4: Kg | J4: 0 | K4: 0 | L4: 0 | M4: 0 | N4: 17 | O4: 0 | P4: =+H4+J4-K4-L4-M4-N4-O4 -> 181 | Q4: KĞ | R4: 100 | S4: 500 | T4: KĞ
A5: 2 | D5: ZZ.RADO (NİTRO) AYAKLI KOL | H5: ='KASIM 1 HAFTA'!P5 -> 30 | I5: Adet | J5: 0 | K5: 0 | L5: 0 | M5: 0 | N5: 0 | O5: 2 | P5: =+H5+J5-K5-L5-M5-N5-O5 -> 28 | R5: 6 | S5: 10
A6: 3 | D6: ZZ.ORBİT (BİLGİN) KOL | H6: ='KASIM 1 HAFTA'!P6 -> 40 | I6: Adet | J6: 0 | K6: 0 | L6: 2 | M6: 0 | N6: 0 | O6: 0 | P6: =+H6+J6-K6-L6-M6-N6-O6 -> 38 | R6: 6 | S6: 10
A7: 4 | D7: ZZ.MAKER YAY KOL | H7: ='KASIM 1 HAFTA'!P7 -> 58 | I7: Adet | J7: 0 | K7: 0 | L7: 0 | M7: 0 | N7: 0 | O7: 0 | P7: =+H7+J7-K7-L7-M7-N7-O7 -> 58 | R7: 6 | S7: 10
A8: 5 | D8: ZZ.JAZZ T KOL | H8: ='KASIM 1 HAFTA'!P8 -> 214 | I8: Adet | J8: 0 | K8: 0 | L8: 0 | M8: 0 | N8: 0 | O8: 0 | P8: =+H8+J8-K8-L8-M8-N8-O8 -> 214 | R8: 100 | S8: 400
A9: 6 | D9: ZZ.STELLA ÜÇGEN PLASTİK KROM KOL | H9: ='KASIM 1 HAFTA'!P9 -> 10 | I9: Adet | J9: 0 | K9: 0 | L9: 10 | M9: 0 | N9: 0 | O9: 0 | P9: =+H9+J9-K9-L9-M9-N9-O9 -> 0 | R9: 60 | S9: 200
A10: 7 | D10: ZZ.PENTA KOL (ayarlı,onyar başlı) | H10: ='KASIM 1 HAFTA'!P10 -> 2151 | I10: Adet | J10: 0 | K10: 0 | L10: 0 | M10: 0 | N10: 0 | O10: 20 | P10: =+H10+J10-K10-L10-M10-N10-O10 -> 2131 | R10: 200 | S10: 500
A11: 8 | D11: ZZ.WENGE KOL PLASTİK | H11: ='KASIM 1 HAFTA'!P11 -> 496 | I11: Adet | J11: 0 | K11: 0 | L11: 0 | M11: 0 | N11: 0 | O11: 0 | P11: =+H11+J11-K11-L11-M11-N11-O11 -> 496 | R11: 0 | S11: 0
A12: 9 | D12: ZZ.PRESTİJ (KİNG EKO PLASTİK ) KOL | H12: ='KASIM 1 HAFTA'!P12 -> 60 | I12: Adet | J12: 0 | K12: 0 | L12: 0 | M12: 0 | N12: 0 | O12: 0 | P12: =+H12+J12-K12-L12-M12-N12-O12 -> 60 | R12: 200 | S12: 400
A13: 10 | D13: ZZ.WARLOCK (ELEGANCE) KOL | H13: ='KASIM 1 HAFTA'!P13 -> 42 | I13: Adet | J13: 0 | K13: 0 | L13: 0 | M13: 0 | N13: 0 | O13: 0 | P13: =+H13+J13-K13-L13-M13-N13-O13 -> 42 | R13: 0
A14: 11 | D14: CYBORG KOL | H14: ='KASIM 1 HAFTA'!P14 -> 14 | I14: Adet | J14: 0 | K14: 0 | L14: 0 | M14: 0 | N14: 8 | O14: 0 | P14: =+H14+J14-K14-L14-M14-N14-O14 -> 6 | R14: 20 | S14: 50
A15: 12 | D15: ZZ. MARKOL(SAKURE) (AHŞAP AÇIK KOL) | H15: ='KASIM 1 HAFTA'!P15 -> 26 | I15: Adet | J15: 0 | K15: 0 | L15: 0 | M15: 0 | N15: 0 | O15: 0 | P15: =+H15+J15-K15-L15-M15-N15-O15 -> 26 | R15: 100 | S15: 200
A16: 13 | D16: ZZ.SEAT ALÜMİNYUM KOL | H16: ='KASIM 1 HAFTA'!P16 -> 90 | I16: Adet | J16: 0 | K16: 0 | L16: 0 | M16: 0 | N16: 0 | O16: 0 | P16: =+H16+J16-K16-L16-M16-N16-O16 -> 90 | R16: 0
A17: 14 | D17: PLASTİK YILDIZ AYAK ÇİN GÜMÜŞ GRİ | H17: ='KASIM 1 HAFTA'!P17 -> 800 | I17: Adet | J17: 0 | K17: 0 | L17: 0 | M17: 0 | N17: 0 | O17: 0 | P17: =+H17+J17-K17-L17-M17-N17-O17 -> 800 | R17: 0
A18: 15 | D18: ZZ.NEO BAR TABURESİ AYAK ÇEMBERİ | H18: 28 | I18: Adet | J18: 0 | K18: 3 | L18: 0 | M18: 0 | N18: 0 | O18: 8 | P18: =+H18+J18-K18-L18-M18-N18-O18 -> 17 | R18: 20 | S18: 50
A19: 16 | D19: ZZ.NEO BAR TEPSİ AYAK 4Q5 | H19: 28 | I19: Adet | J19: 0 | K19: 3 | L19: 0 | M19: 0 | N19: 0 | O19: 8 | P19: =+H19+J19-K19-L19-M19-N19-O19 -> 17 | R19: 20 | S19: 50
A20: 17 | D20: ZZ.NEO BAR AMORTİSÖRÜ 260 LIK | H20: 60 | I20: Adet | J20: 0 | K20: 3 | L20: 0 | M20: 0 | N20: 0 | O20: 8 | P20: =+H20+J20-K20-L20-M20-N20-O20 -> 49 | R20: 20 | S20: 50
A21: 18 | D21: ZZ.EFOR ŞEF SET KOL +SIRT İÇ-DIŞ | H21: ='KASIM 1 HAFTA'!P21 -> 33 | I21: Adet | J21: 0 | K21: 0 | L21: 0 | M21: 0 | N21: 0 | O21: 0 | P21: =+H21+J21-K21-L21-M21-N21-O21 -> 33 | R21: 0
A22: 19 | D22: ZZ.BONCUK ELYAF ( 1 TORBA = 10 KG ) | H22: 30 | I22: Kg | J22: 510 | K22: 0 | L22: 20 | M22: 150 | N22: 10 | O22: 0 | P22: =+H22+J22-K22-L22-M22-N22-O22 -> 360 | Q22: KĞ | R22: 50 | S22: 200
A23: 20 | D23: İNCİ SEKRETER İÇ DIŞ PLASTİĞİ | H23: ='KASIM 1 HAFTA'!P23 -> 2000 | I23: Adet | J23: 0 | K23: 0 | L23: 0 | M23: 0 | N23: 0 | O23: 0 | P23: =+H23+J23-K23-L23-M23-N23-O23 -> 2000 | R23: 0
A24: 21 | D24: TETRA OTURAK İÇ DIŞ PLASTİK AB 3355 | H24: ='KASIM 1 HAFTA'!P24 -> 279 | I24: Adet | J24: 0 | K24: 0 | L24: 0 | M24: 0 | N24: 0 | O24: 0 | P24: =+H24+J24-K24-L24-M24-N24-O24 -> 279 | R24: 0
A25: 22 | D25: EVO SIRT PLASTİĞİ | H25: ='KASIM 1 HAFTA'!P25 -> 40 | I25: Adet | J25: 0 | K25: 0 | L25: 0 | M25: 0 | N25: 0 | O25: 0 | P25: =+H25+J25-K25-L25-M25-N25-O25 -> 40 | R25: 0
A26: 23 | D26: DARK OTURAK İÇ/DIŞ PLASTİK | H26: ='KASIM 1 HAFTA'!P26 -> 168 | I26: Adet | J26: 0 | K26: 0 | L26: 0 | M26: 0 | N26: 0 | O26: 0 | P26: =+H26+J26-K26-L26-M26-N26-O26 -> 168 | R26: 20 | S26: 50
A27: 24 | D27: EVO OTURAK İÇ/DIŞ PLASTİĞİ | H27: ='KASIM 1 HAFTA'!P27 -> 42 | I27: Adet | J27: 0 | K27: 0 | L27: 0 | M27: 0 | N27: 0 | O27: 0 | P27: =+H27+J27-K27-L27-M27-N27-O27 -> 42 | R27: 20 | S27: 50
A28: 25 | D28: ZZ.ZİRVE (BAG 25) SIRT DIŞ KAPAK | H28: ='KASIM 1 HAFTA'!P28 -> 50 | I28: Adet | J28: 0 | K28: 0 | L28: 0 | M28: 0 | N28: 0 | O28: 0 | P28: =+H28+J28-K28-L28-M28-N28-O28 -> 50 | R28: 50 | S28: 100
A29: 26 | D29: ZZ.ZİRVE (BAG 25 ) SIRT İÇ KAPAK | H29: ='KASIM 1 HAFTA'!P29 -> 65 | I29: Adet | J29: 0 | K29: 0 | L29: 0 | M29: 0 | N29: 0 | O29: 0 | P29: =+H29+J29-K29-L29-M29-N29-O29 -> 65 | R29: 50 | S29: 100
A30: 27 | D30: DARK BAŞLIK | H30: ='KASIM 1 HAFTA'!P30 -> 232 | I30: Adet | J30: 0 | K30: 0 | L30: 0 | M30: 0 | N30: 0 | O30: 0 | P30: =+H30+J30-K30-L30-M30-N30-O30 -> 232 | R30: 20 | S30: 50
A31: 28 | D31: ZZ.VOX BAŞLIK | H31: ='KASIM 1 HAFTA'!P31 -> 668 | I31: Adet | J31: 0 | K31: 0 | L31: 0 | M31: 0 | N31: 0 | O31: 0 | P31: =+H31+J31-K31-L31-M31-N31-O31 -> 668 | R31: 50 | S31: 100
A32: 29 | D32: DARK SIRT PLASTİĞİ | H32: ='KASIM 1 HAFTA'!P32 -> 50 | I32: Adet | J32: 0 | K32: 0 | L32: 0 | M32: 0 | N32: 0 | O32: 0 | P32: =+H32+J32-K32-L32-M32-N32-O32 -> 50 | R32: 20 | S32: 50
A33: 30 | D33: SEKRETER İÇ / DIŞ PLASTİĞİ KONYA | H33: ='KASIM 1 HAFTA'!P33 -> 1115 | I33: Adet | J33: 0 | K33: 0 | L33: 0 | M33: 0 | N33: 0 | O33: 0 | P33: =+H33+J33-K33-L33-M33-N33-O33 -> 1115 | R33: 0
A34: 31 | D34: ZZ.NOORD KOL (ALFA) | H34: ='KASIM 1 HAFTA'!P34 -> 546 | I34: Adet | J34: 0 | K34: 0 | L34: 0 | M34: 0 | N34: 0 | O34: 0 | P34: =+H34+J34-K34-L34-M34-N34-O34 -> 546 | R34: 50 | S34: 100
A35: 32 | D35: DARK SIRT İÇ/DIŞ PLASTİĞİ | H35: ='KASIM 1 HAFTA'!P35 -> 100 | I35: Adet | J35: 0 | K35: 0 | L35: 0 | M35: 0 | N35: 0 | O35: 0 | P35: =+H35+J35-K35-L35-M35-N35-O35 -> 100 | R35: 20 | S35: 50
A36: 33 | D36: DORİ PLASTİK BAŞLIK(ALTIN B) | H36: ='KASIM 1 HAFTA'!P36 -> 934 | I36: Adet | J36: 0 | K36: 0 | L36: 0 | M36: 0 | N36: 0 | O36: 0 | P36: =+H36+J36-K36-L36-M36-N36-O36 -> 934 | R36: 0
A37: 34 | D37: ALFA OTURAK İÇ DIŞ PLASTİĞİ | H37: ='KASIM 1 HAFTA'!P37 -> 283 | I37: Adet | J37: 0 | K37: 0 | L37: 0 | M37: 0 | N37: 0 | O37: 0 | P37: =+H37+J37-K37-L37-M37-N37-O37 -> 283 | R37: 50 | S37: 100
A38: 35 | D38: ALFA SIRT PLASTİĞİ | H38: ='KASIM 1 HAFTA'!P38 -> 287 | I38: Adet | J38: 0 | K38: 0 | L38: 0 | M38: 0 | N38: 0 | O38: 0 | P38: =+H38+J38-K38-L38-M38-N38-O38 -> 287 | R38: 50 | S38: 100
A39: 36 | D39: NOORD BAŞLIK PLASTİĞİ (ALFA) | H39: ='KASIM 1 HAFTA'!P39 -> 27 | I39: Adet | J39: 0 | K39: 0 | L39: 0 | M39: 0 | N39: 0 | O39: 0 | P39: =+H39+J39-K39-L39-M39-N39-O39 -> 27 | R39: 50 | S39: 100
A40: 37 | D40: LİMA FONT İÇ PLASTİĞİ | H40: ='KASIM 1 HAFTA'!P40 -> 99 | I40: Adet | J40: 0 | K40: 0 | L40: 0 | M40: 0 | N40: 0 | O40: 0 | P40: =+H40+J40-K40-L40-M40-N40-O40 -> 99 | R40: 0
...

Sheet KASIM 3 HAFTA 
P1: =+H1+J1-K1-L1-M1-N1-O1 -> 0
O2: 44837
A3: S.NO | D3: ÜRÜN ADI | H3: ADET | I3: BİRİM | J3: GİRİŞ | K3: 44879 | L3: 44880 | M3: 44881 | N3: 44882 | O3: 44883 | P3: KALAN | R3: MİNİMUN | S3: MAKSİMUN
A4: 1 | D4: ZZ.KORUMA FİLESİ | H4: ='KASIM 2 HAFTA '!P4 -> 181 | I4: Kg | J4: 0 | K4: 0 | L4: 0 | M4: 0 | N4: 0 | O4: 0 | P4: =+H4+J4-K4-L4-M4-N4-O4 -> 181 | Q4: 17 KĞ | R4: 100 | S4: 500 | T4: KĞ
A5: 2 | D5: ZZ.RADO (NİTRO) AYAKLI KOL | H5: ='KASIM 2 HAFTA '!P5 -> 28 | I5: Adet | J5: 0 | K5: 0 | L5: 0 | M5: 0 | N5: 0 | O5: 0 | P5: =+H5+J5-K5-L5-M5-N5-O5 -> 28 | R5: 6 | S5: 10
A6: 3 | D6: ZZ.ORBİT (BİLGİN) KOL | H6: 14 | I6: Adet | J6: 0 | K6: 0 | L6: 0 | M6: 0 | N6: 0 | O6: 0 | P6: =+H6+J6-K6-L6-M6-N6-O6 -> 14 | R6: 6 | S6: 10
A7: 4 | D7: ZZ.MAKER YAY KOL | H7: ='KASIM 2 HAFTA '!P7 -> 58 | I7: Adet | J7: 0 | K7: 0 | L7: 0 | M7: 0 | N7: 0 | O7: 0 | P7: =+H7+J7-K7-L7-M7-N7-O7 -> 58 | R7: 6 | S7: 10
A8: 5 | D8: ZZ.JAZZ T KOL | H8: ='KASIM 2 HAFTA '!P8 -> 214 | I8: Adet | J8: 0 | K8: 0 | L8: 2 | M8: 14 | N8: 72 | O8: 0 | P8: =+H8+J8-K8-L8-M8-N8-O8 -> 126 | R8: 100 | S8: 400
A9: 6 | D9: ZZ.STELLA ÜÇGEN PLASTİK KROM KOL | H9: ='KASIM 2 HAFTA '!P9 -> 0 | I9: Adet | J9: 200 | K9: 0 | L9: 0 | M9: 40 | N9: 0 | O9: 0 | P9: =+H9+J9-K9-L9-M9-N9-O9 -> 160 | R9: 60 | S9: 200
A10: 7 | D10: ZZ.PENTA KOL (ayarlı,onyar başlı) | H10: ='KASIM 2 HAFTA '!P10 -> 2131 | I10: Adet | J10: 0 | K10: 0 | L10: 0 | M10: 250 | N10: 0 | O10: 14 | P10: =+H10+J10-K10-L10-M10-N10-O10 -> 1867 | R10: 200 | S10: 500
A11: 8 | D11: ZZ.WENGE KOL PLASTİK | H11: ='KASIM 2 HAFTA '!P11 -> 496 | I11: Adet | J11: 0 | K11: 0 | L11: 0 | M11: 0 | N11: 0 | O11: 0 | P11: =+H11+J11-K11-L11-M11-N11-O11 -> 496 | R11: 0 | S11: 0
A12: 9 | D12: ZZ.PRESTİJ (KİNG EKO PLASTİK ) KOL | H12: ='KASIM 2 HAFTA '!P12 -> 60 | I12: Adet | J12: 0 | K12: 0 | L12: 0 | M12: 0 | N12: 0 | O12: 0 | P12: =+H12+J12-K12-L12-M12-N12-O12 -> 60 | R12: 200 | S12: 400
A13: 10 | D13: ZZ.WARLOCK (ELEGANCE) KOL | H13: ='KASIM 2 HAFTA '!P13 -> 42 | I13: Adet | J13: 0 | K13: 0 | L13: 0 | M13: 0 | N13: 0 | O13: 0 | P13: =+H13+J13-K13-L13-M13-N13-O13 -> 42 | R13: 0
A14: 11 | D14: CYBORG KOL | H14: ='KASIM 2 HAFTA '!P14 -> 6 | I14: Adet | J14: 0 | K14: 0 | L14: 0 | M14: 6 | N14: 0 | O14: 0 | P14: =+H14+J14-K14-L14-M14-N14-O14 -> 0 | R14: 20 | S14: 50
A15: 12 | D15: ZZ. MARKOL(SAKURE) (AHŞAP AÇIK KOL) | H15: ='KASIM 2 HAFTA '!P15 -> 26 | I15: Adet | J15: 0 | K15: 0 | L15: 0 | M15: 0 | N15: 0 | O15: 0 | P15: =+H15+J15-K15-L15-M15-N15-O15 -> 26 | R15: 100 | S15: 200
A16: 13 | D16: ZZ.SEAT ALÜMİNYUM KOL | H16: ='KASIM 2 HAFTA '!P16 -> 90 | I16: Adet | J16: 0 | K16: 0 | L16: 0 | M16: 0 | N16: 0 | O16: 0 | P16: =+H16+J16-K16-L16-M16-N16-O16 -> 90 | R16: 0
A17: 14 | D17: PLASTİK YILDIZ AYAK ÇİN GÜMÜŞ GRİ | H17: ='KASIM 2 HAFTA '!P17 -> 800 | I17: Adet | J17: 0 | K17: 0 | L17: 0 | M17: 0 | N17: 0 | O17: 0 | P17: =+H17+J17-K17-L17-M17-N17-O17 -> 800 | R17: 0
A18: 15 | D18: ZZ.NEO BAR TABURESİ AYAK ÇEMBERİ | H18: ='KASIM 2 HAFTA '!P18 -> 17 | I18: Adet | J18: 50 | K18: 0 | L18: 0 | M18: 0 | N18: 5 | O18: 0 | P18: =+H18+J18-K18-L18-M18-N18-O18 -> 62 | R18: 20 | S18: 50
A19: 16 | D19: ZZ.NEO BAR TEPSİ AYAK 4Q5 | H19: ='KASIM 2 HAFTA '!P19 -> 17 | I19: Adet | J19: 50 | K19: 0 | L19: 0 | M19: 0 | N19: 5 | O19: 0 | P19: =+H19+J19-K19-L19-M19-N19-O19 -> 62 | R19: 20 | S19: 50
A20: 17 | D20: ZZ.NEO BAR AMORTİSÖRÜ 260 LIK | H20: ='KASIM 2 HAFTA '!P20 -> 49 | I20: Adet | J20: 50 | K20: 0 | L20: 0 | M20: 0 | N20: 5 | O20: 0 | P20: =+H20+J20-K20-L20-M20-N20-O20 -> 94 | R20: 20 | S20: 50
A21: 18 | D21: ZZ.EFOR ŞEF SET KOL +SIRT İÇ-DIŞ | H21: ='KASIM 2 HAFTA '!P21 -> 33 | I21: Adet | J21: 0 | K21: 0 | L21: 0 | M21: 0 | N21: 0 | O21: 0 | P21: =+H21+J21-K21-L21-M21-N21-O21 -> 33 | R21: 0
A22: 19 | D22: ZZ.BONCUK ELYAF ( 1 TORBA = 10 KG ) | H22: ='KASIM 2 HAFTA '!P22 -> 360 | I22: Kg | J22: 0 | K22: 130 | L22: 10 | M22: 0 | N22: 90 | O22: 0 | P22: =+H22+J22-K22-L22-M22-N22-O22 -> 130 | R22: 50 | S22: 200
A23: 20 | D23: İNCİ SEKRETER İÇ DIŞ PLASTİĞİ | H23: ='KASIM 2 HAFTA '!P23 -> 2000 | I23: Adet | J23: 0 | K23: 0 | L23: 0 | M23: 0 | N23: 0 | O23: 0 | P23: =+H23+J23-K23-L23-M23-N23-O23 -> 2000 | R23: 0
A24: 21 | D24: TETRA OTURAK İÇ DIŞ PLASTİK AB 3355 | H24: ='KASIM 2 HAFTA '!P24 -> 279 | I24: Adet | J24: 0 | K24: 0 | L24: 0 | M24: 0 | N24: 6 | O24: 0 | P24: =+H24+J24-K24-L24-M24-N24-O24 -> 273 | R24: 0
A25: 22 | D25: EVO SIRT PLASTİĞİ | H25: ='KASIM 2 HAFTA '!P25 -> 40 | I25: Adet | J25: 0 | K25: 0 | L25: 0 | M25: 0 | N25: 0 | O25: 0 | P25: =+H25+J25-K25-L25-M25-N25-O25 -> 40 | R25: 0
A26: 23 | D26: DARK OTURAK İÇ/DIŞ PLASTİK | H26: ='KASIM 2 HAFTA '!P26 -> 168 | I26: Adet | J26: 0 | K26: 0 | L26: 0 | M26: 0 | N26: 0 | O26: 0 | P26: =+H26+J26-K26-L26-M26-N26-O26 -> 168 | R26: 20 | S26: 50
A27: 24 | D27: EVO OTURAK İÇ/DIŞ PLASTİĞİ | H27: ='KASIM 2 HAFTA '!P27 -> 42 | I27: Adet | J27: 0 | K27: 0 | L27: 0 | M27: 0 | N27: 0 | O27: 0 | P27: =+H27+J27-K27-L27-M27-N27-O27 -> 42 | R27: 20 | S27: 50
A28: 25 | D28: ZZ.ZİRVE (BAG 25) SIRT DIŞ KAPAK | H28: ='KASIM 2 HAFTA '!P28 -> 50 | I28: Adet | J28: 0 | K28: 0 | L28: 0 | M28: 0 | N28: 0 | O28: 0 | P28: =+H28+J28-K28-L28-M28-N28-O28 -> 50 | R28: 50 | S28: 100
A29: 26 | D29: ZZ.ZİRVE (BAG 25 ) SIRT İÇ KAPAK | H29: ='KASIM 2 HAFTA '!P29 -> 65 | I29: Adet | J29: 0 | K29: 0 | L29: 0 | M29: 0 | N29: 0 | O29: 0 | P29: =+H29+J29-K29-L29-M29-N29-O29 -> 65 | R29: 50 | S29: 100
A30: 27 | D30: DARK BAŞLIK | H30: ='KASIM 2 HAFTA '!P30 -> 232 | I30: Adet | J30: 0 | K30: 0 | L30: 0 | M30: 0 | N30: 0 | O30: 0 | P30: =+H30+J30-K30-L30-M30-N30-O30 -> 232 | R30: 20 | S30: 50
A31: 28 | D31: ZZ.VOX BAŞLIK | H31: ='KASIM 2 HAFTA '!P31 -> 668 | I31: Adet | J31: 0 | K31: 0 | L31: 0 | M31: 112 | N31: 0 | O31: 0 | P31: =+H31+J31-K31-L31-M31-N31-O31 -> 556 | R31: 50 | S31: 100
A32: 29 | D32: DARK SIRT PLASTİĞİ | H32: ='KASIM 2 HAFTA '!P32 -> 50 | I32: Adet | J32: 0 | K32: 0 | L32: 0 | M32: 0 | N32: 0 | O32: 0 | P32: =+H32+J32-K32-L32-M32-N32-O32 -> 50 | R32: 20 | S32: 50
A33: 30 | D33: SEKRETER İÇ / DIŞ PLASTİĞİ KONYA | H33: ='KASIM 2 HAFTA '!P33 -> 1115 | I33: Adet | J33: 0 | K33: 0 | L33: 0 | M33: 0 | N33: 0 | O33: 0 | P33: =+H33+J33-K33-L33-M33-N33-O33 -> 1115 | R33: 0
A34: 31 | D34: ZZ.NOORD KOL (ALFA) | H34: ='KASIM 2 HAFTA '!P34 -> 546 | I34: Adet | J34: 0 | K34: 0 | L34: 0 | M34: 0 | N34: 0 | O34: 0 | P34: =+H34+J34-K34-L34-M34-N34-O34 -> 546 | R34: 50 | S34: 100
A35: 32 | D35: DARK SIRT İÇ/DIŞ PLASTİĞİ | H35: ='KASIM 2 HAFTA '!P35 -> 100 | I35: Adet | J35: 0 | K35: 0 | L35: 0 | M35: 0 | N35: 0 | O35: 6 | P35: =+H35+J35-K35-L35-M35-N35-O35 -> 94 | R35: 20 | S35: 50
A36: 33 | D36: DORİ PLASTİK BAŞLIK(ALTIN B) | H36: ='KASIM 2 HAFTA '!P36 -> 934 | I36: Adet | J36: 0 | K36: 0 | L36: 0 | M36: 0 | N36: 0 | O36: 0 | P36: =+H36+J36-K36-L36-M36-N36-O36 -> 934 | R36: 0
A37: 34 | D37: ALFA OTURAK İÇ DIŞ PLASTİĞİ | H37: ='KASIM 2 HAFTA '!P37 -> 283 | I37: Adet | J37: 0 | K37: 0 | L37: 0 | M37: 0 | N37: 0 | O37: 0 | P37: =+H37+J37-K37-L37-M37-N37-O37 -> 283 | R37: 50 | S37: 100
A38: 35 | D38: ALFA SIRT PLASTİĞİ | H38: ='KASIM 2 HAFTA '!P38 -> 287 | I38: Adet | J38: 0 | K38: 0 | L38: 0 | M38: 0 | N38: 0 | O38: 0 | P38: =+H38+J38-K38-L38-M38-N38-O38 -> 287 | R38: 50 | S38: 100
A39: 36 | D39: NOORD BAŞLIK PLASTİĞİ (ALFA) | H39: ='KASIM 2 HAFTA '!P39 -> 27 | I39: Adet | J39: 0 | K39: 0 | L39: 0 | M39: 0 | N39: 0 | O39: 0 | P39: =+H39+J39-K39-L39-M39-N39-O39 -> 27 | R39: 50 | S39: 100
A40: 37 | D40: LİMA FONT İÇ PLASTİĞİ | H40: ='KASIM 2 HAFTA '!P40 -> 99 | I40: Adet | J40: 0 | K40: 0 | L40: 0 | M40: 0 | N40: 0 | O40: 0 | P40: =+H40+J40-K40-L40-M40-N40-O40 -> 99 | R40: 0
...

Sheet KASIM 4 HAFTA 
P1: =+H1+J1-K1-L1-M1-N1-O1 -> 0
S2: 44837
A3: S.NO | D3: ÜRÜN ADI | H3: ADET | I3: BİRİM | J3: GİRİŞ | K3: 44886 | L3: 44887 | M3: 44888 | N3: 44889 | O3: 44890 | P3: KALAN | R3: MİNİMUN | S3: MAKSİMUN
A4: 1 | D4: ZZ.KORUMA FİLESİ | H4: ='KASIM 3 HAFTA '!P4 -> 181 | I4: Kg | J4: 0 | K4: 0 | L4: 0 | M4: 17 | N4: 0 | O4: 0 | P4: =+H4+J4-K4-L4-M4-N4-O4 -> 164 | Q4: 17 KĞ | R4: 100 | S4: 500 | T4: KĞ
A5: 2 | D5: ZZ.RADO (NİTRO) AYAKLI KOL | H5: ='KASIM 3 HAFTA '!P5 -> 28 | I5: Adet | J5: 0 | K5: 0 | L5: 0 | M5: 0 | N5: 0 | O5: 0 | P5: =+H5+J5-K5-L5-M5-N5-O5 -> 28 | R5: 6 | S5: 10
A6: 3 | D6: ZZ.ORBİT (BİLGİN) KOL | H6: ='KASIM 3 HAFTA '!P6 -> 14 | I6: Adet | J6: 0 | K6: 0 | L6: 0 | M6: 0 | N6: 0 | O6: 0 | P6: =+H6+J6-K6-L6-M6-N6-O6 -> 14 | R6: 6 | S6: 10
A7: 4 | D7: ZZ.MAKER YAY KOL | H7: ='KASIM 3 HAFTA '!P7 -> 58 | I7: Adet | J7: 0 | K7: 0 | L7: 0 | M7: 0 | N7: 0 | O7: 0 | P7: =+H7+J7-K7-L7-M7-N7-O7 -> 58 | R7: 6 | S7: 10
A8: 5 | D8: ZZ.JAZZ T KOL | H8: ='KASIM 3 HAFTA '!P8 -> 126 | I8: Adet | J8: 0 | K8: 0 | L8: 0 | M8: 0 | N8: 4 | O8: 0 | P8: =+H8+J8-K8-L8-M8-N8-O8 -> 122 | R8: 100 | S8: 400
A9: 6 | D9: ZZ.STELLA ÜÇGEN PLASTİK KROM KOL | H9: ='KASIM 3 HAFTA '!P9 -> 160 | I9: Adet | J9: 0 | K9: 0 | L9: 0 | M9: 20 | N9: 0 | O9: 0 | P9: =+H9+J9-K9-L9-M9-N9-O9 -> 140 | R9: 60 | S9: 200
A10: 7 | D10: ZZ.PENTA KOL (ayarlı,onyar başlı) | H10: ='KASIM 3 HAFTA '!P10 -> 1867 | I10: Adet | J10: 0 | K10: 20 | L10: 0 | M10: 0 | N10: 0 | O10: 40 | P10: =+H10+J10-K10-L10-M10-N10-O10 -> 1807 | R10: 200 | S10: 500
A11: 8 | D11: ZZ.WENGE KOL PLASTİK | H11: ='KASIM 3 HAFTA '!P11 -> 496 | I11: Adet | J11: 0 | K11: 0 | L11: 0 | M11: 0 | N11: 0 | O11: 0 | P11: =+H11+J11-K11-L11-M11-N11-O11 -> 496 | R11: 0 | S11: 0
A12: 9 | D12: ZZ.PRESTİJ (KİNG EKO PLASTİK ) KOL | H12: ='KASIM 3 HAFTA '!P12 -> 60 | I12: Adet | J12: 0 | K12: 0 | L12: 0 | M12: 0 | N12: 0 | O12: 0 | P12: =+H12+J12-K12-L12-M12-N12-O12 -> 60 | R12: 200 | S12: 400
A13: 10 | D13: ZZ.WARLOCK (ELEGANCE) KOL | H13: ='KASIM 3 HAFTA '!P13 -> 42 | I13: Adet | J13: 0 | K13: 0 | L13: 0 | M13: 0 | N13: 0 | O13: 0 | P13: =+H13+J13-K13-L13-M13-N13-O13 -> 42 | R13: 0
A14: 11 | D14: CYBORG KOL | H14: ='KASIM 3 HAFTA '!P14 -> 0 | I14: Adet | J14: 0 | K14: 0 | L14: 0 | M14: 0 | N14: 0 | O14: 0 | P14: =+H14+J14-K14-L14-M14-N14-O14 -> 0 | R14: 20 | S14: 50
A15: 12 | D15: ZZ. MARKOL(SAKURE) (AHŞAP AÇIK KOL) | H15: ='KASIM 3 HAFTA '!P15 -> 26 | I15: Adet | J15: 0 | K15: 0 | L15: 0 | M15: 0 | N15: 0 | O15: 0 | P15: =+H15+J15-K15-L15-M15-N15-O15 -> 26 | R15: 100 | S15: 200
A16: 13 | D16: ZZ.SEAT ALÜMİNYUM KOL | H16: ='KASIM 3 HAFTA '!P16 -> 90 | I16: Adet | J16: 0 | K16: 0 | L16: 0 | M16: 0 | N16: 0 | O16: 0 | P16: =+H16+J16-K16-L16-M16-N16-O16 -> 90 | R16: 0
A17: 14 | D17: PLASTİK YILDIZ AYAK ÇİN GÜMÜŞ GRİ | H17: ='KASIM 3 HAFTA '!P17 -> 800 | I17: Adet | J17: 0 | K17: 0 | L17: 0 | M17: 0 | N17: 0 | O17: 0 | P17: =+H17+J17-K17-L17-M17-N17-O17 -> 800 | R17: 0
A18: 15 | D18: ZZ.NEO BAR TABURESİ AYAK ÇEMBERİ | H18: ='KASIM 3 HAFTA '!P18 -> 62 | I18: Adet | J18: 0 | K18: 0 | L18: 0 | M18: 0 | N18: 0 | O18: 0 | P18: =+H18+J18-K18-L18-M18-N18-O18 -> 62 | R18: 20 | S18: 50
A19: 16 | D19: ZZ.NEO BAR TEPSİ AYAK 4Q5 | H19: ='KASIM 3 HAFTA '!P19 -> 62 | I19: Adet | J19: 0 | K19: 0 | L19: 0 | M19: 0 | N19: 0 | O19: 0 | P19: =+H19+J19-K19-L19-M19-N19-O19 -> 62 | R19: 20 | S19: 50
A20: 17 | D20: ZZ.NEO BAR AMORTİSÖRÜ 260 LIK | H20: ='KASIM 3 HAFTA '!P20 -> 94 | I20: Adet | J20: 0 | K20: 0 | L20: 0 | M20: 0 | N20: 0 | O20: 0 | P20: =+H20+J20-K20-L20-M20-N20-O20 -> 94 | R20: 20 | S20: 50
A21: 18 | D21: ZZ.EFOR ŞEF SET KOL +SIRT İÇ-DIŞ | H21: ='KASIM 3 HAFTA '!P21 -> 33 | I21: Adet | J21: 0 | K21: 0 | L21: 0 | M21: 0 | N21: 0 | O21: 0 | P21: =+H21+J21-K21-L21-M21-N21-O21 -> 33 | R21: 0
A22: 19 | D22: ZZ.BONCUK ELYAF ( 1 TORBA = 10 KG ) | H22: ='KASIM 3 HAFTA '!P22 -> 130 | I22: Kg | J22: 0 | K22: 10 | L22: 0 | M22: 0 | N22: 20 | O22: 10 | P22: =+H22+J22-K22-L22-M22-N22-O22 -> 90 | R22: 50 | S22: 200
A23: 20 | D23: İNCİ SEKRETER İÇ DIŞ PLASTİĞİ | H23: ='KASIM 3 HAFTA '!P23 -> 2000 | I23: Adet | J23: 0 | K23: 0 | L23: 0 | M23: 0 | N23: 0 | O23: 0 | P23: =+H23+J23-K23-L23-M23-N23-O23 -> 2000 | R23: 0
A24: 21 | D24: TETRA OTURAK İÇ DIŞ PLASTİK AB 3355 | H24: ='KASIM 3 HAFTA '!P24 -> 273 | I24: Adet | J24: 0 | K24: 0 | L24: 0 | M24: 0 | N24: 0 | O24: 0 | P24: =+H24+J24-K24-L24-M24-N24-O24 -> 273 | R24: 0
A25: 22 | D25: EVO SIRT PLASTİĞİ | H25: ='KASIM 3 HAFTA '!P25 -> 40 | I25: Adet | J25: 0 | K25: 0 | L25: 0 | M25: 0 | N25: 0 | O25: 0 | P25: =+H25+J25-K25-L25-M25-N25-O25 -> 40 | R25: 0
A26: 23 | D26: DARK OTURAK İÇ/DIŞ PLASTİK | H26: ='KASIM 3 HAFTA '!P26 -> 168 | I26: Adet | J26: 0 | K26: 0 | L26: 0 | M26: 0 | N26: 0 | O26: 0 | P26: =+H26+J26-K26-L26-M26-N26-O26 -> 168 | R26: 20 | S26: 50
A27: 24 | D27: EVO OTURAK İÇ/DIŞ PLASTİĞİ | H27: ='KASIM 3 HAFTA '!P27 -> 42 | I27: Adet | J27: 0 | K27: 0 | L27: 0 | M27: 0 | N27: 0 | O27: 0 | P27: =+H27+J27-K27-L27-M27-N27-O27 -> 42 | R27: 20 | S27: 50
A28: 25 | D28: ZZ.ZİRVE (BAG 25) SIRT DIŞ KAPAK | H28: ='KASIM 3 HAFTA '!P28 -> 50 | I28: Adet | J28: 0 | K28: 0 | L28: 0 | M28: 0 | N28: 0 | O28: 40 | P28: =+H28+J28-K28-L28-M28-N28-O28 -> 10 | R28: 50 | S28: 100
A29: 26 | D29: ZZ.ZİRVE (BAG 25 ) SIRT İÇ KAPAK | H29: ='KASIM 3 HAFTA '!P29 -> 65 | I29: Adet | J29: 0 | K29: 0 | L29: 0 | M29: 0 | N29: 0 | O29: 40 | P29: =+H29+J29-K29-L29-M29-N29-O29 -> 25 | R29: 50 | S29: 100
A30: 27 | D30: DARK BAŞLIK | H30: ='KASIM 3 HAFTA '!P30 -> 232 | I30: Adet | J30: 0 | K30: 0 | L30: 0 | M30: 0 | N30: 2 | O30: 0 | P30: =+H30+J30-K30-L30-M30-N30-O30 -> 230 | R30: 20 | S30: 50
A31: 28 | D31: ZZ.VOX BAŞLIK | H31: ='KASIM 3 HAFTA '!P31 -> 556 | I31: Adet | J31: 0 | K31: 5 | L31: 0 | M31: 0 | N31: 0 | O31: 0 | P31: =+H31+J31-K31-L31-M31-N31-O31 -> 551 | R31: 50 | S31: 100
A32: 29 | D32: DARK SIRT PLASTİĞİ | H32: ='KASIM 3 HAFTA '!P32 -> 50 | I32: Adet | J32: 0 | K32: 0 | L32: 0 | M32: 0 | N32: 2 | O32: 0 | P32: =+H32+J32-K32-L32-M32-N32-O32 -> 48 | R32: 20 | S32: 50
A33: 30 | D33: SEKRETER İÇ / DIŞ PLASTİĞİ KONYA | H33: ='KASIM 3 HAFTA '!P33 -> 1115 | I33: Adet | J33: 0 | K33: 0 | L33: 0 | M33: 0 | N33: 0 | O33: 40 | P33: =+H33+J33-K33-L33-M33-N33-O33 -> 1075 | R33: 0
A34: 31 | D34: ZZ.NOORD KOL (ALFA) | H34: ='KASIM 3 HAFTA '!P34 -> 546 | I34: Adet | J34: 0 | K34: 0 | L34: 0 | M34: 0 | N34: 0 | O34: 0 | P34: =+H34+J34-K34-L34-M34-N34-O34 -> 546 | R34: 50 | S34: 100
A35: 32 | D35: DARK SIRT İÇ/DIŞ PLASTİĞİ | H35: ='KASIM 3 HAFTA '!P35 -> 94 | I35: Adet | J35: 0 | K35: 0 | L35: 0 | M35: 0 | N35: 2 | O35: 0 | P35: =+H35+J35-K35-L35-M35-N35-O35 -> 92 | R35: 20 | S35: 50
