Workbook

Sheet KASIM 5 HAFTA   (2)
B1: SÜNGER | C1: EKİM 5. HAFTA
A2: S.NO | B2: ÜRÜN ADI | G2: DEVİR STOK | I2: 44893 | K2: 44894 | M2: 44895 | O2: 44896 | Q2: 44897 | S2: KALAN STOK | U2: STOK GİRİŞİ | W2: TOPLAM STOK MİKTARI
I3: STOK ÇIKIŞI | K3: STOK ÇIKIŞI | M3: STOK ÇIKIŞI | O3: STOK ÇIKIŞI | Q3: STOK ÇIKIŞI
B4: CİNSİ | C4: EN | D4: BOY | E4: YÜKS | F4: br m³ | G4: PLAKA ADET | I4: PLAKA ADET | K4: PLAKA ADET | M4: PLAKA ADET | O4: PLAKA ADET | Q4: PLAKA ADET | S4: PLAKA ADET | U4: PLAKA ADET | W4: PLAKA ADET | Y4: MAKSİMUN | Z4: MİNİMUN
A5: 1 | B5: 22 DN GRİ 1,0 | C5: 140 | D5: 240 | E5: 1 | F5: =(C5*D5*E5)/1000000 -> 0.0336 | G5: ='KASIM 4 HAFTA '!W5 -> 329 | H5: =F5*G5 -> 11.0544 | I5: 103 | J5: =F5*I5 -> 3.4608 | K5: 46 | L5: =F5*K5 -> 1.5456 | M5: 5 | N5: =F5*M5 -> 0.168 | O5: 28 | P5: =F5*O5 -> 0.9408 | Q5: 27 | R5: =F5*Q5 -> 0.9072 | S5: =G5-I5-K5-M5-O5-Q5 -> 120 | T5: =F5*S5 -> 4.032 | U5: 90 | V5: =F5*U5 -> 3.024 | W5: =S5+U5 -> 210 | X5: =F5*W5 -> 7.056 | Y5: 250 | Z5: 750
A6: 2 | B6: 14 DN BEYAZ 0,8 | C6: 140 | D6: 240 | E6: 0.8 | F6: =(C6*D6*E6)/1000000 -> 0.02688 | G6: ='KASIM 4 HAFTA '!W6 -> 138 | H6: =F6*G6 -> 3.70944 | I6: 14 | J6: =F6*I6 -> 0.37632 | K6: 0 | L6: =F6*K6 -> 0 | M6: 35 | N6: =F6*M6 -> 0.9408 | O6: 10 | P6: =F6*O6 -> 0.2688 | Q6: 0 | R6: =F6*Q6 -> 0 | S6: =G6-I6-K6-M6-O6-Q6 -> 79 | T6: =F6*S6 -> 2.12352 | U6: 0 | V6: =F6*U6 -> 0 | W6: =S6+U6 -> 79 | X6: =F6*W6 -> 2.12352 | Y6: 100 | Z6: 300
A7: 3 | B7: 14 DN BEYAZ 1,4 | C7: 140 | D7: 240 | E7: 1.4 | F7: =(C7*D7*E7)/1000000 -> 0.04704 | G7: ='KASIM 4 HAFTA '!W7 -> 78 | H7: =F7*G7 -> 3.66912 | I7: 38 | J7: =F7*I7 -> 1.78752 | K7: 24 | L7: =F7*K7 -> 1.12896 | M7: 2 | N7: =F7*M7 -> 0.09408 | O7: 39 | P7: =F7*O7 -> 1.83456 | Q7: 1 | R7: =F7*Q7 -> 0.04704 | S7: =G7-I7-K7-M7-O7-Q7 -> -26 | T7: =F7*S7 -> -1.22304 | U7: 150 | V7: =F7*U7 -> 7.056 | W7: =S7+U7 -> 124 | X7: =F7*W7 -> 5.83296 | Y7: 250 | Z7: 750
A8: 4 | B8: 22 DN GRİ 4,0 | C8: 140 | D8: 240 | E8: 4 | F8: =(C8*D8*E8)/1000000 -> 0.1344 | G8: ='KASIM 4 HAFTA '!W8 -> 2 | H8: =F8*G8 -> 0.2688 | I8: 2 | J8: =F8*I8 -> 0.2688 | K8: 0 | L8: =F8*K8 -> 0 | M8: 0 | N8: =F8*M8 -> 0 | O8: 0 | P8: =F8*O8 -> 0 | Q8: 0 | R8: =F8*Q8 -> 0 | S8: =G8-I8-K8-M8-O8-Q8 -> 0 | T8: =F8*S8 -> 0 | V8: =F8*U8 -> 0 | W8: =S8+U8 -> 0 | X8: =F8*W8 -> 0 | Y8: 20 | Z8: 50
A9: 5 | B9: 22 DN GRİ 2,0 | C9: 140 | D9: 240 | E9: 2 | F9: =(C9*D9*E9)/1000000 -> 0.0672 | G9: ='KASIM 4 HAFTA '!W9 -> 80 | H9: =F9*G9 -> 5.376 | I9: 0 | J9: =F9*I9 -> 0 | K9: 4 | L9: =F9*K9 -> 0.2688 | M9: 0 | N9: =F9*M9 -> 0 | O9: 2 | P9: =F9*O9 -> 0.1344 | Q9: 1 | R9: =F9*Q9 -> 0.0672 | S9: =G9-I9-K9-M9-O9-Q9 -> 73 | T9: =F9*S9 -> 4.9056 | V9: =F9*U9 -> 0 | W9: =S9+U9 -> 73 | X9: =F9*W9 -> 4.9056 | Y9: 50 | Z9: 150
A10: 6 | B10: 24 DN KUŞTÜYÜ 2 ,0 | C10: 140 | D10: 240 | E10: 2 | F10: =(C10*D10*E10)/1000000 -> 0.0672 | G10: ='KASIM 4 HAFTA '!W10 -> 88 | H10: =F10*G10 -> 5.9136 | I10: 32 | J10: =F10*I10 -> 2.1504 | K10: 0 | L10: =F10*K10 -> 0 | M10: 0 | N10: =F10*M10 -> 0 | O10: 43 | P10: =F10*O10 -> 2.8896 | Q10: 0 | R10: =F10*Q10 -> 0 | S10: =G10-I10-K10-M10-O10-Q10 -> 13 | T10: =F10*S10 -> 0.8736 | V10: =F10*U10 -> 0 | W10: =S10+U10 -> 13 | X10: =F10*W10 -> 0.8736 | Y10: 75 | Z10: 300
A11: 7 | B11: 30 DN LÜKS BEYAZ 7,0 | C11: 140 | D11: 240 | E11: 7 | F11: =(C11*D11*E11)/1000000 -> 0.2352 | G11: ='KASIM 4 HAFTA '!W11 -> 68 | H11: =F11*G11 -> 15.9936 | I11: 0 | J11: =F11*I11 -> 0 | K11: 0 | L11: =F11*K11 -> 0 | M11: 6 | N11: =F11*M11 -> 1.4112 | O11: 4 | P11: =F11*O11 -> 0.9408 | Q11: 0 | R11: =F11*Q11 -> 0 | S11: =G11-I11-K11-M11-O11-Q11 -> 58 | T11: =F11*S11 -> 13.6416 | U11: 0 | V11: =F11*U11 -> 0 | W11: =S11+U11 -> 58 | X11: =F11*W11 -> 13.6416 | Y11: 20 | Z11: 50
A12: 8 | B12: 24 DN KUŞTÜYÜ 5 ,0 | C12: 140 | D12: 240 | E12: 5 | F12: =(C12*D12*E12)/1000000 -> 0.168 | G12: ='KASIM 4 HAFTA '!W12 -> 291 | H12: =F12*G12 -> 48.888 | I12: 0 | J12: =F12*I12 -> 0 | K12: 0 | L12: =F12*K12 -> 0 | M12: 0 | N12: =F12*M12 -> 0 | O12: 0 | P12: =F12*O12 -> 0 | Q12: 0 | R12: =F12*Q12 -> 0 | S12: =G12-I12-K12-M12-O12-Q12 -> 291 | T12: =F12*S12 -> 48.888 | V12: =F12*U12 -> 0 | W12: =S12+U12 -> 291 | X12: =F12*W12 -> 48.888 | Y12: 30 | Z12: 100
A13: 9 | B13: 28 DN GRİ SOFT 5,0 | C13: 140 | D13: 240 | E13: 5 | F13: =(C13*D13*E13)/1000000 -> 0.168 | G13: ='KASIM 4 HAFTA '!W13 -> 0 | H13: =F13*G13 -> 0 | I13: 6 | J13: =F13*I13 -> 1.008 | K13: 0 | L13: =F13*K13 -> 0 | M13: 0 | N13: =F13*M13 -> 0 | O13: 1 | P13: =F13*O13 -> 0.168 | Q13: 0 | R13: =F13*Q13 -> 0 | S13: =G13-I13-K13-M13-O13-Q13 -> -7 | T13: =F13*S13 -> -1.176 | U13: 26 | V13: =F13*U13 -> 4.368 | W13: =S13+U13 -> 19 | X13: =F13*W13 -> 3.192 | Y13: 20 | Z13: 50
A14: 10 | B14: 28 DN GRİ 5,0 | C14: 140 | D14: 240 | E14: 5 | F14: =(C14*D14*E14)/1000000 -> 0.168 | G14: ='KASIM 4 HAFTA '!W14 -> 51 | H14: =F14*G14 -> 8.568 | I14: 0 | J14: =F14*I14 -> 0 | K14: 3 | L14: =F14*K14 -> 0.504 | M14: 0 | N14: =F14*M14 -> 0 | O14: 0 | P14: =F14*O14 -> 0 | Q14: 1 | R14: =F14*Q14 -> 0.168 | S14: =G14-I14-K14-M14-O14-Q14 -> 47 | T14: =F14*S14 -> 7.896 | U14: 102 | V14: =F14*U14 -> 17.136 | W14: =S14+U14 -> 149 | X14: =F14*W14 -> 25.032 | Y14: 30 | Z14: 100
A15: 11 | B15: 28 DN SOFT 10 | C15: 140 | D15: 240 | E15: 10 | F15: =(C15*D15*E15)/1000000 -> 0.336 | G15: 3 | H15: =F15*G15 -> 1.008 | I15: 0 | J15: =F15*I15 -> 0 | K15: 0 | L15: =F15*K15 -> 0 | M15: 0 | N15: =F15*M15 -> 0 | O15: 13 | P15: =F15*O15 -> 4.368 | Q15: 1 | R15: =F15*Q15 -> 0.336 | S15: =G15-I15-K15-M15-O15-Q15 -> -11 | T15: =F15*S15 -> -3.696 | U15: 10 | V15: =F15*U15 -> 3.36 | W15: =S15+U15 -> -1 | X15: =F15*W15 -> -0.336 | Y15: 20 | Z15: 70
A16: 12 | B16: 22 DN GRİ 3,0 | C16: 140 | D16: 240 | E16: 3 | F16: =(C16*D16*E16)/1000000 -> 0.1008 | G16: 1 | H16: =F16*G16 -> 0.1008 | I16: 17 | J16: =F16*I16 -> 1.7136 | K16: 5 | L16: =F16*K16 -> 0.504 | M16: 7 | N16: =F16*M16 -> 0.7056 | O16: 10 | P16: =F16*O16 -> 1.008 | Q16: 3 | R16: =F16*Q16 -> 0.3024 | S16: =G16-I16-K16-M16-O16-Q16 -> -41 | T16: =F16*S16 -> -4.1328 | U16: 85 | V16: =F16*U16 -> 8.568 | W16: =S16+U16 -> 44 | X16: =F16*W16 -> 4.4352 | Y16: 50 | Z16: 150
A17: 13 | B17: 22 DN GRİ 5,0 | C17: 140 | D17: 240 | E17: 5 | F17: =(C17*D17*E17)/1000000 -> 0.168 | G17: ='KASIM 4 HAFTA '!W17 -> 87 | H17: =F17*G17 -> 14.616 | I17: 2 | J17: =F17*I17 -> 0.336 | K17: 0 | L17: =F17*K17 -> 0 | M17: 3 | N17: =F17*M17 -> 0.504 | O17: 0 | P17: =F17*O17 -> 0 | Q17: 0 | R17: =F17*Q17 -> 0 | S17: =G17-I17-K17-M17-O17-Q17 -> 82 | T17: =F17*S17 -> 13.776 | V17: =F17*U17 -> 0 | W17: =S17+U17 -> 82 | X17: =F17*W17 -> 13.776 | Y17: 50 | Z17: 150
A18: 14 | B18: 28 DN GRİ 3,0 | C18: 140 | D18: 240 | E18: 3 | F18: =(C18*D18*E18)/1000000 -> 0.1008 | G18: ='KASIM 4 HAFTA '!W18 -> 2 | H18: =F18*G18 -> 0.2016 | I18: 2 | J18: =F18*I18 -> 0.2016 | K18: 0 | L18: =F18*K18 -> 0 | M18: 0 | N18: =F18*M18 -> 0 | O18: 0 | P18: =F18*O18 -> 0 | Q18: 0 | R18: =F18*Q18 -> 0 | S18: =G18-I18-K18-M18-O18-Q18 -> 0 | T18: =F18*S18 -> 0 | V18: =F18*U18 -> 0 | W18: =S18+U18 -> 0 | X18: =F18*W18 -> 0 | Y18: 30 | Z18: 100
A19: 15 | B19: 24 DN PEMBE 8,0 | C19: 140 | D19: 240 | E19: 8 | F19: =(C19*D19*E19)/1000000 -> 0.2688 | G19: ='KASIM 4 HAFTA '!W19 -> 1 | H19: =F19*G19 -> 0.2688 | I19: 0 | J19: =F19*I19 -> 0 | K19: 0 | L19: =F19*K19 -> 0 | M19: 0 | N19: =F19*M19 -> 0 | O19: 0 | P19: =F19*O19 -> 0 | Q19: 0 | R19: =F19*Q19 -> 0 | S19: =G19-I19-K19-M19-O19-Q19 -> 1 | T19: =F19*S19 -> 0.2688 | V19: =F19*U19 -> 0 | W19: =S19+U19 -> 1 | X19: =F19*W19 -> 0.2688 | Y19: 10 | Z19: 30
A20: 16 | B20: 28 DN SOFT 8,0 | C20: 140 | D20: 240 | E20: 8 | F20: =(C20*D20*E20)/1000000 -> 0.2688 | G20: ='KASIM 4 HAFTA '!W20 -> 0 | H20: =F20*G20 -> 0 | I20: 0 | J20: =F20*I20 -> 0 | K20: 0 | L20: =F20*K20 -> 0 | M20: 0 | N20: =F20*M20 -> 0 | O20: 0 | P20: =F20*O20 -> 0 | Q20: 0 | R20: =F20*Q20 -> 0 | S20: =G20-I20-K20-M20-O20-Q20 -> 0 | T20: =F20*S20 -> 0 | V20: =F20*U20 -> 0 | W20: =S20+U20 -> 0 | X20: =F20*W20 -> 0 | Y20: 0 | Z20: 0
A21: 17 | B21: 22 DN 77*55*8,0 | C21: 77 | D21: 55 | E21: 8 | F21: =(C21*D21*E21)/1000000 -> 0.03388 | G21: ='KASIM 4 HAFTA '!W21 -> 4 | H21: =F21*G21 -> 0.13552 | I21: 0 | J21: =F21*I21 -> 0 | K21: 0 | L21: =F21*K21 -> 0 | M21: 0 | N21: =F21*M21 -> 0 | O21: 0 | P21: =F21*O21 -> 0 | Q21: 0 | R21: =F21*Q21 -> 0 | S21: =G21-I21-K21-M21-O21-Q21 -> 4 | T21: =F21*S21 -> 0.13552 | V21: =F21*U21 -> 0 | W21: =S21+U21 -> 4 | X21: =F21*W21 -> 0.13552 | Y21: 0 | Z21: 0
A22: 18 | B22: 32 DN 65*50*12 | C22: 65 | D22: 50 | E22: 12 | F22: =(C22*D22*E22)/1000000 -> 0.039 | G22: ='KASIM 4 HAFTA '!W22 -> 26 | H22: =F22*G22 -> 1.014 | I22: 0 | J22: =F22*I22 -> 0 | K22: 0 | L22: =F22*K22 -> 0 | M22: 0 | N22: =F22*M22 -> 0 | O22: 0 | P22: =F22*O22 -> 0 | Q22: 0 | R22: =F22*Q22 -> 0 | S22: =G22-I22-K22-M22-O22-Q22 -> 26 | T22: =F22*S22 -> 1.014 | V22: =F22*U22 -> 0 | W22: =S22+U22 -> 26 | X22: =F22*W22 -> 1.014 | Y22: 0 | Z22: 0
A23: 19 | B23: 28 DN 58*58*5,0 | C23: 58 | D23: 58 | E23: 5 | F23: =(C23*D23*E23)/1000000 -> 0.01682 | G23: 150 | H23: =F23*G23 -> 2.523 | I23: 0 | J23: =F23*I23 -> 0 | K23: 0 | L23: =F23*K23 -> 0 | M23: 26 | N23: =F23*M23 -> 0.43732 | O23: 0 | P23: =F23*O23 -> 0 | Q23: 0 | R23: =F23*Q23 -> 0 | S23: =G23-I23-K23-M23-O23-Q23 -> 124 | T23: =F23*S23 -> 2.08568 | V23: =F23*U23 -> 0 | W23: =S23+U23 -> 124 | X23: =F23*W23 -> 2.08568 | Y23: 0 | Z23: 0
A24: 20 | B24: 32 DN 66*56*12 | C24: 66 | D24: 56 | E24: 12 | F24: =(C24*D24*E24)/1000000 -> 0.044352 | G24: ='KASIM 4 HAFTA '!W24 -> 28 | H24: =F24*G24 -> 1.241856 | I24: 0 | J24: =F24*I24 -> 0 | K24: 0 | L24: =F24*K24 -> 0 | M24: 0 | N24: =F24*M24 -> 0 | O24: 0 | P24: =F24*O24 -> 0 | Q24: 0 | R24: =F24*Q24 -> 0 | S24: =G24-I24-K24-M24-O24-Q24 -> 28 | T24: =F24*S24 -> 1.241856 | V24: =F24*U24 -> 0 | W24: =S24+U24 -> 28 | X24: =F24*W24 -> 1.241856 | Y24: 0 | Z24: 0
A25: 21 | B25: 32 DN 61,5*61,5*10 | C25: 61.5 | D25: 61.5 | E25: 10 | F25: =(C25*D25*E25)/1000000 -> 0.0378225 | G25: ='KASIM 4 HAFTA '!W25 -> 0 | H25: =F25*G25 -> 0 | I25: 0 | J25: =F25*I25 -> 0 | K25: 0 | L25: =F25*K25 -> 0 | M25: 0 | N25: =F25*M25 -> 0 | O25: 0 | P25: =F25*O25 -> 0 | Q25: 0 | R25: =F25*Q25 -> 0 | S25: =G25-I25-K25-M25-O25-Q25 -> 0 | T25: =F25*S25 -> 0 | V25: =F25*U25 -> 0 | W25: =S25+U25 -> 0 | X25: =F25*W25 -> 0 | Y25: 30 | Z25: 100
A26: 22 | B26: 18 DN 82*67*5,0 | C26: 82 | D26: 67 | E26: 5 | F26: =(C26*D26*E26)/1000000 -> 0.02747 | G26: ='KASIM 4 HAFTA '!W26 -> 30 | H26: =F26*G26 -> 0.8241 | I26: 0 | J26: =F26*I26 -> 0 | K26: 0 | L26: =F26*K26 -> 0 | M26: 0 | N26: =F26*M26 -> 0 | O26: 0 | P26: =F26*O26 -> 0 | Q26: 0 | R26: =F26*Q26 -> 0 | S26: =G26-I26-K26-M26-O26-Q26 -> 30 | T26: =F26*S26 -> 0.8241 | V26: =F26*U26 -> 0 | W26: =S26+U26 -> 30 | X26: =F26*W26 -> 0.8241 | Y26: 0 | Z26: 0
A27: 23 | B27: 18 DN 80*62*2,0 | C27: 80 | D27: 62 | E27: 2 | F27: =(C27*D27*E27)/1000000 -> 0.00992 | G27: ='KASIM 4 HAFTA '!W27 -> 36 | H27: =F27*G27 -> 0.35712 | I27: 0 | J27: =F27*I27 -> 0 | K27: 0 | L27: =F27*K27 -> 0 | M27: 0 | N27: =F27*M27 -> 0 | O27: 0 | P27: =F27*O27 -> 0 | Q27: 0 | R27: =F27*Q27 -> 0 | S27: =G27-I27-K27-M27-O27-Q27 -> 36 | T27: =F27*S27 -> 0.35712 | V27: =F27*U27 -> 0 | W27: =S27+U27 -> 36 | X27: =F27*W27 -> 0.35712 | Y27: 0 | Z27: 0
A28: 24 | B28: 32 DN 63*55*5,0 | C28: 63 | D28: 55 | E28: 5 | F28: =(C28*D28*E28)/1000000 -> 0.017325 | G28: ='KASIM 4 HAFTA '!W28 -> 19 | H28: =F28*G28 -> 0.329175 | I28: 12 | J28: =F28*I28 -> 0.2079 | K28: 0 | L28: =F28*K28 -> 0 | M28: 0 | N28: =F28*M28 -> 0 | O28: 0 | P28: =F28*O28 -> 0 | Q28: 0 | R28: =F28*Q28 -> 0 | S28: =G28-I28-K28-M28-O28-Q28 -> 7 | T28: =F28*S28 -> 0.121275 | V28: =F28*U28 -> 0 | W28: =S28+U28 -> 7 | X28: =F28*W28 -> 0.121275 | Y28: 0 | Z28: 0
A29: 25 | B29: 18 DN BEYAZ 5,0 | C29: 140 | D29: 240 | E29: 5 | F29: =(C29*D29*E29)/1000000 -> 0.168 | G29: ='KASIM 4 HAFTA '!W29 -> 6 | H29: =F29*G29 -> 1.008 | I29: 0 | J29: =F29*I29 -> 0 | K29: 0 | L29: =F29*K29 -> 0 | M29: 0 | N29: =F29*M29 -> 0 | O29: 0 | P29: =F29*O29 -> 0 | Q29: 0 | R29: =F29*Q29 -> 0 | S29: =G29-I29-K29-M29-O29-Q29 -> 6 | T29: =F29*S29 -> 1.008 | V29: =F29*U29 -> 0 | W29: =S29+U29 -> 6 | X29: =F29*W29 -> 1.008 | Y29: 0 | Z29: 0
A30: 26 | B30: 28 DN GRİ FORZA 10 | C30: 140 | D30: 240 | E30: 10 | F30: =(C30*D30*E30)/1000000 -> 0.336 | G30: 0 | H30: =F30*G30 -> 0 | I30: 0 | J30: =F30*I30 -> 0 | K30: 0 | L30: =F30*K30 -> 0 | M30: 0 | N30: =F30*M30 -> 0 | O30: 0 | P30: =F30*O30 -> 0 | Q30: 0 | R30: =F30*Q30 -> 0 | S30: =G30-I30-K30-M30-O30-Q30 -> 0 | T30: =F30*S30 -> 0 | U30: 56 | V30: =F30*U30 -> 18.816 | W30: =S30+U30 -> 56 | X30: =F30*W30 -> 18.816 | Y30: 0 | Z30: 0
A31: 27 | B31: 22 DN BEYAZ 3,0 | C31: 140 | D31: 240 | E31: 3 | F31: =(C31*D31*E31)/1000000 -> 0.1008 | G31: ='KASIM 4 HAFTA '!W31 -> 26 | H31: =F31*G31 -> 2.6208 | I31: 0 | J31: =F31*I31 -> 0 | K31: 0 | L31: =F31*K31 -> 0 | M31: 0 | N31: =F31*M31 -> 0 | O31: 0 | P31: =F31*O31 -> 0 | Q31: 0 | R31: =F31*Q31 -> 0 | S31: =G31-I31-K31-M31-O31-Q31 -> 26 | T31: =F31*S31 -> 2.6208 | V31: =F31*U31 -> 0 | W31: =S31+U31 -> 26 | X31: =F31*W31 -> 2.6208 | Y31: 0 | Z31: 0
A32: 28 | B32: 28 DN 90*80*8,0 | C32: 90 | D32: 80 | E32: 8 | F32: =(C32*D32*E32)/1000000 -> 0.0576 | G32: ='KASIM 4 HAFTA '!W32 -> 0 | H32: =F32*G32 -> 0 | I32: 0 | J32: =F32*I32 -> 0 | K32: 0 | L32: =F32*K32 -> 0 | M32: 0 | N32: =F32*M32 -> 0 | O32: 0 | P32: =F32*O32 -> 0 | Q32: 0 | R32: =F32*Q32 -> 0 | S32: =G32-I32-K32-M32-O32-Q32 -> 0 | T32: =F32*S32 -> 0 | V32: =F32*U32 -> 0 | W32: =S32+U32 -> 0 | X32: =F32*W32 -> 0 | Y32: 0 | Z32: 0
A33: 29 | B33: 28 DN SOFT 90*80*8,0 | C33: 90 | D33: 80 | E33: 8 | F33: =(C33*D33*E33)/1000000 -> 0.0576 | G33: ='KASIM 4 HAFTA '!W33 -> 0 | H33: =F33*G33 -> 0 | I33: 0 | J33: =F33*I33 -> 0 | K33: 0 | L33: =F33*K33 -> 0 | M33: 0 | N33: =F33*M33 -> 0 | O33: 0 | P33: =F33*O33 -> 0 | Q33: 0 | R33: =F33*Q33 -> 0 | S33: =G33-I33-K33-M33-O33-Q33 -> 0 | T33: =F33*S33 -> 0 | V33: =F33*U33 -> 0 | W33: =S33+U33 -> 0 | X33: =F33*W33 -> 0 | Y33: 0 | Z33: 0
A34: 30 | B34: 22 DN HİLTON OTURK. | F34: =(C34*D34*E34)/1000000 -> 0 | G34: ='KASIM 4 HAFTA '!W34 -> 300 | H34: =F34*G34 -> 0 | I34: 0 | J34: =F34*I34 -> 0 | K34: 0 | L34: =F34*K34 -> 0 | M34: 0 | N34: =F34*M34 -> 0 | O34: 0 | P34: =F34*O34 -> 0 | Q34: 0 | R34: =F34*Q34 -> 0 | S34: =G34-I34-K34-M34-O34-Q34 -> 300 | T34: =F34*S34 -> 0 | V34: =F34*U34 -> 0 | W34: =S34+U34 -> 300 | X34: =F34*W34 -> 0 | Y34: 0 | Z34: 0
A35: 31 | B35: 22 DN 80*66*5,0 | C35: 80 | D35: 66 | E35: 5 | F35: =(C35*D35*E35)/1000000 -> 0.0264 | G35: ='KASIM 4 HAFTA '!W35 -> 56 | H35: =F35*G35 -> 1.4784 | I35: 0 | J35: =F35*I35 -> 0 | K35: 0 | L35: =F35*K35 -> 0 | M35: 0 | N35: =F35*M35 -> 0 | O35: 0 | P35: =F35*O35 -> 0 | Q35: 0 | R35: =F35*Q35 -> 0 | S35: =G35-I35-K35-M35-O35-Q35 -> 56 | T35: =F35*S35 -> 1.4784 | V35: =F35*U35 -> 0 | W35: =S35+U35 -> 56 | X35: =F35*W35 -> 1.4784 | Y35: 0 | Z35: 0
A36: 32 | B36: 22 DN 60*63*5,0 | C36: 60 | D36: 62 | E36: 5 | F36: =(C36*D36*E36)/1000000 -> 0.0186 | G36: ='KASIM 4 HAFTA '!W36 -> 0 | H36: =F36*G36 -> 0 | I36: 0 | J36: =F36*I36 -> 0 | K36: 0 | L36: =F36*K36 -> 0 | M36: 0 | N36: =F36*M36 -> 0 | O36: 0 | P36: =F36*O36 -> 0 | Q36: 0 | R36: =F36*Q36 -> 0 | S36: =G36-I36-K36-M36-O36-Q36 -> 0 | T36: =F36*S36 -> 0 | U36: 15 | V36: =F36*U36 -> 0.279 | W36: =S36+U36 -> 15 | X36: =F36*W36 -> 0.279 | Y36: 0 | Z36: 0
A37: 33 | B37: 28 DN 60*67*3 | C37: 60 | D37: 67 | E37: 3 | F37: =(C37*D37*E37)/1000000 -> 0.01206 | G37: ='KASIM 4 HAFTA '!W37 -> 12 | H37: =F37*G37 -> 0.14472 | I37: 0 | J37: =F37*I37 -> 0 | K37: 0 | L37: =F37*K37 -> 0 | M37: 0 | N37: =F37*M37 -> 0 | O37: 0 | P37: =F37*O37 -> 0 | Q37: 0 | R37: =F37*Q37 -> 0 | S37: =G37-I37-K37-M37-O37-Q37 -> 12 | T37: =F37*S37 -> 0.14472 | V37: =F37*U37 -> 0 | W37: =S37+U37 -> 12 | X37: =F37*W37 -> 0.14472 | Y37: 0 | Z37: 0
A38: 34 | B38: 28 DN GRİ 7,0 | C38: 140 | D38: 240 | E38: 7 | F38: =(C38*D38*E38)/1000000 -> 0.2352 | G38: ='KASIM 4 HAFTA '!W38 -> 0 | H38: =F38*G38 -> 0 | I38: 0 | J38: =F38*I38 -> 0 | K38: 0 | L38: =F38*K38 -> 0 | M38: 0 | N38: =F38*M38 -> 0 | O38: 0 | P38: =F38*O38 -> 0 | Q38: 0 | R38: =F38*Q38 -> 0 | S38: =G38-I38-K38-M38-O38-Q38 -> 0 | T38: =F38*S38 -> 0 | V38: =F38*U38 -> 0 | W38: =S38+U38 -> 0 | X38: =F38*W38 -> 0 | Y38: 0 | Z38: 0
A39: 35 | B39: 18 DN GRİ 60*56*10 | C39: 60 | D39: 56 | E39: 10 | F39: =(C39*D39*E39)/1000000 -> 0.0336 | G39: ='KASIM 4 HAFTA '!W39 -> 0 | H39: =F39*G39 -> 0 | I39: 0 | J39: =F39*I39 -> 0 | K39: 0 | L39: =F39*K39 -> 0 | M39: 0 | N39: =F39*M39 -> 0 | O39: 0 | P39: =F39*O39 -> 0 | Q39: 0 | R39: =F39*Q39 -> 0 | S39: =G39-I39-K39-M39-O39-Q39 -> 0 | T39: =F39*S39 -> 0 | V39: =F39*U39 -> 0 | W39: =S39+U39 -> 0 | X39: =F39*W39 -> 0 | Y39: 0 | Z39: 0
A40: 36 | B40: 18 DN GRİ 58*55*10 | C40: 58 | D40: 55 | E40: 10 | F40: =(C40*D40*E40)/1000000 -> 0.0319 | G40: ='KASIM 4 HAFTA '!W40 -> 0 | H40: =F40*G40 -> 0 | I40: 0 | J40: =F40*I40 -> 0 | K40: 0 | L40: =F40*K40 -> 0 | M40: 0 | N40: =F40*M40 -> 0 | O40: 0 | P40: =F40*O40 -> 0 | Q40: 0 | R40: =F40*Q40 -> 0 | S40: =G40-I40-K40-M40-O40-Q40 -> 0 | T40: =F40*S40 -> 0 | V40: =F40*U40 -> 0 | W40: =S40+U40 -> 0 | X40: =F40*W40 -> 0 | Y40: 0 | Z40: 0
...

Sheet KASIM 3 HAFTA  (2)
A1: SÜNGER | B1: EKİM 4. HAFTA
A2: ÜRÜN ADI | F2: DEVİR STOK | H2: 44879 | J2: 44880 | L2: 44881 | N2: 44882 | P2: 44883 | R2: KALAN STOK | T2: STOK GİRİŞİ | V2: TOPLAM STOK MİKTARI
H3: STOK ÇIKIŞI | J3: STOK ÇIKIŞI | L3: STOK ÇIKIŞI | N3: STOK ÇIKIŞI | P3: STOK ÇIKIŞI
B4: EN | C4: BOY | D4: YÜKS | E4: br m³ | F4: PLAKA ADET | H4: PLAKA ADET | J4: PLAKA ADET | L4: PLAKA ADET | N4: PLAKA ADET | P4: PLAKA ADET | R4: PLAKA ADET | T4: PLAKA ADET | V4: PLAKA ADET
A5: 22 DN GRİ 1,0 | B5: 140 | C5: 240 | D5: 1 | E5: =(B5*C5*D5)/1000000 -> 0.0336 | F5: ='EKİM 4 HAFTA '!V5 -> 118 | G5: =E5*F5 -> 3.9648 | H5: 0 | I5: =E5*H5 -> 0 | J5: 0 | K5: =E5*J5 -> 0 | L5: 0 | M5: =E5*L5 -> 0 | N5: 0 | O5: =E5*N5 -> 0 | P5: 0 | Q5: =E5*P5 -> 0 | R5: =F5-H5-J5-L5-N5-P5 -> 118 | S5: =E5*R5 -> 3.9648 | T5: 0 | U5: =E5*T5 -> 0 | V5: =R5+T5 -> 118 | W5: =E5*V5 -> 3.9648
A6: 14 DN BEYAZ 0,8 | B6: 140 | C6: 240 | D6: 0.8 | E6: =(B6*C6*D6)/1000000 -> 0.02688 | F6: ='EKİM 4 HAFTA '!V6 -> 197 | G6: =E6*F6 -> 5.29536 | H6: 0 | I6: =E6*H6 -> 0 | J6: 0 | K6: =E6*J6 -> 0 | L6: 0 | M6: =E6*L6 -> 0 | N6: 0 | O6: =E6*N6 -> 0 | P6: 0 | Q6: =E6*P6 -> 0 | R6: =F6-H6-J6-L6-N6-P6 -> 197 | S6: =E6*R6 -> 5.29536 | U6: =E6*T6 -> 0 | V6: =R6+T6 -> 197 | W6: =E6*V6 -> 5.29536
A7: 14 DN BEYAZ 1,4 | B7: 140 | C7: 240 | D7: 1.4 | E7: =(B7*C7*D7)/1000000 -> 0.04704 | F7: ='EKİM 4 HAFTA '!V7 -> 49 | G7: =E7*F7 -> 2.30496 | H7: 0 | I7: =E7*H7 -> 0 | J7: 0 | K7: =E7*J7 -> 0 | L7: 0 | M7: =E7*L7 -> 0 | N7: 0 | O7: =E7*N7 -> 0 | P7: 0 | Q7: =E7*P7 -> 0 | R7: =F7-H7-J7-L7-N7-P7 -> 49 | S7: =E7*R7 -> 2.30496 | U7: =E7*T7 -> 0 | V7: =R7+T7 -> 49 | W7: =E7*V7 -> 2.30496
A8: 22 DN GRİ 4,0 | B8: 140 | C8: 240 | D8: 4 | E8: =(B8*C8*D8)/1000000 -> 0.1344 | F8: ='EKİM 4 HAFTA '!V8 -> 27 | G8: =E8*F8 -> 3.6288 | H8: 0 | I8: =E8*H8 -> 0 | J8: 0 | K8: =E8*J8 -> 0 | L8: 0 | M8: =E8*L8 -> 0 | N8: 0 | O8: =E8*N8 -> 0 | P8: 0 | Q8: =E8*P8 -> 0 | R8: =F8-H8-J8-L8-N8-P8 -> 27 | S8: =E8*R8 -> 3.6288 | U8: =E8*T8 -> 0 | V8: =R8+T8 -> 27 | W8: =E8*V8 -> 3.6288
A9: 22 DN GRİ 2,0 | B9: 140 | C9: 240 | D9: 2 | E9: =(B9*C9*D9)/1000000 -> 0.0672 | F9: ='EKİM 4 HAFTA '!V9 -> 0 | G9: =E9*F9 -> 0 | H9: 0 | I9: =E9*H9 -> 0 | J9: 0 | K9: =E9*J9 -> 0 | L9: 0 | M9: =E9*L9 -> 0 | N9: 0 | O9: =E9*N9 -> 0 | P9: 0 | Q9: =E9*P9 -> 0 | R9: =F9-H9-J9-L9-N9-P9 -> 0 | S9: =E9*R9 -> 0 | U9: =E9*T9 -> 0 | V9: =R9+T9 -> 0 | W9: =E9*V9 -> 0
A10: 24 DN KUŞTÜYÜ 2 ,0 | B10: 140 | C10: 240 | D10: 2 | E10: =(B10*C10*D10)/1000000 -> 0.0672 | F10: ='EKİM 4 HAFTA '!V10 -> 182 | G10: =E10*F10 -> 12.2304 | H10: 0 | I10: =E10*H10 -> 0 | J10: 0 | K10: =E10*J10 -> 0 | L10: 0 | M10: =E10*L10 -> 0 | N10: 0 | O10: =E10*N10 -> 0 | P10: 0 | Q10: =E10*P10 -> 0 | R10: =F10-H10-J10-L10-N10-P10 -> 182 | S10: =E10*R10 -> 12.2304 | U10: =E10*T10 -> 0 | V10: =R10+T10 -> 182 | W10: =E10*V10 -> 12.2304
A11: 30 DN LÜKS BEYAZ 7,0 | B11: 140 | C11: 240 | D11: 7 | E11: =(B11*C11*D11)/1000000 -> 0.2352 | F11: ='EKİM 4 HAFTA '!V11 -> 48 | G11: =E11*F11 -> 11.2896 | H11: 0 | I11: =E11*H11 -> 0 | J11: 0 | K11: =E11*J11 -> 0 | L11: 0 | M11: =E11*L11 -> 0 | N11: 0 | O11: =E11*N11 -> 0 | P11: 0 | Q11: =E11*P11 -> 0 | R11: =F11-H11-J11-L11-N11-P11 -> 48 | S11: =E11*R11 -> 11.2896 | T11: 0 | U11: =E11*T11 -> 0 | V11: =R11+T11 -> 48 | W11: =E11*V11 -> 11.2896
A12: 24 DN KUŞTÜYÜ 5 ,0 | B12: 140 | C12: 240 | D12: 5 | E12: =(B12*C12*D12)/1000000 -> 0.168 | F12: ='EKİM 4 HAFTA '!V12 -> 322 | G12: =E12*F12 -> 54.096 | H12: 0 | I12: =E12*H12 -> 0 | J12: 0 | K12: =E12*J12 -> 0 | L12: 0 | M12: =E12*L12 -> 0 | N12: 0 | O12: =E12*N12 -> 0 | P12: 0 | Q12: =E12*P12 -> 0 | R12: =F12-H12-J12-L12-N12-P12 -> 322 | S12: =E12*R12 -> 54.096 | U12: =E12*T12 -> 0 | V12: =R12+T12 -> 322 | W12: =E12*V12 -> 54.096
A13: 28 DN GRİ SOFT 5,0 | B13: 140 | C13: 240 | D13: 5 | E13: =(B13*C13*D13)/1000000 -> 0.168 | F13: ='EKİM 4 HAFTA '!V13 -> 14 | G13: =E13*F13 -> 2.352 | H13: 0 | I13: =E13*H13 -> 0 | J13: 0 | K13: =E13*J13 -> 0 | L13: 0 | M13: =E13*L13 -> 0 | N13: 0 | O13: =E13*N13 -> 0 | P13: 0 | Q13: =E13*P13 -> 0 | R13: =F13-H13-J13-L13-N13-P13 -> 14 | S13: =E13*R13 -> 2.352 | T13: 0 | U13: =E13*T13 -> 0 | V13: =R13+T13 -> 14 | W13: =E13*V13 -> 2.352
A14: 28 DN GRİ 5,0 | B14: 140 | C14: 240 | D14: 5 | E14: =(B14*C14*D14)/1000000 -> 0.168 | F14: ='EKİM 4 HAFTA '!V14 -> 1 | G14: =E14*F14 -> 0.168 | H14: 0 | I14: =E14*H14 -> 0 | J14: 0 | K14: =E14*J14 -> 0 | L14: 0 | M14: =E14*L14 -> 0 | N14: 0 | O14: =E14*N14 -> 0 | P14: 0 | Q14: =E14*P14 -> 0 | R14: =F14-H14-J14-L14-N14-P14 -> 1 | S14: =E14*R14 -> 0.168 | U14: =E14*T14 -> 0 | V14: =R14+T14 -> 1 | W14: =E14*V14 -> 0.168
A15: 28 DN SOFT 10 | B15: 140 | C15: 240 | D15: 10 | E15: =(B15*C15*D15)/1000000 -> 0.336 | F15: ='EKİM 4 HAFTA '!V15 -> 20 | G15: =E15*F15 -> 6.72 | H15: 0 | I15: =E15*H15 -> 0 | J15: 0 | K15: =E15*J15 -> 0 | L15: 0 | M15: =E15*L15 -> 0 | N15: 0 | O15: =E15*N15 -> 0 | P15: 0 | Q15: =E15*P15 -> 0 | R15: =F15-H15-J15-L15-N15-P15 -> 20 | S15: =E15*R15 -> 6.72 | U15: =E15*T15 -> 0 | V15: =R15+T15 -> 20 | W15: =E15*V15 -> 6.72
A16: 22 DN GRİ 3,0 | B16: 140 | C16: 240 | D16: 3 | E16: =(B16*C16*D16)/1000000 -> 0.1008 | F16: ='EKİM 4 HAFTA '!V16 -> 22 | G16: =E16*F16 -> 2.2176 | H16: 0 | I16: =E16*H16 -> 0 | J16: 0 | K16: =E16*J16 -> 0 | L16: 0 | M16: =E16*L16 -> 0 | N16: 0 | O16: =E16*N16 -> 0 | P16: 0 | Q16: =E16*P16 -> 0 | R16: =F16-H16-J16-L16-N16-P16 -> 22 | S16: =E16*R16 -> 2.2176 | U16: =E16*T16 -> 0 | V16: =R16+T16 -> 22 | W16: =E16*V16 -> 2.2176
A17: 22 DN GRİ 5,0 | B17: 140 | C17: 240 | D17: 5 | E17: =(B17*C17*D17)/1000000 -> 0.168 | F17: ='EKİM 4 HAFTA '!V17 -> 0 | G17: =E17*F17 -> 0 | H17: 0 | I17: =E17*H17 -> 0 | J17: 0 | K17: =E17*J17 -> 0 | L17: 0 | M17: =E17*L17 -> 0 | N17: 0 | O17: =E17*N17 -> 0 | P17: 0 | Q17: =E17*P17 -> 0 | R17: =F17-H17-J17-L17-N17-P17 -> 0 | S17: =E17*R17 -> 0 | U17: =E17*T17 -> 0 | V17: =R17+T17 -> 0 | W17: =E17*V17 -> 0
A18: 28 DN GRİ 3,0 | B18: 140 | C18: 240 | D18: 3 | E18: =(B18*C18*D18)/1000000 -> 0.1008 | F18: ='EKİM 4 HAFTA '!V18 -> 129 | G18: =E18*F18 -> 13.0032 | H18: 0 | I18: =E18*H18 -> 0 | J18: 0 | K18: =E18*J18 -> 0 | L18: 0 | M18: =E18*L18 -> 0 | N18: 0 | O18: =E18*N18 -> 0 | P18: 0 | Q18: =E18*P18 -> 0 | R18: =F18-H18-J18-L18-N18-P18 -> 129 | S18: =E18*R18 -> 13.0032 | U18: =E18*T18 -> 0 | V18: =R18+T18 -> 129 | W18: =E18*V18 -> 13.0032
A19: 24 DN PEMBE 8,0 | B19: 140 | C19: 240 | D19: 8 | E19: =(B19*C19*D19)/1000000 -> 0.2688 | F19: ='EKİM 4 HAFTA '!V19 -> 12 | G19: =E19*F19 -> 3.2256 | H19: 0 | I19: =E19*H19 -> 0 | J19: 0 | K19: =E19*J19 -> 0 | L19: 0 | M19: =E19*L19 -> 0 | N19: 0 | O19: =E19*N19 -> 0 | P19: 0 | Q19: =E19*P19 -> 0 | R19: =F19-H19-J19-L19-N19-P19 -> 12 | S19: =E19*R19 -> 3.2256 | U19: =E19*T19 -> 0 | V19: =R19+T19 -> 12 | W19: =E19*V19 -> 3.2256
A20: 28 DN SOFT 8,0 | B20: 140 | C20: 240 | D20: 8 | E20: =(B20*C20*D20)/1000000 -> 0.2688 | F20: ='EKİM 4 HAFTA '!V20 -> 0 | G20: =E20*F20 -> 0 | H20: 0 | I20: =E20*H20 -> 0 | J20: 0 | K20: =E20*J20 -> 0 | L20: 0 | M20: =E20*L20 -> 0 | N20: 0 | O20: =E20*N20 -> 0 | P20: 0 | Q20: =E20*P20 -> 0 | R20: =F20-H20-J20-L20-N20-P20 -> 0 | S20: =E20*R20 -> 0 | U20: =E20*T20 -> 0 | V20: =R20+T20 -> 0 | W20: =E20*V20 -> 0
A21: 22 DN 77*55*8,0 | B21: 77 | C21: 55 | D21: 8 | E21: =(B21*C21*D21)/1000000 -> 0.03388 | F21: ='EKİM 4 HAFTA '!V21 -> 4 | G21: =E21*F21 -> 0.13552 | H21: 0 | I21: =E21*H21 -> 0 | J21: 0 | K21: =E21*J21 -> 0 | L21: 0 | M21: =E21*L21 -> 0 | N21: 0 | O21: =E21*N21 -> 0 | P21: 0 | Q21: =E21*P21 -> 0 | R21: =F21-H21-J21-L21-N21-P21 -> 4 | S21: =E21*R21 -> 0.13552 | U21: =E21*T21 -> 0 | V21: =R21+T21 -> 4 | W21: =E21*V21 -> 0.13552
A22: 32 DN 65*50*12 | B22: 65 | C22: 50 | D22: 12 | E22: =(B22*C22*D22)/1000000 -> 0.039 | F22: ='EKİM 4 HAFTA '!V22 -> 26 | G22: =E22*F22 -> 1.014 | H22: 0 | I22: =E22*H22 -> 0 | J22: 0 | K22: =E22*J22 -> 0 | L22: 0 | M22: =E22*L22 -> 0 | N22: 0 | O22: =E22*N22 -> 0 | P22: 0 | Q22: =E22*P22 -> 0 | R22: =F22-H22-J22-L22-N22-P22 -> 26 | S22: =E22*R22 -> 1.014 | U22: =E22*T22 -> 0 | V22: =R22+T22 -> 26 | W22: =E22*V22 -> 1.014
A23: SİLİNDİR | E23: =(B23*C23*D23)/1000000 -> 0 | F23: ='EKİM 4 HAFTA '!V23 -> 74 | G23: =E23*F23 -> 0 | H23: 0 | I23: =E23*H23 -> 0 | J23: 0 | K23: =E23*J23 -> 0 | L23: 0 | M23: =E23*L23 -> 0 | N23: 0 | O23: =E23*N23 -> 0 | P23: 0 | Q23: =E23*P23 -> 0 | R23: =F23-H23-J23-L23-N23-P23 -> 74 | S23: =E23*R23 -> 0 | U23: =E23*T23 -> 0 | V23: =R23+T23 -> 74 | W23: =E23*V23 -> 0
A24: 32 DN 66*56*12 | B24: 66 | C24: 56 | D24: 12 | E24: =(B24*C24*D24)/1000000 -> 0.044352 | F24: ='EKİM 4 HAFTA '!V24 -> 28 | G24: =E24*F24 -> 1.241856 | H24: 0 | I24: =E24*H24 -> 0 | J24: 0 | K24: =E24*J24 -> 0 | L24: 0 | M24: =E24*L24 -> 0 | N24: 0 | O24: =E24*N24 -> 0 | P24: 0 | Q24: =E24*P24 -> 0 | R24: =F24-H24-J24-L24-N24-P24 -> 28 | S24: =E24*R24 -> 1.241856 | U24: =E24*T24 -> 0 | V24: =R24+T24 -> 28 | W24: =E24*V24 -> 1.241856
A25: 32 DN 61,5*61,5*10 | B25: 61.5 | C25: 61.5 | D25: 10 | E25: =(B25*C25*D25)/1000000 -> 0.0378225 | F25: ='EKİM 4 HAFTA '!V25 -> 48 | G25: =E25*F25 -> 1.81548 | H25: 0 | I25: =E25*H25 -> 0 | J25: 0 | K25: =E25*J25 -> 0 | L25: 0 | M25: =E25*L25 -> 0 | N25: 0 | O25: =E25*N25 -> 0 | P25: 0 | Q25: =E25*P25 -> 0 | R25: =F25-H25-J25-L25-N25-P25 -> 48 | S25: =E25*R25 -> 1.81548 | U25: =E25*T25 -> 0 | V25: =R25+T25 -> 48 | W25: =E25*V25 -> 1.81548
A26: 18 DN 82*67*5,0 | B26: 82 | C26: 67 | D26: 5 | E26: =(B26*C26*D26)/1000000 -> 0.02747 | F26: ='EKİM 4 HAFTA '!V26 -> 30 | G26: =E26*F26 -> 0.8241 | H26: 0 | I26: =E26*H26 -> 0 | J26: 0 | K26: =E26*J26 -> 0 | L26: 0 | M26: =E26*L26 -> 0 | N26: 0 | O26: =E26*N26 -> 0 | P26: 0 | Q26: =E26*P26 -> 0 | R26: =F26-H26-J26-L26-N26-P26 -> 30 | S26: =E26*R26 -> 0.8241 | U26: =E26*T26 -> 0 | V26: =R26+T26 -> 30 | W26: =E26*V26 -> 0.8241
A27: 18 DN 80*62*2,0 | B27: 80 | C27: 62 | D27: 2 | E27: =(B27*C27*D27)/1000000 -> 0.00992 | F27: ='EKİM 4 HAFTA '!V27 -> 36 | G27: =E27*F27 -> 0.35712 | H27: 0 | I27: =E27*H27 -> 0 | J27: 0 | K27: =E27*J27 -> 0 | L27: 0 | M27: =E27*L27 -> 0 | N27: 0 | O27: =E27*N27 -> 0 | P27: 0 | Q27: =E27*P27 -> 0 | R27: =F27-H27-J27-L27-N27-P27 -> 36 | S27: =E27*R27 -> 0.35712 | U27: =E27*T27 -> 0 | V27: =R27+T27 -> 36 | W27: =E27*V27 -> 0.35712
A28: 32 DN 63*55*5,0 | B28: 63 | C28: 55 | D28: 5 | E28: =(B28*C28*D28)/1000000 -> 0.017325 | F28: ='EKİM 4 HAFTA '!V28 -> 19 | G28: =E28*F28 -> 0.329175 | H28: 0 | I28: =E28*H28 -> 0 | J28: 0 | K28: =E28*J28 -> 0 | L28: 0 | M28: =E28*L28 -> 0 | N28: 0 | O28: =E28*N28 -> 0 | P28: 0 | Q28: =E28*P28 -> 0 | R28: =F28-H28-J28-L28-N28-P28 -> 19 | S28: =E28*R28 -> 0.329175 | U28: =E28*T28 -> 0 | V28: =R28+T28 -> 19 | W28: =E28*V28 -> 0.329175
A29: 18 DN BEYAZ 5,0 | B29: 140 | C29: 240 | D29: 5 | E29: =(B29*C29*D29)/1000000 -> 0.168 | F29: ='EKİM 4 HAFTA '!V29 -> 6 | G29: =E29*F29 -> 1.008 | H29: 0 | I29: =E29*H29 -> 0 | J29: 0 | K29: =E29*J29 -> 0 | L29: 0 | M29: =E29*L29 -> 0 | N29: 0 | O29: =E29*N29 -> 0 | P29: 0 | Q29: =E29*P29 -> 0 | R29: =F29-H29-J29-L29-N29-P29 -> 6 | S29: =E29*R29 -> 1.008 | U29: =E29*T29 -> 0 | V29: =R29+T29 -> 6 | W29: =E29*V29 -> 1.008
A30: 15 DN BEYAZ 10 | B30: 140 | C30: 240 | D30: 10 | E30: =(B30*C30*D30)/1000000 -> 0.336 | F30: ='EKİM 4 HAFTA '!V30 -> 11 | G30: =E30*F30 -> 3.696 | H30: 0 | I30: =E30*H30 -> 0 | J30: 0 | K30: =E30*J30 -> 0 | L30: 0 | M30: =E30*L30 -> 0 | N30: 0 | O30: =E30*N30 -> 0 | P30: 0 | Q30: =E30*P30 -> 0 | R30: =F30-H30-J30-L30-N30-P30 -> 11 | S30: =E30*R30 -> 3.696 | U30: =E30*T30 -> 0 | V30: =R30+T30 -> 11 | W30: =E30*V30 -> 3.696
A31: 22 DN BEYAZ 3,0 | B31: 140 | C31: 240 | D31: 3 | E31: =(B31*C31*D31)/1000000 -> 0.1008 | F31: ='EKİM 4 HAFTA '!V31 -> 26 | G31: =E31*F31 -> 2.6208 | H31: 0 | I31: =E31*H31 -> 0 | J31: 0 | K31: =E31*J31 -> 0 | L31: 0 | M31: =E31*L31 -> 0 | N31: 0 | O31: =E31*N31 -> 0 | P31: 0 | Q31: =E31*P31 -> 0 | R31: =F31-H31-J31-L31-N31-P31 -> 26 | S31: =E31*R31 -> 2.6208 | U31: =E31*T31 -> 0 | V31: =R31+T31 -> 26 | W31: =E31*V31 -> 2.6208
A32: 28 DN 90*80*8,0 | B32: 90 | C32: 80 | D32: 8 | E32: =(B32*C32*D32)/1000000 -> 0.0576 | F32: ='EKİM 4 HAFTA '!V32 -> 0 | G32: =E32*F32 -> 0 | H32: 0 | I32: =E32*H32 -> 0 | J32: 0 | K32: =E32*J32 -> 0 | L32: 0 | M32: =E32*L32 -> 0 | N32: 0 | O32: =E32*N32 -> 0 | P32: 0 | Q32: =E32*P32 -> 0 | R32: =F32-H32-J32-L32-N32-P32 -> 0 | S32: =E32*R32 -> 0 | U32: =E32*T32 -> 0 | V32: =R32+T32 -> 0 | W32: =E32*V32 -> 0
A33: 28 DN SOFT 90*80*8,0 | B33: 90 | C33: 80 | D33: 8 | E33: =(B33*C33*D33)/1000000 -> 0.0576 | F33: ='EKİM 4 HAFTA '!V33 -> 0 | G33: =E33*F33 -> 0 | H33: 0 | I33: =E33*H33 -> 0 | J33: 0 | K33: =E33*J33 -> 0 | L33: 0 | M33: =E33*L33 -> 0 | N33: 0 | O33: =E33*N33 -> 0 | P33: 0 | Q33: =E33*P33 -> 0 | R33: =F33-H33-J33-L33-N33-P33 -> 0 | S33: =E33*R33 -> 0 | U33: =E33*T33 -> 0 | V33: =R33+T33 -> 0 | W33: =E33*V33 -> 0
A34: 22 DN HİLTON OTURK. | E34: =(B34*C34*D34)/1000000 -> 0 | F34: ='EKİM 4 HAFTA '!V34 -> 300 | G34: =E34*F34 -> 0 | H34: 0 | I34: =E34*H34 -> 0 | J34: 0 | K34: =E34*J34 -> 0 | L34: 0 | M34: =E34*L34 -> 0 | N34: 0 | O34: =E34*N34 -> 0 | P34: 0 | Q34: =E34*P34 -> 0 | R34: =F34-H34-J34-L34-N34-P34 -> 300 | S34: =E34*R34 -> 0 | U34: =E34*T34 -> 0 | V34: =R34+T34 -> 300 | W34: =E34*V34 -> 0
A35: 22 DN 80*66*5,0 | B35: 80 | C35: 66 | D35: 5 | E35: =(B35*C35*D35)/1000000 -> 0.0264 | F35: ='EKİM 4 HAFTA '!V35 -> 56 | G35: =E35*F35 -> 1.4784 | H35: 0 | I35: =E35*H35 -> 0 | J35: 0 | K35: =E35*J35 -> 0 | L35: 0 | M35: =E35*L35 -> 0 | N35: 0 | O35: =E35*N35 -> 0 | P35: 0 | Q35: =E35*P35 -> 0 | R35: =F35-H35-J35-L35-N35-P35 -> 56 | S35: =E35*R35 -> 1.4784 | U35: =E35*T35 -> 0 | V35: =R35+T35 -> 56 | W35: =E35*V35 -> 1.4784
A36: 22 DN 60*62*5,0 | B36: 60 | C36: 62 | D36: 5 | E36: =(B36*C36*D36)/1000000 -> 0.0186 | F36: ='EKİM 4 HAFTA '!V36 -> 4 | G36: =E36*F36 -> 0.0744 | H36: 0 | I36: =E36*H36 -> 0 | J36: 0 | K36: =E36*J36 -> 0 | L36: 0 | M36: =E36*L36 -> 0 | N36: 0 | O36: =E36*N36 -> 0 | P36: 0 | Q36: =E36*P36 -> 0 | R36: =F36-H36-J36-L36-N36-P36 -> 4 | S36: =E36*R36 -> 0.0744 | U36: =E36*T36 -> 0 | V36: =R36+T36 -> 4 | W36: =E36*V36 -> 0.0744
A37: 28 DN 60*67*3 | B37: 60 | C37: 67 | D37: 3 | E37: =(B37*C37*D37)/1000000 -> 0.01206 | F37: ='EKİM 4 HAFTA '!V37 -> 12 | G37: =E37*F37 -> 0.14472 | H37: 0 | I37: =E37*H37 -> 0 | J37: 0 | K37: =E37*J37 -> 0 | L37: 0 | M37: =E37*L37 -> 0 | N37: 0 | O37: =E37*N37 -> 0 | P37: 0 | Q37: =E37*P37 -> 0 | R37: =F37-H37-J37-L37-N37-P37 -> 12 | S37: =E37*R37 -> 0.14472 | U37: =E37*T37 -> 0 | V37: =R37+T37 -> 12 | W37: =E37*V37 -> 0.14472
A38: 28 DN GRİ 7,0 | B38: 140 | C38: 240 | D38: 7 | E38: =(B38*C38*D38)/1000000 -> 0.2352 | F38: ='EKİM 4 HAFTA '!V38 -> 4 | G38: =E38*F38 -> 0.9408 | H38: 0 | I38: =E38*H38 -> 0 | J38: 0 | K38: =E38*J38 -> 0 | L38: 0 | M38: =E38*L38 -> 0 | N38: 0 | O38: =E38*N38 -> 0 | P38: 0 | Q38: =E38*P38 -> 0 | R38: =F38-H38-J38-L38-N38-P38 -> 4 | S38: =E38*R38 -> 0.9408 | U38: =E38*T38 -> 0 | V38: =R38+T38 -> 4 | W38: =E38*V38 -> 0.9408
A39: 18 DN GRİ 60*56*10 | B39: 60 | C39: 56 | D39: 10 | E39: =(B39*C39*D39)/1000000 -> 0.0336 | F39: ='EKİM 4 HAFTA '!V39 -> 0 | G39: =E39*F39 -> 0 | H39: 0 | I39: =E39*H39 -> 0 | J39: 0 | K39: =E39*J39 -> 0 | L39: 0 | M39: =E39*L39 -> 0 | N39: 0 | O39: =E39*N39 -> 0 | P39: 0 | Q39: =E39*P39 -> 0 | R39: =F39-H39-J39-L39-N39-P39 -> 0 | S39: =E39*R39 -> 0 | U39: =E39*T39 -> 0 | V39: =R39+T39 -> 0 | W39: =E39*V39 -> 0
A40: 18 DN GRİ 58*55*10 | B40: 58 | C40: 55 | D40: 10 | E40: =(B40*C40*D40)/1000000 -> 0.0319 | F40: ='EKİM 4 HAFTA '!V40 -> 0 | G40: =E40*F40 -> 0 | H40: 0 | I40: =E40*H40 -> 0 | J40: 0 | K40: =E40*J40 -> 0 | L40: 0 | M40: =E40*L40 -> 0 | N40: 0 | O40: =E40*N40 -> 0 | P40: 0 | Q40: =E40*P40 -> 0 | R40: =F40-H40-J40-L40-N40-P40 -> 0 | S40: =E40*R40 -> 0 | U40: =E40*T40 -> 0 | V40: =R40+T40 -> 0 | W40: =E40*V40 -> 0
...

Sheet AĞUSTOS 5. HAFTA
A1: SÜNGER | B1: AĞUSTOS 5. HAFTA
A2: ÜRÜN ADI | F2: DEVİR STOK | H2: 44798 | J2: 44799 | L2: 44802 | N2: 44803 | P2: 44804 | R2: 44805 | T2: 44806 | V2: KALAN STOK | X2: STOK GİRİŞİ | Z2: TOPLAM STOK MİKTARI
H3: STOK ÇIKIŞI | J3: STOK ÇIKIŞI | L3: STOK ÇIKIŞI | N3: STOK ÇIKIŞI | P3: STOK ÇIKIŞI | R3: STOK ÇIKIŞI | T3: STOK ÇIKIŞI
B4: EN | C4: BOY | D4: YÜKS | E4: br m³ | F4: PLAKA ADET | H4: PLAKA ADET | J4: PLAKA ADET | L4: PLAKA ADET | N4: PLAKA ADET | P4: PLAKA ADET | R4: PLAKA ADET | T4: PLAKA ADET | V4: PLAKA ADET | X4: PLAKA ADET | Z4: PLAKA ADET
A5: 22 DN GRİ 1,0 | B5: 140 | C5: 240 | D5: 1 | E5: =(B5*C5*D5)/1000000 -> 0.0336 | F5: 14 | G5: =E5*F5 -> 0.4704 | H5: 14 | I5: =E5*H5 -> 0.4704 | J5: 1 | K5: =E5*J5 -> 0.0336 | L5: 29 | M5: =E5*L5 -> 0.9744 | N5: 27 | O5: =E5*N5 -> 0.9072 | P5: 48 | Q5: =E5*P5 -> 1.6128 | R5: 33 | S5: =E5*R5 -> 1.1088 | U5: =E5*T5 -> 0 | V5: =F5-H5-J5-L5-N5-P5-R5-T5 -> -138 | W5: =E5*V5 -> -4.6368 | X5: 618 | Y5: =E5*X5 -> 20.7648 | Z5: =V5+X5 -> 480 | AA5: =I5*Z5 -> 225.792 | AB5: =+R5+T5 -> 33
A6: 14 DN BEYAZ 0,8 | B6: 140 | C6: 240 | D6: 0.8 | E6: =(B6*C6*D6)/1000000 -> 0.02688 | F6: 569 | G6: =E6*F6 -> 15.29472 | I6: =E6*H6 -> 0 | K6: =E6*J6 -> 0 | M6: =E6*L6 -> 0 | O6: =E6*N6 -> 0 | P6: 6 | Q6: =E6*P6 -> 0.16128 | R6: 3 | S6: =E6*R6 -> 0.08064 | U6: =E6*T6 -> 0 | V6: =F6-H6-J6-L6-N6-P6-R6-T6 -> 560 | W6: =E6*V6 -> 15.0528 | Y6: =E6*X6 -> 0 | Z6: =V6+X6 -> 560 | AA6: =E6*Z6 -> 15.0528 | AB6: =+R6+T6 -> 3
A7: 14 DN BEYAZ 1,4 | B7: 140 | C7: 240 | D7: 1.4 | E7: =(B7*C7*D7)/1000000 -> 0.04704 | F7: 402 | G7: =E7*F7 -> 18.91008 | H7: 1 | I7: =E7*H7 -> 0.04704 | J7: 20 | K7: =E7*J7 -> 0.9408 | L7: 36 | M7: =E7*L7 -> 1.69344 | N7: 6 | O7: =E7*N7 -> 0.28224 | P7: 5 | Q7: =E7*P7 -> 0.2352 | R7: 27 | S7: =E7*R7 -> 1.27008 | U7: =E7*T7 -> 0 | V7: =F7-H7-J7-L7-N7-P7-R7-T7 -> 307 | W7: =E7*V7 -> 14.44128 | Y7: =E7*X7 -> 0 | Z7: =V7+X7 -> 307 | AA7: =E7*Z7 -> 14.44128 | AB7: =+R7+T7 -> 27
A8: 22 DN GRİ 4,0 | B8: 140 | C8: 240 | D8: 4 | E8: =(B8*C8*D8)/1000000 -> 0.1344 | F8: 59 | G8: =E8*F8 -> 7.9296 | H8: 1 | I8: =E8*H8 -> 0.1344 | K8: =E8*J8 -> 0 | M8: =E8*L8 -> 0 | O8: =E8*N8 -> 0 | P8: 2 | Q8: =E8*P8 -> 0.2688 | S8: =E8*R8 -> 0 | U8: =E8*T8 -> 0 | V8: =F8-H8-J8-L8-N8-P8-R8-T8 -> 56 | W8: =E8*V8 -> 7.5264 | Y8: =E8*X8 -> 0 | Z8: =V8+X8 -> 56 | AA8: =E8*Z8 -> 7.5264 | AB8: =+R8+T8 -> 0
A9: 22 DN GRİ 2,0 | B9: 140 | C9: 240 | D9: 2 | E9: =(B9*C9*D9)/1000000 -> 0.0672 | F9: 134 | G9: =E9*F9 -> 9.0048 | H9: 3 | I9: =E9*H9 -> 0.2016 | K9: =E9*J9 -> 0 | L9: 1 | M9: =E9*L9 -> 0.0672 | O9: =E9*N9 -> 0 | P9: 12 | Q9: =E9*P9 -> 0.8064 | S9: =E9*R9 -> 0 | U9: =E9*T9 -> 0 | V9: =F9-H9-J9-L9-N9-P9-R9-T9 -> 118 | W9: =E9*V9 -> 7.9296 | X9: 33 | Y9: =E9*X9 -> 2.2176 | Z9: =V9+X9 -> 151 | AA9: =E9*Z9 -> 10.1472 | AB9: =+R9+T9 -> 0
A10: 24 DN KUŞTÜYÜ 2 ,0 | B10: 140 | C10: 240 | D10: 2 | E10: =(B10*C10*D10)/1000000 -> 0.0672 | F10: 0 | G10: =E10*F10 -> 0 | H10: 0 | I10: =E10*H10 -> 0 | K10: =E10*J10 -> 0 | L10: 26 | M10: =E10*L10 -> 1.7472 | O10: =E10*N10 -> 0 | Q10: =E10*P10 -> 0 | R10: 14 | S10: =E10*R10 -> 0.9408 | U10: =E10*T10 -> 0 | V10: =F10-H10-J10-L10-N10-P10-R10-T10 -> -40 | W10: =E10*V10 -> -2.688 | X10: 100 | Y10: =E10*X10 -> 6.72 | Z10: =V10+X10 -> 60 | AA10: =E10*Z10 -> 4.032 | AB10: =+R10+T10 -> 14
A11: 30 DN LÜKS BEYAZ 7,0 | B11: 140 | C11: 240 | D11: 7 | E11: =(B11*C11*D11)/1000000 -> 0.2352 | F11: 9 | G11: =E11*F11 -> 2.1168 | I11: =E11*H11 -> 0 | K11: =E11*J11 -> 0 | M11: =E11*L11 -> 0 | O11: =E11*N11 -> 0 | Q11: =E11*P11 -> 0 | S11: =E11*R11 -> 0 | U11: =E11*T11 -> 0 | V11: =F11-H11-J11-L11-N11-P11-R11-T11 -> 9 | W11: =E11*V11 -> 2.1168 | Y11: =E11*X11 -> 0 | Z11: =V11+X11 -> 9 | AA11: =E11*Z11 -> 2.1168 | AB11: =+R11+T11 -> 0
A12: 24 DN KUŞTÜYÜ 5 ,0 | B12: 140 | C12: 240 | D12: 5 | E12: =(B12*C12*D12)/1000000 -> 0.168 | F12: 23 | G12: =E12*F12 -> 3.864 | H12: 16 | I12: =E12*H12 -> 2.688 | J12: 3 | K12: =E12*J12 -> 0.504 | M12: =E12*L12 -> 0 | O12: =E12*N12 -> 0 | P12: 4 | Q12: =E12*P12 -> 0.672 | S12: =E12*R12 -> 0 | U12: =E12*T12 -> 0 | V12: =F12-H12-J12-L12-N12-P12-R12-T12 -> 0 | W12: =E12*V12 -> 0 | Y12: =E12*X12 -> 0 | Z12: =V12+X12 -> 0 | AA12: =E12*Z12 -> 0 | AB12: =+R12+T12 -> 0
A13: 28 DN GRİ SOFT 5,0 | B13: 140 | C13: 240 | D13: 5 | E13: =(B13*C13*D13)/1000000 -> 0.168 | F13: 52 | G13: =E13*F13 -> 8.736 | H13: 1 | I13: =E13*H13 -> 0.168 | K13: =E13*J13 -> 0 | M13: =E13*L13 -> 0 | O13: =E13*N13 -> 0 | Q13: =E13*P13 -> 0 | S13: =E13*R13 -> 0 | U13: =E13*T13 -> 0 | V13: =F13-H13-J13-L13-N13-P13-R13-T13 -> 51 | W13: =E13*V13 -> 8.568 | Y13: =E13*X13 -> 0 | Z13: =V13+X13 -> 51 | AA13: =E13*Z13 -> 8.568 | AB13: =+R13+T13 -> 0
A14: 28 DN GRİ 5,0 | B14: 140 | C14: 240 | D14: 5 | E14: =(B14*C14*D14)/1000000 -> 0.168 | F14: 10 | G14: =E14*F14 -> 1.68 | I14: =E14*H14 -> 0 | K14: =E14*J14 -> 0 | M14: =E14*L14 -> 0 | O14: =E14*N14 -> 0 | Q14: =E14*P14 -> 0 | R14: 11 | S14: =E14*R14 -> 1.848 | U14: =E14*T14 -> 0 | V14: =F14-H14-J14-L14-N14-P14-R14-T14 -> -1 | W14: =E14*V14 -> -0.168 | X14: 100 | Y14: =E14*X14 -> 16.8 | Z14: =V14+X14 -> 99 | AA14: =E14*Z14 -> 16.632 | AB14: =+R14+T14 -> 11
A15: 28 DN SOFT 10 | B15: 140 | C15: 240 | D15: 10 | E15: =(B15*C15*D15)/1000000 -> 0.336 | F15: 11 | G15: =E15*F15 -> 3.696 | I15: =E15*H15 -> 0 | K15: =E15*J15 -> 0 | M15: =E15*L15 -> 0 | O15: =E15*N15 -> 0 | P15: 2 | Q15: =E15*P15 -> 0.672 | S15: =E15*R15 -> 0 | T15: 1 | U15: =E15*T15 -> 0.336 | V15: =F15-H15-J15-L15-N15-P15-R15-T15 -> 8 | W15: =E15*V15 -> 2.688 | Y15: =E15*X15 -> 0 | Z15: =V15+X15 -> 8 | AA15: =E15*Z15 -> 2.688 | AB15: =+R15+T15 -> 1
A16: 22 DN GRİ 3,0 | B16: 140 | C16: 240 | D16: 3 | E16: =(B16*C16*D16)/1000000 -> 0.1008 | F16: 82 | G16: =E16*F16 -> 8.2656 | H16: 1 | I16: =E16*H16 -> 0.1008 | K16: =E16*J16 -> 0 | M16: =E16*L16 -> 0 | O16: =E16*N16 -> 0 | P16: 3 | Q16: =E16*P16 -> 0.3024 | S16: =E16*R16 -> 0 | T16: 5 | U16: =E16*T16 -> 0.504 | V16: =F16-H16-J16-L16-N16-P16-R16-T16 -> 73 | W16: =E16*V16 -> 7.3584 | Y16: =E16*X16 -> 0 | Z16: =V16+X16 -> 73 | AA16: =E16*Z16 -> 7.3584 | AB16: =+R16+T16 -> 5
A17: 22 DN GRİ 5,0 | B17: 140 | C17: 240 | D17: 5 | E17: =(B17*C17*D17)/1000000 -> 0.168 | F17: 60 | G17: =E17*F17 -> 10.08 | I17: =E17*H17 -> 0 | K17: =E17*J17 -> 0 | M17: =E17*L17 -> 0 | O17: =E17*N17 -> 0 | P17: 17 | Q17: =E17*P17 -> 2.856 | S17: =E17*R17 -> 0 | U17: =E17*T17 -> 0 | V17: =F17-H17-J17-L17-N17-P17-R17-T17 -> 43 | W17: =E17*V17 -> 7.224 | Y17: =E17*X17 -> 0 | Z17: =V17+X17 -> 43 | AA17: =E17*Z17 -> 7.224 | AB17: =+R17+T17 -> 0
A18: 28 DN GRİ 3,0 | B18: 140 | C18: 240 | D18: 3 | E18: =(B18*C18*D18)/1000000 -> 0.1008 | F18: 0 | G18: =E18*F18 -> 0 | I18: =E18*H18 -> 0 | J18: 0 | K18: =E18*J18 -> 0 | L18: 0 | M18: =E18*L18 -> 0 | N18: 113 | O18: =E18*N18 -> 11.3904 | Q18: =E18*P18 -> 0 | R18: 16 | S18: =E18*R18 -> 1.6128 | U18: =E18*T18 -> 0 | V18: =F18-H18-J18-L18-N18-P18-R18-T18 -> -129 | W18: =E18*V18 -> -13.0032 | X18: 347 | Y18: =E18*X18 -> 34.9776 | Z18: =V18+X18 -> 218 | AA18: =E18*Z18 -> 21.9744 | AB18: =+R18+T18 -> 16
A19: 24 DN KUŞTÜYÜ 8,0 | B19: 140 | C19: 240 | D19: 8 | E19: =(B19*C19*D19)/1000000 -> 0.2688 | F19: 0 | G19: =E19*F19 -> 0 | I19: =E19*H19 -> 0 | K19: =E19*J19 -> 0 | M19: =E19*L19 -> 0 | O19: =E19*N19 -> 0 | P19: 3 | Q19: =E19*P19 -> 0.8064 | S19: =E19*R19 -> 0 | U19: =E19*T19 -> 0 | V19: =F19-H19-J19-L19-N19-P19-R19-T19 -> -3 | W19: =E19*V19 -> -0.8064 | X19: 20 | Y19: =E19*X19 -> 5.376 | Z19: =V19+X19 -> 17 | AA19: =E19*Z19 -> 4.5696 | AB19: =+R19+T19 -> 0
A20: 28 DN SOFT 8,0 | B20: 140 | C20: 240 | D20: 8 | E20: =(B20*C20*D20)/1000000 -> 0.2688 | F20: 0 | G20: =E20*F20 -> 0 | I20: =E20*H20 -> 0 | K20: =E20*J20 -> 0 | M20: =E20*L20 -> 0 | O20: =E20*N20 -> 0 | Q20: =E20*P20 -> 0 | S20: =E20*R20 -> 0 | U20: =E20*T20 -> 0 | V20: =F20-H20-J20-L20-N20-P20-R20-T20 -> 0 | W20: =E20*V20 -> 0 | Y20: =E20*X20 -> 0 | Z20: =V20+X20 -> 0 | AA20: =E20*Z20 -> 0 | AB20: =+R20+T20 -> 0
A21: 22 DN 77*55*8,0 | B21: 77 | C21: 55 | D21: 8 | E21: =(B21*C21*D21)/1000000 -> 0.03388 | F21: 4 | G21: =E21*F21 -> 0.13552 | I21: =E21*H21 -> 0 | K21: =E21*J21 -> 0 | M21: =E21*L21 -> 0 | O21: =E21*N21 -> 0 | Q21: =E21*P21 -> 0 | S21: =E21*R21 -> 0 | U21: =E21*T21 -> 0 | V21: =F21-H21-J21-L21-N21-P21-R21-T21 -> 4 | W21: =E21*V21 -> 0.13552 | Y21: =E21*X21 -> 0 | Z21: =V21+X21 -> 4 | AA21: =E21*Z21 -> 0.13552 | AB21: =+R21+T21 -> 0
A22: 32 DN 65*50*12 | B22: 65 | C22: 50 | D22: 12 | E22: =(B22*C22*D22)/1000000 -> 0.039 | F22: 26 | G22: =E22*F22 -> 1.014 | I22: =E22*H22 -> 0 | K22: =E22*J22 -> 0 | M22: =E22*L22 -> 0 | O22: =E22*N22 -> 0 | Q22: =E22*P22 -> 0 | S22: =E22*R22 -> 0 | U22: =E22*T22 -> 0 | V22: =F22-H22-J22-L22-N22-P22-R22-T22 -> 26 | W22: =E22*V22 -> 1.014 | Y22: =E22*X22 -> 0 | Z22: =V22+X22 -> 26 | AA22: =E22*Z22 -> 1.014 | AB22: =+R22+T22 -> 0
A23: SİLİNDİR | E23: =(B23*C23*D23)/1000000 -> 0 | F23: 74 | G23: =E23*F23 -> 0 | I23: =E23*H23 -> 0 | K23: =E23*J23 -> 0 | M23: =E23*L23 -> 0 | O23: =E23*N23 -> 0 | Q23: =E23*P23 -> 0 | S23: =E23*R23 -> 0 | U23: =E23*T23 -> 0 | V23: =F23-H23-J23-L23-N23-P23-R23-T23 -> 74 | W23: =E23*V23 -> 0 | Y23: =E23*X23 -> 0 | Z23: =V23+X23 -> 74 | AA23: =E23*Z23 -> 0 | AB23: =+R23+T23 -> 0
A24: 32 DN 66*56*12 | B24: 66 | C24: 56 | D24: 12 | E24: =(B24*C24*D24)/1000000 -> 0.044352 | F24: 28 | G24: =E24*F24 -> 1.241856 | I24: =E24*H24 -> 0 | K24: =E24*J24 -> 0 | M24: =E24*L24 -> 0 | O24: =E24*N24 -> 0 | Q24: =E24*P24 -> 0 | S24: =E24*R24 -> 0 | U24: =E24*T24 -> 0 | V24: =F24-H24-J24-L24-N24-P24-R24-T24 -> 28 | W24: =E24*V24 -> 1.241856 | Y24: =E24*X24 -> 0 | Z24: =V24+X24 -> 28 | AA24: =E24*Z24 -> 1.241856 | AB24: =+R24+T24 -> 0
A25: 32 DN 61,5*61,5*10 | B25: 61.5 | C25: 61.5 | D25: 10 | E25: =(B25*C25*D25)/1000000 -> 0.0378225 | F25: 30 | G25: =E25*F25 -> 1.134675 | I25: =E25*H25 -> 0 | K25: =E25*J25 -> 0 | M25: =E25*L25 -> 0 | O25: =E25*N25 -> 0 | P25: 30 | Q25: =E25*P25 -> 1.134675 | S25: =E25*R25 -> 0 | U25: =E25*T25 -> 0 | V25: =F25-H25-J25-L25-N25-P25-R25-T25 -> 0 | W25: =E25*V25 -> 0 | Y25: =E25*X25 -> 0 | Z25: =V25+X25 -> 0 | AA25: =E25*Z25 -> 0 | AB25: =+R25+T25 -> 0
A26: 18 DN 82*67*5,0 | B26: 82 | C26: 67 | D26: 5 | E26: =(B26*C26*D26)/1000000 -> 0.02747 | F26: 30 | G26: =E26*F26 -> 0.8241 | I26: =E26*H26 -> 0 | K26: =E26*J26 -> 0 | M26: =E26*L26 -> 0 | O26: =E26*N26 -> 0 | Q26: =E26*P26 -> 0 | S26: =E26*R26 -> 0 | U26: =E26*T26 -> 0 | V26: =F26-H26-J26-L26-N26-P26-R26-T26 -> 30 | W26: =E26*V26 -> 0.8241 | Y26: =E26*X26 -> 0 | Z26: =V26+X26 -> 30 | AA26: =E26*Z26 -> 0.8241 | AB26: =+R26+T26 -> 0
A27: 18 DN 80*62*2,0 | B27: 80 | C27: 62 | D27: 2 | E27: =(B27*C27*D27)/1000000 -> 0.00992 | F27: 36 | G27: =E27*F27 -> 0.35712 | I27: =E27*H27 -> 0 | K27: =E27*J27 -> 0 | M27: =E27*L27 -> 0 | O27: =E27*N27 -> 0 | Q27: =E27*P27 -> 0 | S27: =E27*R27 -> 0 | U27: =E27*T27 -> 0 | V27: =F27-H27-J27-L27-N27-P27-R27-T27 -> 36 | W27: =E27*V27 -> 0.35712 | Y27: =E27*X27 -> 0 | Z27: =V27+X27 -> 36 | AA27: =E27*Z27 -> 0.35712 | AB27: =+R27+T27 -> 0
A28: 32 DN 63*55*5,0 | B28: 63 | C28: 55 | D28: 5 | E28: =(B28*C28*D28)/1000000 -> 0.017325 | F28: 19 | G28: =E28*F28 -> 0.329175 | I28: =E28*H28 -> 0 | K28: =E28*J28 -> 0 | M28: =E28*L28 -> 0 | O28: =E28*N28 -> 0 | Q28: =E28*P28 -> 0 | S28: =E28*R28 -> 0 | U28: =E28*T28 -> 0 | V28: =F28-H28-J28-L28-N28-P28-R28-T28 -> 19 | W28: =E28*V28 -> 0.329175 | Y28: =E28*X28 -> 0 | Z28: =V28+X28 -> 19 | AA28: =E28*Z28 -> 0.329175 | AB28: =+R28+T28 -> 0
A29: 18 DN BEYAZ 5,0 | B29: 140 | C29: 240 | D29: 5 | E29: =(B29*C29*D29)/1000000 -> 0.168 | F29: 7 | G29: =E29*F29 -> 1.176 | I29: =E29*H29 -> 0 | K29: =E29*J29 -> 0 | M29: =E29*L29 -> 0 | O29: =E29*N29 -> 0 | P29: 1 | Q29: =E29*P29 -> 0.168 | S29: =E29*R29 -> 0 | U29: =E29*T29 -> 0 | V29: =F29-H29-J29-L29-N29-P29-R29-T29 -> 6 | W29: =E29*V29 -> 1.008 | Y29: =E29*X29 -> 0 | Z29: =V29+X29 -> 6 | AA29: =E29*Z29 -> 1.008 | AB29: =+R29+T29 -> 0
A30: 15 DN BEYAZ 10 | B30: 140 | C30: 240 | D30: 10 | E30: =(B30*C30*D30)/1000000 -> 0.336 | F30: 11 | G30: =E30*F30 -> 3.696 | I30: =E30*H30 -> 0 | K30: =E30*J30 -> 0 | M30: =E30*L30 -> 0 | O30: =E30*N30 -> 0 | Q30: =E30*P30 -> 0 | S30: =E30*R30 -> 0 | U30: =E30*T30 -> 0 | V30: =F30-H30-J30-L30-N30-P30-R30-T30 -> 11 | W30: =E30*V30 -> 3.696 | Y30: =E30*X30 -> 0 | Z30: =V30+X30 -> 11 | AA30: =E30*Z30 -> 3.696 | AB30: =+R30+T30 -> 0
A31: 22 DN BEYAZ 3,0 | B31: 140 | C31: 240 | D31: 3 | E31: =(B31*C31*D31)/1000000 -> 0.1008 | F31: 40 | G31: =E31*F31 -> 4.032 | I31: =E31*H31 -> 0 | K31: =E31*J31 -> 0 | M31: =E31*L31 -> 0 | N31: 2 | O31: =E31*N31 -> 0.2016 | Q31: =E31*P31 -> 0 | S31: =E31*R31 -> 0 | U31: =E31*T31 -> 0 | V31: =F31-H31-J31-L31-N31-P31-R31-T31 -> 38 | W31: =E31*V31 -> 3.8304 | Y31: =E31*X31 -> 0 | Z31: =V31+X31 -> 38 | AA31: =E31*Z31 -> 3.8304 | AB31: =+R31+T31 -> 0
A32: 28 DN 90*80*8,0 | B32: 90 | C32: 80 | D32: 8 | E32: =(B32*C32*D32)/1000000 -> 0.0576 | F32: 24 | G32: =E32*F32 -> 1.3824 | I32: =E32*H32 -> 0 | K32: =E32*J32 -> 0 | M32: =E32*L32 -> 0 | O32: =E32*N32 -> 0 | Q32: =E32*P32 -> 0 | S32: =E32*R32 -> 0 | U32: =E32*T32 -> 0 | V32: =F32-H32-J32-L32-N32-P32-R32-T32 -> 24 | W32: =E32*V32 -> 1.3824 | Y32: =E32*X32 -> 0 | Z32: =V32+X32 -> 24 | AA32: =E32*Z32 -> 1.3824 | AB32: =+R32+T32 -> 0
A33: 28 DN SOFT 90*80*8,0 | B33: 90 | C33: 80 | D33: 8 | E33: =(B33*C33*D33)/1000000 -> 0.0576 | F33: 7 | G33: =E33*F33 -> 0.4032 | I33: =E33*H33 -> 0 | K33: =E33*J33 -> 0 | M33: =E33*L33 -> 0 | O33: =E33*N33 -> 0 | Q33: =E33*P33 -> 0 | S33: =E33*R33 -> 0 | U33: =E33*T33 -> 0 | V33: =F33-H33-J33-L33-N33-P33-R33-T33 -> 7 | W33: =E33*V33 -> 0.4032 | Y33: =E33*X33 -> 0 | Z33: =V33+X33 -> 7 | AA33: =E33*Z33 -> 0.4032 | AB33: =+R33+T33 -> 0
A34: 22 DN HİLTON OTURK. | E34: =(B34*C34*D34)/1000000 -> 0 | F34: 300 | G34: =E34*F34 -> 0 | I34: =E34*H34 -> 0 | K34: =E34*J34 -> 0 | M34: =E34*L34 -> 0 | O34: =E34*N34 -> 0 | Q34: =E34*P34 -> 0 | S34: =E34*R34 -> 0 | U34: =E34*T34 -> 0 | V34: =F34-H34-J34-L34-N34-P34-R34-T34 -> 300 | W34: =E34*V34 -> 0 | Y34: =E34*X34 -> 0 | Z34: =V34+X34 -> 300 | AA34: =E34*Z34 -> 0 | AB34: =+R34+T34 -> 0
A35: 22 DN 80*66*5,0 | B35: 80 | C35: 66 | D35: 5 | E35: =(B35*C35*D35)/1000000 -> 0.0264 | F35: 56 | G35: =E35*F35 -> 1.4784 | I35: =E35*H35 -> 0 | K35: =E35*J35 -> 0 | M35: =E35*L35 -> 0 | O35: =E35*N35 -> 0 | Q35: =E35*P35 -> 0 | S35: =E35*R35 -> 0 | U35: =E35*T35 -> 0 | V35: =F35-H35-J35-L35-N35-P35-R35-T35 -> 56 | W35: =E35*V35 -> 1.4784 | Y35: =E35*X35 -> 0 | Z35: =V35+X35 -> 56 | AA35: =E35*Z35 -> 1.4784 | AB35: =+R35+T35 -> 0
A36: 22 DN 60*62*5,0 | B36: 60 | C36: 62 | D36: 5 | E36: =(B36*C36*D36)/1000000 -> 0.0186 | F36: 17 | G36: =E36*F36 -> 0.3162 | I36: =E36*H36 -> 0 | K36: =E36*J36 -> 0 | M36: =E36*L36 -> 0 | O36: =E36*N36 -> 0 | Q36: =E36*P36 -> 0 | S36: =E36*R36 -> 0 | U36: =E36*T36 -> 0 | V36: =F36-H36-J36-L36-N36-P36-R36-T36 -> 17 | W36: =E36*V36 -> 0.3162 | Y36: =E36*X36 -> 0 | Z36: =V36+X36 -> 17 | AA36: =E36*Z36 -> 0.3162 | AB36: =+R36+T36 -> 0
A37: 28 DN 60*67*3 | B37: 60 | C37: 67 | D37: 3 | E37: =(B37*C37*D37)/1000000 -> 0.01206 | F37: 62 | G37: =E37*F37 -> 0.74772 | I37: =E37*H37 -> 0 | K37: =E37*J37 -> 0 | M37: =E37*L37 -> 0 | O37: =E37*N37 -> 0 | P37: 50 | Q37: =E37*P37 -> 0.603 | S37: =E37*R37 -> 0 | U37: =E37*T37 -> 0 | V37: =F37-H37-J37-L37-N37-P37-R37-T37 -> 12 | W37: =E37*V37 -> 0.14472 | Y37: =E37*X37 -> 0 | Z37: =V37+X37 -> 12 | AA37: =E37*Z37 -> 0.14472 | AB37: =+R37+T37 -> 0
A38: 28 DN GRİ 7,0 | B38: 140 | C38: 240 | D38: 7 | E38: =(B38*C38*D38)/1000000 -> 0.2352 | F38: 6 | G38: =E38*F38 -> 1.4112 | I38: =E38*H38 -> 0 | K38: =E38*J38 -> 0 | M38: =E38*L38 -> 0 | O38: =E38*N38 -> 0 | P38: 1 | Q38: =E38*P38 -> 0.2352 | S38: =E38*R38 -> 0 | U38: =E38*T38 -> 0 | V38: =F38-H38-J38-L38-N38-P38-R38-T38 -> 5 | W38: =E38*V38 -> 1.176 | Y38: =E38*X38 -> 0 | Z38: =V38+X38 -> 5 | AA38: =E38*Z38 -> 1.176 | AB38: =+R38+T38 -> 0
A39: 18 DN GRİ 60*56*10 | B39: 60 | C39: 56 | D39: 10 | E39: =(B39*C39*D39)/1000000 -> 0.0336 | F39: 30 | G39: =E39*F39 -> 1.008 | I39: =E39*H39 -> 0 | K39: =E39*J39 -> 0 | M39: =E39*L39 -> 0 | O39: =E39*N39 -> 0 | Q39: =E39*P39 -> 0 | S39: =E39*R39 -> 0 | U39: =E39*T39 -> 0 | V39: =F39-H39-J39-L39-N39-P39-R39-T39 -> 30 | W39: =E39*V39 -> 1.008 | Y39: =E39*X39 -> 0 | Z39: =V39+X39 -> 30 | AA39: =E39*Z39 -> 1.008 | AB39: =+R39+T39 -> 0
A40: 18 DN GRİ 58*55*10 | B40: 58 | C40: 55 | D40: 10 | E40: =(B40*C40*D40)/1000000 -> 0.0319 | F40: 66 | G40: =E40*F40 -> 2.1054 | I40: =E40*H40 -> 0 | K40: =E40*J40 -> 0 | M40: =E40*L40 -> 0 | O40: =E40*N40 -> 0 | Q40: =E40*P40 -> 0 | S40: =E40*R40 -> 0 | U40: =E40*T40 -> 0 | V40: =F40-H40-J40-L40-N40-P40-R40-T40 -> 66 | W40: =E40*V40 -> 2.1054 | Y40: =E40*X40 -> 0 | Z40: =V40+X40 -> 66 | AA40: =E40*Z40 -> 2.1054 | AB40: =+R40+T40 -> 0
...

Sheet EYLÜL 1. HAFTA
A1: SÜNGER | B1: EYLÜL 1. HAFTA
A2: ÜRÜN ADI | F2: DEVİR STOK | H2: 44809 | J2: 44810 | L2: 44811 | N2: 44812 | P2: 44813 | R2: KALAN STOK | T2: STOK GİRİŞİ | V2: TOPLAM STOK MİKTARI
H3: STOK ÇIKIŞI | J3: STOK ÇIKIŞI | L3: STOK ÇIKIŞI | N3: STOK ÇIKIŞI | P3: STOK ÇIKIŞI
B4: EN | C4: BOY | D4: YÜKS | E4: br m³ | F4: PLAKA ADET | H4: PLAKA ADET | J4: PLAKA ADET | L4: PLAKA ADET | N4: PLAKA ADET | P4: PLAKA ADET | R4: PLAKA ADET | T4: PLAKA ADET | V4: PLAKA ADET
A5: 22 DN GRİ 1,0 | B5: 140 | C5: 240 | D5: 1 | E5: =(B5*C5*D5)/1000000 -> 0.0336 | F5: ='AĞUSTOS 5. HAFTA'!Z5 -> 480 | G5: =E5*F5 -> 16.128 | H5: 0 | I5: =E5*H5 -> 0 | K5: =E5*J5 -> 0 | L5: 5 | M5: 0.168 | N5: 37 | O5: =E5*N5 -> 1.2432 | P5: 19 | Q5: =E5*P5 -> 0.6384 | R5: =F5-H5-J5-L5-N5-P5 -> 419 | S5: =E5*R5 -> 14.0784 | U5: =E5*T5 -> 0 | V5: =R5+T5 -> 419 | W5: =E5*V5 -> 14.0784 | X5: =+H5+J5+L5+N5+P5 -> 61
A6: 14 DN BEYAZ 0,8 | B6: 140 | C6: 240 | D6: 0.8 | E6: =(B6*C6*D6)/1000000 -> 0.02688 | F6: ='AĞUSTOS 5. HAFTA'!Z6 -> 560 | G6: =E6*F6 -> 15.0528 | H6: 36 | I6: =E6*H6 -> 0.96768 | J6: 2 | K6: =E6*J6 -> 0.05376 | L6: 2 | M6: =E6*L6 -> 0.05376 | N6: 18 | O6: =E6*N6 -> 0.48384 | P6: 20 | Q6: =E6*P6 -> 0.5376 | R6: =F6-H6-J6-L6-N6-P6 -> 482 | S6: =E6*R6 -> 12.95616 | U6: =E6*T6 -> 0 | V6: =R6+T6 -> 482 | W6: =E6*V6 -> 12.95616 | X6: =+H6+J6+L6+N6+P6 -> 78
A7: 14 DN BEYAZ 1,4 | B7: 140 | C7: 240 | D7: 1.4 | E7: =(B7*C7*D7)/1000000 -> 0.04704 | F7: ='AĞUSTOS 5. HAFTA'!Z7 -> 307 | G7: =E7*F7 -> 14.44128 | H7: 21 | I7: =E7*H7 -> 0.98784 | J7: 111 | K7: =E7*J7 -> 5.22144 | L7: 58 | M7: =E7*L7 -> 2.72832 | N7: 18 | O7: =E7*N7 -> 0.84672 | P7: 7 | Q7: =E7*P7 -> 0.32928 | R7: =F7-H7-J7-L7-N7-P7 -> 92 | S7: =E7*R7 -> 4.32768 | U7: =E7*T7 -> 0 | V7: =R7+T7 -> 92 | W7: =E7*V7 -> 4.32768 | X7: =+H7+J7+L7+N7+P7 -> 215
A8: 22 DN GRİ 4,0 | B8: 140 | C8: 240 | D8: 4 | E8: =(B8*C8*D8)/1000000 -> 0.1344 | F8: ='AĞUSTOS 5. HAFTA'!Z8 -> 56 | G8: =E8*F8 -> 7.5264 | I8: =E8*H8 -> 0 | K8: =E8*J8 -> 0 | L8: 2 | M8: =E8*L8 -> 0.2688 | N8: 10 | O8: =E8*N8 -> 1.344 | Q8: =E8*P8 -> 0 | R8: =F8-H8-J8-L8-N8-P8 -> 44 | S8: =E8*R8 -> 5.9136 | U8: =E8*T8 -> 0 | V8: =R8+T8 -> 44 | W8: =E8*V8 -> 5.9136 | X8: =+H8+J8+L8+N8+P8 -> 12
A9: 22 DN GRİ 2,0 | B9: 140 | C9: 240 | D9: 2 | E9: =(B9*C9*D9)/1000000 -> 0.0672 | F9: ='AĞUSTOS 5. HAFTA'!Z9 -> 151 | G9: =E9*F9 -> 10.1472 | H9: 151 | I9: =E9*H9 -> 10.1472 | K9: =E9*J9 -> 0 | L9: 3 | M9: =E9*L9 -> 0.2016 | N9: 5 | O9: =E9*N9 -> 0.336 | P9: 13 | Q9: =E9*P9 -> 0.8736 | R9: =F9-H9-J9-L9-N9-P9 -> -21 | S9: =E9*R9 -> -1.4112 | T9: 131 | U9: =E9*T9 -> 8.8032 | V9: =R9+T9 -> 110 | W9: =E9*V9 -> 7.392 | X9: =+H9+J9+L9+N9+P9 -> 172
A10: 24 DN KUŞTÜYÜ 2 ,0 | B10: 140 | C10: 240 | D10: 2 | E10: =(B10*C10*D10)/1000000 -> 0.0672 | F10: ='AĞUSTOS 5. HAFTA'!Z10 -> 60 | G10: =E10*F10 -> 4.032 | I10: =E10*H10 -> 0 | K10: =E10*J10 -> 0 | M10: =E10*L10 -> 0 | O10: =E10*N10 -> 0 | P10: 1 | Q10: =E10*P10 -> 0.0672 | R10: 45 | S10: =E10*R10 -> 3.024 | U10: =E10*T10 -> 0 | V10: =R10+T10 -> 45 | W10: =E10*V10 -> 3.024 | X10: =+H10+J10+L10+N10+P10 -> 1
A11: 30 DN LÜKS BEYAZ 7,0 | B11: 140 | C11: 240 | D11: 7 | E11: =(B11*C11*D11)/1000000 -> 0.2352 | F11: ='AĞUSTOS 5. HAFTA'!Z11 -> 9 | G11: =E11*F11 -> 2.1168 | I11: =E11*H11 -> 0 | K11: =E11*J11 -> 0 | M11: =E11*L11 -> 0 | O11: =E11*N11 -> 0 | Q11: =E11*P11 -> 0 | R11: =F11-H11-J11-L11-N11-P11 -> 9 | S11: =E11*R11 -> 2.1168 | U11: =E11*T11 -> 0 | V11: =R11+T11 -> 9 | W11: =E11*V11 -> 2.1168 | X11: =+H11+J11+L11+N11+P11 -> 0
A12: 24 DN KUŞTÜYÜ 5 ,0 | B12: 140 | C12: 240 | D12: 5 | E12: =(B12*C12*D12)/1000000 -> 0.168 | F12: ='AĞUSTOS 5. HAFTA'!Z12 -> 0 | G12: =E12*F12 -> 0 | I12: =E12*H12 -> 0 | K12: =E12*J12 -> 0 | L12: 2 | M12: =E12*L12 -> 0.336 | N12: 8 | O12: =E12*N12 -> 1.344 | P12: 1 | Q12: =E12*P12 -> 0.168 | R12: =F12-H12-J12-L12-N12-P12 -> -11 | S12: =E12*R12 -> -1.848 | T12: 394 | U12: =E12*T12 -> 66.192 | V12: =R12+T12 -> 383 | W12: =E12*V12 -> 64.344 | X12: =+H12+J12+L12+N12+P12 -> 11
A13: 28 DN GRİ SOFT 5,0 | B13: 140 | C13: 240 | D13: 5 | E13: =(B13*C13*D13)/1000000 -> 0.168 | F13: ='AĞUSTOS 5. HAFTA'!Z13 -> 51 | G13: =E13*F13 -> 8.568 | I13: =E13*H13 -> 0 | K13: =E13*J13 -> 0 | M13: =E13*L13 -> 0 | O13: =E13*N13 -> 0 | Q13: =E13*P13 -> 0 | R13: =F13-H13-J13-L13-N13-P13 -> 51 | S13: =E13*R13 -> 8.568 | U13: =E13*T13 -> 0 | V13: =R13+T13 -> 51 | W13: =E13*V13 -> 8.568 | X13: =+H13+J13+L13+N13+P13 -> 0
A14: 28 DN GRİ 5,0 | B14: 140 | C14: 240 | D14: 5 | E14: =(B14*C14*D14)/1000000 -> 0.168 | F14: ='AĞUSTOS 5. HAFTA'!Z14 -> 99 | G14: =E14*F14 -> 16.632 | H14: 1 | I14: =E14*H14 -> 0.168 | J14: 1 | K14: =E14*J14 -> 0.168 | M14: =E14*L14 -> 0 | N14: 1 | O14: =E14*N14 -> 0.168 | P14: 1 | Q14: =E14*P14 -> 0.168 | R14: =F14-H14-J14-L14-N14-P14 -> 95 | S14: =E14*R14 -> 15.96 | U14: =E14*T14 -> 0 | V14: =R14+T14 -> 95 | W14: =E14*V14 -> 15.96 | X14: =+H14+J14+L14+N14+P14 -> 4
A15: 28 DN SOFT 10 | B15: 140 | C15: 240 | D15: 10 | E15: =(B15*C15*D15)/1000000 -> 0.336 | F15: ='AĞUSTOS 5. HAFTA'!Z15 -> 8 | G15: =E15*F15 -> 2.688 | H15: 1 | I15: =E15*H15 -> 0.336 | K15: =E15*J15 -> 0 | M15: =E15*L15 -> 0 | N15: 2 | O15: =E15*N15 -> 0.672 | P15: 3 | Q15: =E15*P15 -> 1.008 | R15: =F15-H15-J15-L15-N15-P15 -> 2 | S15: =E15*R15 -> 0.672 | T15: 50 | U15: =E15*T15 -> 16.8 | V15: =R15+T15 -> 52 | W15: =E15*V15 -> 17.472 | X15: =+H15+J15+L15+N15+P15 -> 6
A16: 22 DN GRİ 3,0 | B16: 140 | C16: 240 | D16: 3 | E16: =(B16*C16*D16)/1000000 -> 0.1008 | F16: ='AĞUSTOS 5. HAFTA'!Z16 -> 73 | G16: =E16*F16 -> 7.3584 | I16: =E16*H16 -> 0 | J16: 6 | K16: =E16*J16 -> 0.6048 | M16: =E16*L16 -> 0 | N16: 4 | O16: =E16*N16 -> 0.4032 | P16: 6 | Q16: =E16*P16 -> 0.6048 | R16: =F16-H16-J16-L16-N16-P16 -> 57 | S16: =E16*R16 -> 5.7456 | T16: 150 | U16: =E16*T16 -> 15.12 | V16: =R16+T16 -> 207 | W16: =E16*V16 -> 20.8656 | X16: =+H16+J16+L16+N16+P16 -> 16
A17: 22 DN GRİ 5,0 | B17: 140 | C17: 240 | D17: 5 | E17: =(B17*C17*D17)/1000000 -> 0.168 | F17: ='AĞUSTOS 5. HAFTA'!Z17 -> 43 | G17: =E17*F17 -> 7.224 | I17: =E17*H17 -> 0 | K17: =E17*J17 -> 0 | M17: =E17*L17 -> 0 | N17: 3 | O17: =E17*N17 -> 0.504 | P17: 9 | Q17: =E17*P17 -> 1.512 | R17: =F17-H17-J17-L17-N17-P17 -> 31 | S17: =E17*R17 -> 5.208 | U17: =E17*T17 -> 0 | V17: =R17+T17 -> 31 | W17: =E17*V17 -> 5.208 | X17: =+H17+J17+L17+N17+P17 -> 12
A18: 28 DN GRİ 3,0 | B18: 140 | C18: 240 | D18: 3 | E18: =(B18*C18*D18)/1000000 -> 0.1008 | F18: ='AĞUSTOS 5. HAFTA'!Z18 -> 218 | G18: =E18*F18 -> 21.9744 | I18: =E18*H18 -> 0 | K18: =E18*J18 -> 0 | M18: =E18*L18 -> 0 | O18: =E18*N18 -> 0 | P18: 1 | Q18: =E18*P18 -> 0.1008 | R18: =F18-H18-J18-L18-N18-P18 -> 217 | S18: =E18*R18 -> 21.8736 | U18: =E18*T18 -> 0 | V18: =R18+T18 -> 217 | W18: =E18*V18 -> 21.8736 | X18: =+H18+J18+L18+N18+P18 -> 1
A19: 24 DN PEMBE 8,0 | B19: 140 | C19: 240 | D19: 8 | E19: =(B19*C19*D19)/1000000 -> 0.2688 | F19: ='AĞUSTOS 5. HAFTA'!Z19 -> 17 | G19: =E19*F19 -> 4.5696 | I19: =E19*H19 -> 0 | K19: =E19*J19 -> 0 | M19: =E19*L19 -> 0 | O19: =E19*N19 -> 0 | Q19: =E19*P19 -> 0 | R19: =F19-H19-J19-L19-N19-P19 -> 17 | S19: =E19*R19 -> 4.5696 | U19: =E19*T19 -> 0 | V19: =R19+T19 -> 17 | W19: =E19*V19 -> 4.5696 | X19: =+H19+J19+L19+N19+P19 -> 0
A20: 28 DN SOFT 8,0 | B20: 140 | C20: 240 | D20: 8 | E20: =(B20*C20*D20)/1000000 -> 0.2688 | F20: ='AĞUSTOS 5. HAFTA'!Z20 -> 0 | G20: =E20*F20 -> 0 | I20: =E20*H20 -> 0 | K20: =E20*J20 -> 0 | M20: =E20*L20 -> 0 | O20: =E20*N20 -> 0 | Q20: =E20*P20 -> 0 | R20: =F20-H20-J20-L20-N20-P20 -> 0 | S20: =E20*R20 -> 0 | U20: =E20*T20 -> 0 | V20: =R20+T20 -> 0 | W20: =E20*V20 -> 0 | X20: =+H20+J20+L20+N20+P20 -> 0
A21: 22 DN 77*55*8,0 | B21: 77 | C21: 55 | D21: 8 | E21: =(B21*C21*D21)/1000000 -> 0.03388 | F21: ='AĞUSTOS 5. HAFTA'!Z21 -> 4 | G21: =E21*F21 -> 0.13552 | I21: =E21*H21 -> 0 | K21: =E21*J21 -> 0 | M21: =E21*L21 -> 0 | O21: =E21*N21 -> 0 | Q21: =E21*P21 -> 0 | R21: =F21-H21-J21-L21-N21-P21 -> 4 | S21: =E21*R21 -> 0.13552 | U21: =E21*T21 -> 0 | V21: =R21+T21 -> 4 | W21: =E21*V21 -> 0.13552 | X21: =+H21+J21+L21+N21+P21 -> 0
A22: 32 DN 65*50*12 | B22: 65 | C22: 50 | D22: 12 | E22: =(B22*C22*D22)/1000000 -> 0.039 | F22: ='AĞUSTOS 5. HAFTA'!Z22 -> 26 | G22: =E22*F22 -> 1.014 | I22: =E22*H22 -> 0 | K22: =E22*J22 -> 0 | M22: =E22*L22 -> 0 | O22: =E22*N22 -> 0 | Q22: =E22*P22 -> 0 | R22: =F22-H22-J22-L22-N22-P22 -> 26 | S22: =E22*R22 -> 1.014 | U22: =E22*T22 -> 0 | V22: =R22+T22 -> 26 | W22: =E22*V22 -> 1.014 | X22: =+H22+J22+L22+N22+P22 -> 0
A23: SİLİNDİR | E23: =(B23*C23*D23)/1000000 -> 0 | F23: ='AĞUSTOS 5. HAFTA'!Z23 -> 74 | G23: =E23*F23 -> 0 | I23: =E23*H23 -> 0 | K23: =E23*J23 -> 0 | M23: =E23*L23 -> 0 | O23: =E23*N23 -> 0 | Q23: =E23*P23 -> 0 | R23: =F23-H23-J23-L23-N23-P23 -> 74 | S23: =E23*R23 -> 0 | U23: =E23*T23 -> 0 | V23: =R23+T23 -> 74 | W23: =E23*V23 -> 0 | X23: =+H23+J23+L23+N23+P23 -> 0
A24: 32 DN 66*56*12 | B24: 66 | C24: 56 | D24: 12 | E24: =(B24*C24*D24)/1000000 -> 0.044352 | F24: ='AĞUSTOS 5. HAFTA'!Z24 -> 28 | G24: =E24*F24 -> 1.241856 | I24: =E24*H24 -> 0 | K24: =E24*J24 -> 0 | M24: =E24*L24 -> 0 | O24: =E24*N24 -> 0 | Q24: =E24*P24 -> 0 | R24: =F24-H24-J24-L24-N24-P24 -> 28 | S24: =E24*R24 -> 1.241856 | U24: =E24*T24 -> 0 | V24: =R24+T24 -> 28 | W24: =E24*V24 -> 1.241856 | X24: =+H24+J24+L24+N24+P24 -> 0
A25: 32 DN 61,5*61,5*10 | B25: 61.5 | C25: 61.5 | D25: 10 | E25: =(B25*C25*D25)/1000000 -> 0.0378225 | F25: ='AĞUSTOS 5. HAFTA'!Z25 -> 0 | G25: =E25*F25 -> 0 | I25: =E25*H25 -> 0 | K25: =E25*J25 -> 0 | M25: =E25*L25 -> 0 | O25: =E25*N25 -> 0 | Q25: =E25*P25 -> 0 | R25: =F25-H25-J25-L25-N25-P25 -> 0 | S25: =E25*R25 -> 0 | U25: =E25*T25 -> 0 | V25: =R25+T25 -> 0 | W25: =E25*V25 -> 0 | X25: =+H25+J25+L25+N25+P25 -> 0
A26: 18 DN 82*67*5,0 | B26: 82 | C26: 67 | D26: 5 | E26: =(B26*C26*D26)/1000000 -> 0.02747 | F26: ='AĞUSTOS 5. HAFTA'!Z26 -> 30 | G26: =E26*F26 -> 0.8241 | I26: =E26*H26 -> 0 | K26: =E26*J26 -> 0 | M26: =E26*L26 -> 0 | O26: =E26*N26 -> 0 | Q26: =E26*P26 -> 0 | R26: =F26-H26-J26-L26-N26-P26 -> 30 | S26: =E26*R26 -> 0.8241 | U26: =E26*T26 -> 0 | V26: =R26+T26 -> 30 | W26: =E26*V26 -> 0.8241 | X26: =+H26+J26+L26+N26+P26 -> 0
A27: 18 DN 80*62*2,0 | B27: 80 | C27: 62 | D27: 2 | E27: =(B27*C27*D27)/1000000 -> 0.00992 | F27: ='AĞUSTOS 5. HAFTA'!Z27 -> 36 | G27: =E27*F27 -> 0.35712 | I27: =E27*H27 -> 0 | K27: =E27*J27 -> 0 | M27: =E27*L27 -> 0 | O27: =E27*N27 -> 0 | Q27: =E27*P27 -> 0 | R27: =F27-H27-J27-L27-N27-P27 -> 36 | S27: =E27*R27 -> 0.35712 | U27: =E27*T27 -> 0 | V27: =R27+T27 -> 36 | W27: =E27*V27 -> 0.35712 | X27: =+H27+J27+L27+N27+P27 -> 0
