Workbook

Sheet EYLÜL 2025 (2)
B1: EYLÜL | Q1: 45656
A2: S.NO | B2: ÜRÜN CİNSİ | F2: ADET | G2: devir | H2: GELEN | I2: 45905 | J2: 45912 | K2: 45919 | L2: 45926 | M2: 45930 | N2: KALAN | O2: AÇIKLAMA | P2: MİNİMUN | Q2: MAKSİMUN
A3: 1 | B3: U BAĞLANTI DEMİRİ | F3: 1950 | H3: 5000 | I3: 0 | J3: 0 | K3: 500 | L3: 500 | M3: 500 | N3: =+F3-I3-J3-K3-L3-M3+H3 -> 5450 | P3: 3000 | Q3: 10000
A4: 2 | B4: AYAK SOMUNU(BIDIK) | F4: 6500 | H4: 0 | I4: 0 | J4: 0 | K4: 0 | L4: 0 | M4: 1500 | N4: =+F4-I4-J4-K4-L4-M4+H4 -> 5000 | P4: 7000 | Q4: 20000
A5: 3 | B5: AMT. SEKRETER KÖRÜK | F5: 750 | G5: 1000 | H5: 0 | I5: 0 | J5: 0 | K5: 0 | L5: 0 | M5: 150 | N5: =+F5-I5-J5-K5-L5-M5+H5 -> 600 | P5: 500 | Q5: 2000
A6: 4 | B6: M8 CİVATALI BİNGO | F6: 3000 | H6: 0 | I6: 0 | J6: 0 | K6: 0 | L6: 0 | M6: 500 | N6: =+F6-I6-J6-K6-L6-M6+H6 -> 2500 | O6: PLASTİK SİY.BÜYÜK | P6: 250 | Q6: 1000
A7: 5 | B7: M8 OYNAR BAŞLIKLI BİNGO | F7: 121 | H7: 0 | I7: 0 | J7: 0 | K7: 0 | L7: 0 | M7: 0 | N7: =+F7-I7-J7-K7-L7-M7+H7 -> 121 | O7: KROM | P7: 100 | Q7: 500
A8: 6 | B8: M8 SOKET | F8: 2000 | H8: 0 | I8: 0 | J8: 0 | K8: 0 | L8: 0 | M8: 0 | N8: =+F8-I8-J8-K8-L8-M8+H8 -> 2000 | P8: 1000 | Q8: 10000
A9: 7 | B9: M8 CİVATALI BİNGO_MOB. | F9: 1000 | H9: 1000 | I9: 0 | J9: 0 | K9: 0 | L9: 0 | M9: 500 | N9: =+F9-I9-J9-K9-L9-M9+H9 -> 1500 | O9: REFAKATÇI SİY.KÜÇÜK | P9: 1000 | Q9: 3000
A10: 8 | B10: M6 SOKET | F10: 12000 | H10: 0 | I10: 0 | J10: 0 | K10: 0 | L10: 0 | M10: 2000 | N10: =+F10-I10-J10-K10-L10-M10+H10 -> 10000 | P10: 10000 | Q10: 50000
A11: 9 | B11: PİMLİ TEKER NAYLON 50 | F11: 5000 | G11: 0 | H11: 15000 | I11: 1000 | J11: 1800 | K11: 1750 | L11: 1000 | M11: 850 | N11: =+F11-I11-J11-K11-L11-M11+H11 -> 13600 | P11: 7500 | Q11: 30000
A12: 10 | B12: YARASA ŞASE KUYRUKLU | F12: 1187 | H12: 0 | I12: 0 | J12: 4 | K12: 0 | L12: 0 | M12: 4 | N12: =+F12-I12-J12-K12-L12-M12+H12 -> 1179 | P12: 200 | Q12: 1500
A13: 11 | B13: PİMLİ BİNGO | F13: 700 | H13: 0 | I13: 0 | J13: 0 | K13: 0 | L13: 0 | M13: 0 | N13: =+F13-I13-J13-K13-L13-M13+H13 -> 700 | P13: 2000 | Q13: 5000
A14: 12 | B14: LALE AYAK ÇEKYAT GEÇMELİ | F14: 500 | H14: 0 | I14: 0 | J14: 0 | K14: 0 | L14: 51 | M14: 0 | N14: =+F14-I14-J14-K14-L14-M14+H14 -> 449 | P14: 500 | Q14: 3000
A15: 13 | B15: TOKMAK | F15: 500 | H15: 0 | I15: 0 | J15: 0 | K15: 0 | L15: 0 | M15: 0 | N15: =+F15-I15-J15-K15-L15-M15+H15 -> 500 | P15: 500 | Q15: 3000
A16: 14 | B16: EKO SEKRETER KÖRÜK | C16: 350 | F16: 1650 | H16: 0 | I16: 0 | J16: 0 | K16: 0 | L16: 0 | M16: 0 | N16: =+F16-I16-J16-K16-L16-M16+H16 -> 1650 | P16: 500 | Q16: 2000
A17: 15 | B17: AHŞAP TELESKOP KÖRÜK | F17: 250 | G17: 165 | H17: 0 | I17: 0 | J17: 40 | K17: 40 | L17: 0 | M17: 0 | N17: =+F17-I17-J17-K17-L17-M17+H17 -> 170 | P17: 200 | Q17: 1000
A18: 16 | B18: VEGA KÖRÜK | F18: 4500 | G18: 500 | H18: 0 | I18: 0 | J18: 0 | K18: 0 | L18: 0 | M18: 0 | N18: =+F18-I18-J18-K18-L18-M18+H18 -> 4500 | P18: 2000 | Q18: 5000
A19: 17 | B19: YAZI TABLASI | F19: 66 | H19: 100 | I19: 0 | J19: 0 | K19: 30 | L19: 0 | M19: 0 | N19: =+F19-I19-J19-K19-L19-M19+H19 -> 136 | P19: 100 | Q19: 300
A20: 18 | B20: VEGA ÇAKMA KOL | F20: 50 | H20: 50 | I20: 0 | J20: 0 | K20: 70 | L20: 0 | M20: 0 | N20: =+F20-I20-J20-K20-L20-M20+H20 -> 30 | O20: TK | P20: 100 | Q20: 300
A21: 19 | F21: 0 | G21: 425 | H21: 0 | I21: 0 | J21: 0 | K21: 0 | L21: 0 | M21: 0 | N21: =+F21-I21-J21-K21-L21-M21+H21 -> 0
A22: 20 | B22: KUYRUKLU TİLK MEKANİZMA | F22: 1409 | H22: 0 | I22: 0 | J22: 32 | K22: 44 | L22: 8 | M22: 0 | N22: =+F22-I22-J22-K22-L22-M22+H22 -> 1325 | P22: 500 | Q22: 1000
A23: 21 | B23: ÇİFT KOLLU TİLK MEK. | F23: 1451 | H23: 1000 | I23: 0 | J23: 360 | K23: 240 | L23: 320 | M23: 1000 | N23: =+F23-I23-J23-K23-L23-M23+H23 -> 531 | P23: 1000 | Q23: 5000
A24: 22 | B24: VEGA KONFERANS KOL | F24: 120 | H24: 100 | I24: 0 | J24: 0 | K24: 30 | L24: 0 | M24: 0 | N24: =+F24-I24-J24-K24-L24-M24+H24 -> 190 | P24: 100 | Q24: 250
A25: 23 | B25: SİNEMA KISA KAPAK | F25: 305 | H25: 657 | I25: 150 | J25: 0 | K25: 0 | L25: 0 | M25: 0 | N25: =+F25-I25-J25-K25-L25-M25+H25 -> 812 | P25: 300 | Q25: 100
A26: 24 | B26: PİMLİ TEKER NAYLON 60 | F26: 9200 | H26: 0 | I26: 0 | J26: 600 | K26: 2400 | L26: 0 | M26: 1000 | N26: =+F26-I26-J26-K26-L26-M26+H26 -> 5200 | P26: 7500 | Q26: 15000
A27: 25 | B27: 5 cm krom ayarlı ayak | F27: 368 | H27: 0 | I27: 0 | J27: 0 | K27: 0 | L27: 30 | M27: 30 | N27: =+F27-I27-J27-K27-L27-M27+H27 -> 308 | P27: 300 | Q27: 1000
A28: 26 | G28: 0 | H28: 0 | I28: 0 | J28: 0 | K28: 0 | L28: 0 | M28: 0 | N28: 0 | Q28: 0
A29: 27 | B29: YARASA ŞASE | F29: 703 | H29: 0 | I29: 0 | J29: 4 | K29: 0 | L29: 0 | M29: 0 | N29: =+F29-I29-J29-K29-L29-M29+H29 -> 699 | P29: 200 | Q29: 750
A30: 28 | B30: TELLY KUYRUKLU ŞASE | F30: 0 | H30: 504 | I30: 0 | J30: 0 | K30: 0 | L30: 0 | M30: 0 | N30: =+F30-I30-J30-K30-L30-M30+H30 -> 504 | P30: 100 | Q30: 300
A31: 29 | B31: ZIMBA TELİ 9240 / KOLİ | F31: 5 | H31: 0 | I31: 0 | J31: 0 | K31: 0 | L31: 0 | M31: 0 | N31: =+F31-I31-J31-K31-L31-M31+H31 -> 5 | P31: 10 | Q31: 50
A32: 30 | B32: ZIMBA TELİ 8014 | F32: 0 | H32: 0 | I32: 0 | J32: 0 | K32: 0 | L32: 0 | M32: 0 | N32: =+F32-I32-J32-K32-L32-M32+H32 -> 0 | P32: 7 | Q32: 40
A33: 31 | B33: ZIMBA TELİ 8008 | F33: 2 | H33: 0 | I33: 0 | J33: 0 | K33: 0 | L33: 0 | M33: 0 | N33: =+F33-I33-J33-K33-L33-M33+H33 -> 2 | P33: 5 | Q33: 20
A34: 32 | B34: AYAK TASI KROM | F34: 450 | H34: 1000 | I34: 0 | J34: 40 | K34: 257 | L34: 153 | M34: 0 | N34: =+F34-I34-J34-K34-L34-M34+H34 -> 1000 | P34: 300 | Q34: 2000
A35: 33 | B35: AYAK TASI SİYAH | F35: 1000 | H35: 0 | I35: 0 | J35: 40 | K35: 40 | L35: 0 | M35: 0 | N35: =+F35-I35-J35-K35-L35-M35+H35 -> 920 | P35: 500 | Q35: 5000
A36: 34 | H36: 0 | I36: 0 | J36: 0 | K36: 0 | L36: 0 | M36: 0 | N36: =+F36-I36-J36-K36-L36-M36+H36 -> 0
A37: 35 | H37: 0 | I37: 0 | J37: 0 | K37: 0 | L37: 0 | M37: 0 | N37: =+F37-I37-J37-K37-L37-M37+H37 -> 0

Sheet eylül 4 hafta
A2: ÜRÜN CİNSİ | F2: devir | G2: GELEN | H2: 44830 | I2: 44831 | J2: 44832 | K2: 44833 | L2: 44834 | M2: KALAN | N2: AÇIKLAMA
A3: U BAĞLANTI DEMİRİ | E3: 10000 | G3: 0 | H3: 0 | M3: =+E3-H3-I3-J3-K3-L3+G3 -> 10000
A4: AYAK SOMUNU(BIDIK) | E4: 27238 | G4: 0 | L4: 0 | M4: =+E4-H4-I4-J4-K4-L4+G4 -> 27238
A5: M10 OYNAR BAŞLIKLI BİNGO | E5: 153 | G5: 0 | J5: 0 | M5: =+E5-H5-I5-J5-K5-L5+G5 -> 153 | N5: PLASTİK SİY.BÜYÜK
A6: M8 CİVATALI BİNGO | E6: 1644 | G6: 0 | J6: 0 | L6: 0 | M6: =+E6-H6-I6-J6-K6-L6+G6 -> 1644 | N6: PLASTİK SİY.BÜYÜK
A7: M8 OYNAR BAŞLIKLI BİNGO | E7: 400 | G7: 0 | H7: 0 | J7: 31 | K7: 26 | L7: 0 | M7: =+E7-H7-I7-J7-K7-L7+G7 -> 343 | N7: KROM
A8: M8 CİVATALI BİNGO | E8: 1656 | G8: 0 | K8: 100 | M8: =+E8-H8-I8-J8-K8-L8+G8 -> 1556 | N8: SİYAH KÜÇÜK
A9: M8 CİVATALI BİNGO_MOB. | E9: 1760 | G9: 0 | M9: =+E9-H9-I9-J9-K9-L9+G9 -> 1760 | N9: REFAKATÇI SİY.KÜÇÜK
A10: M6 SOKET | E10: 163000 | G10: 0 | J10: 0 | K10: 0 | L10: 0 | M10: =+E10-H10-I10-J10-K10-L10+G10 -> 163000
A11: PİMLİ TEKER NAYLON 50 | E11: 62380 | F11: 0 | G11: 0 | H11: 1260 | I11: 260 | J11: 620 | K11: 0 | L11: 0 | M11: =+E11-H11-I11-J11-K11-L11+G11 -> 60240
A12: SİLİKON TEKER | E12: 820 | G12: 0 | M12: =+E12-H12-I12-J12-K12-L12+G12 -> 820
A13: PİMLİ BİNGO | E13: 7430 | K13: 0 | L13: 0 | M13: =+E13-H13-I13-J13-K13-L13+G13 -> 7430
A14: LALE AYAK ÇEKYAT GEÇMELİ | E14: 0 | G14: 2000 | I14: 0 | J14: 0 | M14: =+E14-H14-I14-J14-K14-L14+G14 -> 2000
A15: TOKMAK | E15: 500 | M15: =+E15-H15-I15-J15-K15-L15+G15 -> 500
A16: SEKRETER KÖRÜK | B16: 350 | E16: 3500 | G16: 0 | M16: =+E16-H16-I16-J16-K16-L16+G16 -> 3500
A17: VEGA KÖRÜK | E17: 10000 | M17: =+E17-H17-I17-J17-K17-L17+G17 -> 10000
A18: VEGA KONFERANS KOL | E18: 300 | M18: =+E18-H18-I18-J18-K18-L18+G18 -> 300
A19: VEGA ÇAKMA KOL | E19: 400 | M19: =+E19-H19-I19-J19-K19-L19+G19 -> 400
A20: SİNEMA KAPAK KISA | E20: 500 | J20: 75 | M20: =+E20-H20-I20-J20-K20-L20+G20 -> 425

Sheet ekim 1 hafta 
A2: ÜRÜN CİNSİ | F2: devir | G2: GELEN | H2: 44837 | I2: 44838 | J2: 44839 | K2: 44840 | L2: 44841 | M2: KALAN | N2: AÇIKLAMA
A3: U BAĞLANTI DEMİRİ | E3: 10000 | G3: 0 | H3: 0 | I3: 2000 | J3: 0 | K3: 0 | L3: 0 | M3: =+E3-H3-I3-J3-K3-L3+G3 -> 8000
A4: AYAK SOMUNU(BIDIK) | E4: 27238 | G4: 0 | H4: 0 | I4: 0 | J4: 0 | K4: 0 | L4: 0 | M4: =+E4-H4-I4-J4-K4-L4+G4 -> 27238
A5: M10 OYNAR BAŞLIKLI BİNGO | E5: 153 | G5: 0 | H5: 0 | I5: 0 | J5: 0 | K5: 0 | L5: 0 | M5: =+E5-H5-I5-J5-K5-L5+G5 -> 153 | N5: PLASTİK SİY.BÜYÜK
A6: M8 CİVATALI BİNGO | E6: 1644 | G6: 0 | H6: 0 | I6: 0 | J6: 900 | K6: 0 | L6: 0 | M6: =+E6-H6-I6-J6-K6-L6+G6 -> 744 | N6: PLASTİK SİY.BÜYÜK
A7: M8 OYNAR BAŞLIKLI BİNGO | E7: 343 | G7: 0 | H7: 0 | I7: 0 | J7: 0 | K7: 0 | L7: 10 | M7: =+E7-H7-I7-J7-K7-L7+G7 -> 333 | N7: KROM
A8: M8 CİVATALI BİNGO | E8: 1556 | G8: 0 | H8: 0 | I8: 0 | J8: 0 | K8: 0 | L8: 0 | M8: =+E8-H8-I8-J8-K8-L8+G8 -> 1556 | N8: SİYAH KÜÇÜK
A9: M8 CİVATALI BİNGO_MOB. | E9: 1760 | G9: 0 | H9: 0 | I9: 0 | J9: 0 | K9: 0 | L9: 0 | M9: =+E9-H9-I9-J9-K9-L9+G9 -> 1760 | N9: REFAKATÇI SİY.KÜÇÜK
A10: M6 SOKET | E10: 163000 | G10: 0 | H10: 0 | I10: 2000 | J10: 0 | K10: 0 | L10: 0 | M10: =+E10-H10-I10-J10-K10-L10+G10 -> 161000
A11: PİMLİ TEKER NAYLON 50 | E11: 60240 | F11: 0 | G11: 0 | H11: 0 | I11: 200 | J11: 1300 | K11: 520 | L11: 1320 | M11: =+E11-H11-I11-J11-K11-L11+G11 -> 56900
A12: SİLİKON TEKER | E12: 820 | G12: 0 | H12: 0 | I12: 0 | J12: 0 | K12: 0 | L12: 0 | M12: =+E12-H12-I12-J12-K12-L12+G12 -> 820
A13: PİMLİ BİNGO | E13: 7430 | G13: 0 | H13: 0 | I13: 0 | J13: 0 | K13: 0 | L13: 0 | M13: =+E13-H13-I13-J13-K13-L13+G13 -> 7430
A14: LALE AYAK ÇEKYAT GEÇMELİ | E14: 900 | G14: 0 | H14: 0 | I14: 0 | J14: 0 | K14: 0 | L14: 0 | M14: =+E14-H14-I14-J14-K14-L14+G14 -> 900
A15: TOKMAK | E15: 500 | G15: 0 | H15: 0 | I15: 0 | J15: 0 | K15: 0 | L15: 0 | M15: =+E15-H15-I15-J15-K15-L15+G15 -> 500
A16: SEKRETER KÖRÜK | B16: 350 | E16: 3500 | G16: 0 | H16: 0 | I16: 0 | J16: 0 | K16: 0 | L16: 0 | M16: =+E16-H16-I16-J16-K16-L16+G16 -> 3500
A17: VEGA KÖRÜK | E17: 10000 | G17: 0 | H17: 0 | I17: 0 | J17: 0 | K17: 0 | L17: 0 | M17: =+E17-H17-I17-J17-K17-L17+G17 -> 10000
A18: VEGA KONFERANS KOL | E18: 300 | G18: 0 | H18: 0 | I18: 0 | J18: 0 | K18: 0 | L18: 0 | M18: =+E18-H18-I18-J18-K18-L18+G18 -> 300
A19: VEGA ÇAKMA KOL | E19: 400 | G19: 0 | H19: 0 | I19: 0 | J19: 0 | K19: 0 | L19: 0 | M19: =+E19-H19-I19-J19-K19-L19+G19 -> 400
A20: SİNEMA KAPAK KISA | E20: 425 | F20: 425 | G20: 0 | H20: 0 | I20: 0 | J20: 0 | K20: 0 | L20: 0 | M20: =+E20-H20-I20-J20-K20-L20+G20 -> 425
A21: KUYRUKLU TİLK MEKANİZMA | E21: 0 | G21: 504 | M21: =+E21-H21-I21-J21-K21-L21+G21 -> 504

Sheet ekim 2 hafta 
A2: ÜRÜN CİNSİ | F2: devir | G2: GELEN | H2: 44844 | I2: 44845 | J2: 44846 | K2: 44847 | L2: 44848 | M2: KALAN | N2: AÇIKLAMA
A3: U BAĞLANTI DEMİRİ | E3: 8000 | G3: 0 | H3: 0 | I3: 0 | J3: 0 | K3: 0 | L3: 1000 | M3: =+E3-H3-I3-J3-K3-L3+G3 -> 7000
A4: AYAK SOMUNU(BIDIK) | E4: 27238 | G4: 0 | H4: 0 | I4: 0 | J4: 0 | K4: 0 | L4: 0 | M4: =+E4-H4-I4-J4-K4-L4+G4 -> 27238
A5: M10 OYNAR BAŞLIKLI BİNGO | E5: 153 | G5: 0 | H5: 0 | I5: 0 | J5: 0 | K5: 0 | L5: 0 | M5: =+E5-H5-I5-J5-K5-L5+G5 -> 153 | N5: PLASTİK SİY.BÜYÜK
A6: M8 CİVATALI BİNGO | E6: 744 | G6: 0 | H6: 0 | I6: 0 | J6: 0 | K6: 0 | L6: 0 | M6: =+E6-H6-I6-J6-K6-L6+G6 -> 744 | N6: PLASTİK SİY.BÜYÜK
A7: M8 OYNAR BAŞLIKLI BİNGO | E7: 333 | G7: 1000 | H7: 0 | I7: 0 | J7: 0 | K7: 333 | L7: 0 | M7: =+E7-H7-I7-J7-K7-L7+G7 -> 1000 | N7: KROM
A8: M8 CİVATALI BİNGO | E8: 1556 | G8: 0 | H8: 0 | I8: 0 | J8: 0 | K8: 0 | L8: 0 | M8: =+E8-H8-I8-J8-K8-L8+G8 -> 1556 | N8: SİYAH KÜÇÜK
A9: M8 CİVATALI BİNGO_MOB. | E9: 1760 | G9: 0 | H9: 0 | I9: 0 | J9: 0 | K9: 0 | L9: 0 | M9: =+E9-H9-I9-J9-K9-L9+G9 -> 1760 | N9: REFAKATÇI SİY.KÜÇÜK
A10: M6 SOKET | E10: 161000 | G10: 0 | H10: 0 | I10: 0 | J10: 10000 | K10: 0 | L10: 10000 | M10: =+E10-H10-I10-J10-K10-L10+G10 -> 141000
A11: PİMLİ TEKER NAYLON 50 | E11: 56900 | F11: 0 | G11: 0 | H11: 1434 | I11: 780 | J11: 260 | K11: 260 | L11: 520 | M11: =+E11-H11-I11-J11-K11-L11+G11 -> 53646
A12: SİLİKON TEKER | E12: 820 | G12: 0 | H12: 0 | I12: 0 | J12: 0 | K12: 0 | L12: 0 | M12: =+E12-H12-I12-J12-K12-L12+G12 -> 820
A13: PİMLİ BİNGO | E13: 7430 | G13: 0 | H13: 0 | I13: 0 | J13: 0 | K13: 0 | L13: 0 | M13: =+E13-H13-I13-J13-K13-L13+G13 -> 7430
A14: LALE AYAK ÇEKYAT GEÇMELİ | E14: 900 | G14: 0 | H14: 0 | I14: 0 | J14: 0 | K14: 0 | L14: 0 | M14: =+E14-H14-I14-J14-K14-L14+G14 -> 900
A15: TOKMAK | E15: 500 | G15: 0 | H15: 0 | I15: 0 | J15: 0 | K15: 0 | L15: 0 | M15: =+E15-H15-I15-J15-K15-L15+G15 -> 500
A16: SEKRETER KÖRÜK | B16: 350 | E16: 3500 | G16: 0 | H16: 0 | I16: 0 | J16: 350 | K16: 0 | L16: 0 | M16: =+E16-H16-I16-J16-K16-L16+G16 -> 3150
A17: VEGA KÖRÜK | E17: 10000 | G17: 0 | H17: 0 | I17: 0 | J17: 2000 | K17: 0 | L17: 1000 | M17: =+E17-H17-I17-J17-K17-L17+G17 -> 7000
A18: VEGA KONFERANS KOL | E18: 300 | G18: 0 | H18: 0 | I18: 0 | J18: 0 | K18: 0 | L18: 0 | M18: =+E18-H18-I18-J18-K18-L18+G18 -> 300
A19: VEGA ÇAKMA KOL | E19: 400 | G19: 0 | H19: 0 | I19: 0 | J19: 0 | K19: 0 | L19: 0 | M19: =+E19-H19-I19-J19-K19-L19+G19 -> 400
A20: SİNEMA KAPAK KISA | E20: 425 | F20: 425 | G20: 0 | H20: 0 | I20: 0 | J20: 0 | K20: 0 | L20: 0 | M20: =+E20-H20-I20-J20-K20-L20+G20 -> 425
A21: KUYRUKLU TİLK MEKANİZMA | E21: 504 | G21: 0 | H21: 2 | I21: 3 | J21: 6 | K21: 6 | M21: =+E21-H21-I21-J21-K21-L21+G21 -> 487

Sheet ekim 3 hafta
A2: ÜRÜN CİNSİ | F2: devir | G2: GELEN | H2: 44851 | I2: 44852 | J2: 44853 | K2: 44854 | L2: 44855 | M2: KALAN | N2: AÇIKLAMA
A3: U BAĞLANTI DEMİRİ | E3: ='ekim 2 hafta '!M3 -> 7000 | G3: 0 | H3: 1500 | I3: 0 | J3: 0 | K3: 0 | L3: 1500 | M3: =+E3-H3-I3-J3-K3-L3+G3 -> 4000
A4: AYAK SOMUNU(BIDIK) | E4: ='ekim 2 hafta '!M4 -> 27238 | G4: 0 | H4: 5000 | I4: 0 | J4: 0 | K4: 0 | L4: 0 | M4: =+E4-H4-I4-J4-K4-L4+G4 -> 22238
A5: M10 OYNAR BAŞLIKLI BİNGO | E5: ='ekim 2 hafta '!M5 -> 153 | G5: 0 | H5: 0 | I5: 0 | J5: 0 | K5: 0 | L5: 0 | M5: =+E5-H5-I5-J5-K5-L5+G5 -> 153 | N5: PLASTİK SİY.BÜYÜK
A6: M8 CİVATALI BİNGO | E6: ='ekim 2 hafta '!M6 -> 744 | G6: 0 | H6: 0 | I6: 0 | J6: 0 | K6: 0 | L6: 0 | M6: =+E6-H6-I6-J6-K6-L6+G6 -> 744 | N6: PLASTİK SİY.BÜYÜK
A7: M8 OYNAR BAŞLIKLI BİNGO | E7: ='ekim 2 hafta '!M7 -> 1000 | G7: 0 | H7: 0 | I7: 500 | J7: 0 | K7: 0 | L7: 0 | M7: =+E7-H7-I7-J7-K7-L7+G7 -> 500 | N7: KROM
A8: M8 CİVATALI BİNGO | E8: ='ekim 2 hafta '!M8 -> 1556 | G8: 0 | H8: 500 | I8: 0 | J8: 0 | K8: 0 | L8: 0 | M8: =+E8-H8-I8-J8-K8-L8+G8 -> 1056 | N8: SİYAH KÜÇÜK
A9: M8 CİVATALI BİNGO_MOB. | E9: ='ekim 2 hafta '!M9 -> 1760 | G9: 0 | H9: 0 | I9: 0 | J9: 0 | K9: 0 | L9: 0 | M9: =+E9-H9-I9-J9-K9-L9+G9 -> 1760 | N9: REFAKATÇI SİY.KÜÇÜK
A10: M6 SOKET | E10: ='ekim 2 hafta '!M10 -> 141000 | G10: 0 | H10: 4000 | I10: 0 | J10: 0 | K10: 0 | L10: 0 | M10: =+E10-H10-I10-J10-K10-L10+G10 -> 137000
A11: PİMLİ TEKER NAYLON 50 | E11: ='ekim 2 hafta '!M11 -> 53646 | F11: 0 | G11: 0 | H11: 525 | I11: 150 | J11: 1920 | K11: 260 | L11: 0 | M11: =+E11-H11-I11-J11-K11-L11+G11 -> 50791
A12: SİLİKON TEKER | E12: ='ekim 2 hafta '!M12 -> 820 | G12: 0 | H12: 0 | I12: 0 | J12: 0 | K12: 0 | L12: 0 | M12: =+E12-H12-I12-J12-K12-L12+G12 -> 820
A13: PİMLİ BİNGO | E13: ='ekim 2 hafta '!M13 -> 7430 | G13: 0 | H13: 0 | I13: 0 | J13: 0 | K13: 0 | L13: 0 | M13: =+E13-H13-I13-J13-K13-L13+G13 -> 7430
A14: LALE AYAK ÇEKYAT GEÇMELİ | E14: ='ekim 2 hafta '!M14 -> 900 | G14: 0 | H14: 0 | I14: 0 | J14: 0 | K14: 0 | L14: 0 | M14: =+E14-H14-I14-J14-K14-L14+G14 -> 900
A15: TOKMAK | E15: 1500 | G15: 0 | H15: 0 | I15: 0 | J15: 700 | K15: 0 | L15: 0 | M15: =+E15-H15-I15-J15-K15-L15+G15 -> 800
A16: SEKRETER KÖRÜK | B16: 350 | E16: ='ekim 2 hafta '!M16 -> 3150 | G16: 0 | H16: 0 | I16: 0 | J16: 0 | K16: 0 | L16: 0 | M16: =+E16-H16-I16-J16-K16-L16+G16 -> 3150
A17: VEGA KÖRÜK | E17: ='ekim 2 hafta '!M17 -> 7000 | G17: 0 | H17: 0 | I17: 0 | J17: 0 | K17: 0 | L17: 0 | M17: =+E17-H17-I17-J17-K17-L17+G17 -> 7000
A18: VEGA KONFERANS KOL | E18: ='ekim 2 hafta '!M18 -> 300 | G18: 0 | H18: 0 | I18: 0 | J18: 0 | K18: 0 | L18: 0 | M18: =+E18-H18-I18-J18-K18-L18+G18 -> 300
A19: VEGA ÇAKMA KOL | E19: ='ekim 2 hafta '!M19 -> 400 | G19: 0 | H19: 0 | I19: 0 | J19: 0 | K19: 0 | L19: 0 | M19: =+E19-H19-I19-J19-K19-L19+G19 -> 400
A20: SİNEMA KAPAK KISA | E20: ='ekim 2 hafta '!M20 -> 425 | F20: 425 | G20: 0 | H20: 0 | I20: 0 | J20: 0 | K20: 0 | L20: 0 | M20: =+E20-H20-I20-J20-K20-L20+G20 -> 425
A21: KUYRUKLU TİLK MEKANİZMA | E21: ='ekim 2 hafta '!M21 -> 487 | G21: 0 | H21: 6 | I21: 0 | J21: 0 | K21: 0 | L21: 0 | M21: =+E21-H21-I21-J21-K21-L21+G21 -> 481
A22: AHŞAP KÖRÜK | E22: 520 | J22: 80 | M22: =+E22-H22-I22-J22-K22-L22+G22 -> 440

Sheet ekim 4 hafta 
A2: ÜRÜN CİNSİ | F2: devir | G2: GELEN | H2: 44858 | I2: 44859 | J2: 44860 | K2: 44861 | L2: 44862 | M2: KALAN | N2: AÇIKLAMA
A3: U BAĞLANTI DEMİRİ | E3: ='ekim 3 hafta'!M3 -> 4000 | G3: 0 | H3: 0 | I3: 0 | J3: 0 | K3: 0 | L3: 0 | M3: 7000
A4: AYAK SOMUNU(BIDIK) | E4: ='ekim 3 hafta'!M4 -> 22238 | G4: 0 | H4: 0 | I4: 5000 | J4: 0 | K4: 0 | L4: 0 | M4: =+E4-H4-I4-J4-K4-L4+G4 -> 17238
A5: M10 OYNAR BAŞLIKLI BİNGO | E5: ='ekim 3 hafta'!M5 -> 153 | G5: 0 | H5: 0 | I5: 0 | J5: 0 | K5: 0 | L5: 0 | M5: =+E5-H5-I5-J5-K5-L5+G5 -> 153 | N5: PLASTİK SİY.BÜYÜK
A6: M8 CİVATALI BİNGO | E6: ='ekim 3 hafta'!M6 -> 744 | G6: 0 | H6: 0 | I6: 0 | J6: 0 | K6: 0 | L6: 0 | M6: =+E6-H6-I6-J6-K6-L6+G6 -> 744 | N6: PLASTİK SİY.BÜYÜK
A7: M8 OYNAR BAŞLIKLI BİNGO | E7: ='ekim 3 hafta'!M7 -> 500 | G7: 0 | H7: 0 | I7: 0 | J7: 0 | K7: 0 | L7: 0 | M7: =+E7-H7-I7-J7-K7-L7+G7 -> 500 | N7: KROM
A8: M8 CİVATALI BİNGO | E8: ='ekim 3 hafta'!M8 -> 1056 | G8: 0 | H8: 0 | I8: 0 | J8: 0 | K8: 0 | L8: 0 | M8: =+E8-H8-I8-J8-K8-L8+G8 -> 1056 | N8: SİYAH KÜÇÜK
A9: M8 CİVATALI BİNGO_MOB. | E9: ='ekim 3 hafta'!M9 -> 1760 | G9: 0 | H9: 0 | I9: 0 | J9: 0 | K9: 0 | L9: 0 | M9: =+E9-H9-I9-J9-K9-L9+G9 -> 1760 | N9: REFAKATÇI SİY.KÜÇÜK
A10: M6 SOKET | E10: ='ekim 3 hafta'!M10 -> 137000 | G10: 0 | H10: 0 | I10: 0 | J10: 10000 | K10: 0 | L10: 0 | M10: =+E10-H10-I10-J10-K10-L10+G10 -> 127000
A11: PİMLİ TEKER NAYLON 50 | E11: ='ekim 3 hafta'!M11 -> 50791 | F11: 0 | G11: 0 | H11: 0 | I11: 260 | J11: 1180 | K11: 0 | L11: 520 | M11: =+E11-H11-I11-J11-K11-L11+G11 -> 48831
A12: SİLİKON TEKER | E12: ='ekim 3 hafta'!M12 -> 820 | G12: 0 | H12: 0 | I12: 0 | J12: 0 | K12: 0 | L12: 0 | M12: =+E12-H12-I12-J12-K12-L12+G12 -> 820
A13: PİMLİ BİNGO | E13: ='ekim 3 hafta'!M13 -> 7430 | G13: 0 | H13: 0 | I13: 300 | J13: 0 | K13: 0 | L13: 0 | M13: =+E13-H13-I13-J13-K13-L13+G13 -> 7130
A14: LALE AYAK ÇEKYAT GEÇMELİ | E14: ='ekim 3 hafta'!M14 -> 900 | G14: 0 | H14: 0 | I14: 0 | J14: 0 | K14: 0 | L14: 0 | M14: =+E14-H14-I14-J14-K14-L14+G14 -> 900
A15: TOKMAK | E15: ='ekim 3 hafta'!M15 -> 800 | G15: 0 | H15: 0 | I15: 0 | J15: 0 | K15: 0 | L15: 0 | M15: =+E15-H15-I15-J15-K15-L15+G15 -> 800
A16: SEKRETER KÖRÜK | B16: 350 | E16: ='ekim 3 hafta'!M16 -> 3150 | G16: 0 | H16: 0 | I16: 0 | J16: 0 | K16: 0 | L16: 0 | M16: =+E16-H16-I16-J16-K16-L16+G16 -> 3150
A17: VEGA KÖRÜK | E17: ='ekim 3 hafta'!M17 -> 7000 | G17: 0 | H17: 0 | I17: 0 | J17: 500 | K17: 500 | L17: 0 | M17: =+E17-H17-I17-J17-K17-L17+G17 -> 6000
A18: VEGA KONFERANS KOL | E18: ='ekim 3 hafta'!M18 -> 300 | G18: 0 | H18: 0 | I18: 0 | J18: 0 | K18: 0 | L18: 0 | M18: =+E18-H18-I18-J18-K18-L18+G18 -> 300
A19: VEGA ÇAKMA KOL | E19: ='ekim 3 hafta'!M19 -> 400 | G19: 0 | H19: 0 | I19: 0 | J19: 0 | K19: 0 | L19: 0 | M19: =+E19-H19-I19-J19-K19-L19+G19 -> 400
A20: SİNEMA KAPAK KISA | E20: ='ekim 3 hafta'!M20 -> 425 | F20: 425 | G20: 0 | H20: 0 | I20: 0 | J20: 0 | K20: 0 | L20: 0 | M20: =+E20-H20-I20-J20-K20-L20+G20 -> 425
A21: KUYRUKLU TİLK MEKANİZMA | E21: ='ekim 3 hafta'!M21 -> 481 | G21: 0 | H21: 15 | I21: 24 | J21: 6 | K21: 0 | L21: 1 | M21: =+E21-H21-I21-J21-K21-L21+G21 -> 435
A22: 5 cm krom ayarlı ayak | E22: 2100 | M22: =+E22-H22-I22-J22-K22-L22+G22 -> 2100

Sheet KASIM 1 HAFTA
A2: ÜRÜN CİNSİ | F2: devir | G2: GELEN | H2: 44865 | I2: 44866 | J2: 44867 | K2: 44868 | L2: 44869 | M2: KALAN | N2: AÇIKLAMA
A3: U BAĞLANTI DEMİRİ | E3: ='ekim 4 hafta '!M3 -> 7000 | G3: 0 | H3: 0 | I3: 0 | J3: 0 | K3: 1000 | L3: 0 | M3: 7000
A4: AYAK SOMUNU(BIDIK) | E4: ='ekim 4 hafta '!M4 -> 17238 | G4: 0 | H4: 0 | I4: 0 | J4: 0 | K4: 0 | L4: 0 | M4: =+E4-H4-I4-J4-K4-L4+G4 -> 17238
A5: M10 OYNAR BAŞLIKLI BİNGO | E5: ='ekim 4 hafta '!M5 -> 153 | G5: 0 | H5: 0 | I5: 0 | J5: 0 | K5: 0 | L5: 0 | M5: =+E5-H5-I5-J5-K5-L5+G5 -> 153 | N5: PLASTİK SİY.BÜYÜK
A6: M8 CİVATALI BİNGO | E6: ='ekim 4 hafta '!M6 -> 744 | G6: 0 | H6: 0 | I6: 0 | J6: 0 | K6: 0 | L6: 0 | M6: =+E6-H6-I6-J6-K6-L6+G6 -> 744 | N6: PLASTİK SİY.BÜYÜK
A7: M8 OYNAR BAŞLIKLI BİNGO | E7: ='ekim 4 hafta '!M7 -> 500 | G7: 0 | H7: 0 | I7: 0 | J7: 0 | K7: 0 | L7: 0 | M7: =+E7-H7-I7-J7-K7-L7+G7 -> 500 | N7: KROM
A8: M8 CİVATALI BİNGO | E8: ='ekim 4 hafta '!M8 -> 1056 | G8: 0 | H8: 0 | I8: 0 | J8: 0 | K8: 0 | L8: 0 | M8: =+E8-H8-I8-J8-K8-L8+G8 -> 1056 | N8: SİYAH KÜÇÜK
A9: M8 CİVATALI BİNGO_MOB. | E9: ='ekim 4 hafta '!M9 -> 1760 | G9: 0 | H9: 0 | I9: 0 | J9: 0 | K9: 0 | L9: 0 | M9: =+E9-H9-I9-J9-K9-L9+G9 -> 1760 | N9: REFAKATÇI SİY.KÜÇÜK
A10: M6 SOKET | E10: ='ekim 4 hafta '!M10 -> 127000 | G10: 0 | H10: 0 | I10: 0 | J10: 0 | K10: 0 | L10: 0 | M10: =+E10-H10-I10-J10-K10-L10+G10 -> 127000
A11: PİMLİ TEKER NAYLON 50 | E11: ='ekim 4 hafta '!M11 -> 48831 | F11: 0 | G11: 0 | H11: 500 | I11: 0 | J11: 500 | K11: 0 | L11: 0 | M11: =+E11-H11-I11-J11-K11-L11+G11 -> 47831
A12: SİLİKON TEKER | E12: ='ekim 4 hafta '!M12 -> 820 | G12: 0 | H12: 0 | I12: 0 | J12: 0 | K12: 0 | L12: 0 | M12: =+E12-H12-I12-J12-K12-L12+G12 -> 820
A13: PİMLİ BİNGO | E13: ='ekim 4 hafta '!M13 -> 7130 | G13: 0 | H13: 0 | I13: 0 | J13: 0 | K13: 0 | L13: 0 | M13: =+E13-H13-I13-J13-K13-L13+G13 -> 7130
A14: LALE AYAK ÇEKYAT GEÇMELİ | E14: ='ekim 4 hafta '!M14 -> 900 | G14: 0 | H14: 0 | I14: 0 | J14: 0 | K14: 0 | L14: 0 | M14: =+E14-H14-I14-J14-K14-L14+G14 -> 900
A15: TOKMAK | E15: ='ekim 4 hafta '!M15 -> 800 | G15: 0 | H15: 0 | I15: 0 | J15: 0 | K15: 0 | L15: 0 | M15: =+E15-H15-I15-J15-K15-L15+G15 -> 800
A16: SEKRETER KÖRÜK | B16: 350 | E16: ='ekim 4 hafta '!M16 -> 3150 | G16: 0 | H16: 0 | I16: 0 | J16: 0 | K16: 0 | L16: 0 | M16: =+E16-H16-I16-J16-K16-L16+G16 -> 3150
A17: VEGA KÖRÜK | E17: ='ekim 4 hafta '!M17 -> 6000 | G17: 0 | H17: 0 | I17: 0 | J17: 0 | K17: 0 | L17: 0 | M17: =+E17-H17-I17-J17-K17-L17+G17 -> 6000
A18: VEGA KONFERANS KOL | E18: ='ekim 4 hafta '!M18 -> 300 | G18: 0 | H18: 0 | I18: 0 | J18: 0 | K18: 0 | L18: 0 | M18: =+E18-H18-I18-J18-K18-L18+G18 -> 300
A19: VEGA ÇAKMA KOL | E19: ='ekim 4 hafta '!M19 -> 400 | G19: 0 | H19: 0 | I19: 0 | J19: 0 | K19: 0 | L19: 0 | M19: =+E19-H19-I19-J19-K19-L19+G19 -> 400
A20: SİNEMA KAPAK KISA | E20: ='ekim 4 hafta '!M20 -> 425 | F20: 425 | G20: 0 | H20: 0 | I20: 0 | J20: 0 | K20: 0 | L20: 0 | M20: =+E20-H20-I20-J20-K20-L20+G20 -> 425
A21: KUYRUKLU TİLK MEKANİZMA | E21: ='ekim 4 hafta '!M21 -> 435 | G21: 0 | H21: 0 | I21: 0 | J21: 0 | K21: 0 | L21: 0 | M21: =+E21-H21-I21-J21-K21-L21+G21 -> 435
A22: 5 cm krom ayarlı ayak | E22: ='ekim 4 hafta '!M22 -> 2100 | G22: 0 | H22: 0 | I22: 0 | J22: 0 | K22: 0 | L22: 0 | M22: =+E22-H22-I22-J22-K22-L22+G22 -> 2100

Sheet KASIM 2 HAFTA 
A2: S.NO | B2: ÜRÜN CİNSİ | G2: devir | H2: GELEN | I2: 44872 | J2: 44873 | K2: 44874 | L2: 44875 | M2: 44876 | N2: KALAN | O2: AÇIKLAMA | P2: MİNİMUN | Q2: MAKSİMUN
A3: 1 | B3: U BAĞLANTI DEMİRİ | F3: ='KASIM 1 HAFTA'!M3 -> 7000 | H3: 15000 | I3: 2000 | J3: 0 | K3: 0 | L3: 0 | M3: 0 | N3: =+F3-I3-J3-K3-L3-M3+H3 -> 20000 | P3: 1000 | Q3: 10000
A4: 2 | B4: AYAK SOMUNU(BIDIK) | F4: ='KASIM 1 HAFTA'!M4 -> 17238 | H4: 0 | I4: 2000 | J4: 0 | K4: 0 | L4: 0 | M4: 0 | N4: =+F4-I4-J4-K4-L4-M4+H4 -> 15238 | P4: 5000 | Q4: 20000
A5: 3 | B5: M10 OYNAR BAŞLIKLI BİNGO | F5: ='KASIM 1 HAFTA'!M5 -> 153 | H5: 0 | I5: 0 | J5: 0 | K5: 0 | L5: 0 | M5: 0 | N5: =+F5-I5-J5-K5-L5-M5+H5 -> 153 | O5: PLASTİK SİY.BÜYÜK | P5: 300 | Q5: 1000
A6: 4 | B6: M8 CİVATALI BİNGO | F6: ='KASIM 1 HAFTA'!M6 -> 744 | H6: 0 | I6: 0 | J6: 0 | K6: 0 | L6: 0 | M6: 0 | N6: =+F6-I6-J6-K6-L6-M6+H6 -> 744 | O6: PLASTİK SİY.BÜYÜK | P6: 0
A7: 5 | B7: M8 OYNAR BAŞLIKLI BİNGO | F7: ='KASIM 1 HAFTA'!M7 -> 500 | H7: 0 | I7: 0 | J7: 0 | K7: 0 | L7: 0 | M7: 0 | N7: =+F7-I7-J7-K7-L7-M7+H7 -> 500 | O7: KROM | P7: 300 | Q7: 1000
A8: 6 | B8: M8 CİVATALI BİNGO | F8: ='KASIM 1 HAFTA'!M8 -> 1056 | H8: 0 | I8: 0 | J8: 0 | K8: 0 | L8: 0 | M8: 0 | N8: =+F8-I8-J8-K8-L8-M8+H8 -> 1056 | O8: SİYAH KÜÇÜK | P8: 200 | Q8: 500
A9: 7 | B9: M8 CİVATALI BİNGO_MOB. | F9: ='KASIM 1 HAFTA'!M9 -> 1760 | H9: 0 | I9: 0 | J9: 1000 | K9: 0 | L9: 0 | M9: 0 | N9: =+F9-I9-J9-K9-L9-M9+H9 -> 760 | O9: REFAKATÇI SİY.KÜÇÜK | P9: 200 | Q9: 500
A10: 8 | B10: M6 SOKET | F10: 27000 | H10: 0 | I10: 0 | J10: 0 | K10: 0 | L10: 0 | M10: 5000 | N10: =+F10-I10-J10-K10-L10-M10+H10 -> 22000 | P10: 10000 | Q10: 50000
A11: 9 | B11: PİMLİ TEKER NAYLON 50 | F11: ='KASIM 1 HAFTA'!M11 -> 47831 | G11: 0 | H11: 0 | I11: 780 | J11: 400 | K11: 100 | L11: 0 | M11: 400 | N11: =+F11-I11-J11-K11-L11-M11+H11 -> 46151 | P11: 5000 | Q11: 30000
A12: 10 | B12: SİLİKON TEKER | F12: ='KASIM 1 HAFTA'!M12 -> 820 | H12: 0 | I12: 0 | J12: 0 | K12: 0 | L12: 0 | M12: 0 | N12: =+F12-I12-J12-K12-L12-M12+H12 -> 820 | P12: 0
A13: 11 | B13: PİMLİ BİNGO | F13: ='KASIM 1 HAFTA'!M13 -> 7130 | H13: 0 | I13: 0 | J13: 0 | K13: 55 | L13: 0 | M13: 0 | N13: =+F13-I13-J13-K13-L13-M13+H13 -> 7075 | P13: 1000 | Q13: 5000
A14: 12 | B14: LALE AYAK ÇEKYAT GEÇMELİ | F14: ='KASIM 1 HAFTA'!M14 -> 900 | H14: 0 | I14: 0 | J14: 0 | K14: 0 | L14: 0 | M14: 0 | N14: =+F14-I14-J14-K14-L14-M14+H14 -> 900 | P14: 250 | Q14: 1000
A15: 13 | B15: TOKMAK | F15: ='KASIM 1 HAFTA'!M15 -> 800 | H15: 0 | I15: 0 | J15: 0 | K15: 0 | L15: 0 | M15: 0 | N15: =+F15-I15-J15-K15-L15-M15+H15 -> 800 | P15: 250 | Q15: 500
A16: 14 | B16: SEKRETER KÖRÜK | C16: 350 | F16: ='KASIM 1 HAFTA'!M16 -> 3150 | H16: 0 | I16: 0 | J16: 0 | K16: 0 | L16: 0 | M16: 0 | N16: =+F16-I16-J16-K16-L16-M16+H16 -> 3150 | P16: 500 | Q16: 2000
A17: 15 | B17: AHŞAP TELESKOP KÖRÜK | F17: 300 | I17: 50 | N17: =+F17-I17-J17-K17-L17-M17+H17 -> 250 | P17: 100 | Q17: 500
A18: 16 | B18: VEGA KÖRÜK | F18: ='KASIM 1 HAFTA'!M17 -> 6000 | H18: 0 | I18: 0 | J18: 0 | K18: 0 | L18: 0 | M18: 0 | N18: =+F18-I18-J18-K18-L18-M18+H18 -> 6000 | P18: 1000 | Q18: 5000
A19: 17 | B19: VEGA KONFERANS KOL | F19: ='KASIM 1 HAFTA'!M18 -> 300 | H19: 0 | I19: 0 | J19: 0 | K19: 0 | L19: 0 | M19: 0 | N19: =+F19-I19-J19-K19-L19-M19+H19 -> 300 | P19: 100 | Q19: 300
A20: 18 | B20: VEGA ÇAKMA KOL | F20: ='KASIM 1 HAFTA'!M19 -> 400 | H20: 0 | I20: 0 | J20: 0 | K20: 0 | L20: 0 | M20: 0 | N20: =+F20-I20-J20-K20-L20-M20+H20 -> 400 | P20: 100 | Q20: 300
A21: 19 | B21: SİNEMA KAPAK KISA | F21: ='KASIM 1 HAFTA'!M20 -> 425 | G21: 425 | H21: 0 | I21: 0 | J21: 0 | K21: 0 | L21: 0 | M21: 85 | N21: =+F21-I21-J21-K21-L21-M21+H21 -> 340 | P21: 200 | Q21: 500
A22: 20 | B22: KUYRUKLU TİLK MEKANİZMA | F22: ='KASIM 1 HAFTA'!M21 -> 435 | H22: 0 | I22: 0 | J22: 0 | K22: 0 | L22: 6 | M22: 2 | N22: =+F22-I22-J22-K22-L22-M22+H22 -> 427 | P22: 100 | Q22: 300
A23: 21 | B23: 5 cm krom ayarlı ayak | F23: ='KASIM 1 HAFTA'!M22 -> 2100 | H23: 0 | I23: 0 | J23: 100 | K23: 600 | L23: 0 | M23: 0 | N23: =+F23-I23-J23-K23-L23-M23+H23 -> 1400 | P23: 100 | Q23: 500

Sheet KASIM 3 HAFTA 
A2: S.NO | B2: ÜRÜN CİNSİ | F2: DEVİR | G2: devir | H2: GELEN | I2: 44879 | J2: 44880 | K2: 44881 | L2: 44882 | M2: 44883 | N2: KALAN | O2: AÇIKLAMA | P2: MİNİMUN | Q2: MAKSİMUN
A3: 1 | B3: U BAĞLANTI DEMİRİ | F3: ='KASIM 2 HAFTA '!N3 -> 20000 | H3: 15000 | I3: 0 | J3: 500 | K3: 0 | L3: 0 | M3: 0 | N3: =+F3-I3-J3-K3-L3-M3+H3 -> 34500 | P3: 1000 | Q3: 10000
A4: 2 | B4: AYAK SOMUNU(BIDIK) | F4: ='KASIM 2 HAFTA '!N4 -> 15238 | H4: 0 | I4: 0 | J4: 0 | K4: 0 | L4: 0 | M4: 0 | N4: =+F4-I4-J4-K4-L4-M4+H4 -> 15238 | P4: 5000 | Q4: 20000
A5: 3 | B5: M10 OYNAR BAŞLIKLI BİNGO | F5: ='KASIM 2 HAFTA '!N5 -> 153 | H5: 0 | I5: 0 | J5: 0 | K5: 0 | L5: 0 | M5: 0 | N5: =+F5-I5-J5-K5-L5-M5+H5 -> 153 | O5: PLASTİK SİY.BÜYÜK | P5: 300 | Q5: 1000
A6: 4 | B6: M8 CİVATALI BİNGO | F6: ='KASIM 2 HAFTA '!N6 -> 744 | H6: 0 | I6: 0 | J6: 0 | K6: 0 | L6: 0 | M6: 0 | N6: =+F6-I6-J6-K6-L6-M6+H6 -> 744 | O6: PLASTİK SİY.BÜYÜK | P6: 0
A7: 5 | B7: M8 OYNAR BAŞLIKLI BİNGO | F7: ='KASIM 2 HAFTA '!N7 -> 500 | H7: 0 | I7: 0 | J7: 0 | K7: 0 | L7: 0 | M7: 0 | N7: =+F7-I7-J7-K7-L7-M7+H7 -> 500 | O7: KROM | P7: 300 | Q7: 1000
A8: 6 | B8: M8 CİVATALI BİNGO | F8: ='KASIM 2 HAFTA '!N8 -> 1056 | H8: 0 | I8: 0 | J8: 0 | K8: 520 | L8: 250 | M8: 0 | N8: =+F8-I8-J8-K8-L8-M8+H8 -> 286 | O8: SİYAH KÜÇÜK | P8: 200 | Q8: 500
A9: 7 | B9: M8 CİVATALI BİNGO_MOB. | F9: ='KASIM 2 HAFTA '!N9 -> 760 | H9: 0 | I9: 0 | J9: 0 | K9: 0 | L9: 0 | M9: 0 | N9: =+F9-I9-J9-K9-L9-M9+H9 -> 760 | O9: REFAKATÇI SİY.KÜÇÜK | P9: 200 | Q9: 500
A10: 8 | B10: M6 SOKET | F10: ='KASIM 2 HAFTA '!N10 -> 22000 | H10: 0 | I10: 0 | J10: 0 | K10: 0 | L10: 0 | M10: 0 | N10: =+F10-I10-J10-K10-L10-M10+H10 -> 22000 | P10: 10000 | Q10: 50000
A11: 9 | B11: PİMLİ TEKER NAYLON 50 | F11: ='KASIM 2 HAFTA '!N11 -> 46151 | G11: 0 | H11: 0 | I11: 100 | J11: 400 | K11: 0 | L11: 260 | M11: 260 | N11: =+F11-I11-J11-K11-L11-M11+H11 -> 45131 | P11: 5000 | Q11: 30000
A12: 10 | B12: SİLİKON TEKER | F12: ='KASIM 2 HAFTA '!N12 -> 820 | H12: 0 | I12: 0 | J12: 0 | K12: 0 | L12: 0 | M12: 0 | N12: =+F12-I12-J12-K12-L12-M12+H12 -> 820 | P12: 0
A13: 11 | B13: PİMLİ BİNGO | F13: ='KASIM 2 HAFTA '!N13 -> 7075 | H13: 0 | I13: 0 | J13: 0 | K13: 0 | L13: 0 | M13: 0 | N13: =+F13-I13-J13-K13-L13-M13+H13 -> 7075 | P13: 1000 | Q13: 5000
A14: 12 | B14: LALE AYAK ÇEKYAT GEÇMELİ | F14: ='KASIM 2 HAFTA '!N14 -> 900 | H14: 0 | I14: 0 | J14: 0 | K14: 0 | L14: 0 | M14: 0 | N14: =+F14-I14-J14-K14-L14-M14+H14 -> 900 | P14: 250 | Q14: 1000
A15: 13 | B15: TOKMAK | F15: ='KASIM 2 HAFTA '!N15 -> 800 | H15: 0 | I15: 0 | J15: 0 | K15: 0 | L15: 0 | M15: 0 | N15: =+F15-I15-J15-K15-L15-M15+H15 -> 800 | P15: 250 | Q15: 500
A16: 14 | B16: SEKRETER KÖRÜK | C16: 350 | F16: ='KASIM 2 HAFTA '!N16 -> 3150 | H16: 0 | I16: 0 | J16: 0 | K16: 0 | L16: 0 | M16: 0 | N16: =+F16-I16-J16-K16-L16-M16+H16 -> 3150 | P16: 500 | Q16: 2000
A17: 15 | B17: AHŞAP TELESKOP KÖRÜK | F17: ='KASIM 2 HAFTA '!N17 -> 250 | H17: 220 | J17: 250 | N17: =+F17-I17-J17-K17-L17-M17+H17 -> 220 | P17: 100 | Q17: 500
A18: 16 | B18: VEGA KÖRÜK | F18: ='KASIM 2 HAFTA '!N18 -> 6000 | H18: 0 | I18: 0 | J18: 0 | K18: 0 | L18: 0 | M18: 500 | N18: =+F18-I18-J18-K18-L18-M18+H18 -> 5500 | P18: 1000 | Q18: 5000
A19: 17 | B19: VEGA KONFERANS KOL tablalı | F19: 200 | H19: 0 | I19: 0 | J19: 0 | K19: 72 | L19: 40 | M19: 0 | N19: =+F19-I19-J19-K19-L19-M19+H19 -> 88 | P19: 100 | Q19: 300
A20: 18 | B20: VEGA ÇAKMA KOL | F20: ='KASIM 2 HAFTA '!N20 -> 400 | H20: 0 | I20: 0 | J20: 0 | K20: 0 | L20: 0 | M20: 0 | N20: =+F20-I20-J20-K20-L20-M20+H20 -> 400 | P20: 100 | Q20: 300
A21: 19 | B21: SİNEMA KAPAK KISA | F21: ='KASIM 2 HAFTA '!N21 -> 340 | G21: 425 | H21: 0 | I21: 0 | J21: 0 | K21: 0 | L21: 0 | M21: 0 | N21: =+F21-I21-J21-K21-L21-M21+H21 -> 340 | P21: 200 | Q21: 500
A22: 20 | B22: KUYRUKLU TİLK MEKANİZMA | F22: ='KASIM 2 HAFTA '!N22 -> 427 | H22: 0 | I22: 0 | J22: 0 | K22: 6 | L22: 102 | M22: 0 | N22: =+F22-I22-J22-K22-L22-M22+H22 -> 319 | P22: 100 | Q22: 300
A23: 21 | B23: 5 cm krom ayarlı ayak | F23: ='KASIM 2 HAFTA '!N23 -> 1400 | H23: 300 | I23: 0 | J23: 900 | K23: 0 | L23: 0 | M23: 0 | N23: =+F23-I23-J23-K23-L23-M23+H23 -> 800 | P23: 100 | Q23: 500
E24: ='KASIM 2 HAFTA '!N24 -> 0

Sheet KASIM 4 HAFTA 
A2: S.NO | B2: ÜRÜN CİNSİ | F2: ADET | G2: devir | H2: GELEN | I2: 44886 | J2: 44887 | K2: 44888 | L2: 44889 | M2: 44890 | N2: KALAN | O2: AÇIKLAMA | P2: MİNİMUN | Q2: MAKSİMUN
A3: 1 | B3: U BAĞLANTI DEMİRİ | F3: ='KASIM 3 HAFTA '!N3 -> 34500 | H3: 0 | I3: 0 | J3: 0 | K3: 0 | L3: 0 | M3: 0 | N3: =+F3-I3-J3-K3-L3-M3+H3 -> 34500 | P3: 1000 | Q3: 10000
A4: 2 | B4: AYAK SOMUNU(BIDIK) | F4: ='KASIM 3 HAFTA '!N4 -> 15238 | H4: 0 | I4: 0 | J4: 0 | K4: 0 | L4: 0 | M4: 0 | N4: =+F4-I4-J4-K4-L4-M4+H4 -> 15238 | P4: 5000 | Q4: 20000
A5: 3 | B5: M10 OYNAR BAŞLIKLI BİNGO | F5: ='KASIM 3 HAFTA '!N5 -> 153 | H5: 0 | I5: 0 | J5: 0 | K5: 0 | L5: 0 | M5: 0 | N5: =+F5-I5-J5-K5-L5-M5+H5 -> 153 | O5: PLASTİK SİY.BÜYÜK | P5: 300 | Q5: 1000
A6: 4 | B6: M8 CİVATALI BİNGO | F6: ='KASIM 3 HAFTA '!N6 -> 744 | H6: 0 | I6: 0 | J6: 0 | K6: 0 | L6: 500 | M6: 0 | N6: =+F6-I6-J6-K6-L6-M6+H6 -> 244 | O6: PLASTİK SİY.BÜYÜK | P6: 0
A7: 5 | B7: M8 OYNAR BAŞLIKLI BİNGO | F7: ='KASIM 3 HAFTA '!N7 -> 500 | H7: 0 | I7: 0 | J7: 0 | K7: 0 | L7: 0 | M7: 0 | N7: =+F7-I7-J7-K7-L7-M7+H7 -> 500 | O7: KROM | P7: 300 | Q7: 1000
A8: 6 | B8: M8 CİVATALI BİNGO | F8: ='KASIM 3 HAFTA '!N8 -> 286 | H8: 0 | I8: 0 | J8: 0 | K8: 0 | L8: 0 | M8: 0 | N8: =+F8-I8-J8-K8-L8-M8+H8 -> 286 | O8: SİYAH KÜÇÜK | P8: 200 | Q8: 500
A9: 7 | B9: M8 CİVATALI BİNGO_MOB. | F9: ='KASIM 3 HAFTA '!N9 -> 760 | H9: 0 | I9: 0 | J9: 0 | K9: 0 | L9: 0 | M9: 0 | N9: =+F9-I9-J9-K9-L9-M9+H9 -> 760 | O9: REFAKATÇI SİY.KÜÇÜK | P9: 200 | Q9: 500
A10: 8 | B10: M6 SOKET | F10: ='KASIM 3 HAFTA '!N10 -> 22000 | H10: 0 | I10: 0 | J10: 0 | K10: 0 | L10: 5000 | M10: 5000 | N10: =+F10-I10-J10-K10-L10-M10+H10 -> 12000 | P10: 10000 | Q10: 50000
A11: 9 | B11: PİMLİ TEKER NAYLON 50 | F11: ='KASIM 3 HAFTA '!N11 -> 45131 | G11: 0 | H11: 0 | I11: 0 | J11: 1040 | K11: 100 | L11: 200 | M11: 1020 | N11: =+F11-I11-J11-K11-L11-M11+H11 -> 42771 | P11: 5000 | Q11: 30000
A12: 10 | B12: SİLİKON TEKER | F12: ='KASIM 3 HAFTA '!N12 -> 820 | H12: 0 | I12: 0 | J12: 0 | K12: 0 | L12: 0 | M12: 0 | N12: =+F12-I12-J12-K12-L12-M12+H12 -> 820 | P12: 0
A13: 11 | B13: PİMLİ BİNGO | F13: ='KASIM 3 HAFTA '!N13 -> 7075 | H13: 0 | I13: 0 | J13: 0 | K13: 0 | L13: 0 | M13: 0 | N13: =+F13-I13-J13-K13-L13-M13+H13 -> 7075 | P13: 1000 | Q13: 5000
A14: 12 | B14: LALE AYAK ÇEKYAT GEÇMELİ | F14: 1000 | H14: 2000 | I14: 0 | J14: 0 | K14: 500 | L14: 0 | M14: 0 | N14: =+F14-I14-J14-K14-L14-M14+H14 -> 2500 | P14: 250 | Q14: 1000
A15: 13 | B15: TOKMAK | F15: ='KASIM 3 HAFTA '!N15 -> 800 | H15: 0 | I15: 0 | J15: 0 | K15: 0 | L15: 0 | M15: 0 | N15: =+F15-I15-J15-K15-L15-M15+H15 -> 800 | P15: 250 | Q15: 500
A16: 14 | B16: SEKRETER KÖRÜK | C16: 350 | F16: ='KASIM 3 HAFTA '!N16 -> 3150 | H16: 0 | I16: 0 | J16: 0 | K16: 0 | L16: 0 | M16: 0 | N16: =+F16-I16-J16-K16-L16-M16+H16 -> 3150 | P16: 500 | Q16: 2000
A17: 15 | B17: AHŞAP TELESKOP KÖRÜK | F17: ='KASIM 3 HAFTA '!N17 -> 220 | G17: 0 | H17: 280 | J17: 0 | N17: =+F17-I17-J17-K17-L17-M17+H17 -> 500 | P17: 100 | Q17: 500
A18: 16 | B18: VEGA KÖRÜK | F18: ='KASIM 3 HAFTA '!N18 -> 5500 | H18: 0 | I18: 0 | J18: 0 | K18: 0 | L18: 0 | M18: 0 | N18: =+F18-I18-J18-K18-L18-M18+H18 -> 5500 | P18: 1000 | Q18: 5000
A19: 17 | B19: VEGA KONFERANS KOL | F19: ='KASIM 3 HAFTA '!N19 -> 88 | H19: 0 | I19: 0 | J19: 0 | K19: 0 | L19: 0 | M19: 0 | N19: =+F19-I19-J19-K19-L19-M19+H19 -> 88 | P19: 100 | Q19: 300
A20: 18 | B20: VEGA ÇAKMA KOL | F20: ='KASIM 3 HAFTA '!N20 -> 400 | H20: 0 | I20: 0 | J20: 0 | K20: 0 | L20: 0 | M20: 0 | N20: =+F20-I20-J20-K20-L20-M20+H20 -> 400 | P20: 100 | Q20: 300
A21: 19 | B21: SİNEMA KAPAK KISA | F21: ='KASIM 3 HAFTA '!N21 -> 340 | G21: 425 | H21: 0 | I21: 0 | J21: 0 | K21: 0 | L21: 0 | M21: 74 | N21: =+F21-I21-J21-K21-L21-M21+H21 -> 266 | P21: 200 | Q21: 500
A22: 20 | B22: KUYRUKLU TİLK MEKANİZMA | F22: ='KASIM 3 HAFTA '!N22 -> 319 | H22: 0 | I22: 0 | J22: 6 | K22: 0 | L22: 3 | M22: 0 | N22: =+F22-I22-J22-K22-L22-M22+H22 -> 310 | P22: 100 | Q22: 300
A23: 21 | B23: 5 cm krom ayarlı ayak | F23: 800 | H23: 0 | I23: 0 | J23: 0 | K23: 50 | L23: 0 | M23: 0 | N23: =+F23-I23-J23-K23-L23-M23+H23 -> 750 | P23: 100 | Q23: 500
A24: 22 | B24: 28 MM İÇ TAKOZ | H24: 5000 | N24: =+F24-I24-J24-K24-L24-M24+H24 -> 5000
A25: 23 | B25: 19 MM İÇ TAKOZ | H25: 5000 | N25: =+F25-I25-J25-K25-L25-M25+H25 -> 5000

Sheet KASIM 5 HAFTA  
A2: S.NO | B2: ÜRÜN CİNSİ | F2: ADET | G2: devir | H2: GELEN | I2: 44893 | J2: 44894 | K2: 44895 | L2: 44896 | M2: 44897 | N2: KALAN | O2: AÇIKLAMA | P2: MİNİMUN | Q2: MAKSİMUN
A3: 1 | B3: U BAĞLANTI DEMİRİ | F3: ='KASIM 3 HAFTA '!N3 -> 34500 | H3: 0 | I3: 500 | J3: 0 | K3: 0 | L3: 0 | M3: 0 | N3: =+F3-I3-J3-K3-L3-M3+H3 -> 34000 | P3: 1000 | Q3: 10000
A4: 2 | B4: AYAK SOMUNU(BIDIK) | F4: ='KASIM 3 HAFTA '!N4 -> 15238 | H4: 0 | I4: 0 | J4: 0 | K4: 0 | L4: 0 | M4: 0 | N4: =+F4-I4-J4-K4-L4-M4+H4 -> 15238 | P4: 5000 | Q4: 20000
A5: 3 | B5: M10 OYNAR BAŞLIKLI BİNGO | F5: ='KASIM 3 HAFTA '!N5 -> 153 | H5: 0 | I5: 0 | J5: 0 | K5: 0 | L5: 0 | M5: 0 | N5: =+F5-I5-J5-K5-L5-M5+H5 -> 153 | O5: PLASTİK SİY.BÜYÜK | P5: 300 | Q5: 1000
A6: 4 | B6: M8 CİVATALI BİNGO | F6: 244 | H6: 0 | I6: 0 | J6: 0 | K6: 0 | L6: 0 | M6: 0 | N6: =+F6-I6-J6-K6-L6-M6+H6 -> 244 | O6: PLASTİK SİY.BÜYÜK | P6: 0
A7: 5 | B7: M8 OYNAR BAŞLIKLI BİNGO | F7: ='KASIM 3 HAFTA '!N7 -> 500 | H7: 0 | I7: 0 | J7: 0 | K7: 0 | L7: 0 | M7: 0 | N7: =+F7-I7-J7-K7-L7-M7+H7 -> 500 | O7: KROM | P7: 300 | Q7: 1000
A8: 6 | B8: M8 CİVATALI BİNGO | F8: ='KASIM 3 HAFTA '!N8 -> 286 | H8: 0 | I8: 0 | J8: 0 | K8: 0 | L8: 0 | M8: 0 | N8: =+F8-I8-J8-K8-L8-M8+H8 -> 286 | O8: SİYAH KÜÇÜK | P8: 200 | Q8: 500
A9: 7 | B9: M8 CİVATALI BİNGO_MOB. | F9: ='KASIM 3 HAFTA '!N9 -> 760 | H9: 0 | I9: 0 | J9: 0 | K9: 0 | L9: 0 | M9: 0 | N9: =+F9-I9-J9-K9-L9-M9+H9 -> 760 | O9: REFAKATÇI SİY.KÜÇÜK | P9: 200 | Q9: 500
A10: 8 | B10: M6 SOKET | F10: 12000 | H10: 10000 | I10: 0 | J10: 0 | K10: 0 | L10: 0 | M10: 0 | N10: =+F10-I10-J10-K10-L10-M10+H10 -> 22000 | P10: 10000 | Q10: 50000
A11: 9 | B11: PİMLİ TEKER NAYLON 50 | F11: 42771 | G11: 0 | H11: 0 | I11: 50 | J11: 200 | K11: 2160 | L11: 0 | M11: 400 | N11: =+F11-I11-J11-K11-L11-M11+H11 -> 39961 | P11: 5000 | Q11: 30000
A12: 10 | B12: SİLİKON TEKER | F12: ='KASIM 3 HAFTA '!N12 -> 820 | H12: 0 | I12: 0 | J12: 0 | K12: 0 | L12: 0 | M12: 0 | N12: =+F12-I12-J12-K12-L12-M12+H12 -> 820 | P12: 0
A13: 11 | B13: PİMLİ BİNGO | F13: ='KASIM 3 HAFTA '!N13 -> 7075 | H13: 0 | I13: 0 | J13: 0 | K13: 0 | L13: 500 | M13: 0 | N13: =+F13-I13-J13-K13-L13-M13+H13 -> 6575 | P13: 1000 | Q13: 5000
A14: 12 | B14: LALE AYAK ÇEKYAT GEÇMELİ | F14: 2500 | H14: 0 | I14: 0 | J14: 1296 | K14: 500 | L14: 0 | M14: 0 | N14: =+F14-I14-J14-K14-L14-M14+H14 -> 704 | P14: 250 | Q14: 1000
A15: 13 | B15: TOKMAK | F15: ='KASIM 3 HAFTA '!N15 -> 800 | H15: 0 | I15: 0 | J15: 0 | K15: 0 | L15: 0 | M15: 0 | N15: =+F15-I15-J15-K15-L15-M15+H15 -> 800 | P15: 250 | Q15: 500
A16: 14 | B16: SEKRETER KÖRÜK | C16: 350 | F16: ='KASIM 3 HAFTA '!N16 -> 3150 | H16: 0 | I16: 0 | J16: 0 | K16: 0 | L16: 0 | M16: 0 | N16: =+F16-I16-J16-K16-L16-M16+H16 -> 3150 | P16: 500 | Q16: 2000
A17: 15 | B17: AHŞAP TELESKOP KÖRÜK | F17: 500 | G17: 0 | H17: 0 | I17: 0 | J17: 0 | K17: 0 | L17: 0 | M17: 0 | N17: =+F17-I17-J17-K17-L17-M17+H17 -> 500 | P17: 100 | Q17: 500
A18: 16 | B18: VEGA KÖRÜK | F18: ='KASIM 3 HAFTA '!N18 -> 5500 | H18: 0 | I18: 500 | J18: 0 | K18: 0 | L18: 0 | M18: 0 | N18: =+F18-I18-J18-K18-L18-M18+H18 -> 5000 | P18: 1000 | Q18: 5000
A19: 17 | B19: VEGA KONFERANS KOL | F19: ='KASIM 3 HAFTA '!N19 -> 88 | H19: 0 | I19: 0 | J19: 0 | K19: 0 | L19: 0 | M19: 0 | N19: =+F19-I19-J19-K19-L19-M19+H19 -> 88 | P19: 100 | Q19: 300
A20: 18 | B20: VEGA ÇAKMA KOL | F20: ='KASIM 3 HAFTA '!N20 -> 400 | H20: 0 | I20: 0 | J20: 0 | K20: 0 | L20: 0 | M20: 0 | N20: =+F20-I20-J20-K20-L20-M20+H20 -> 400 | P20: 100 | Q20: 300
A21: 19 | B21: SİNEMA KAPAK KISA | F21: 266 | G21: 425 | H21: 0 | I21: 0 | J21: 0 | K21: 0 | L21: 0 | M21: 0 | N21: =+F21-I21-J21-K21-L21-M21+H21 -> 266 | P21: 200 | Q21: 500
A22: 20 | B22: KUYRUKLU TİLK MEKANİZMA | F22: 310 | H22: 0 | I22: 8 | J22: 12 | K22: 0 | L22: 12 | M22: 24 | N22: =+F22-I22-J22-K22-L22-M22+H22 -> 254 | P22: 100 | Q22: 300
A23: 21 | B23: 5 cm krom ayarlı ayak | F23: 750 | H23: 0 | I23: 0 | J23: 0 | K23: 0 | L23: 0 | M23: 0 | N23: =+F23-I23-J23-K23-L23-M23+H23 -> 750 | P23: 100 | Q23: 500
A24: 22 | B24: 28 MM İÇ TAKOZ | F24: 5000 | H24: 0 | I24: 0 | J24: 0 | K24: 0 | L24: 0 | M24: 0 | N24: =+F24-I24-J24-K24-L24-M24+H24 -> 5000
A25: 23 | B25: 19 MM İÇ TAKOZ | F25: 5000 | H25: 0 | I25: 0 | J25: 0 | K25: 0 | L25: 0 | M25: 0 | N25: =+F25-I25-J25-K25-L25-M25+H25 -> 5000

Sheet ARALIK 1 HAFTA
B1: ARALIK 1 HAFTA
A2: S.NO | B2: ÜRÜN CİNSİ | F2: ADET | G2: devir | H2: GELEN | I2: 44900 | J2: 44901 | K2: 44902 | L2: 44903 | M2: 44904 | N2: KALAN | O2: AÇIKLAMA | P2: MİNİMUN | Q2: MAKSİMUN
A3: 1 | B3: U BAĞLANTI DEMİRİ | F3: 34000 | H3: 0 | I3: 0 | J3: 0 | K3: 500 | L3: 0 | M3: 0 | N3: =+F3-I3-J3-K3-L3-M3+H3 -> 33500 | P3: 1000 | Q3: 10000
A4: 2 | B4: AYAK SOMUNU(BIDIK) | F4: ='KASIM 3 HAFTA '!N4 -> 15238 | H4: 0 | I4: 0 | J4: 0 | K4: 0 | L4: 0 | M4: 0 | N4: =+F4-I4-J4-K4-L4-M4+H4 -> 15238 | P4: 5000 | Q4: 20000
A5: 3 | B5: M10 OYNAR BAŞLIKLI BİNGO | F5: ='KASIM 3 HAFTA '!N5 -> 153 | H5: 0 | I5: 0 | J5: 0 | K5: 0 | L5: 0 | M5: 0 | N5: =+F5-I5-J5-K5-L5-M5+H5 -> 153 | O5: PLASTİK SİY.BÜYÜK | P5: 300 | Q5: 1000
A6: 4 | B6: M8 CİVATALI BİNGO | F6: 244 | H6: 0 | I6: 0 | J6: 0 | K6: 0 | L6: 0 | M6: 0 | N6: =+F6-I6-J6-K6-L6-M6+H6 -> 244 | O6: PLASTİK SİY.BÜYÜK | P6: 0
A7: 5 | B7: M8 OYNAR BAŞLIKLI BİNGO | F7: ='KASIM 3 HAFTA '!N7 -> 500 | H7: 0 | I7: 0 | J7: 0 | K7: 0 | L7: 0 | M7: 0 | N7: =+F7-I7-J7-K7-L7-M7+H7 -> 500 | O7: KROM | P7: 300 | Q7: 1000
A8: 6 | B8: M8 CİVATALI BİNGO | F8: ='KASIM 3 HAFTA '!N8 -> 286 | H8: 0 | I8: 0 | J8: 0 | K8: 0 | L8: 0 | M8: 0 | N8: =+F8-I8-J8-K8-L8-M8+H8 -> 286 | O8: SİYAH KÜÇÜK | P8: 200 | Q8: 500
A9: 7 | B9: M8 CİVATALI BİNGO_MOB. | F9: ='KASIM 3 HAFTA '!N9 -> 760 | H9: 1000 | I9: 0 | J9: 760 | K9: 0 | L9: 500 | M9: 0 | N9: =+F9-I9-J9-K9-L9-M9+H9 -> 500 | O9: REFAKATÇI SİY.KÜÇÜK | P9: 200 | Q9: 500
A10: 8 | B10: M6 SOKET | F10: 22000 | H10: 0 | I10: 0 | J10: 0 | K10: 1000 | L10: 0 | M10: 5000 | N10: =+F10-I10-J10-K10-L10-M10+H10 -> 16000 | P10: 10000 | Q10: 50000
A11: 9 | B11: PİMLİ TEKER NAYLON 50 | F11: 39961 | G11: 0 | H11: 0 | I11: 0 | J11: 260 | K11: 260 | L11: 400 | M11: 1040 | N11: =+F11-I11-J11-K11-L11-M11+H11 -> 38001 | P11: 5000 | Q11: 30000
A12: 10 | B12: SİLİKON TEKER | F12: ='KASIM 3 HAFTA '!N12 -> 820 | H12: 0 | I12: 0 | J12: 0 | K12: 0 | L12: 0 | M12: 0 | N12: =+F12-I12-J12-K12-L12-M12+H12 -> 820 | P12: 0
A13: 11 | B13: PİMLİ BİNGO | F13: 6575 | H13: 0 | I13: 0 | J13: 0 | K13: 500 | L13: 0 | M13: 0 | N13: =+F13-I13-J13-K13-L13-M13+H13 -> 6075 | P13: 1000 | Q13: 5000
A14: 12 | B14: LALE AYAK ÇEKYAT GEÇMELİ | F14: 704 | H14: 0 | I14: 0 | J14: 0 | K14: 0 | L14: 0 | M14: 0 | N14: =+F14-I14-J14-K14-L14-M14+H14 -> 704 | P14: 250 | Q14: 1000
A15: 13 | B15: TOKMAK | F15: ='KASIM 3 HAFTA '!N15 -> 800 | H15: 0 | I15: 0 | J15: 0 | K15: 0 | L15: 0 | M15: 0 | N15: =+F15-I15-J15-K15-L15-M15+H15 -> 800 | P15: 250 | Q15: 500
A16: 14 | B16: SEKRETER KÖRÜK | C16: 350 | F16: ='KASIM 3 HAFTA '!N16 -> 3150 | H16: 0 | I16: 0 | J16: 0 | K16: 0 | L16: 0 | M16: 0 | N16: =+F16-I16-J16-K16-L16-M16+H16 -> 3150 | P16: 500 | Q16: 2000
A17: 15 | B17: AHŞAP TELESKOP KÖRÜK | F17: 500 | G17: 0 | H17: 0 | I17: 0 | J17: 0 | K17: 100 | L17: 0 | M17: 0 | N17: =+F17-I17-J17-K17-L17-M17+H17 -> 400 | P17: 100 | Q17: 500
A18: 16 | B18: VEGA KÖRÜK | F18: 5000 | H18: 0 | I18: 0 | J18: 0 | K18: 500 | L18: 0 | M18: 0 | N18: =+F18-I18-J18-K18-L18-M18+H18 -> 4500 | P18: 1000 | Q18: 5000
A19: 17 | B19: VEGA KONFERANS KOL | F19: ='KASIM 3 HAFTA '!N19 -> 88 | H19: 0 | I19: 0 | J19: 0 | K19: 0 | L19: 0 | M19: 0 | N19: =+F19-I19-J19-K19-L19-M19+H19 -> 88 | P19: 100 | Q19: 300
A20: 18 | B20: VEGA ÇAKMA KOL SEHPALI | F20: ='KASIM 3 HAFTA '!N20 -> 400 | H20: 0 | I20: 0 | J20: 0 | K20: 0 | L20: 76 | M20: 0 | N20: =+F20-I20-J20-K20-L20-M20+H20 -> 324 | P20: 100 | Q20: 300
A21: 19 | B21: SİNEMA KAPAK KISA | F21: 266 | G21: 425 | H21: 500 | I21: 266 | J21: 0 | K21: 0 | L21: 0 | M21: 112 | N21: =+F21-I21-J21-K21-L21-M21+H21 -> 388 | P21: 200 | Q21: 500
A22: 20 | B22: KUYRUKLU TİLK MEKANİZMA | F22: 254 | H22: 0 | I22: 0 | J22: 12 | K22: 0 | L22: 0 | M22: 0 | N22: =+F22-I22-J22-K22-L22-M22+H22 -> 242 | P22: 100 | Q22: 300
A23: 21 | B23: 5 cm krom ayarlı ayak | F23: 750 | H23: 0 | I23: 0 | J23: 400 | K23: 150 | L23: 0 | M23: 0 | N23: =+F23-I23-J23-K23-L23-M23+H23 -> 200 | P23: 100 | Q23: 500
A24: 22 | B24: 28 MM İÇ TAKOZ | F24: 5000 | H24: 0 | I24: 0 | J24: 0 | K24: 0 | L24: 0 | M24: 1000 | N24: =+F24-I24-J24-K24-L24-M24+H24 -> 4000
A25: 23 | B25: 19 MM İÇ TAKOZ | F25: 5000 | H25: 0 | I25: 0 | J25: 5000 | K25: 0 | L25: 0 | M25: 0 | N25: =+F25-I25-J25-K25-L25-M25+H25 -> 0
A26: 24 | B26: ÇİFT KOLLU TİLK MEK. / GÖLCÜ | F26: 0 | H26: 2000 | L26: 79 | M26: 321 | N26: =+F26-I26-J26-K26-L26-M26+H26 -> 1600
A27: 25 | B27: TORNA AYAK AHŞAP | H27: 20 | N27: =+F27-I27-J27-K27-L27-M27+H27 -> 20

Sheet ARALIK 2 HAFTA 
B1: ARALIK 2 HAFTA
A2: S.NO | B2: ÜRÜN CİNSİ | F2: ADET | G2: devir | H2: GELEN | I2: 44907 | J2: 44908 | K2: 44909 | L2: 44910 | M2: 44911 | N2: KALAN | O2: AÇIKLAMA | P2: MİNİMUN | Q2: MAKSİMUN
A3: 1 | B3: U BAĞLANTI DEMİRİ | F3: 33500 | H3: 0 | I3: 500 | J3: 0 | K3: 0 | L3: 0 | M3: 0 | N3: =+F3-I3-J3-K3-L3-M3+H3 -> 33000 | P3: 1000 | Q3: 10000
A4: 2 | B4: AYAK SOMUNU(BIDIK) | F4: ='KASIM 3 HAFTA '!N4 -> 15238 | H4: 0 | I4: 0 | J4: 0 | K4: 0 | L4: 0 | M4: 0 | N4: =+F4-I4-J4-K4-L4-M4+H4 -> 15238 | P4: 5000 | Q4: 20000
A5: 3 | B5: M10 OYNAR BAŞLIKLI BİNGO | F5: ='KASIM 3 HAFTA '!N5 -> 153 | H5: 0 | I5: 0 | J5: 0 | K5: 0 | L5: 0 | M5: 0 | N5: =+F5-I5-J5-K5-L5-M5+H5 -> 153 | O5: PLASTİK SİY.BÜYÜK | P5: 300 | Q5: 1000
A6: 4 | B6: M8 CİVATALI BİNGO | F6: 244 | H6: 0 | I6: 0 | J6: 0 | K6: 0 | L6: 0 | M6: 0 | N6: =+F6-I6-J6-K6-L6-M6+H6 -> 244 | O6: PLASTİK SİY.BÜYÜK | P6: 0
A7: 5 | B7: M8 OYNAR BAŞLIKLI BİNGO | F7: ='KASIM 3 HAFTA '!N7 -> 500 | H7: 0 | I7: 0 | J7: 0 | K7: 0 | L7: 0 | M7: 0 | N7: =+F7-I7-J7-K7-L7-M7+H7 -> 500 | O7: KROM | P7: 300 | Q7: 1000
A8: 6 | B8: M8 CİVATALI BİNGO | F8: ='KASIM 3 HAFTA '!N8 -> 286 | H8: 0 | I8: 0 | J8: 0 | K8: 0 | L8: 0 | M8: 100 | N8: =+F8-I8-J8-K8-L8-M8+H8 -> 186 | O8: SİYAH KÜÇÜK | P8: 200 | Q8: 500
A9: 7 | B9: M8 CİVATALI BİNGO_MOB. | F9: 500 | H9: 0 | I9: 0 | J9: 0 | K9: 0 | L9: 0 | M9: 500 | N9: =+F9-I9-J9-K9-L9-M9+H9 -> 0 | O9: REFAKATÇI SİY.KÜÇÜK | P9: 200 | Q9: 500
A10: 8 | B10: M6 SOKET | F10: 16000 | H10: 0 | I10: 0 | J10: 0 | K10: 0 | L10: 0 | M10: 5000 | N10: =+F10-I10-J10-K10-L10-M10+H10 -> 11000 | P10: 10000 | Q10: 50000
A11: 9 | B11: PİMLİ TEKER NAYLON 50 | F11: 38000 | G11: 0 | H11: 0 | I11: 0 | J11: 400 | K11: 12700 | L11: 0 | M11: 0 | N11: =+F11-I11-J11-K11-L11-M11+H11 -> 24900 | P11: 5000 | Q11: 30000
A12: 10 | B12: SİLİKON TEKER | F12: ='KASIM 3 HAFTA '!N12 -> 820 | H12: 0 | I12: 0 | J12: 0 | K12: 0 | L12: 0 | M12: 0 | N12: =+F12-I12-J12-K12-L12-M12+H12 -> 820 | P12: 0
A13: 11 | B13: PİMLİ BİNGO | F13: 6075 | H13: 0 | I13: 0 | J13: 0 | K13: 0 | L13: 0 | M13: 0 | N13: =+F13-I13-J13-K13-L13-M13+H13 -> 6075 | P13: 1000 | Q13: 5000
A14: 12 | B14: LALE AYAK ÇEKYAT GEÇMELİ | F14: 704 | H14: 0 | I14: 0 | J14: 0 | K14: 0 | L14: 0 | M14: 0 | N14: =+F14-I14-J14-K14-L14-M14+H14 -> 704 | P14: 250 | Q14: 1000
A15: 13 | B15: TOKMAK | F15: ='KASIM 3 HAFTA '!N15 -> 800 | H15: 0 | I15: 0 | J15: 0 | K15: 0 | L15: 0 | M15: 0 | N15: =+F15-I15-J15-K15-L15-M15+H15 -> 800 | P15: 250 | Q15: 500
A16: 14 | B16: SEKRETER KÖRÜK | C16: 350 | F16: ='KASIM 3 HAFTA '!N16 -> 3150 | H16: 0 | I16: 0 | J16: 0 | K16: 0 | L16: 0 | M16: 0 | N16: =+F16-I16-J16-K16-L16-M16+H16 -> 3150 | P16: 500 | Q16: 2000
A17: 15 | B17: AHŞAP TELESKOP KÖRÜK | F17: 400 | G17: 0 | H17: 0 | I17: 0 | J17: 40 | K17: 0 | L17: 0 | M17: 0 | N17: =+F17-I17-J17-K17-L17-M17+H17 -> 360 | P17: 100 | Q17: 500
A18: 16 | B18: VEGA KÖRÜK | F18: 4500 | H18: 0 | I18: 0 | J18: 0 | K18: 1000 | L18: 0 | M18: 0 | N18: =+F18-I18-J18-K18-L18-M18+H18 -> 3500 | P18: 1000 | Q18: 5000
A19: 17 | B19: VEGA KONFERANS KOL | F19: ='KASIM 3 HAFTA '!N19 -> 88 | H19: 0 | I19: 0 | J19: 0 | K19: 0 | L19: 0 | M19: 0 | N19: =+F19-I19-J19-K19-L19-M19+H19 -> 88 | P19: 100 | Q19: 300
A20: 18 | B20: VEGA ÇAKMA KOL SEHPALI | F20: 324 | H20: 0 | I20: 0 | J20: 0 | K20: 0 | L20: 0 | M20: 0 | N20: =+F20-I20-J20-K20-L20-M20+H20 -> 324 | P20: 100 | Q20: 300
A21: 19 | B21: SİNEMA KAPAK KISA | F21: 388 | G21: 425 | H21: 0 | I21: 0 | J21: 0 | K21: 0 | L21: 0 | M21: 0 | N21: =+F21-I21-J21-K21-L21-M21+H21 -> 388 | P21: 200 | Q21: 500
A22: 20 | B22: KUYRUKLU TİLK MEKANİZMA | F22: 242 | H22: 0 | I22: 31 | J22: 6 | K22: 0 | L22: 3 | M22: 36 | N22: =+F22-I22-J22-K22-L22-M22+H22 -> 166 | P22: 100 | Q22: 300
A23: 21 | B23: 5 cm krom ayarlı ayak | F23: 200 | H23: 0 | I23: 0 | J23: 0 | K23: 0 | L23: 0 | M23: 0 | N23: =+F23-I23-J23-K23-L23-M23+H23 -> 200 | P23: 100 | Q23: 500
A24: 22 | B24: 28 MM İÇ TAKOZ | F24: 4000 | H24: 0 | I24: 0 | J24: 0 | K24: 0 | L24: 0 | M24: 0 | N24: =+F24-I24-J24-K24-L24-M24+H24 -> 4000
A25: 23 | B25: 19 MM İÇ TAKOZ | F25: 0 | H25: 0 | I25: 0 | J25: 0 | K25: 0 | L25: 0 | M25: 0 | N25: =+F25-I25-J25-K25-L25-M25+H25 -> 0
A26: 24 | B26: ÇİFT KOLLU TİLK MEK. / GÖLCÜ | F26: 1600 | H26: 2000 | I26: 0 | J26: 0 | K26: 2500 | L26: 0 | M26: 37 | N26: =+F26-I26-J26-K26-L26-M26+H26 -> 1063
A27: 25 | B27: TORNA AYAK AHŞAP | F27: 20 | H27: 0 | I27: 0 | J27: 0 | K27: 0 | L27: 0 | M27: 0 | N27: =+F27-I27-J27-K27-L27-M27+H27 -> 20
A28: 26 | B28: PİMLİ TEKER NAYLON 60 | H28: 5000 | L28: 800 | N28: =+F28-I28-J28-K28-L28-M28+H28 -> 4200

Sheet ARALIK 3 HAFTA 
B1: ARALIK 3 HAFTA
A2: S.NO | B2: ÜRÜN CİNSİ | F2: ADET | G2: devir | H2: GELEN | I2: 44914 | J2: 44915 | K2: 44916 | L2: 44917 | M2: 44918 | N2: KALAN | O2: AÇIKLAMA | P2: MİNİMUN | Q2: MAKSİMUN
A3: 1 | B3: U BAĞLANTI DEMİRİ | F3: 33000 | H3: 0 | I3: 0 | J3: 5000 | K3: 5000 | L3: 0 | M3: 0 | N3: =+F3-I3-J3-K3-L3-M3+H3 -> 23000 | P3: 1000 | Q3: 10000
A4: 2 | B4: AYAK SOMUNU(BIDIK) | F4: ='KASIM 3 HAFTA '!N4 -> 15238 | H4: 0 | I4: 0 | J4: 0 | K4: 0 | L4: 0 | M4: 0 | N4: =+F4-I4-J4-K4-L4-M4+H4 -> 15238 | P4: 5000 | Q4: 20000
A5: 3 | B5: M10 OYNAR BAŞLIKLI BİNGO | F5: ='KASIM 3 HAFTA '!N5 -> 153 | H5: 0 | I5: 0 | J5: 0 | K5: 0 | L5: 0 | M5: 0 | N5: =+F5-I5-J5-K5-L5-M5+H5 -> 153 | O5: PLASTİK SİY.BÜYÜK | P5: 300 | Q5: 1000
A6: 4 | B6: M8 CİVATALI BİNGO | F6: 244 | H6: 0 | I6: 0 | J6: 0 | K6: 0 | L6: 0 | M6: 0 | N6: =+F6-I6-J6-K6-L6-M6+H6 -> 244 | O6: PLASTİK SİY.BÜYÜK | P6: 0
A7: 5 | B7: M8 OYNAR BAŞLIKLI BİNGO | F7: ='KASIM 3 HAFTA '!N7 -> 500 | H7: 0 | I7: 0 | J7: 0 | K7: 0 | L7: 0 | M7: 0 | N7: =+F7-I7-J7-K7-L7-M7+H7 -> 500 | O7: KROM | P7: 300 | Q7: 1000
A8: 6 | B8: M8 CİVATALI BİNGO | F8: 186 | H8: 0 | I8: 0 | J8: 0 | K8: 0 | L8: 0 | M8: 0 | N8: =+F8-I8-J8-K8-L8-M8+H8 -> 186 | O8: SİYAH KÜÇÜK | P8: 200 | Q8: 500
A9: 7 | B9: M8 CİVATALI BİNGO_MOB. | F9: 0 | H9: 0 | I9: 0 | J9: 0 | K9: 0 | L9: 0 | M9: 0 | N9: =+F9-I9-J9-K9-L9-M9+H9 -> 0 | O9: REFAKATÇI SİY.KÜÇÜK | P9: 200 | Q9: 500
A10: 8 | B10: M6 SOKET | F10: 11000 | H10: 0 | I10: 5000 | J10: 0 | K10: 0 | L10: 5000 | M10: 0 | N10: =+F10-I10-J10-K10-L10-M10+H10 -> 1000 | P10: 10000 | Q10: 50000
A11: 9 | B11: PİMLİ TEKER NAYLON 50 | F11: 24900 | G11: 0 | H11: 0 | I11: 700 | J11: 20 | K11: 1700 | L11: 500 | M11: 1150 | N11: =+F11-I11-J11-K11-L11-M11+H11 -> 20830 | P11: 5000 | Q11: 30000
A12: 10 | B12: SİLİKON TEKER | F12: ='KASIM 3 HAFTA '!N12 -> 820 | H12: 0 | I12: 0 | J12: 0 | K12: 0 | L12: 0 | M12: 0 | N12: =+F12-I12-J12-K12-L12-M12+H12 -> 820 | P12: 0
A13: 11 | B13: PİMLİ BİNGO | F13: 6075 | H13: 0 | I13: 0 | J13: 0 | K13: 0 | L13: 0 | M13: 30 | N13: =+F13-I13-J13-K13-L13-M13+H13 -> 6045 | P13: 1000 | Q13: 5000
A14: 12 | B14: LALE AYAK ÇEKYAT GEÇMELİ | F14: 704 | H14: 0 | I14: 0 | J14: 0 | K14: 0 | L14: 0 | M14: 0 | N14: =+F14-I14-J14-K14-L14-M14+H14 -> 704 | P14: 250 | Q14: 1000
A15: 13 | B15: TOKMAK | F15: ='KASIM 3 HAFTA '!N15 -> 800 | H15: 0 | I15: 0 | J15: 0 | K15: 0 | L15: 0 | M15: 0 | N15: =+F15-I15-J15-K15-L15-M15+H15 -> 800 | P15: 250 | Q15: 500
A16: 14 | B16: SEKRETER KÖRÜK | C16: 350 | F16: ='KASIM 3 HAFTA '!N16 -> 3150 | H16: 0 | I16: 0 | J16: 0 | K16: 0 | L16: 0 | M16: 0 | N16: =+F16-I16-J16-K16-L16-M16+H16 -> 3150 | P16: 500 | Q16: 2000
A17: 15 | B17: AHŞAP TELESKOP KÖRÜK | F17: 360 | G17: 0 | H17: 0 | I17: 0 | J17: 40 | K17: 0 | L17: 0 | M17: 60 | N17: =+F17-I17-J17-K17-L17-M17+H17 -> 260 | P17: 100 | Q17: 500
A18: 16 | B18: VEGA KÖRÜK | F18: 3500 | H18: 0 | I18: 1000 | J18: 0 | K18: 1500 | L18: 0 | M18: 0 | N18: =+F18-I18-J18-K18-L18-M18+H18 -> 1000 | P18: 1000 | Q18: 5000
A19: 17 | B19: VEGA KONFERANS KOL | F19: ='KASIM 3 HAFTA '!N19 -> 88 | H19: 0 | I19: 0 | J19: 0 | K19: 0 | L19: 0 | M19: 2 | N19: =+F19-I19-J19-K19-L19-M19+H19 -> 86 | P19: 100 | Q19: 300
A20: 18 | B20: VEGA ÇAKMA KOL SEHPALI | F20: 324 | H20: 0 | I20: 0 | J20: 0 | K20: 0 | L20: 0 | M20: 0 | N20: =+F20-I20-J20-K20-L20-M20+H20 -> 324 | P20: 100 | Q20: 300
A21: 19 | B21: SİNEMA KAPAK KISA | F21: 388 | G21: 425 | H21: 0 | I21: 0 | J21: 0 | K21: 0 | L21: 0 | M21: 0 | N21: =+F21-I21-J21-K21-L21-M21+H21 -> 388 | P21: 200 | Q21: 500
A22: 20 | B22: KUYRUKLU TİLK MEKANİZMA | F22: 166 | H22: 49 | I22: 166 | J22: 0 | K22: 0 | L22: 0 | M22: 49 | N22: =+F22-I22-J22-K22-L22-M22+H22 -> 0 | P22: 100 | Q22: 300
A23: 21 | B23: 5 cm krom ayarlı ayak | F23: 200 | H23: 0 | I23: 0 | J23: 200 | K23: 0 | L23: 0 | M23: 0 | N23: =+F23-I23-J23-K23-L23-M23+H23 -> 0 | P23: 100 | Q23: 500
A24: 22 | B24: 28 MM İÇ TAKOZ | F24: 4000 | H24: 0 | I24: 0 | J24: 0 | K24: 0 | L24: 0 | M24: 0 | N24: =+F24-I24-J24-K24-L24-M24+H24 -> 4000
A25: 23 | B25: 19 MM İÇ TAKOZ | F25: 0 | H25: 0 | I25: 0 | J25: 0 | K25: 0 | L25: 0 | M25: 0 | N25: =+F25-I25-J25-K25-L25-M25+H25 -> 0
A26: 24 | B26: ÇİFT KOLLU TİLK MEK. / GÖLCÜ | F26: 1063 | H26: 0 | I26: 0 | J26: 0 | K26: 0 | L26: 20 | M26: 0 | N26: =+F26-I26-J26-K26-L26-M26+H26 -> 1043
A27: 25 | B27: TORNA AYAK AHŞAP | F27: 20 | H27: 0 | I27: 0 | J27: 0 | K27: 0 | L27: 0 | M27: 0 | N27: =+F27-I27-J27-K27-L27-M27+H27 -> 20
A28: 26 | B28: PİMLİ TEKER NAYLON 60 | F28: 4200 | H28: 0 | I28: 0 | J28: 0 | K28: 0 | L28: 0 | M28: 0 | N28: =+F28-I28-J28-K28-L28-M28+H28 -> 4200

Sheet ARALIK 4 HAFTA
B1: ARALIK 4 HAFTA
A2: S.NO | B2: ÜRÜN CİNSİ | F2: ADET | G2: devir | H2: GELEN | I2: 44921 | J2: 44922 | K2: 44923 | L2: 44924 | M2: 44925 | N2: KALAN | O2: AÇIKLAMA | P2: MİNİMUN | Q2: MAKSİMUN
A3: 1 | B3: U BAĞLANTI DEMİRİ | F3: 23000 | H3: 0 | I3: 0 | J3: 0 | K3: 5000 | L3: 0 | M3: 5000 | N3: =+F3-I3-J3-K3-L3-M3+H3 -> 13000 | P3: 1000 | Q3: 10000
A4: 2 | B4: AYAK SOMUNU(BIDIK) | F4: ='KASIM 3 HAFTA '!N4 -> 15238 | H4: 0 | I4: 0 | J4: 0 | K4: 0 | L4: 0 | M4: 0 | N4: =+F4-I4-J4-K4-L4-M4+H4 -> 15238 | P4: 5000 | Q4: 20000
A5: 3 | B5: M10 OYNAR BAŞLIKLI BİNGO | F5: ='KASIM 3 HAFTA '!N5 -> 153 | H5: 0 | I5: 0 | J5: 0 | K5: 0 | L5: 0 | M5: 0 | N5: =+F5-I5-J5-K5-L5-M5+H5 -> 153 | O5: PLASTİK SİY.BÜYÜK | P5: 300 | Q5: 1000
A6: 4 | B6: M8 CİVATALI BİNGO | F6: 244 | H6: 0 | I6: 0 | J6: 0 | K6: 0 | L6: 0 | M6: 0 | N6: =+F6-I6-J6-K6-L6-M6+H6 -> 244 | O6: PLASTİK SİY.BÜYÜK | P6: 0
A7: 5 | B7: M8 OYNAR BAŞLIKLI BİNGO | F7: ='KASIM 3 HAFTA '!N7 -> 500 | H7: 0 | I7: 0 | J7: 0 | K7: 0 | L7: 0 | M7: 0 | N7: =+F7-I7-J7-K7-L7-M7+H7 -> 500 | O7: KROM | P7: 300 | Q7: 1000
A8: 6 | B8: M8 CİVATALI BİNGO | F8: 186 | H8: 0 | I8: 0 | J8: 0 | K8: 0 | L8: 0 | M8: 0 | N8: =+F8-I8-J8-K8-L8-M8+H8 -> 186 | O8: SİYAH KÜÇÜK | P8: 200 | Q8: 500
A9: 7 | B9: M8 CİVATALI BİNGO_MOB. | F9: 0 | H9: 0 | I9: 0 | J9: 0 | K9: 0 | L9: 0 | M9: 0 | N9: =+F9-I9-J9-K9-L9-M9+H9 -> 0 | O9: REFAKATÇI SİY.KÜÇÜK | P9: 200 | Q9: 500
A10: 8 | B10: M6 SOKET | F10: 1000 | H10: 0 | I10: 0 | J10: 0 | K10: 0 | L10: 600 | M10: 0 | N10: =+F10-I10-J10-K10-L10-M10+H10 -> 400 | P10: 10000 | Q10: 50000
A11: 9 | B11: PİMLİ TEKER NAYLON 50 | F11: 20830 | G11: 0 | H11: 0 | I11: 200 | J11: 200 | K11: 200 | L11: 0 | M11: 0 | N11: =+F11-I11-J11-K11-L11-M11+H11 -> 20230 | P11: 5000 | Q11: 30000
A12: 10 | B12: SİLİKON TEKER | F12: ='KASIM 3 HAFTA '!N12 -> 820 | H12: 0 | I12: 0 | J12: 0 | K12: 0 | L12: 0 | M12: 0 | N12: =+F12-I12-J12-K12-L12-M12+H12 -> 820 | P12: 0
A13: 11 | B13: PİMLİ BİNGO | F13: 6045 | H13: 0 | I13: 0 | J13: 0 | K13: 0 | L13: 0 | M13: 0 | N13: =+F13-I13-J13-K13-L13-M13+H13 -> 6045 | P13: 1000 | Q13: 5000
A14: 12 | B14: LALE AYAK ÇEKYAT GEÇMELİ | F14: 704 | H14: 0 | I14: 0 | J14: 0 | K14: 0 | L14: 0 | M14: 0 | N14: =+F14-I14-J14-K14-L14-M14+H14 -> 704 | P14: 250 | Q14: 1000
A15: 13 | B15: TOKMAK | F15: ='KASIM 3 HAFTA '!N15 -> 800 | H15: 0 | I15: 0 | J15: 0 | K15: 0 | L15: 0 | M15: 0 | N15: =+F15-I15-J15-K15-L15-M15+H15 -> 800 | P15: 250 | Q15: 500
A16: 14 | B16: SEKRETER KÖRÜK | C16: 350 | F16: ='KASIM 3 HAFTA '!N16 -> 3150 | H16: 0 | I16: 0 | J16: 0 | K16: 0 | L16: 0 | M16: 0 | N16: =+F16-I16-J16-K16-L16-M16+H16 -> 3150 | P16: 500 | Q16: 2000
A17: 15 | B17: AHŞAP TELESKOP KÖRÜK | F17: 260 | G17: 0 | H17: 640 | I17: 0 | J17: 0 | K17: 0 | L17: 0 | M17: 0 | N17: =+F17-I17-J17-K17-L17-M17+H17 -> 900 | P17: 100 | Q17: 500
A18: 16 | B18: VEGA KÖRÜK | F18: 1000 | H18: 0 | I18: 0 | J18: 0 | K18: 0 | L18: 0 | M18: 0 | N18: =+F18-I18-J18-K18-L18-M18+H18 -> 1000 | P18: 1000 | Q18: 5000
A19: 17 | B19: VEGA KONFERANS KOL | F19: 86 | H19: 0 | I19: 0 | J19: 0 | K19: 0 | L19: 0 | M19: 0 | N19: =+F19-I19-J19-K19-L19-M19+H19 -> 86 | P19: 100 | Q19: 300
A20: 18 | B20: VEGA ÇAKMA KOL SEHPALI | F20: 324 | H20: 0 | I20: 0 | J20: 0 | K20: 0 | L20: 0 | M20: 0 | N20: =+F20-I20-J20-K20-L20-M20+H20 -> 324 | P20: 100 | Q20: 300
A21: 19 | B21: SİNEMA KAPAK KISA | F21: 388 | G21: 425 | H21: 0 | I21: 0 | J21: 0 | K21: 0 | L21: 0 | M21: 0 | N21: =+F21-I21-J21-K21-L21-M21+H21 -> 388 | P21: 200 | Q21: 500
A22: 20 | B22: KUYRUKLU TİLK MEKANİZMA | F22: 0 | H22: 203 | I22: 0 | J22: 0 | K22: 6 | L22: 0 | M22: 0 | N22: =+F22-I22-J22-K22-L22-M22+H22 -> 197 | P22: 100 | Q22: 300
A23: 21 | B23: 5 cm krom ayarlı ayak | F23: 11 | H23: 0 | I23: 0 | J23: 0 | K23: 0 | L23: 0 | M23: 0 | N23: =+F23-I23-J23-K23-L23-M23+H23 -> 11 | P23: 100 | Q23: 500
A24: 22 | B24: 28 MM İÇ TAKOZ | F24: 4000 | H24: 0 | I24: 0 | J24: 0 | K24: 0 | L24: 0 | M24: 0 | N24: =+F24-I24-J24-K24-L24-M24+H24 -> 4000
A25: 23 | B25: 19 MM İÇ TAKOZ | F25: 0 | H25: 0 | I25: 0 | J25: 0 | K25: 0 | L25: 0 | M25: 0 | N25: =+F25-I25-J25-K25-L25-M25+H25 -> 0
A26: 24 | B26: ÇİFT KOLLU TİLK MEK. | F26: 1043 | H26: 0 | I26: 28 | J26: 0 | K26: 14 | L26: 0 | M26: 0 | N26: =+F26-I26-J26-K26-L26-M26+H26 -> 1001
A27: 25 | B27: TORNA AYAK AHŞAP | F27: 20 | H27: 0 | I27: 0 | J27: 0 | K27: 0 | L27: 0 | M27: 0 | N27: =+F27-I27-J27-K27-L27-M27+H27 -> 20
A28: 26 | B28: PİMLİ TEKER NAYLON 60 | F28: 4200 | H28: 0 | I28: 0 | J28: 0 | K28: 0 | L28: 0 | M28: 0 | N28: =+F28-I28-J28-K28-L28-M28+H28 -> 4200

Sheet OCAK 1 HAFTA
B1: OCAK 1 HAFTA
A2: S.NO | B2: ÜRÜN CİNSİ | F2: ADET | G2: devir | H2: GELEN | I2: 44928 | J2: 44929 | K2: 44930 | L2: 44931 | M2: 44932 | N2: KALAN | O2: AÇIKLAMA | P2: MİNİMUN | Q2: MAKSİMUN
A3: 1 | B3: U BAĞLANTI DEMİRİ | F3: 13000 | H3: 0 | I3: 0 | J3: 0 | K3: 0 | L3: 0 | M3: 500 | N3: =+F3-I3-J3-K3-L3-M3+H3 -> 12500 | P3: 1000 | Q3: 10000
A4: 2 | B4: AYAK SOMUNU(BIDIK) | F4: ='KASIM 3 HAFTA '!N4 -> 15238 | H4: 0 | I4: 0 | J4: 0 | K4: 0 | L4: 0 | M4: 0 | N4: =+F4-I4-J4-K4-L4-M4+H4 -> 15238 | P4: 5000 | Q4: 20000
A5: 3 | B5: M10 OYNAR BAŞLIKLI BİNGO | F5: ='KASIM 3 HAFTA '!N5 -> 153 | H5: 0 | I5: 0 | J5: 0 | K5: 0 | L5: 0 | M5: 0 | N5: =+F5-I5-J5-K5-L5-M5+H5 -> 153 | O5: PLASTİK SİY.BÜYÜK | P5: 300 | Q5: 1000
A6: 4 | B6: M8 CİVATALI BİNGO | F6: 244 | H6: 0 | I6: 0 | J6: 0 | K6: 0 | L6: 0 | M6: 0 | N6: =+F6-I6-J6-K6-L6-M6+H6 -> 244 | O6: PLASTİK SİY.BÜYÜK | P6: 0
A7: 5 | B7: M8 OYNAR BAŞLIKLI BİNGO | F7: ='KASIM 3 HAFTA '!N7 -> 500 | H7: 0 | I7: 0 | J7: 0 | K7: 0 | L7: 0 | M7: 0 | N7: =+F7-I7-J7-K7-L7-M7+H7 -> 500 | O7: KROM | P7: 300 | Q7: 1000
A8: 6 | F8: 0 | H8: 0 | I8: 0 | J8: 0 | K8: 0 | L8: 0 | M8: 0 | N8: =+F8-I8-J8-K8-L8-M8+H8 -> 0 | P8: 200 | Q8: 500
A9: 7 | B9: M8 CİVATALI BİNGO_MOB. | F9: 0 | H9: 1000 | I9: 0 | J9: 0 | K9: 0 | L9: 0 | M9: 0 | N9: =+F9-I9-J9-K9-L9-M9+H9 -> 1000 | O9: REFAKATÇI SİY.KÜÇÜK | P9: 200 | Q9: 500
A10: 8 | B10: M6 SOKET | F10: 400 | H10: 0 | I10: 0 | J10: 0 | K10: 0 | L10: 0 | M10: 0 | N10: =+F10-I10-J10-K10-L10-M10+H10 -> 400 | P10: 10000 | Q10: 50000
A11: 9 | B11: PİMLİ TEKER NAYLON 50 | F11: 20230 | G11: 0 | H11: 12500 | I11: 600 | J11: 260 | K11: 200 | L11: 1000 | M11: 500 | N11: =+F11-I11-J11-K11-L11-M11+H11 -> 30170 | P11: 5000 | Q11: 30000
A12: 10 | B12: SİLİKON TEKER | F12: ='KASIM 3 HAFTA '!N12 -> 820 | H12: 0 | I12: 0 | J12: 0 | K12: 0 | L12: 0 | M12: 0 | N12: =+F12-I12-J12-K12-L12-M12+H12 -> 820 | P12: 0
