Workbook

Sheet eylül 4 hafta
A1: TAHTA SAYIMI | J1: 44809
A2: S.NO | B2: CİNSİ | C2: DEVİR | D2: GELEN | E2: 44830 | F2: 44831 | G2: 44832 | H2: 44833 | I2: 44834 | J2: KALAN
A3: 1 | B3: SANDALYE TAHTASI | C3: 37 | D3: 0 | E3: 0 | J3: =+C3-E3-F3-G3-H3-I3+D3 -> 37
A4: 2 | B4: EKO KLAS MÜDÜR TAHTASI | C4: 3 | J4: =+C4-E4-F4-G4-H4-I4+D4 -> 3
A5: 3 | B5: KESİLMEMİŞTAHTA | C5: 107 | J5: =+C5-E5-F5-G5-H5-I5+D5 -> 107
A6: 4 | B6: RECENT MİSAFİR | C6: 55 | J6: =+C6-E6-F6-G6-H6-I6+D6 -> 55
A7: 5 | B7: RECENT MÜDÜR | C7: 30 | F7: 3 | J7: =+C7-E7-F7-G7-H7-I7+D7 -> 27
A8: 6 | B8: PUFFY MİSAFİR | C8: 37 | F8: 12 | J8: =+C8-E8-F8-G8-H8-I8+D8 -> 25
A9: 6 | B9: PUFFY MÜDÜR | C9: 18 | J9: =+C9-E9-F9-G9-H9-I9+D9 -> 18
A10: 7 | B10: KESİLMEMİŞ MÜDÜR KON | C10: 44 | D10: 41 | J10: =+C10-E10-F10-G10-H10-I10+D10 -> 85
A11: 8 | B11: CEZAR MÜDÜR | C11: 242 | D11: 177 | J11: =+C11-E11-F11-G11-H11-I11+D11 -> 419
A12: 9 | B12: CEZAR MİSAFİR | C12: 322 | D12: 60 | E12: 4 | J12: =+C12-E12-F12-G12-H12-I12+D12 -> 378
A13: 10 | B13: LENUX MİSAFİR | C13: 78 | J13: =+C13-E13-F13-G13-H13-I13+D13 -> 78
A14: 11 | B14: LENUX MÜDÜR | C14: 45 | J14: =+C14-E14-F14-G14-H14-I14+D14 -> 45
A15: 12 | B15: WARLCOK MÜDÜR | C15: 141 | E15: 1 | J15: =+C15-E15-F15-G15-H15-I15+D15 -> 140
A16: 13 | B16: WARLCOK MİSAFİR | C16: 50 | E16: 2 | J16: =+C16-E16-F16-G16-H16-I16+D16 -> 48
A17: 14 | B17: VİSİON MÜDÜR | C17: 234 | D17: 57 | E17: 4 | G17: 3 | J17: =+C17-E17-F17-G17-H17-I17+D17 -> 284
A18: 15 | B18: VİSİON MİSAFİR | C18: 205 | E18: 3 | G18: 4 | J18: =+C18-E18-F18-G18-H18-I18+D18 -> 198
A19: 16 | B19: PENTA MÜDÜR | C19: 111 | D19: 30 | J19: =+C19-E19-F19-G19-H19-I19+D19 -> 141
A20: 17 | B20: PENTA MİSAFİR | C20: 8 | J20: =+C20-E20-F20-G20-H20-I20+D20 -> 8
A21: 18 | B21: ACTİON MÜDÜR | C21: 15 | G21: 1 | J21: =+C21-E21-F21-G21-H21-I21+D21 -> 14
A22: 19 | B22: YENİ MODEL OTURAK | C22: 118 | J22: =+C22-E22-F22-G22-H22-I22+D22 -> 118
A23: 20 | B23: CARENS MÜDÜR KONT | C23: 38 | J23: =+C23-E23-F23-G23-H23-I23+D23 -> 38
A24: 21 | B24: GRAFTER MÜDÜR | C24: 7 | J24: =+C24-E24-F24-G24-H24-I24+D24 -> 7
A25: 22 | B25: GRAFTER MİSAFİR | C25: 42 | J25: =+C25-E25-F25-G25-H25-I25+D25 -> 42
A26: 23 | B26: ELNORA -LEGENT MÜDÜR | C26: 483 | J26: =+C26-E26-F26-G26-H26-I26+D26 -> 483
A27: 24 | B27: LEGENT MÜDÜR UZUN | C27: 62 | J27: =+C27-E27-F27-G27-H27-I27+D27 -> 62
A28: 25 | B28: ANFİ TAHTASI | C28: 13 | J28: =+C28-E28-F28-G28-H28-I28+D28 -> 13
A29: 26 | B29: VEGA SIRT | C29: 60 | J29: =+C29-E29-F29-G29-H29-I29+D29 -> 60
A30: 26 | B30: VEGA TABAN | C30: 78 | J30: =+C30-E30-F30-G30-H30-I30+D30 -> 78
A31: 27 | B31: VENESSA MİS.KONTRASI | C31: 293 | J31: =+C31-E31-F31-G31-H31-I31+D31 -> 293
A32: 28 | B32: POLİ DABAN | C32: 217 | D32: 87 | G32: 24 | J32: =+C32-E32-F32-G32-H32-I32+D32 -> 280
A33: 29 | B33: SANDALYE SIRT | C33: 17 | J33: =+C33-E33-F33-G33-H33-I33+D33 -> 17
A34: 30 | B34: SANDALYE DABAN | C34: 45 | J34: =+C34-E34-F34-G34-H34-I34+D34 -> 45
A35: 31 | B35: MİSAFİR SIRT | C35: 166 | J35: =+C35-E35-F35-G35-H35-I35+D35 -> 166
A36: 32 | B36: MİSAFİR OTURAK | C36: 538 | J36: =+C36-E36-F36-G36-H36-I36+D36 -> 538
A37: 33 | B37: VİVA DABAN | C37: 66 | J37: =+C37-E37-F37-G37-H37-I37+D37 -> 66
A38: 34 | B38: SENS MÜDÜR SIRT | C38: 36 | J38: =+C38-E38-F38-G38-H38-I38+D38 -> 36
A39: 35 | B39: ZEUGMA | C39: 24 | J39: =+C39-E39-F39-G39-H39-I39+D39 -> 24
A40: 36 | B40: SOVRANO MİSAFİR | C40: 10 | J40: =+C40-E40-F40-G40-H40-I40+D40 -> 10
...

Sheet ekim 1 hafta 
A1: TAHTA SAYIMI | J1: 44837
A2: S.NO | B2: CİNSİ | C2: DEVİR | D2: GELEN | E2: 44837 | F2: 44838 | G2: 44839 | H2: 44840 | I2: 44841 | J2: KALAN
A3: 1 | B3: SANDALYE TAHTASI | C3: 37 | J3: =+C3-E3-F3-G3-H3-I3+D3 -> 37
A4: 2 | B4: EKO KLAS MÜDÜR TAHTASI | C4: 3 | J4: =+C4-E4-F4-G4-H4-I4+D4 -> 3
A5: 3 | B5: KESİLMEMİŞTAHTA | C5: 107 | E5: 5 | J5: =+C5-E5-F5-G5-H5-I5+D5 -> 102
A6: 4 | B6: RECENT MİSAFİR | C6: 55 | J6: =+C6-E6-F6-G6-H6-I6+D6 -> 55
A7: 5 | B7: RECENT MÜDÜR | C7: 27 | J7: =+C7-E7-F7-G7-H7-I7+D7 -> 27
A8: 6 | B8: PUFFY MİSAFİR | C8: 25 | J8: =+C8-E8-F8-G8-H8-I8+D8 -> 25
A9: 6 | B9: PUFFY MÜDÜR | C9: 18 | J9: =+C9-E9-F9-G9-H9-I9+D9 -> 18
A10: 7 | B10: KESİLMEMİŞ MÜDÜR KON | C10: 85 | G10: 2 | J10: =+C10-E10-F10-G10-H10-I10+D10 -> 83
A11: 8 | B11: CEZAR MÜDÜR | C11: 419 | E11: 50 | F11: 91 | J11: =+C11-E11-F11-G11-H11-I11+D11 -> 278
A12: 9 | B12: CEZAR MİSAFİR | C12: 378 | E12: 90 | J12: =+C12-E12-F12-G12-H12-I12+D12 -> 288
A13: 10 | B13: LENUX MİSAFİR | C13: 78 | J13: =+C13-E13-F13-G13-H13-I13+D13 -> 78
A14: 11 | B14: LENUX MÜDÜR | C14: 45 | J14: =+C14-E14-F14-G14-H14-I14+D14 -> 45
A15: 12 | B15: WARLCOK MÜDÜR | C15: 140 | H15: 4 | J15: =+C15-E15-F15-G15-H15-I15+D15 -> 136
A16: 13 | B16: WARLCOK MİSAFİR | C16: 48 | H16: 48 | J16: =+C16-E16-F16-G16-H16-I16+D16 -> 0
A17: 14 | B17: VİSİON MÜDÜR | C17: 284 | G17: 4 | J17: =+C17-E17-F17-G17-H17-I17+D17 -> 280
A18: 15 | B18: VİSİON MİSAFİR | C18: 198 | G18: 6 | J18: =+C18-E18-F18-G18-H18-I18+D18 -> 192
A19: 16 | B19: PENTA MÜDÜR | C19: 141 | E19: 11 | J19: =+C19-E19-F19-G19-H19-I19+D19 -> 130
A20: 17 | B20: PENTA MİSAFİR | C20: 8 | J20: =+C20-E20-F20-G20-H20-I20+D20 -> 8
A21: 18 | B21: ACTİON MÜDÜR | C21: 14 | H21: 2 | J21: =+C21-E21-F21-G21-H21-I21+D21 -> 12
A22: 19 | B22: ACTİON MİSAFİR | C22: 17 | H22: 2 | J22: =+C22-E22-F22-G22-H22-I22+D22 -> 15
A23: 20 | B23: YENİ MODEL OTURAK | C23: 118 | J23: =+C23-E23-F23-G23-H23-I23+D23 -> 118
A24: 21 | B24: CARENS MÜDÜR KONT | C24: 38 | J24: =+C24-E24-F24-G24-H24-I24+D24 -> 38
A25: 22 | B25: GRAFTER MÜDÜR | C25: 7 | J25: =+C25-E25-F25-G25-H25-I25+D25 -> 7
A26: 23 | B26: GRAFTER MİSAFİR | C26: 42 | J26: =+C26-E26-F26-G26-H26-I26+D26 -> 42
A27: 24 | B27: ELNORA -LEGENT MÜDÜR | C27: 483 | J27: =+C27-E27-F27-G27-H27-I27+D27 -> 483
A28: 25 | B28: LEGENT MÜDÜR UZUN | C28: 62 | J28: =+C28-E28-F28-G28-H28-I28+D28 -> 62
A29: 26 | B29: ANFİ TAHTASI | C29: 13 | J29: =+C29-E29-F29-G29-H29-I29+D29 -> 13
A30: 27 | B30: VEGA SIRT | C30: 60 | J30: =+C30-E30-F30-G30-H30-I30+D30 -> 60
A31: 28 | B31: VEGA TABAN | C31: 78 | J31: =+C31-E31-F31-G31-H31-I31+D31 -> 78
A32: 29 | B32: VENESSA MİS.KONTRASI | C32: 293 | J32: =+C32-E32-F32-G32-H32-I32+D32 -> 293
A33: 30 | B33: POLİ DABAN | C33: 280 | G33: 40 | J33: =+C33-E33-F33-G33-H33-I33+D33 -> 240
A34: 31 | B34: SANDALYE SIRT | C34: 17 | J34: =+C34-E34-F34-G34-H34-I34+D34 -> 17
A35: 32 | B35: SANDALYE DABAN | C35: 45 | J35: =+C35-E35-F35-G35-H35-I35+D35 -> 45
A36: 33 | B36: MİSAFİR SIRT | C36: 166 | J36: =+C36-E36-F36-G36-H36-I36+D36 -> 166
A37: 34 | B37: MİSAFİR OTURAK | C37: 538 | J37: =+C37-E37-F37-G37-H37-I37+D37 -> 538
A38: 35 | B38: VİVA DABAN | C38: 66 | J38: =+C38-E38-F38-G38-H38-I38+D38 -> 66
A39: 36 | B39: SENS MÜDÜR SIRT | C39: 36 | J39: =+C39-E39-F39-G39-H39-I39+D39 -> 36
A40: 37 | B40: ZEUGMA | C40: 24 | J40: =+C40-E40-F40-G40-H40-I40+D40 -> 24
...

Sheet ekim 2 hafta 
A1: TAHTA SAYIMI | J1: 44837
A2: S.NO | B2: CİNSİ | C2: DEVİR | D2: GELEN | E2: 44844 | F2: 44845 | G2: 44846 | H2: 44847 | I2: 44848 | J2: KALAN
A3: 1 | B3: SANDALYE TAHTASI | C3: ='ekim 1 hafta '!J3 -> 37 | J3: =+C3-E3-F3-G3-H3-I3+D3 -> 37
A4: 2 | B4: EKO KLAS MÜDÜR TAHTASI | C4: ='ekim 1 hafta '!J4 -> 3 | J4: =+C4-E4-F4-G4-H4-I4+D4 -> 3
A5: 3 | B5: KESİLMEMİŞTAHTA | C5: ='ekim 1 hafta '!J5 -> 102 | F5: 5 | J5: =+C5-E5-F5-G5-H5-I5+D5 -> 97
A6: 4 | B6: RECENT MİSAFİR | C6: ='ekim 1 hafta '!J6 -> 55 | J6: =+C6-E6-F6-G6-H6-I6+D6 -> 55
A7: 5 | B7: RECENT MÜDÜR | C7: ='ekim 1 hafta '!J7 -> 27 | G7: 1 | J7: =+C7-E7-F7-G7-H7-I7+D7 -> 26
A8: 6 | B8: PUFFY MİSAFİR | C8: ='ekim 1 hafta '!J8 -> 25 | J8: =+C8-E8-F8-G8-H8-I8+D8 -> 25
A9: 6 | B9: PUFFY MÜDÜR | C9: ='ekim 1 hafta '!J9 -> 18 | J9: =+C9-E9-F9-G9-H9-I9+D9 -> 18
A10: 7 | B10: KESİLMEMİŞ MÜDÜR KON | C10: ='ekim 1 hafta '!J10 -> 83 | J10: =+C10-E10-F10-G10-H10-I10+D10 -> 83
A11: 8 | B11: CEZAR MÜDÜR | C11: ='ekim 1 hafta '!J11 -> 278 | D11: 34 | F11: 30 | J11: =+C11-E11-F11-G11-H11-I11+D11 -> 282
A12: 9 | B12: CEZAR MİSAFİR | C12: ='ekim 1 hafta '!J12 -> 288 | D12: 428 | J12: =+C12-E12-F12-G12-H12-I12+D12 -> 716
A13: 10 | B13: LENUX MİSAFİR | C13: ='ekim 1 hafta '!J13 -> 78 | J13: =+C13-E13-F13-G13-H13-I13+D13 -> 78
A14: 11 | B14: LENUX MÜDÜR | C14: ='ekim 1 hafta '!J14 -> 45 | J14: =+C14-E14-F14-G14-H14-I14+D14 -> 45
A15: 12 | B15: WARLCOK MÜDÜR | C15: ='ekim 1 hafta '!J15 -> 136 | F15: 12 | J15: =+C15-E15-F15-G15-H15-I15+D15 -> 124
A16: 13 | B16: WARLCOK MİSAFİR | C16: ='ekim 1 hafta '!J16 -> 0 | J16: =+C16-E16-F16-G16-H16-I16+D16 -> 0
A17: 14 | B17: VİSİON MÜDÜR | C17: ='ekim 1 hafta '!J17 -> 280 | D17: 27 | E17: 18 | F17: 15 | G17: 1 | H17: 2 | I17: 10 | J17: =+C17-E17-F17-G17-H17-I17+D17 -> 261
A18: 15 | B18: VİSİON MİSAFİR | C18: ='ekim 1 hafta '!J18 -> 192 | E18: 14 | H18: 10 | J18: =+C18-E18-F18-G18-H18-I18+D18 -> 168
A19: 16 | B19: PENTA MÜDÜR | C19: ='ekim 1 hafta '!J19 -> 130 | J19: =+C19-E19-F19-G19-H19-I19+D19 -> 130
A20: 17 | B20: PENTA MİSAFİR | C20: ='ekim 1 hafta '!J20 -> 8 | D20: 30 | J20: =+C20-E20-F20-G20-H20-I20+D20 -> 38
A21: 18 | B21: ACTİON MÜDÜR | C21: ='ekim 1 hafta '!J21 -> 12 | G21: 1 | J21: =+C21-E21-F21-G21-H21-I21+D21 -> 11
A22: 19 | B22: YENİ MODEL OTURAK | C22: ='ekim 1 hafta '!J22 -> 15 | F22: 3 | J22: =+C22-E22-F22-G22-H22-I22+D22 -> 12
A23: 20 | B23: CARENS MÜDÜR KONT | C23: ='ekim 1 hafta '!J23 -> 118 | D23: 14 | J23: =+C23-E23-F23-G23-H23-I23+D23 -> 132
A24: 21 | B24: GRAFTER MÜDÜR | C24: ='ekim 1 hafta '!J24 -> 38 | J24: =+C24-E24-F24-G24-H24-I24+D24 -> 38
A25: 22 | B25: GRAFTER MİSAFİR | C25: ='ekim 1 hafta '!J25 -> 7 | J25: =+C25-E25-F25-G25-H25-I25+D25 -> 7
A26: 23 | B26: ELNORA -LEGENT MÜDÜR | C26: ='ekim 1 hafta '!J26 -> 42 | D26: 199 | F26: 6 | J26: =+C26-E26-F26-G26-H26-I26+D26 -> 235
A27: 24 | B27: LEGENT MÜDÜR UZUN | C27: ='ekim 1 hafta '!J27 -> 483 | J27: =+C27-E27-F27-G27-H27-I27+D27 -> 483
A28: 25 | B28: ANFİ TAHTASI | C28: ='ekim 1 hafta '!J28 -> 62 | J28: =+C28-E28-F28-G28-H28-I28+D28 -> 62
A29: 26 | B29: VEGA SIRT | C29: ='ekim 1 hafta '!J29 -> 13 | J29: =+C29-E29-F29-G29-H29-I29+D29 -> 13
A30: 26 | B30: VEGA TABAN | C30: ='ekim 1 hafta '!J30 -> 60 | J30: =+C30-E30-F30-G30-H30-I30+D30 -> 60
A31: 27 | B31: VENESSA MİS.KONTRASI | C31: ='ekim 1 hafta '!J31 -> 78 | J31: =+C31-E31-F31-G31-H31-I31+D31 -> 78
A32: 28 | B32: POLİ DABAN | C32: ='ekim 1 hafta '!J32 -> 293 | G32: 100 | J32: =+C32-E32-F32-G32-H32-I32+D32 -> 193
A33: 29 | B33: SANDALYE SIRT | C33: ='ekim 1 hafta '!J33 -> 240 | J33: =+C33-E33-F33-G33-H33-I33+D33 -> 240
A34: 30 | B34: SANDALYE DABAN | C34: ='ekim 1 hafta '!J34 -> 17 | J34: =+C34-E34-F34-G34-H34-I34+D34 -> 17
A35: 31 | B35: MİSAFİR SIRT | C35: ='ekim 1 hafta '!J35 -> 45 | J35: =+C35-E35-F35-G35-H35-I35+D35 -> 45
A36: 32 | B36: MİSAFİR OTURAK | C36: ='ekim 1 hafta '!J36 -> 166 | J36: =+C36-E36-F36-G36-H36-I36+D36 -> 166
A37: 33 | B37: VİVA DABAN | C37: ='ekim 1 hafta '!J37 -> 538 | G37: 1 | J37: =+C37-E37-F37-G37-H37-I37+D37 -> 537
A38: 34 | B38: SENS MÜDÜR SIRT | C38: ='ekim 1 hafta '!J38 -> 66 | J38: =+C38-E38-F38-G38-H38-I38+D38 -> 66
A39: 35 | B39: ZEUGMA | C39: ='ekim 1 hafta '!J39 -> 36 | J39: =+C39-E39-F39-G39-H39-I39+D39 -> 36
A40: 36 | B40: SOVRANO MİSAFİR | C40: ='ekim 1 hafta '!J40 -> 24 | J40: =+C40-E40-F40-G40-H40-I40+D40 -> 24
...

Sheet ekim 3 hafta
A1: TAHTA SAYIMI | J1: 44837
A2: S.NO | B2: CİNSİ | C2: DEVİR | D2: GELEN | E2: 44851 | F2: 44852 | G2: 44853 | H2: 44854 | I2: 44855 | J2: KALAN
A3: 1 | B3: SANDALYE TAHTASI | C3: 37 | J3: =+C3-E3-F3-G3-H3-I3+D3 -> 37
A4: 2 | B4: EKO KLAS MÜDÜR TAHTASI | C4: 3 | J4: =+C4-E4-F4-G4-H4-I4+D4 -> 3
A5: 3 | B5: KESİLMEMİŞTAHTA | C5: 107 | J5: =+C5-E5-F5-G5-H5-I5+D5 -> 107
A6: 4 | B6: RECENT MİSAFİR | C6: 55 | J6: =+C6-E6-F6-G6-H6-I6+D6 -> 55
A7: 5 | B7: RECENT MÜDÜR | C7: 27 | J7: =+C7-E7-F7-G7-H7-I7+D7 -> 27
A8: 6 | B8: PUFFY MİSAFİR | C8: 25 | J8: =+C8-E8-F8-G8-H8-I8+D8 -> 25
A9: 6 | B9: PUFFY MÜDÜR | C9: 18 | J9: =+C9-E9-F9-G9-H9-I9+D9 -> 18
A10: 7 | B10: KESİLMEMİŞ MÜDÜR KON | C10: 83 | J10: =+C10-E10-F10-G10-H10-I10+D10 -> 83
A11: 8 | B11: CEZAR MÜDÜR | C11: 282 | I11: 50 | J11: =+C11-E11-F11-G11-H11-I11+D11 -> 232
A12: 9 | B12: CEZAR MİSAFİR | C12: 716 | E12: 23 | H12: 6 | I12: 54 | J12: =+C12-E12-F12-G12-H12-I12+D12 -> 633
A13: 10 | B13: LENUX MİSAFİR | C13: 78 | J13: =+C13-E13-F13-G13-H13-I13+D13 -> 78
A14: 11 | B14: LENUX MÜDÜR | C14: 45 | J14: =+C14-E14-F14-G14-H14-I14+D14 -> 45
A15: 12 | B15: WARLCOK MÜDÜR | C15: 124 | H15: 1 | J15: =+C15-E15-F15-G15-H15-I15+D15 -> 123
A16: 13 | B16: WARLCOK MİSAFİR | C16: 0 | J16: =+C16-E16-F16-G16-H16-I16+D16 -> 0
A17: 14 | B17: VİSİON MÜDÜR | C17: 261 | E17: 7 | F17: 5 | H17: 2 | I17: 1 | J17: =+C17-E17-F17-G17-H17-I17+D17 -> 246
A18: 15 | B18: VİSİON MİSAFİR | C18: 168 | F18: 4 | J18: =+C18-E18-F18-G18-H18-I18+D18 -> 164
A19: 16 | B19: PENTA MÜDÜR | C19: 130 | J19: =+C19-E19-F19-G19-H19-I19+D19 -> 130
A20: 17 | B20: PENTA MİSAFİR | C20: 38 | J20: =+C20-E20-F20-G20-H20-I20+D20 -> 38
A21: 18 | B21: ACTİON MÜDÜR | C21: 11 | F21: 2 | H21: 2 | I21: 1 | J21: =+C21-E21-F21-G21-H21-I21+D21 -> 6
A22: 19 | B22: YENİ MODEL OTURAK | C22: 12 | F22: 4 | H22: 6 | J22: =+C22-E22-F22-G22-H22-I22+D22 -> 2
A23: 20 | B23: CARENS MÜDÜR KONT | C23: 132 | H23: 1 | I23: 1 | J23: =+C23-E23-F23-G23-H23-I23+D23 -> 130
A24: 21 | B24: GRAFTER MÜDÜR | C24: 38 | J24: =+C24-E24-F24-G24-H24-I24+D24 -> 38
A25: 22 | B25: GRAFTER MİSAFİR | C25: 7 | J25: =+C25-E25-F25-G25-H25-I25+D25 -> 7
A26: 23 | B26: ELNORA -LEGENT MÜDÜR | C26: 235 | J26: =+C26-E26-F26-G26-H26-I26+D26 -> 235
A27: 24 | B27: LEGENT MÜDÜR UZUN | C27: 483 | J27: =+C27-E27-F27-G27-H27-I27+D27 -> 483
A28: 25 | B28: ANFİ TAHTASI | C28: 62 | J28: =+C28-E28-F28-G28-H28-I28+D28 -> 62
A29: 26 | B29: VEGA SIRT | C29: 13 | J29: =+C29-E29-F29-G29-H29-I29+D29 -> 13
A30: 26 | B30: VEGA TABAN | C30: 60 | J30: =+C30-E30-F30-G30-H30-I30+D30 -> 60
A31: 27 | B31: VENESSA MİS.KONTRASI | C31: 78 | J31: =+C31-E31-F31-G31-H31-I31+D31 -> 78
A32: 28 | B32: POLİ DABAN | C32: 193 | J32: =+C32-E32-F32-G32-H32-I32+D32 -> 193
A33: 29 | B33: SANDALYE SIRT | C33: 240 | J33: =+C33-E33-F33-G33-H33-I33+D33 -> 240
A34: 30 | B34: SANDALYE DABAN | C34: 17 | J34: =+C34-E34-F34-G34-H34-I34+D34 -> 17
A35: 31 | B35: MİSAFİR SIRT | C35: 45 | J35: =+C35-E35-F35-G35-H35-I35+D35 -> 45
... A40: 36 | B40: SOVRANO MİSAFİR | C40: 24 | J40: =+C40-E40-F40-G40-H40-I40+D40 -> 24
A41: 37 | B41: SOVRANO MÜDÜR | C41: 10 | I41: 1 | J41: =+C41-E41-F41-G41-H41-I41+D41 -> 9
A42: 38 | B42: POLO MİSAFİR | C42: 38 | E42: 2 | J42: =+C42-E42-F42-G42-H42-I42+D42 -> 36
A43: 39 | B43: POLO MÜDÜR | C43: 32 | E43: 2 | H43: 1 | I43: 1 | J43: =+C43-E43-F43-G43-H43-I43+D43 -> 28
A44: 40 | B44: ELNORA MİSAFİR | C44: 70 | H44: 3 | J44: =+C44-E44-F44-G44-H44-I44+D44 -> 67
...

Sheet ekim 4 hafta 
A1: TAHTA SAYIMI | J1: 44837
A2: S.NO | B2: CİNSİ | C2: DEVİR | D2: GELEN | E2: 44858 | F2: 44859 | G2: 44860 | H2: 44861 | I2: 44862 | J2: KALAN
A3: 1 | B3: SANDALYE TAHTASI | C3: ='ekim 3 hafta'!J3 -> 37 | J3: =+C3-E3-F3-G3-H3-I3+D3 -> 37
A4: 2 | B4: EKO KLAS MÜDÜR TAHTASI | C4: ='ekim 3 hafta'!J4 -> 3 | J4: =+C4-E4-F4-G4-H4-I4+D4 -> 3
A5: 3 | B5: KESİLMEMİŞTAHTA | C5: ='ekim 3 hafta'!J5 -> 107 | F5: 2 | J5: =+C5-E5-F5-G5-H5-I5+D5 -> 105
A6: 4 | B6: RECENT MİSAFİR | C6: ='ekim 3 hafta'!J6 -> 55 | J6: =+C6-E6-F6-G6-H6-I6+D6 -> 55
A7: 5 | B7: RECENT MÜDÜR | C7: ='ekim 3 hafta'!J7 -> 27 | J7: =+C7-E7-F7-G7-H7-I7+D7 -> 27
A8: 6 | B8: PUFFY MİSAFİR | C8: ='ekim 3 hafta'!J8 -> 25 | I8: 4 | J8: =+C8-E8-F8-G8-H8-I8+D8 -> 21
A9: 6 | B9: PUFFY MÜDÜR | C9: ='ekim 3 hafta'!J9 -> 18 | I9: 2 | J9: =+C9-E9-F9-G9-H9-I9+D9 -> 16
A10: 7 | B10: KESİLMEMİŞ MÜDÜR KON | C10: ='ekim 3 hafta'!J10 -> 83 | J10: =+C10-E10-F10-G10-H10-I10+D10 -> 83
A11: 8 | B11: CEZAR MÜDÜR | C11: 122 | E11: 48 | J11: =+C11-E11-F11-G11-H11-I11+D11 -> 74
A12: 9 | B12: CEZAR MİSAFİR | C12: ='ekim 3 hafta'!J12 -> 633 | F12: 50 | J12: =+C12-E12-F12-G12-H12-I12+D12 -> 583
A13: 10 | B13: LENUX MİSAFİR | C13: ='ekim 3 hafta'!J13 -> 78 | J13: =+C13-E13-F13-G13-H13-I13+D13 -> 78
A14: 11 | B14: LENUX MÜDÜR | C14: ='ekim 3 hafta'!J14 -> 45 | J14: =+C14-E14-F14-G14-H14-I14+D14 -> 45
A15: 12 | B15: WARLCOK MÜDÜR | C15: 85 | J15: =+C15-E15-F15-G15-H15-I15+D15 -> 85
A16: 13 | B16: WARLCOK MİSAFİR | C16: ='ekim 3 hafta'!J16 -> 0 | D16: 28 | J16: =+C16-E16-F16-G16-H16-I16+D16 -> 28
A17: 14 | B17: VİSİON MÜDÜR | C17: ='ekim 3 hafta'!J17 -> 246 | E17: 5 | H17: 2 | I17: 1 | J17: =+C17-E17-F17-G17-H17-I17+D17 -> 238
A18: 15 | B18: VİSİON MİSAFİR | C18: 124 | H18: 4 | J18: =+C18-E18-F18-G18-H18-I18+D18 -> 120
A19: 16 | B19: PENTA MÜDÜR | C19: 120 | E19: 2 | J19: =+C19-E19-F19-G19-H19-I19+D19 -> 118
A20: 17 | B20: PENTA MİSAFİR | C20: ='ekim 3 hafta'!J20 -> 38 | D20: 35 | J20: =+C20-E20-F20-G20-H20-I20+D20 -> 73
A21: 18 | B21: ACTİON MÜDÜR | C21: ='ekim 3 hafta'!J21 -> 6 | G21: 2 | H21: 2 | I21: 2 | J21: =+C21-E21-F21-G21-H21-I21+D21 -> 0
A22: 19 | B22: YENİ MODEL OTURAK | C22: ='ekim 3 hafta'!J22 -> 2 | I22: 1 | J22: =+C22-E22-F22-G22-H22-I22+D22 -> 1
A23: 20 | B23: CARENS MÜDÜR KONT | C23: ='ekim 3 hafta'!J23 -> 130 | J23: =+C23-E23-F23-G23-H23-I23+D23 -> 130
A24: 21 | B24: GRAFTER MÜDÜR | C24: ='ekim 3 hafta'!J24 -> 38 | J24: =+C24-E24-F24-G24-H24-I24+D24 -> 38
A25: 22 | B25: GRAFTER MİSAFİR | C25: ='ekim 3 hafta'!J25 -> 7 | J25: =+C25-E25-F25-G25-H25-I25+D25 -> 7
A26: 23 | B26: ELNORA -LEGENT MÜDÜR | C26: ='ekim 3 hafta'!J26 -> 235 | E26: 12 | J26: =+C26-E26-F26-G26-H26-I26+D26 -> 223
A27: 24 | B27: LEGENT MÜDÜR UZUN | C27: ='ekim 3 hafta'!J27 -> 483 | J27: =+C27-E27-F27-G27-H27-I27+D27 -> 483
A28: 25 | B28: ANFİ TAHTASI | C28: ='ekim 3 hafta'!J28 -> 62 | J28: =+C28-E28-F28-G28-H28-I28+D28 -> 62
A29: 26 | B29: VEGA SIRT | C29: ='ekim 3 hafta'!J29 -> 13 | J29: =+C29-E29-F29-G29-H29-I29+D29 -> 13
A30: 26 | B30: VEGA TABAN | C30: ='ekim 3 hafta'!J30 -> 60 | J30: =+C30-E30-F30-G30-H30-I30+D30 -> 60
A31: 27 | B31: VENESSA MİS.KONTRASI | C31: ='ekim 3 hafta'!J31 -> 78 | J31: =+C31-E31-F31-G31-H31-I31+D31 -> 78
A32: 28 | B32: POLİ DABAN | C32: ='ekim 3 hafta'!J32 -> 193 | D32: 515 | E32: 70 | J32: =+C32-E32-F32-G32-H32-I32+D32 -> 638
A33: 29 | B33: SANDALYE SIRT | C33: ='ekim 3 hafta'!J33 -> 240 | J33: =+C33-E33-F33-G33-H33-I33+D33 -> 240
A34: 30 | B34: SANDALYE DABAN | C34: ='ekim 3 hafta'!J34 -> 17 | J34: =+C34-E34-F34-G34-H34-I34+D34 -> 17
A35: 31 | B35: MİSAFİR SIRT | C35: ='ekim 3 hafta'!J35 -> 45 | E35: 16 | J35: =+C35-E35-F35-G35-H35-I35+D35 -> 29
A36: 32 | B36: MİSAFİR OTURAK | C36: ='ekim 3 hafta'!J36 -> 166 | J36: =+C36-E36-F36-G36-H36-I36+D36 -> 166
A37: 33 | B37: VİVA DABAN | C37: ='ekim 3 hafta'!J37 -> 537 | J37: =+C37-E37-F37-G37-H37-I37+D37 -> 537
A38: 34 | B38: SENS MÜDÜR SIRT | C38: ='ekim 3 hafta'!J38 -> 66 | J38: =+C38-E38-F38-G38-H38-I38+D38 -> 66
A39: 35 | B39: ZEUGMA | C39: ='ekim 3 hafta'!J39 -> 36 | J39: =+C39-E39-F39-G39-H39-I39+D39 -> 36
A40: 36 | B40: SOVRANO MİSAFİR | C40: ='ekim 3 hafta'!J40 -> 24 | J40: =+C40-E40-F40-G40-H40-I40+D40 -> 24
...

Sheet KASIM 1 HAFTA
A1: TAHTA SAYIMI | J1: 44837
A2: S.NO | B2: CİNSİ | C2: DEVİR | D2: GELEN | E2: 44865 | F2: 44866 | G2: 44867 | H2: 44868 | I2: 44869 | J2: KALAN
A3: 1 | B3: SANDALYE TAHTASI | C3: ='ekim 4 hafta '!J3 -> 37 | J3: =+C3-E3-F3-G3-H3-I3+D3 -> 37
A4: 2 | B4: EKO KLAS MÜDÜR TAHTASI | C4: ='ekim 4 hafta '!J4 -> 3 | J4: =+C4-E4-F4-G4-H4-I4+D4 -> 3
A5: 3 | B5: KESİLMEMİŞTAHTA | C5: ='ekim 4 hafta '!J5 -> 105 | J5: =+C5-E5-F5-G5-H5-I5+D5 -> 105
A6: 4 | B6: RECENT MİSAFİR | C6: ='ekim 4 hafta '!J6 -> 55 | J6: =+C6-E6-F6-G6-H6-I6+D6 -> 55
A7: 5 | B7: RECENT MÜDÜR | C7: ='ekim 4 hafta '!J7 -> 27 | J7: =+C7-E7-F7-G7-H7-I7+D7 -> 27
A8: 6 | B8: PUFFY MİSAFİR | C8: ='ekim 4 hafta '!J8 -> 21 | J8: =+C8-E8-F8-G8-H8-I8+D8 -> 21
A9: 6 | B9: PUFFY MÜDÜR | C9: ='ekim 4 hafta '!J9 -> 16 | J9: =+C9-E9-F9-G9-H9-I9+D9 -> 16
A10: 7 | B10: KESİLMEMİŞ MÜDÜR KON | C10: ='ekim 4 hafta '!J10 -> 83 | J10: =+C10-E10-F10-G10-H10-I10+D10 -> 83
A11: 8 | B11: CEZAR MÜDÜR | C11: ='ekim 4 hafta '!J11 -> 74 | F11: 10 | J11: =+C11-E11-F11-G11-H11-I11+D11 -> 64
A12: 9 | B12: CEZAR MİSAFİR | C12: ='ekim 4 hafta '!J12 -> 583 | F12: 25 | J12: =+C12-E12-F12-G12-H12-I12+D12 -> 558
A13: 10 | B13: LENUX MİSAFİR | C13: ='ekim 4 hafta '!J13 -> 78 | J13: =+C13-E13-F13-G13-H13-I13+D13 -> 78
A14: 11 | B14: LENUX MÜDÜR | C14: ='ekim 4 hafta '!J14 -> 45 | H14: 3 | J14: =+C14-E14-F14-G14-H14-I14+D14 -> 42
A15: 12 | B15: WARLCOK MÜDÜR | C15: ='ekim 4 hafta '!J15 -> 85 | J15: =+C15-E15-F15-G15-H15-I15+D15 -> 85
A16: 13 | B16: WARLCOK MİSAFİR | C16: ='ekim 4 hafta '!J16 -> 28 | J16: =+C16-E16-F16-G16-H16-I16+D16 -> 28
A17: 14 | B17: VİSİON MÜDÜR | C17: ='ekim 4 hafta '!J17 -> 238 | F17: 15 | H17: 5 | J17: =+C17-E17-F17-G17-H17-I17+D17 -> 218
A18: 15 | B18: VİSİON MİSAFİR | C18: ='ekim 4 hafta '!J18 -> 120 | F18: 25 | J18: =+C18-E18-F18-G18-H18-I18+D18 -> 95
A19: 16 | B19: PENTA MÜDÜR | C19: ='ekim 4 hafta '!J19 -> 118 | H19: 10 | J19: =+C19-E19-F19-G19-H19-I19+D19 -> 108
A20: 17 | B20: PENTA MİSAFİR | C20: ='ekim 4 hafta '!J20 -> 73 | H20: 6 | J20: =+C20-E20-F20-G20-H20-I20+D20 -> 67
A21: 18 | B21: ACTİON MÜDÜR | C21: ='ekim 4 hafta '!J21 -> 0 | J21: =+C21-E21-F21-G21-H21-I21+D21 -> 0
A22: 19 | B22: YENİ MODEL OTURAK | C22: ='ekim 4 hafta '!J22 -> 1 | J22: =+C22-E22-F22-G22-H22-I22+D22 -> 1
A23: 20 | B23: CARENS MÜDÜR KONT | C23: ='ekim 4 hafta '!J23 -> 130 | J23: =+C23-E23-F23-G23-H23-I23+D23 -> 130
A24: 21 | B24: GRAFTER MÜDÜR | C24: ='ekim 4 hafta '!J24 -> 38 | J24: =+C24-E24-F24-G24-H24-I24+D24 -> 38
A25: 22 | B25: GRAFTER MİSAFİR | C25: ='ekim 4 hafta '!J25 -> 7 | J25: =+C25-E25-F25-G25-H25-I25+D25 -> 7
A26: 23 | B26: ELNORA -LEGENT MÜDÜR | C26: ='ekim 4 hafta '!J26 -> 223 | J26: =+C26-E26-F26-G26-H26-I26+D26 -> 223
A27: 24 | B27: LEGENT MÜDÜR UZUN | C27: ='ekim 4 hafta '!J27 -> 483 | J27: =+C27-E27-F27-G27-H27-I27+D27 -> 483
A28: 25 | B28: ANFİ TAHTASI | C28: ='ekim 4 hafta '!J28 -> 62 | J28: =+C28-E28-F28-G28-H28-I28+D28 -> 62
A29: 26 | B29: VEGA SIRT | C29: ='ekim 4 hafta '!J29 -> 13 | J29: =+C29-E29-F29-G29-H29-I29+D29 -> 13
A30: 26 | B30: VEGA TABAN | C30: ='ekim 4 hafta '!J30 -> 60 | J30: =+C30-E30-F30-G30-H30-I30+D30 -> 60
A31: 27 | B31: VENESSA MİS.KONTRASI | C31: ='ekim 4 hafta '!J31 -> 78 | J31: =+C31-E31-F31-G31-H31-I31+D31 -> 78
A32: 28 | B32: POLİ DABAN | C32: ='ekim 4 hafta '!J32 -> 638 | J32: =+C32-E32-F32-G32-H32-I32+D32 -> 638
... A40: 36 | B40: SOVRANO MİSAFİR | C40: ='ekim 4 hafta '!J40 -> 24 | J40: =+C40-E40-F40-G40-H40-I40+D40 -> 24
A41: 37 | B41: SOVRANO MÜDÜR | C41: ='ekim 4 hafta '!J41 -> 9 | H41: 9 | J41: =+C41-E41-F41-G41-H41-I41+D41 -> 0
A42: 38 | B42: POLO MİSAFİR | C42: ='ekim 4 hafta '!J42 -> 58 | J42: =+C42-E42-F42-G42-H42-I42+D42 -> 58
A43: 39 | B43: POLO MÜDÜR | C43: ='ekim 4 hafta '!J43 -> 42 | H43: 11 | J43: =+C43-E43-F43-G43-H43-I43+D43 -> 31
A44: 40 | B44: ELNORA MİSAFİR | C44: ='ekim 4 hafta '!J44 -> 67 | J44: =+C44-E44-F44-G44-H44-I44+D44 -> 67
A45: 41 | B45: STELL MİSAFİR | C45: ='ekim 4 hafta '!J45 -> 150 | J45: =+C45-E45-F45-G45-H45-I45+D45 -> 150
A46: 42 | B46: GRANADA MİSAFİR | C46: ='ekim 4 hafta '!J46 -> 42 | J46: =+C46-E46-F46-G46-H46-I46+D46 -> 42
A47: 43 | B47: NOWEL MİSAFİR | C47: ='ekim 4 hafta '!J47 -> 67 | J47: =+C47-E47-F47-G47-H47-I47+D47 -> 67
...

Sheet KASIM 2 HAFTA 
A1: TAHTA SAYIMI | J1: 44837
A2: S.NO | B2: CİNSİ | C2: DEVİR | D2: GELEN | E2: 44872 | F2: 44873 | G2: 44874 | H2: 44875 | I2: 44876 | J2: KALAN | K2: MİNİMUN | L2: MAXSİMUN
A3: 1 | B3: SANDALYE TAHTASI | C3: ='KASIM 1 HAFTA'!J3 -> 37 | J3: =+C3-E3-F3-G3-H3-I3+D3 -> 37 | K3: 0
A4: 2 | B4: EKO KLAS MÜDÜR TAHTASI | C4: ='KASIM 1 HAFTA'!J4 -> 3 | J4: =+C4-E4-F4-G4-H4-I4+D4 -> 3 | K4: 0
A5: 3 | B5: KESİLMEMİŞTAHTA | C5: ='KASIM 1 HAFTA'!J5 -> 105 | J5: =+C5-E5-F5-G5-H5-I5+D5 -> 105 | K5: 0
A6: 4 | B6: RECENT MİSAFİR | C6: ='KASIM 1 HAFTA'!J6 -> 55 | J6: =+C6-E6-F6-G6-H6-I6+D6 -> 55 | K6: 30 | L6: 100
A7: 5 | B7: RECENT MÜDÜR | C7: ='KASIM 1 HAFTA'!J7 -> 27 | F7: 3 | J7: =+C7-E7-F7-G7-H7-I7+D7 -> 24 | K7: 30 | L7: 100
A8: 6 | B8: PUFFY MİSAFİR | C8: ='KASIM 1 HAFTA'!J8 -> 21 | J8: =+C8-E8-F8-G8-H8-I8+D8 -> 21 | K8: 15 | L8: 50
A9: 7 | B9: PUFFY MÜDÜR | C9: ='KASIM 1 HAFTA'!J9 -> 16 | H9: 2 | J9: =+C9-E9-F9-G9-H9-I9+D9 -> 14 | K9: 15 | L9: 30
A10: 8 | B10: KESİLMEMİŞ MÜDÜR KON | C10: ='KASIM 1 HAFTA'!J10 -> 83 | J10: =+C10-E10-F10-G10-H10-I10+D10 -> 83 | K10: 0
A11: 9 | B11: CEZAR MÜDÜR | C11: ='KASIM 1 HAFTA'!J11 -> 64 | D11: 3 | J11: =+C11-E11-F11-G11-H11-I11+D11 -> 67 | K11: 150 | L11: 500
A12: 10 | B12: CEZAR MİSAFİR | C12: ='KASIM 1 HAFTA'!J12 -> 558 | J12: =+C12-E12-F12-G12-H12-I12+D12 -> 558 | K12: 200 | L12: 750
A13: 11 | B13: LENUX MİSAFİR | C13: ='KASIM 1 HAFTA'!J13 -> 78 | J13: =+C13-E13-F13-G13-H13-I13+D13 -> 78 | K13: 10 | L13: 30
A14: 12 | B14: LENUX MÜDÜR | C14: ='KASIM 1 HAFTA'!J14 -> 42 | J14: =+C14-E14-F14-G14-H14-I14+D14 -> 42 | K14: 10 | L14: 20
A15: 13 | B15: WARLCOK MÜDÜR | C15: ='KASIM 1 HAFTA'!J15 -> 85 | D15: 32 | G15: 1 | H15: 18 | J15: =+C15-E15-F15-G15-H15-I15+D15 -> 98 | K15: 10 | L15: 20
A16: 14 | B16: WARLCOK MİSAFİR | C16: ='KASIM 1 HAFTA'!J16 -> 28 | H16: 28 | J16: =+C16-E16-F16-G16-H16-I16+D16 -> 0 | K16: 10 | L16: 20
A17: 15 | B17: VİSİON MÜDÜR | C17: ='KASIM 1 HAFTA'!J17 -> 218 | D17: 22 | E17: 7 | F17: 3 | G17: 4 | J17: =+C17-E17-F17-G17-H17-I17+D17 -> 226 | K17: 50 | L17: 200
A18: 16 | B18: VİSİON MİSAFİR | C18: ='KASIM 1 HAFTA'!J18 -> 95 | D18: 6 | I18: 8 | J18: =+C18-E18-F18-G18-H18-I18+D18 -> 93 | K18: 50 | L18: 150
A19: 17 | B19: PENTA MÜDÜR | C19: ='KASIM 1 HAFTA'!J19 -> 108 | G19: 1 | J19: =+C19-E19-F19-G19-H19-I19+D19 -> 107 | K19: 30 | L19: 100
A20: 18 | B20: PENTA MİSAFİR | C20: ='KASIM 1 HAFTA'!J20 -> 67 | G20: 1 | J20: =+C20-E20-F20-G20-H20-I20+D20 -> 66 | K20: 30 | L20: 100
A21: 19 | B21: ACTİON MÜDÜR | C21: ='KASIM 1 HAFTA'!J21 -> 0 | D21: 20 | H21: 1 | J21: =+C21-E21-F21-G21-H21-I21+D21 -> 19 | K21: 20 | L21: 50
A22: 20 | B22: TELLY OTURAK TAHTASI | C22: 0 | D22: 143 | H22: 3 | J22: =+C22-E22-F22-G22-H22-I22+D22 -> 140 | K22: 100 | L22: 300
A23: 21 | B23: CARENS MÜDÜR KONT | C23: ='KASIM 1 HAFTA'!J23 -> 130 | J23: =+C23-E23-F23-G23-H23-I23+D23 -> 130 | K23: 5 | L23: 10
A24: 22 | B24: GRAFTER MÜDÜR | C24: ='KASIM 1 HAFTA'!J24 -> 38 | J24: =+C24-E24-F24-G24-H24-I24+D24 -> 38 | K24: 5 | L24: 10
A25: 23 | B25: GRAFTER MİSAFİR | C25: ='KASIM 1 HAFTA'!J25 -> 7 | J25: =+C25-E25-F25-G25-H25-I25+D25 -> 7 | K25: 5 | L25: 10
A26: 24 | B26: ELNORA -LEGENT MÜDÜR | C26: ='KASIM 1 HAFTA'!J26 -> 223 | J26: =+C26-E26-F26-G26-H26-I26+D26 -> 223 | K26: 100 | L26: 200
A27: 25 | B27: LEGENT MÜDÜR UZUN | C27: ='KASIM 1 HAFTA'!J27 -> 483 | J27: =+C27-E27-F27-G27-H27-I27+D27 -> 483 | K27: 0
A28: 26 | B28: ANFİ TAHTASI | C28: ='KASIM 1 HAFTA'!J28 -> 62 | J28: =+C28-E28-F28-G28-H28-I28+D28 -> 62 | K28: 0
A29: 27 | B29: VEGA SIRT | C29: ='KASIM 1 HAFTA'!J29 -> 13 | J29: =+C29-E29-F29-G29-H29-I29+D29 -> 13 | K29: 0
A30: 28 | B30: VEGA TABAN | C30: ='KASIM 1 HAFTA'!J30 -> 60 | J30: =+C30-E30-F30-G30-H30-I30+D30 -> 60 | K30: 0
A31: 29 | B31: VENESSA MİS.KONTRASI | C31: 290 | E31: 290 | J31: =+C31-E31-F31-G31-H31-I31+D31 -> 0 | K31: 0
A32: 30 | B32: POLİ DABAN | C32: ='KASIM 1 HAFTA'!J32 -> 638 | J32: =+C32-E32-F32-G32-H32-I32+D32 -> 638 | K32: 200 | L32: 400
A33: 31 | B33: SANDALYE SIRT | C33: ='KASIM 1 HAFTA'!J33 -> 240 | J33: =+C33-E33-F33-G33-H33-I33+D33 -> 240 | K33: 0
A34: 32 | B34: SANDALYE DABAN | C34: ='KASIM 1 HAFTA'!J34 -> 17 | J34: =+C34-E34-F34-G34-H34-I34+D34 -> 17 | K34: 0
A35: 33 | B35: MİSAFİR SIRT | C35: ='KASIM 1 HAFTA'!J35 -> 29 | J35: =+C35-E35-F35-G35-H35-I35+D35 -> 29 | K35: 0
A36: 34 | B36: VİVA DABAN | C36: ='KASIM 1 HAFTA'!J37 -> 537 | J36: =+C36-E36-F36-G36-H36-I36+D36 -> 537 | K36: 0
A37: 35 | B37: SENS MÜDÜR SIRT | C37: ='KASIM 1 HAFTA'!J38 -> 66 | D37: 67 | J37: =+C37-E37-F37-G37-H37-I37+D37 -> 133 | K37: 10 | L37: 30
A38: 36 | B38: ZEUGMA | C38: ='KASIM 1 HAFTA'!J39 -> 36 | J38: =+C38-E38-F38-G38-H38-I38+D38 -> 36 | K38: 10 | L38: 20
A39: 37 | B39: SOVRANO MİSAFİR | C39: ='KASIM 1 HAFTA'!J40 -> 24 | J39: =+C39-E39-F39-G39-H39-I39+D39 -> 24 | K39: 10 | L39: 30
A40: 38 | B40: SOVRANO MÜDÜR | C40: ='KASIM 1 HAFTA'!J41 -> 0 | D40: 94 | E40: 46 | F40: 1 | J40: =+C40-E40-F40-G40-H40-I40+D40 -> 47 | K40: 20 | L40: 40
...

Sheet KASIM 3 HAFTA 
A1: TAHTA SAYIMI | L1: 44837
A2: S.NO | B2: CİNSİ | C2: DEVİR | D2: GELEN | E2: 44879 | F2: 44880 | G2: 44881 | H2: 44882 | I2: 44883 | J2: KALAN | K2: MİNİMUN | L2: MAXSİMUN
A3: 1 | B3: SANDALYE TAHTASI | C3: ='KASIM 2 HAFTA '!J3 -> 37 | J3: =+C3-E3-F3-G3-H3-I3+D3 -> 37 | K3: 0
A4: 2 | B4: EKO KLAS MÜDÜR TAHTASI | C4: ='KASIM 2 HAFTA '!J4 -> 3 | J4: =+C4-E4-F4-G4-H4-I4+D4 -> 3 | K4: 0
A5: 3 | B5: KESİLMEMİŞTAHTA | C5: ='KASIM 2 HAFTA '!J5 -> 105 | J5: =+C5-E5-F5-G5-H5-I5+D5 -> 105 | K5: 0
A6: 4 | B6: RECENT MİSAFİR | C6: ='KASIM 2 HAFTA '!J6 -> 55 | J6: =+C6-E6-F6-G6-H6-I6+D6 -> 55 | K6: 30 | L6: 100
A7: 5 | B7: RECENT MÜDÜR | C7: ='KASIM 2 HAFTA '!J7 -> 24 | E7: 7 | J7: =+C7-E7-F7-G7-H7-I7+D7 -> 17 | K7: 30 | L7: 100
A8: 6 | B8: PUFFY MİSAFİR | C8: ='KASIM 2 HAFTA '!J8 -> 21 | J8: =+C8-E8-F8-G8-H8-I8+D8 -> 21 | K8: 15 | L8: 50
A9: 7 | B9: PUFFY MÜDÜR | C9: ='KASIM 2 HAFTA '!J9 -> 14 | H9: 2 | J9: =+C9-E9-F9-G9-H9-I9+D9 -> 12 | K9: 15 | L9: 30
A10: 8 | B10: KESİLMEMİŞ MÜDÜR KON | C10: ='KASIM 2 HAFTA '!J10 -> 83 | J10: =+C10-E10-F10-G10-H10-I10+D10 -> 83 | K10: 0
A11: 9 | B11: CEZAR MÜDÜR | C11: ='KASIM 2 HAFTA '!J11 -> 67 | H11: 5 | I11: 30 | J11: =+C11-E11-F11-G11-H11-I11+D11 -> 32 | K11: 150 | L11: 500
A12: 10 | B12: CEZAR MİSAFİR | C12: ='KASIM 2 HAFTA '!J12 -> 558 | J12: =+C12-E12-F12-G12-H12-I12+D12 -> 558 | K12: 200 | L12: 750
A13: 11 | B13: LENUX MİSAFİR | C13: ='KASIM 2 HAFTA '!J13 -> 78 | J13: =+C13-E13-F13-G13-H13-I13+D13 -> 78 | K13: 10 | L13: 30
A14: 12 | B14: LENUX MÜDÜR | C14: ='KASIM 2 HAFTA '!J14 -> 42 | J14: =+C14-E14-F14-G14-H14-I14+D14 -> 42 | K14: 10 | L14: 20
A15: 13 | B15: WARLCOK MÜDÜR | C15: ='KASIM 2 HAFTA '!J15 -> 98 | J15: =+C15-E15-F15-G15-H15-I15+D15 -> 98 | K15: 10 | L15: 20
A16: 14 | B16: WARLCOK MİSAFİR | C16: ='KASIM 2 HAFTA '!J16 -> 0 | J16: =+C16-E16-F16-G16-H16-I16+D16 -> 0 | K16: 10 | L16: 20
A17: 15 | B17: VİSİON MÜDÜR | C17: ='KASIM 2 HAFTA '!J17 -> 226 | F17: 44 | H17: 2 | I17: 24 | J17: =+C17-E17-F17-G17-H17-I17+D17 -> 156 | K17: 50 | L17: 200
A18: 16 | B18: VİSİON MİSAFİR | C18: ='KASIM 2 HAFTA '!J18 -> 93 | F18: 42 | I18: 16 | J18: =+C18-E18-F18-G18-H18-I18+D18 -> 35 | K18: 50 | L18: 150
A19: 17 | B19: PENTA MÜDÜR | C19: ='KASIM 2 HAFTA '!J19 -> 107 | E19: 13 | J19: =+C19-E19-F19-G19-H19-I19+D19 -> 94 | K19: 30 | L19: 100
A20: 18 | B20: PENTA MİSAFİR | C20: ='KASIM 2 HAFTA '!J20 -> 66 | E20: 6 | J20: =+C20-E20-F20-G20-H20-I20+D20 -> 60 | K20: 30 | L20: 100
A21: 19 | B21: ACTİON MÜDÜR | C21: ='KASIM 2 HAFTA '!J21 -> 19 | H21: 2 | I21: 1 | J21: =+C21-E21-F21-G21-H21-I21+D21 -> 16 | K21: 20 | L21: 50
A22: 20 | B22: TELLY OTURAK TAHTASI | C22: ='KASIM 2 HAFTA '!J22 -> 140 | J22: =+C22-E22-F22-G22-H22-I22+D22 -> 140 | K22: 100 | L22: 300
A23: 21 | B23: CARENS MÜDÜR KONT | C23: ='KASIM 2 HAFTA '!J23 -> 130 | J23: =+C23-E23-F23-G23-H23-I23+D23 -> 130 | K23: 5 | L23: 10
A24: 22 | B24: GRAFTER MÜDÜR | C24: ='KASIM 2 HAFTA '!J24 -> 38 | J24: =+C24-E24-F24-G24-H24-I24+D24 -> 38 | K24: 5 | L24: 10
A25: 23 | B25: GRAFTER MİSAFİR | C25: ='KASIM 2 HAFTA '!J25 -> 7 | J25: =+C25-E25-F25-G25-H25-I25+D25 -> 7 | K25: 5 | L25: 10
A26: 24 | B26: ELNORA -LEGENT MÜDÜR | C26: ='KASIM 2 HAFTA '!J26 -> 223 | J26: =+C26-E26-F26-G26-H26-I26+D26 -> 223 | K26: 100 | L26: 200
A27: 25 | B27: LEGENT MÜDÜR UZUN | C27: ='KASIM 2 HAFTA '!J27 -> 483 | J27: =+C27-E27-F27-G27-H27-I27+D27 -> 483 | K27: 0
A28: 26 | B28: ANFİ TAHTASI | C28: ='KASIM 2 HAFTA '!J28 -> 62 | J28: =+C28-E28-F28-G28-H28-I28+D28 -> 62 | K28: 0
A29: 27 | B29: VEGA SIRT | C29: ='KASIM 2 HAFTA '!J29 -> 13 | J29: =+C29-E29-F29-G29-H29-I29+D29 -> 13 | K29: 0
A30: 28 | B30: VEGA TABAN | C30: ='KASIM 2 HAFTA '!J30 -> 60 | J30: =+C30-E30-F30-G30-H30-I30+D30 -> 60 | K30: 0
A31: 29 | B31: VENESSA MİS.KONTRASI | C31: ='KASIM 2 HAFTA '!J31 -> 0 | J31: =+C31-E31-F31-G31-H31-I31+D31 -> 0 | K31: 0
A32: 30 | B32: POLİ DABAN | C32: ='KASIM 2 HAFTA '!J32 -> 638 | J32: =+C32-E32-F32-G32-H32-I32+D32 -> 638 | K32: 200 | L32: 400
A33: 31 | B33: SANDALYE SIRT | C33: ='KASIM 2 HAFTA '!J33 -> 240 | J33: =+C33-E33-F33-G33-H33-I33+D33 -> 240 | K33: 0
A34: 32 | B34: SANDALYE DABAN | C34: ='KASIM 2 HAFTA '!J34 -> 17 | J34: =+C34-E34-F34-G34-H34-I34+D34 -> 17 | K34: 0
A35: 33 | B35: MİSAFİR SIRT | C35: ='KASIM 2 HAFTA '!J35 -> 29 | J35: =+C35-E35-F35-G35-H35-I35+D35 -> 29 | K35: 0
A36: 34 | B36: VİVA DABAN | C36: ='KASIM 2 HAFTA '!J36 -> 537 | J36: =+C36-E36-F36-G36-H36-I36+D36 -> 537 | K36: 0
A37: 35 | B37: SENS MÜDÜR SIRT | C37: ='KASIM 2 HAFTA '!J37 -> 133 | E37: 6 | J37: =+C37-E37-F37-G37-H37-I37+D37 -> 127 | K37: 10 | L37: 30
A38: 36 | B38: ZEUGMA | C38: ='KASIM 2 HAFTA '!J38 -> 36 | J38: =+C38-E38-F38-G38-H38-I38+D38 -> 36 | K38: 10 | L38: 20
A39: 37 | B39: SOVRANO MİSAFİR | C39: ='KASIM 2 HAFTA '!J39 -> 24 | J39: =+C39-E39-F39-G39-H39-I39+D39 -> 24 | K39: 10 | L39: 30
A40: 38 | B40: SOVRANO MÜDÜR | C40: ='KASIM 2 HAFTA '!J40 -> 47 | F40: 10 | J40: =+C40-E40-F40-G40-H40-I40+D40 -> 37 | K40: 20 | L40: 40
...

Sheet KASIM 4 HAFTA 
A1: TAHTA SAYIMI | L1: 44837
A2: S.NO | B2: CİNSİ | C2: DEVİR | D2: GELEN | E2: 44886 | F2: 44887 | G2: 44888 | H2: 44889 | I2: 44890 | J2: KALAN | K2: MİNİMUN | L2: MAXSİMUN
A3: 1 | B3: SANDALYE TAHTASI | C3: ='KASIM 3 HAFTA '!J3 -> 37 | J3: =+C3-E3-F3-G3-H3-I3+D3 -> 37 | K3: 0
A4: 2 | B4: EKO KLAS MÜDÜR TAHTASI | C4: ='KASIM 3 HAFTA '!J4 -> 3 | G4: 3 | J4: =+C4-E4-F4-G4-H4-I4+D4 -> 0 | K4: 0
A5: 3 | B5: KESİLMEMİŞTAHTA | C5: ='KASIM 3 HAFTA '!J5 -> 105 | E5: 6 | H5: 5 | J5: =+C5-E5-F5-G5-H5-I5+D5 -> 94 | K5: 0
A6: 4 | B6: RECENT MİSAFİR | C6: ='KASIM 3 HAFTA '!J6 -> 55 | J6: =+C6-E6-F6-G6-H6-I6+D6 -> 55 | K6: 30 | L6: 100
A7: 5 | B7: RECENT MÜDÜR | C7: ='KASIM 3 HAFTA '!J7 -> 17 | E7: 2 | J7: =+C7-E7-F7-G7-H7-I7+D7 -> 15 | K7: 30 | L7: 100
A8: 6 | B8: PUFFY MİSAFİR | C8: ='KASIM 3 HAFTA '!J8 -> 21 | J8: =+C8-E8-F8-G8-H8-I8+D8 -> 21 | K8: 15 | L8: 50
A9: 7 | B9: PUFFY MÜDÜR | C9: ='KASIM 3 HAFTA '!J9 -> 12 | J9: =+C9-E9-F9-G9-H9-I9+D9 -> 12 | K9: 15 | L9: 30
A10: 8 | B10: KESİLMEMİŞ MÜDÜR KON | C10: ='KASIM 3 HAFTA '!J10 -> 83 | G10: 8 | J10: =+C10-E10-F10-G10-H10-I10+D10 -> 75 | K10: 0
A11: 9 | B11: CEZAR MÜDÜR | C11: ='KASIM 3 HAFTA '!J11 -> 32 | I11: 1 | J11: =+C11-E11-F11-G11-H11-I11+D11 -> 31 | K11: 150 | L11: 500
A12: 10 | B12: CEZAR MİSAFİR | C12: ='KASIM 3 HAFTA '!J12 -> 558 | E12: 500 | F12: 58 | J12: =+C12-E12-F12-G12-H12-I12+D12 -> 0 | K12: 200 | L12: 750
A13: 11 | B13: LENUX MİSAFİR | C13: ='KASIM 3 HAFTA '!J13 -> 78 | J13: =+C13-E13-F13-G13-H13-I13+D13 -> 78 | K13: 10 | L13: 30
A14: 12 | B14: LENUX MÜDÜR | C14: ='KASIM 3 HAFTA '!J14 -> 42 | J14: =+C14-E14-F14-G14-H14-I14+D14 -> 42 | K14: 10 | L14: 20
A15: 13 | B15: WARLCOK MÜDÜR | C15: ='KASIM 3 HAFTA '!J15 -> 98 | J15: =+C15-E15-F15-G15-H15-I15+D15 -> 98 | K15: 10 | L15: 20
A16: 14 | B16: WARLCOK MİSAFİR | C16: ='KASIM 3 HAFTA '!J16 -> 0 | J16: =+C16-E16-F16-G16-H16-I16+D16 -> 0 | K16: 10 | L16: 20
A17: 15 | B17: VİSİON MÜDÜR | C17: ='KASIM 3 HAFTA '!J17 -> 156 | E17: 1 | I17: 10 | J17: =+C17-E17-F17-G17-H17-I17+D17 -> 145 | K17: 50 | L17: 200
A18: 16 | B18: VİSİON MİSAFİR | C18: ='KASIM 3 HAFTA '!J18 -> 35 | I18: 35 | J18: =+C18-E18-F18-G18-H18-I18+D18 -> 0 | K18: 50 | L18: 150
A19: 17 | B19: PENTA MÜDÜR | C19: ='KASIM 3 HAFTA '!J19 -> 94 | F19: 1 | J19: =+C19-E19-F19-G19-H19-I19+D19 -> 93 | K19: 30 | L19: 100
A20: 18 | B20: PENTA MİSAFİR | C20: ='KASIM 3 HAFTA '!J20 -> 60 | J20: =+C20-E20-F20-G20-H20-I20+D20 -> 60 | K20: 30 | L20: 100
A21: 19 | B21: ACTİON MÜDÜR | C21: ='KASIM 3 HAFTA '!J21 -> 16 | F21: 3 | J21: =+C21-E21-F21-G21-H21-I21+D21 -> 13 | K21: 20 | L21: 50
A22: 20 | B22: TELLY OTURAK TAHTASI | C22: ='KASIM 3 HAFTA '!J22 -> 140 | J22: =+C22-E22-F22-G22-H22-I22+D22 -> 140 | K22: 100 | L22: 300
A23: 21 | B23: CARENS MÜDÜR KONT | C23: ='KASIM 3 HAFTA '!J23 -> 130 | J23: =+C23-E23-F23-G23-H23-I23+D23 -> 130 | K23: 5 | L23: 10
A24: 22 | B24: GRAFTER MÜDÜR | C24: ='KASIM 3 HAFTA '!J24 -> 38 | J24: =+C24-E24-F24-G24-H24-I24+D24 -> 38 | K24: 5 | L24: 10
A25: 23 | B25: GRAFTER MİSAFİR | C25: ='KASIM 3 HAFTA '!J25 -> 7 | J25: =+C25-E25-F25-G25-H25-I25+D25 -> 7 | K25: 5 | L25: 10
A26: 24 | B26: ELNORA -LEGENT MÜDÜR | C26: ='KASIM 3 HAFTA '!J26 -> 223 | J26: =+C26-E26-F26-G26-H26-I26+D26 -> 223 | K26: 100 | L26: 200
A27: 25 | B27: LEGENT MÜDÜR UZUN | C27: ='KASIM 3 HAFTA '!J27 -> 483 | J27: =+C27-E27-F27-G27-H27-I27+D27 -> 483 | K27: 0
A28: 26 | B28: ANFİ TAHTASI | C28: ='KASIM 3 HAFTA '!J28 -> 62 | J28: =+C28-E28-F28-G28-H28-I28+D28 -> 62 | K28: 0
A29: 27 | B29: VEGA SIRT | C29: ='KASIM 3 HAFTA '!J29 -> 13 | J29: =+C29-E29-F29-G29-H29-I29+D29 -> 13 | K29: 0
A30: 28 | B30: VEGA TABAN | C30: ='KASIM 3 HAFTA '!J30 -> 60 | J30: =+C30-E30-F30-G30-H30-I30+D30 -> 60 | K30: 0
A31: 29 | B31: VENESSA MİS.KONTRASI | C31: ='KASIM 3 HAFTA '!J31 -> 0 | J31: =+C31-E31-F31-G31-H31-I31+D31 -> 0 | K31: 0
A32: 30 | B32: POLİ DABAN | C32: ='KASIM 3 HAFTA '!J32 -> 638 | F32: 35 | J32: =+C32-E32-F32-G32-H32-I32+D32 -> 603 | K32: 200 | L32: 400
A33: 31 | B33: SANDALYE SIRT | C33: ='KASIM 3 HAFTA '!J33 -> 240 | J33: =+C33-E33-F33-G33-H33-I33+D33 -> 240 | K33: 0
A34: 32 | B34: SANDALYE DABAN | C34: ='KASIM 3 HAFTA '!J34 -> 17 | J34: =+C34-E34-F34-G34-H34-I34+D34 -> 17 | K34: 0
A35: 33 | B35: MİSAFİR SIRT | C35: ='KASIM 3 HAFTA '!J35 -> 29 | J35: =+C35-E35-F35-G35-H35-I35+D35 -> 29 | K35: 0
A36: 34 | B36: VİVA DABAN | C36: ='KASIM 3 HAFTA '!J36 -> 537 | J36: =+C36-E36-F36-G36-H36-I36+D36 -> 537 | K36: 0
A37: 35 | B37: SENS MÜDÜR SIRT | C37: ='KASIM 3 HAFTA '!J37 -> 127 | E37: 2 | J37: =+C37-E37-F37-G37-H37-I37+D37 -> 125 | K37: 10 | L37: 30
A38: 36 | B38: ZEUGMA | C38: ='KASIM 3 HAFTA '!J38 -> 36 | J38: =+C38-E38-F38-G38-H38-I38+D38 -> 36 | K38: 10 | L38: 20
A39: 37 | B39: SOVRANO MİSAFİR | C39: ='KASIM 3 HAFTA '!J39 -> 24 | J39: =+C39-E39-F39-G39-H39-I39+D39 -> 24 | K39: 10 | L39: 30
A40: 38 | B40: SOVRANO MÜDÜR | C40: ='KASIM 3 HAFTA '!J40 -> 37 | F40: 2 | J40: =+C40-E40-F40-G40-H40-I40+D40 -> 35 | K40: 20 | L40: 40
...

Sheet KASIM 5 HAFTA 
A1: TAHTA SAYIMI | L1: 44837
A2: S.NO | B2: CİNSİ | C2: DEVİR | D2: GELEN | E2: 44893 | F2: 44894 | G2: 44895 | H2: 44896 | I2: 44897 | J2: KALAN | K2: MİNİMUN | L2: MAXSİMUN
A3: 1 | B3: SANDALYE TAHTASI | C3: ='KASIM 3 HAFTA '!J3 -> 37 | J3: =+C3-E3-F3-G3-H3-I3+D3 -> 37 | K3: 0
A4: 2 | B4: EKO KLAS MÜDÜR TAHTASI | C4: 0 | J4: =+C4-E4-F4-G4-H4-I4+D4 -> 0 | K4: 0
A5: 3 | B5: KESİLMEMİŞTAHTA | C5: 94 | H5: 13 | I5: 1 | J5: =+C5-E5-F5-G5-H5-I5+D5 -> 80 | K5: 0
A6: 4 | B6: RECENT MİSAFİR | C6: ='KASIM 3 HAFTA '!J6 -> 55 | J6: =+C6-E6-F6-G6-H6-I6+D6 -> 55 | K6: 30 | L6: 100
A7: 5 | B7: RECENT MÜDÜR | C7: 15 | J7: =+C7-E7-F7-G7-H7-I7+D7 -> 15 | K7: 30 | L7: 100
A8: 6 | B8: PUFFY MİSAFİR | C8: ='KASIM 3 HAFTA '!J8 -> 21 | J8: =+C8-E8-F8-G8-H8-I8+D8 -> 21 | K8: 15 | L8: 50
A9: 7 | B9: PUFFY MÜDÜR | C9: ='KASIM 3 HAFTA '!J9 -> 12 | J9: =+C9-E9-F9-G9-H9-I9+D9 -> 12 | K9: 15 | L9: 30
A10: 8 | B10: KESİLMEMİŞ MÜDÜR KON | C10: 75 | J10: =+C10-E10-F10-G10-H10-I10+D10 -> 75 | K10: 0
A11: 9 | B11: CEZAR MÜDÜR | C11: 31 | H11: 16 | J11: =+C11-E11-F11-G11-H11-I11+D11 -> 15 | K11: 150 | L11: 500
A12: 10 | B12: CEZAR MİSAFİR | C12: 0 | J12: =+C12-E12-F12-G12-H12-I12+D12 -> 0 | K12: 200 | L12: 750
A13: 11 | B13: LENUX MİSAFİR | C13: ='KASIM 3 HAFTA '!J13 -> 78 | J13: =+C13-E13-F13-G13-H13-I13+D13 -> 78 | K13: 10 | L13: 30
A14: 12 | B14: LENUX MÜDÜR | C14: ='KASIM 3 HAFTA '!J14 -> 42 | J14: =+C14-E14-F14-G14-H14-I14+D14 -> 42 | K14: 10 | L14: 20
A15: 13 | B15: WARLCOK MÜDÜR | C15: ='KASIM 3 HAFTA '!J15 -> 98 | H15: 5 | J15: =+C15-E15-F15-G15-H15-I15+D15 -> 93 | K15: 10 | L15: 20
A16: 14 | B16: WARLCOK MİSAFİR | C16: ='KASIM 3 HAFTA '!J16 -> 0 | J16: =+C16-E16-F16-G16-H16-I16+D16 -> 0 | K16: 10 | L16: 20
A17: 15 | B17: VİSİON MÜDÜR | C17: 145 | E17: 15 | J17: =+C17-E17-F17-G17-H17-I17+D17 -> 130 | K17: 50 | L17: 200
A18: 16 | B18: VİSİON MİSAFİR | C18: 0 | J18: =+C18-E18-F18-G18-H18-I18+D18 -> 0 | K18: 50 | L18: 150
A19: 17 | B19: PENTA MÜDÜR | C19: 93 | F19: 5 | J19: =+C19-E19-F19-G19-H19-I19+D19 -> 88 | K19: 30 | L19: 100
A20: 18 | B20: PENTA MİSAFİR | C20: ='KASIM 3 HAFTA '!J20 -> 60 | F20: 4 | J20: =+C20-E20-F20-G20-H20-I20+D20 -> 56 | K20: 30 | L20: 100
A21: 19 | B21: ACTİON MÜDÜR | C21: 13 | J21: =+C21-E21-F21-G21-H21-I21+D21 -> 13 | K21: 20 | L21: 50
A22: 20 | B22: TELLY OTURAK TAHTASI | C22: ='KASIM 3 HAFTA '!J22 -> 140 | I22: 6 | J22: =+C22-E22-F22-G22-H22-I22+D22 -> 134 | K22: 100 | L22: 300
A23: 21 | B23: CARENS MÜDÜR KONT | C23: ='KASIM 3 HAFTA '!J23 -> 130 | J23: =+C23-E23-F23-G23-H23-I23+D23 -> 130 | K23: 5 | L23: 10
A24: 22 | B24: GRAFTER MÜDÜR | C24: ='KASIM 3 HAFTA '!J24 -> 38 | J24: =+C24-E24-F24-G24-H24-I24+D24 -> 38 | K24: 5 | L24: 10
A25: 23 | B25: GRAFTER MİSAFİR | C25: ='KASIM 3 HAFTA '!J25 -> 7 | J25: =+C25-E25-F25-G25-H25-I25+D25 -> 7 | K25: 5 | L25: 10
A26: 24 | B26: ELNORA -LEGENT MÜDÜR | C26: ='KASIM 3 HAFTA '!J26 -> 223 | J26: =+C26-E26-F26-G26-H26-I26+D26 -> 223 | K26: 100 | L26: 200
A27: 25 | B27: LEGENT MÜDÜR UZUN | C27: ='KASIM 3 HAFTA '!J27 -> 483 | J27: =+C27-E27-F27-G27-H27-I27+D27 -> 483 | K27: 0
A28: 26 | B28: ANFİ TAHTASI | C28: ='KASIM 3 HAFTA '!J28 -> 62 | J28: =+C28-E28-F28-G28-H28-I28+D28 -> 62 | K28: 0
A29: 27 | B29: VEGA SIRT | C29: ='KASIM 3 HAFTA '!J29 -> 13 | J29: =+C29-E29-F29-G29-H29-I29+D29 -> 13 | K29: 0
A30: 28 | B30: VEGA TABAN | C30: ='KASIM 3 HAFTA '!J30 -> 60 | J30: =+C30-E30-F30-G30-H30-I30+D30 -> 60 | K30: 0
A31: 29 | B31: VENESSA MİS.KONTRASI | C31: ='KASIM 3 HAFTA '!J31 -> 0 | J31: =+C31-E31-F31-G31-H31-I31+D31 -> 0 | K31: 0
A32: 30 | B32: POLİ DABAN | C32: 603 | I32: 6 | J32: =+C32-E32-F32-G32-H32-I32+D32 -> 597 | K32: 200 | L32: 400
A33: 31 | B33: SANDALYE SIRT | C33: ='KASIM 3 HAFTA '!J33 -> 240 | J33: =+C33-E33-F33-G33-H33-I33+D33 -> 240 | K33: 0
A34: 32 | B34: SANDALYE DABAN | C34: ='KASIM 3 HAFTA '!J34 -> 17 | J34: =+C34-E34-F34-G34-H34-I34+D34 -> 17 | K34: 0
A35: 33 | B35: MİSAFİR SIRT | C35: ='KASIM 3 HAFTA '!J35 -> 29 | J35: =+C35-E35-F35-G35-H35-I35+D35 -> 29 | K35: 0
A36: 34 | B36: VİVA DABAN | C36: ='KASIM 3 HAFTA '!J36 -> 537 | I36: 4 | J36: =+C36-E36-F36-G36-H36-I36+D36 -> 533 | K36: 0
A37: 35 | B37: SENS MÜDÜR SIRT | C37: 125 | I37: 4 | J37: =+C37-E37-F37-G37-H37-I37+D37 -> 121 | K37: 10 | L37: 30
A38: 36 | B38: ZEUGMA | C38: ='KASIM 3 HAFTA '!J38 -> 36 | J38: =+C38-E38-F38-G38-H38-I38+D38 -> 36 | K38: 10 | L38: 20
A39: 37 | B39: SOVRANO MİSAFİR | C39: ='KASIM 3 HAFTA '!J39 -> 24 | J39: =+C39-E39-F39-G39-H39-I39+D39 -> 24 | K39: 10 | L39: 30
A40: 38 | B40: SOVRANO MÜDÜR | C40: 35 | H40: 6 | I40: 14 | J40: =+C40-E40-F40-G40-H40-I40+D40 -> 15 | K40: 20 | L40: 40
...

Sheet ARALIK 1 HAFTA
A1: TAHTA SAYIMI | C1: ARALIK 1 HAFTA | L1: 44837
A2: S.NO | B2: CİNSİ | C2: DEVİR | D2: GELEN | E2: 44900 | F2: 44901 | G2: 44902 | H2: 44903 | I2: 44904 | J2: KALAN | K2: MİNİMUN | L2: MAXSİMUN
A3: 1 | B3: SANDALYE TAHTASI | C3: ='KASIM 3 HAFTA '!J3 -> 37 | J3: =+C3-E3-F3-G3-H3-I3+D3 -> 37 | K3: 0
A4: 2 | B4: EKO KLAS MÜDÜR TAHTASI | C4: 0 | J4: =+C4-E4-F4-G4-H4-I4+D4 -> 0 | K4: 0
A5: 3 | B5: KESİLMEMİŞTAHTA | C5: 80 | E5: 2 | J5: =+C5-E5-F5-G5-H5-I5+D5 -> 78 | K5: 0
A6: 4 | B6: RECENT MİSAFİR | C6: ='KASIM 3 HAFTA '!J6 -> 55 | D6: 39 | J6: =+C6-E6-F6-G6-H6-I6+D6 -> 94 | K6: 30 | L6: 100
A7: 5 | B7: RECENT MÜDÜR | C7: 15 | D7: 26 | J7: =+C7-E7-F7-G7-H7-I7+D7 -> 41 | K7: 30 | L7: 100
A8: 6 | B8: PUFFY MİSAFİR | C8: ='KASIM 3 HAFTA '!J8 -> 21 | J8: =+C8-E8-F8-G8-H8-I8+D8 -> 21 | K8: 15 | L8: 50
A9: 7 | B9: PUFFY MÜDÜR | C9: ='KASIM 3 HAFTA '!J9 -> 12 | J9: =+C9-E9-F9-G9-H9-I9+D9 -> 12 | K9: 15 | L9: 30
A10: 8 | B10: KESİLMEMİŞ MÜDÜR KON | C10: 75 | J10: =+C10-E10-F10-G10-H10-I10+D10 -> 75 | K10: 0
A11: 9 | B11: CEZAR MÜDÜR | C11: 15 | E11: 6 | J11: =+C11-E11-F11-G11-H11-I11+D11 -> 9 | K11: 150 | L11: 500
A12: 10 | B12: CEZAR MİSAFİR | C12: 0 | D12: 598 | E12: 22 | I12: 22 | J12: =+C12-E12-F12-G12-H12-I12+D12 -> 554 | K12: 200 | L12: 750
A13: 11 | B13: LENUX MİSAFİR | C13: ='KASIM 3 HAFTA '!J13 -> 78 | J13: =+C13-E13-F13-G13-H13-I13+D13 -> 78 | K13: 10 | L13: 30
A14: 12 | B14: LENUX MÜDÜR | C14: ='KASIM 3 HAFTA '!J14 -> 42 | J14: =+C14-E14-F14-G14-H14-I14+D14 -> 42 | K14: 10 | L14: 20
A15: 13 | B15: WARLCOK MÜDÜR | C15: 93 | J15: =+C15-E15-F15-G15-H15-I15+D15 -> 93 | K15: 10 | L15: 20
A16: 14 | B16: WARLCOK MİSAFİR | C16: ='KASIM 3 HAFTA '!J16 -> 0 | J16: =+C16-E16-F16-G16-H16-I16+D16 -> 0 | K16: 10 | L16: 20
A17: 15 | B17: VİSİON MÜDÜR | C17: 130 | D17: 194 | E17: 25 | F17: 13 | H17: 23 | J17: =+C17-E17-F17-G17-H17-I17+D17 -> 263 | K17: 50 | L17: 200
A18: 16 | B18: VİSİON MİSAFİR | C18: 0 | J18: =+C18-E18-F18-G18-H18-I18+D18 -> 0 | K18: 50 | L18: 150
A19: 17 | B19: PENTA MÜDÜR | C19: 88 | J19: =+C19-E19-F19-G19-H19-I19+D19 -> 88 | K19: 30 | L19: 100
A20: 18 | B20: PENTA MİSAFİR | C20: 56 | J20: =+C20-E20-F20-G20-H20-I20+D20 -> 56 | K20: 30 | L20: 100
A21: 19 | B21: ACTİON MÜDÜR | C21: 13 | D21: 25 | H21: 6 | J21: =+C21-E21-F21-G21-H21-I21+D21 -> 32 | K21: 20 | L21: 50
A22: 20 | B22: TELLY(VOX)OTURAK TAHTASI | C22: 134 | D22: 324 | J22: =+C22-E22-F22-G22-H22-I22+D22 -> 458 | K22: 100 | L22: 300
A23: 21 | B23: CARENS MÜDÜR KONT | C23: ='KASIM 3 HAFTA '!J23 -> 130 | J23: =+C23-E23-F23-G23-H23-I23+D23 -> 130 | K23: 5 | L23: 10
A24: 22 | B24: GRAFTER MÜDÜR | C24: ='KASIM 3 HAFTA '!J24 -> 38 | J24: =+C24-E24-F24-G24-H24-I24+D24 -> 38 | K24: 5 | L24: 10
A25: 23 | B25: GRAFTER MİSAFİR | C25: ='KASIM 3 HAFTA '!J25 -> 7 | J25: =+C25-E25-F25-G25-H25-I25+D25 -> 7 | K25: 5 | L25: 10
A26: 24 | B26: ELNORA -LEGENT MÜDÜR | C26: ='KASIM 3 HAFTA '!J26 -> 223 | J26: =+C26-E26-F26-G26-H26-I26+D26 -> 223 | K26: 100 | L26: 200
A27: 25 | B27: LEGENT MÜDÜR UZUN | C27: ='KASIM 3 HAFTA '!J27 -> 483 | J27: =+C27-E27-F27-G27-H27-I27+D27 -> 483 | K27: 0
A28: 26 | B28: ANFİ TAHTASI | C28: ='KASIM 3 HAFTA '!J28 -> 62 | J28: =+C28-E28-F28-G28-H28-I28+D28 -> 62 | K28: 0
A29: 27 | B29: VEGA SIRT | C29: ='KASIM 3 HAFTA '!J29 -> 13 | J29: =+C29-E29-F29-G29-H29-I29+D29 -> 13 | K29: 0
A30: 28 | B30: VEGA TABAN | C30: ='KASIM 3 HAFTA '!J30 -> 60 | J30: =+C30-E30-F30-G30-H30-I30+D30 -> 60 | K30: 0
A31: 29 | B31: VENESSA MİS.KONTRASI | C31: ='KASIM 3 HAFTA '!J31 -> 0 | J31: =+C31-E31-F31-G31-H31-I31+D31 -> 0 | K31: 0
A32: 30 | B32: POLİ DABAN | C32: 597 | J32: =+C32-E32-F32-G32-H32-I32+D32 -> 597 | K32: 200 | L32: 400
A33: 31 | B33: SANDALYE SIRT | C33: ='KASIM 3 HAFTA '!J33 -> 240 | J33: =+C33-E33-F33-G33-H33-I33+D33 -> 240 | K33: 0
A34: 32 | B34: SANDALYE DABAN | C34: ='KASIM 3 HAFTA '!J34 -> 17 | J34: =+C34-E34-F34-G34-H34-I34+D34 -> 17 | K34: 0
A35: 33 | B35: MİSAFİR SIRT | C35: ='KASIM 3 HAFTA '!J35 -> 29 | J35: =+C35-E35-F35-G35-H35-I35+D35 -> 29 | K35: 0
A36: 34 | B36: VİVA DABAN | C36: 533 | J36: =+C36-E36-F36-G36-H36-I36+D36 -> 533 | K36: 0
A37: 35 | B37: SENS MÜDÜR SIRT | C37: 121 | J37: =+C37-E37-F37-G37-H37-I37+D37 -> 121 | K37: 10 | L37: 30
A38: 36 | B38: ZEUGMA | C38: ='KASIM 3 HAFTA '!J38 -> 36 | J38: =+C38-E38-F38-G38-H38-I38+D38 -> 36 | K38: 10 | L38: 20
A39: 37 | B39: SOVRANO MİSAFİR | C39: ='KASIM 3 HAFTA '!J39 -> 24 | J39: =+C39-E39-F39-G39-H39-I39+D39 -> 24 | K39: 10 | L39: 30
A40: 38 | B40: SOVRANO MÜDÜR | C40: 15 | F40: 6 | J40: =+C40-E40-F40-G40-H40-I40+D40 -> 9 | K40: 20 | L40: 40
...

Sheet ARALIK 2 HAFTA 
A1: TAHTA SAYIMI | C1: ARALIK 2 HAFTA | L1: 44837
A2: S.NO | B2: CİNSİ | C2: DEVİR | D2: GELEN | E2: 44907 | F2: 44908 | G2: 44909 | H2: 44910 | I2: 44911 | J2: KALAN | K2: MİNİMUN | L2: MAXSİMUN
A3: 1 | B3: SANDALYE TAHTASI | C3: ='KASIM 3 HAFTA '!J3 -> 37 | J3: =+C3-E3-F3-G3-H3-I3+D3 -> 37 | K3: 0
A4: 2 | B4: EKO KLAS MÜDÜR TAHTASI | C4: 0 | J4: =+C4-E4-F4-G4-H4-I4+D4 -> 0 | K4: 0
A5: 3 | B5: KESİLMEMİŞTAHTA | C5: 78 | J5: =+C5-E5-F5-G5-H5-I5+D5 -> 78 | K5: 0
A6: 4 | B6: RECENT MİSAFİR | C6: 94 | J6: =+C6-E6-F6-G6-H6-I6+D6 -> 94 | K6: 30 | L6: 100
A7: 5 | B7: RECENT MÜDÜR | C7: 41 | J7: =+C7-E7-F7-G7-H7-I7+D7 -> 41 | K7: 30 | L7: 100
A8: 6 | B8: PUFFY MİSAFİR | C8: ='KASIM 3 HAFTA '!J8 -> 21 | E8: 4 | J8: =+C8-E8-F8-G8-H8-I8+D8 -> 17 | K8: 15 | L8: 50
A9: 7 | B9: PUFFY MÜDÜR | C9: ='KASIM 3 HAFTA '!J9 -> 12 | J9: =+C9-E9-F9-G9-H9-I9+D9 -> 12 | K9: 15 | L9: 30
A10: 8 | B10: KESİLMEMİŞ MÜDÜR KON | C10: 75 | J10: =+C10-E10-F10-G10-H10-I10+D10 -> 75 | K10: 0
A11: 9 | B11: CEZAR MÜDÜR | C11: 9 | D11: 190 | H11: 20 | J11: =+C11-E11-F11-G11-H11-I11+D11 -> 179 | K11: 150 | L11: 500
A12: 10 | B12: CEZAR MİSAFİR | C12: 554 | D12: 103 | I12: 85 | J12: =+C12-E12-F12-G12-H12-I12+D12 -> 572 | K12: 200 | L12: 750
A13: 11 | B13: LENUX MİSAFİR | C13: ='KASIM 3 HAFTA '!J13 -> 78 | J13: =+C13-E13-F13-G13-H13-I13+D13 -> 78 | K13: 10 | L13: 30
A14: 12 | B14: LENUX MÜDÜR | C14: ='KASIM 3 HAFTA '!J14 -> 42 | J14: =+C14-E14-F14-G14-H14-I14+D14 -> 42 | K14: 10 | L14: 20
A15: 13 | B15: WARLCOK MÜDÜR | C15: 93 | J15: =+C15-E15-F15-G15-H15-I15+D15 -> 93 | K15: 10 | L15: 20
A16: 14 | B16: WARLCOK MİSAFİR | C16: ='KASIM 3 HAFTA '!J16 -> 0 | J16: =+C16-E16-F16-G16-H16-I16+D16 -> 0 | K16: 10 | L16: 20
A17: 15 | B17: VİSİON MÜDÜR/RETRO | C17: 263 | E17: 10 | H17: 20 | J17: =+C17-E17-F17-G17-H17-I17+D17 -> 233 | K17: 50 | L17: 200
A18: 16 | B18: VİSİON MİSAFİR | C18: 0 | D18: 84 | I18: 18 | J18: =+C18-E18-F18-G18-H18-I18+D18 -> 66 | K18: 50 | L18: 150
A19: 17 | B19: PENTA MÜDÜR | C19: 88 | F19: 8 | J19: =+C19-E19-F19-G19-H19-I19+D19 -> 80 | K19: 30 | L19: 100
A20: 18 | B20: PENTA MİSAFİR | C20: 56 | J20: =+C20-E20-F20-G20-H20-I20+D20 -> 56 | K20: 30 | L20: 100
A21: 19 | B21: ACTİON MÜDÜR | C21: 32 | G21: 2 | J21: =+C21-E21-F21-G21-H21-I21+D21 -> 30 | K21: 20 | L21: 50
A22: 20 | B22: TELLY(VOX)OTURAK TAHTASI | C22: 458 | J22: =+C22-E22-F22-G22-H22-I22+D22 -> 458 | K22: 100 | L22: 300
A23: 21 | B23: CARENS MÜDÜR KONT | C23: ='KASIM 3 HAFTA '!J23 -> 130 | E23: 5 | J23: =+C23-E23-F23-G23-H23-I23+D23 -> 125 | K23: 5 | L23: 10
A24: 22 | B24: GRAFTER MÜDÜR | C24: ='KASIM 3 HAFTA '!J24 -> 38 | J24: =+C24-E24-F24-G24-H24-I24+D24 -> 38 | K24: 5 | L24: 10
A25: 23 | B25: GRAFTER MİSAFİR | C25: ='KASIM 3 HAFTA '!J25 -> 7 | J25: =+C25-E25-F25-G25-H25-I25+D25 -> 7 | K25: 5 | L25: 10
A26: 24 | B26: ELNORA -LEGENT MÜDÜR | C26: ='KASIM 3 HAFTA '!J26 -> 223 | J26: =+C26-E26-F26-G26-H26-I26+D26 -> 223 | K26: 100 | L26: 200
A27: 25 | B27: LEGENT MÜDÜR UZUN | C27: ='KASIM 3 HAFTA '!J27 -> 483 | J27: =+C27-E27-F27-G27-H27-I27+D27 -> 483 | K27: 0
A28: 26 | B28: ANFİ TAHTASI | C28: ='KASIM 3 HAFTA '!J28 -> 62 | J28: =+C28-E28-F28-G28-H28-I28+D28 -> 62 | K28: 0
A29: 27 | B29: VEGA SIRT | C29: ='KASIM 3 HAFTA '!J29 -> 13 | J29: =+C29-E29-F29-G29-H29-I29+D29 -> 13 | K29: 0
A30: 28 | B30: VEGA TABAN | C30: ='KASIM 3 HAFTA '!J30 -> 60 | J30: =+C30-E30-F30-G30-H30-I30+D30 -> 60 | K30: 0
A31: 29 | B31: VENESSA MİS.KONTRASI | C31: ='KASIM 3 HAFTA '!J31 -> 0 | J31: =+C31-E31-F31-G31-H31-I31+D31 -> 0 | K31: 0
A32: 30 | B32: POLİ DABAN | C32: 597 | J32: =+C32-E32-F32-G32-H32-I32+D32 -> 597 | K32: 200 | L32: 400
A33: 31 | B33: SANDALYE SIRT | C33: ='KASIM 3 HAFTA '!J33 -> 240 | J33: =+C33-E33-F33-G33-H33-I33+D33 -> 240 | K33: 0
A34: 32 | B34: SANDALYE DABAN | C34: ='KASIM 3 HAFTA '!J34 -> 17 | J34: =+C34-E34-F34-G34-H34-I34+D34 -> 17 | K34: 0
A35: 33 | B35: MİSAFİR SIRT | C35: ='KASIM 3 HAFTA '!J35 -> 29 | J35: =+C35-E35-F35-G35-H35-I35+D35 -> 29 | K35: 0
A36: 34 | B36: VİVA DABAN | C36: 533 | J36: =+C36-E36-F36-G36-H36-I36+D36 -> 533 | K36: 0
A37: 35 | B37: SENS MÜDÜR SIRT | C37: 121 | G37: 2 | J37: =+C37-E37-F37-G37-H37-I37+D37 -> 119 | K37: 10 | L37: 30
A38: 36 | B38: ZEUGMA | C38: ='KASIM 3 HAFTA '!J38 -> 36 | J38: =+C38-E38-F38-G38-H38-I38+D38 -> 36 | K38: 10 | L38: 20
A39: 37 | B39: SOVRANO MİSAFİR | C39: ='KASIM 3 HAFTA '!J39 -> 24 | J39: =+C39-E39-F39-G39-H39-I39+D39 -> 24 | K39: 10 | L39: 30
A40: 38 | B40: SOVRANO MÜDÜR | C40: 9 | J40: =+C40-E40-F40-G40-H40-I40+D40 -> 9 | K40: 20 | L40: 40
...

Sheet ARALIK 3 HAFTA 
A1: TAHTA SAYIMI | C1: ARALIK 3. HAFTA | L1: 44837
A2: S.NO | B2: CİNSİ | C2: DEVİR | D2: GELEN | E2: 44914 | F2: 44915 | G2: 44916 | H2: 44917 | I2: 44918 | J2: KALAN | K2: MİNİMUN | L2: MAXSİMUN
A3: 1 | B3: SANDALYE TAHTASI | C3: ='KASIM 3 HAFTA '!J3 -> 37 | J3: =+C3-E3-F3-G3-H3-I3+D3 -> 37 | K3: 0
A4: 2 | B4: EKO KLAS MÜDÜR TAHTASI | C4: 0 | J4: =+C4-E4-F4-G4-H4-I4+D4 -> 0 | K4: 0
A5: 3 | B5: KESİLMEMİŞTAHTA | C5: 78 | J5: =+C5-E5-F5-G5-H5-I5+D5 -> 78 | K5: 0
A6: 4 | B6: RECENT MİSAFİR | C6: 94 | J6: =+C6-E6-F6-G6-H6-I6+D6 -> 94 | K6: 30 | L6: 100
A7: 5 | B7: RECENT MÜDÜR | C7: 41 | E7: 12 | H7: 1 | I7: 5 | J7: =+C7-E7-F7-G7-H7-I7+D7 -> 23 | K7: 30 | L7: 100
A8: 6 | B8: PUFFY MİSAFİR | C8: 17 | I8: 4 | J8: =+C8-E8-F8-G8-H8-I8+D8 -> 13 | K8: 15 | L8: 50
A9: 7 | B9: PUFFY MÜDÜR | C9: ='KASIM 3 HAFTA '!J9 -> 12 | J9: =+C9-E9-F9-G9-H9-I9+D9 -> 12 | K9: 15 | L9: 30
A10: 8 | B10: KESİLMEMİŞ MÜDÜR KON | C10: 75 | J10: =+C10-E10-F10-G10-H10-I10+D10 -> 75 | K10: 0
A11: 9 | B11: CEZAR MÜDÜR | C11: 179 | E11: 54 | F11: 0 | I11: 45 | J11: =+C11-E11-F11-G11-H11-I11+D11 -> 80 | K11: 150 | L11: 500
A12: 10 | B12: CEZAR MİSAFİR | C12: 572 | F12: 80 | G12: 50 | J12: =+C12-E12-F12-G12-H12-I12+D12 -> 442 | K12: 200 | L12: 750
A13: 11 | B13: LENUX MİSAFİR | C13: ='KASIM 3 HAFTA '!J13 -> 78 | J13: =+C13-E13-F13-G13-H13-I13+D13 -> 78 | K13: 10 | L13: 30
A14: 12 | B14: LENUX MÜDÜR | C14: ='KASIM 3 HAFTA '!J14 -> 42 | J14: =+C14-E14-F14-G14-H14-I14+D14 -> 42 | K14: 10 | L14: 20
A15: 13 | B15: WARLCOK MÜDÜR | C15: 93 | J15: =+C15-E15-F15-G15-H15-I15+D15 -> 93 | K15: 10 | L15: 20
A16: 14 | B16: WARLCOK MİSAFİR | C16: ='KASIM 3 HAFTA '!J16 -> 0 | J16: =+C16-E16-F16-G16-H16-I16+D16 -> 0 | K16: 10 | L16: 20
A17: 15 | B17: VİSİON MÜDÜR/RETRO | C17: 233 | D17: 42 | E17: 4 | G17: 13 | H17: 1 | J17: =+C17-E17-F17-G17-H17-I17+D17 -> 257 | K17: 50 | L17: 200
A18: 16 | B18: VİSİON MİSAFİR | C18: 66 | D18: 102 | E18: 2 | G18: 6 | H18: 4 | J18: =+C18-E18-F18-G18-H18-I18+D18 -> 156 | K18: 50 | L18: 150
A19: 17 | B19: PENTA MÜDÜR | C19: 80 | J19: =+C19-E19-F19-G19-H19-I19+D19 -> 80 | K19: 30 | L19: 100
A20: 18 | B20: PENTA MİSAFİR | C20: 56 | J20: =+C20-E20-F20-G20-H20-I20+D20 -> 56 | K20: 30 | L20: 100
A21: 19 | B21: ACTİON MÜDÜR | C21: 30 | E21: 6 | J21: =+C21-E21-F21-G21-H21-I21+D21 -> 24 | K21: 20 | L21: 50
A22: 20 | B22: TELLY(VOX)OTURAK TAHTASI | C22: 458 | H22: 13 | J22: =+C22-E22-F22-G22-H22-I22+D22 -> 445 | K22: 100 | L22: 300
A23: 21 | B23: CARENS MÜDÜR KONT | C23: 125 | H23: 1 | J23: =+C23-E23-F23-G23-H23-I23+D23 -> 124 | K23: 5 | L23: 10
A24: 22 | B24: GRAFTER MÜDÜR | C24: ='KASIM 3 HAFTA '!J24 -> 38 | J24: =+C24-E24-F24-G24-H24-I24+D24 -> 38 | K24: 5 | L24: 10
A25: 23 | B25: GRAFTER MİSAFİR | C25: ='KASIM 3 HAFTA '!J25 -> 7 | J25: =+C25-E25-F25-G25-H25-I25+D25 -> 7 | K25: 5 | L25: 10
A26: 24 | B26: ELNORA -LEGENT MÜDÜR | C26: ='KASIM 3 HAFTA '!J26 -> 223 | J26: =+C26-E26-F26-G26-H26-I26+D26 -> 223 | K26: 100 | L26: 200
A27: 25 | B27: LEGENT MÜDÜR UZUN | C27: ='KASIM 3 HAFTA '!J27 -> 483 | J27: =+C27-E27-F27-G27-H27-I27+D27 -> 483 | K27: 0
A28: 26 | B28: ANFİ TAHTASI | C28: ='KASIM 3 HAFTA '!J28 -> 62 | J28: =+C28-E28-F28-G28-H28-I28+D28 -> 62 | K28: 0
A29: 27 | B29: VEGA SIRT | C29: ='KASIM 3 HAFTA '!J29 -> 13 | J29: =+C29-E29-F29-G29-H29-I29+D29 -> 13 | K29: 0
A30: 28 | B30: VEGA TABAN | C30: ='KASIM 3 HAFTA '!J30 -> 60 | J30: =+C30-E30-F30-G30-H30-I30+D30 -> 60 | K30: 0
A31: 29 | B31: VENESSA MİS.KONTRASI | C31: ='KASIM 3 HAFTA '!J31 -> 0 | J31: =+C31-E31-F31-G31-H31-I31+D31 -> 0 | K31: 0
A32: 30 | B32: POLİ DABAN | C32: 597 | G32: 5 | H32: 50 | J32: =+C32-E32-F32-G32-H32-I32+D32 -> 542 | K32: 200 | L32: 400
A33: 31 | B33: SANDALYE SIRT | C33: ='KASIM 3 HAFTA '!J33 -> 240 | J33: =+C33-E33-F33-G33-H33-I33+D33 -> 240 | K33: 0
A34: 32 | B34: SANDALYE DABAN | C34: ='KASIM 3 HAFTA '!J34 -> 17 | J34: =+C34-E34-F34-G34-H34-I34+D34 -> 17 | K34: 0
A35: 33 | B35: MİSAFİR SIRT | C35: ='KASIM 3 HAFTA '!J35 -> 29 | J35: =+C35-E35-F35-G35-H35-I35+D35 -> 29 | K35: 0
A36: 34 | B36: VİVA DABAN | C36: 533 | J36: =+C36-E36-F36-G36-H36-I36+D36 -> 533 | K36: 0
A37: 35 | B37: SENS MÜDÜR SIRT | C37: 119 | J37: =+C37-E37-F37-G37-H37-I37+D37 -> 119 | K37: 10 | L37: 30
A38: 36 | B38: ZEUGMA | C38: ='KASIM 3 HAFTA '!J38 -> 36 | J38: =+C38-E38-F38-G38-H38-I38+D38 -> 36 | K38: 10 | L38: 20
A39: 37 | B39: SOVRANO MİSAFİR | C39: ='KASIM 3 HAFTA '!J39 -> 24 | J39: =+C39-E39-F39-G39-H39-I39+D39 -> 24 | K39: 10 | L39: 30
A40: 38 | B40: SOVRANO MÜDÜR | C40: 9 | J40: =+C40-E40-F40-G40-H40-I40+D40 -> 9 | K40: 20 | L40: 40
...

Sheet ARALIK 4 HAFTA 
A1: TAHTA SAYIMI | C1: ARALIK.4 HAFTA | L1: 44837
A2: S.NO | B2: CİNSİ | C2: DEVİR | D2: GELEN | E2: 44921 | F2: 44922 | G2: 44923 | H2: 44924 | I2: 44925 | J2: KALAN | K2: MİNİMUN | L2: MAXSİMUN
A3: 1 | B3: SANDALYE TAHTASI | C3: ='KASIM 3 HAFTA '!J3 -> 37 | J3: =+C3-E3-F3-G3-H3-I3+D3 -> 37 | K3: 0
A4: 2 | B4: EKO KLAS MÜDÜR TAHTASI | C4: 0 | J4: =+C4-E4-F4-G4-H4-I4+D4 -> 0 | K4: 0
A5: 3 | B5: KESİLMEMİŞTAHTA | C5: 78 | J5: =+C5-E5-F5-G5-H5-I5+D5 -> 78 | K5: 0
A6: 4 | B6: RECENT MİSAFİR | C6: 94 | J6: =+C6-E6-F6-G6-H6-I6+D6 -> 94 | K6: 30 | L6: 100
A7: 5 | B7: RECENT MÜDÜR | C7: 23 | E7: 4 | I7: 16 | J7: =+C7-E7-F7-G7-H7-I7+D7 -> 3 | K7: 30 | L7: 100
A8: 6 | B8: PUFFY MİSAFİR | C8: 0 | J8: =+C8-E8-F8-G8-H8-I8+D8 -> 0 | K8: 15 | L8: 50
A9: 7 | B9: PUFFY MÜDÜR | C9: 0 | J9: =+C9-E9-F9-G9-H9-I9+D9 -> 0 | K9: 15 | L9: 30
A10: 8 | B10: KESİLMEMİŞ MÜDÜR KON | C10: 5 | J10: =+C10-E10-F10-G10-H10-I10+D10 -> 5 | K10: 0
A11: 9 | B11: CEZAR MÜDÜR | C11: 80 | D11: 62 | J11: =+C11-E11-F11-G11-H11-I11+D11 -> 142 | K11: 150 | L11: 500
A12: 10 | B12: CEZAR MİSAFİR | C12: 442 | J12: =+C12-E12-F12-G12-H12-I12+D12 -> 442 | K12: 200 | L12: 750
A13: 11 | B13: LENUX MİSAFİR | C13: ='KASIM 3 HAFTA '!J13 -> 78 | J13: =+C13-E13-F13-G13-H13-I13+D13 -> 78 | K13: 10 | L13: 30
A14: 12 | B14: LENUX MÜDÜR | C14: ='KASIM 3 HAFTA '!J14 -> 42 | J14: =+C14-E14-F14-G14-H14-I14+D14 -> 42 | K14: 10 | L14: 20
A15: 13 | B15: WARLCOK MÜDÜR | C15: 24 | J15: =+C15-E15-F15-G15-H15-I15+D15 -> 24 | K15: 10 | L15: 20
A16: 14 | B16: WARLCOK MİSAFİR | C16: ='KASIM 3 HAFTA '!J16 -> 0 | J16: =+C16-E16-F16-G16-H16-I16+D16 -> 0 | K16: 10 | L16: 20
A17: 15 | B17: VİSİON MÜDÜR/RETRO | C17: 252 | E17: 9 | F17: 2 | G17: 22 | J17: =+C17-E17-F17-G17-H17-I17+D17 -> 219 | K17: 50 | L17: 200
A18: 16 | B18: VİSİON MİSAFİR | C18: 156 | E18: 10 | G18: 2 | J18: =+C18-E18-F18-G18-H18-I18+D18 -> 144 | K18: 50 | L18: 150
A19: 17 | B19: PENTA MÜDÜR | C19: 80 | F19: 2 | J19: =+C19-E19-F19-G19-H19-I19+D19 -> 78 | K19: 30 | L19: 100
A20: 18 | B20: PENTA MİSAFİR | C20: 56 | J20: =+C20-E20-F20-G20-H20-I20+D20 -> 56 | K20: 30 | L20: 100
A21: 19 | B21: ACTİON MÜDÜR | C21: 24 | G21: 4 | J21: =+C21-E21-F21-G21-H21-I21+D21 -> 20 | K21: 20 | L21: 50
A22: 20 | B22: TELLY(VOX)OTURAK TAHTASI | C22: 445 | J22: =+C22-E22-F22-G22-H22-I22+D22 -> 445 | K22: 100 | L22: 300
A23: 21 | B23: CARENS MÜDÜR KONT | C23: 124 | J23: =+C23-E23-F23-G23-H23-I23+D23 -> 124 | K23: 5 | L23: 10
A24: 22 | B24: GRAFTER MÜDÜR | C24: ='KASIM 3 HAFTA '!J24 -> 38 | J24: =+C24-E24-F24-G24-H24-I24+D24 -> 38 | K24: 5 | L24: 10
A25: 23 | B25: GRAFTER MİSAFİR | C25: ='KASIM 3 HAFTA '!J25 -> 7 | J25: =+C25-E25-F25-G25-H25-I25+D25 -> 7 | K25: 5 | L25: 10
A26: 24 | B26: ELNORA -LEGENT MÜDÜR | C26: ='KASIM 3 HAFTA '!J26 -> 223 | J26: =+C26-E26-F26-G26-H26-I26+D26 -> 223 | K26: 100 | L26: 200
A27: 25 | B27: LEGENT MÜDÜR UZUN | C27: ='KASIM 3 HAFTA '!J27 -> 483 | J27: =+C27-E27-F27-G27-H27-I27+D27 -> 483 | K27: 0
A28: 26 | B28: ANFİ TAHTASI | C28: ='KASIM 3 HAFTA '!J28 -> 62 | J28: =+C28-E28-F28-G28-H28-I28+D28 -> 62 | K28: 0
A29: 27 | B29: VEGA SIRT | C29: ='KASIM 3 HAFTA '!J29 -> 13 | J29: =+C29-E29-F29-G29-H29-I29+D29 -> 13 | K29: 0
A30: 28 | B30: VEGA TABAN | C30: ='KASIM 3 HAFTA '!J30 -> 60 | J30: =+C30-E30-F30-G30-H30-I30+D30 -> 60 | K30: 0
A31: 29 | B31: VENESSA MİS.KONTRASI | C31: ='KASIM 3 HAFTA '!J31 -> 0 | J31: =+C31-E31-F31-G31-H31-I31+D31 -> 0 | K31: 0
A32: 30 | B32: POLİ DABAN | C32: 542 | I32: 10 | J32: =+C32-E32-F32-G32-H32-I32+D32 -> 532 | K32: 200 | L32: 400
A33: 31 | B33: SANDALYE SIRT | C33: ='KASIM 3 HAFTA '!J33 -> 240 | J33: =+C33-E33-F33-G33-H33-I33+D33 -> 240 | K33: 0
